Workbook
Name excelContent: #REF!
Name excelContent: #REF!

Sheet 일별현황_2026
B1: 중소기업 혁신바우처 사업
B2: 원가감리 업무 일별 현황
U4: =TODAY() -> 46189
B5: 기준일 : | C5: =TODAY() -> 46189
B6: 사업연도 | C6: 운영기관 | D6: 2026 | E6: 제출상태 | J6: =TODAY() -> 46189 | L6: 진행중 | M6: 비고
D7: 누계 | E7: 미착수 | F7: 미완료 | G7: 완료 | H7: 세금계산서 발행 (누적) | I7: 취소* | J7: 금일 제출완료 | K7: 금일 신규
B8: 2026년도 (26.01.01 ~ 26.12.31) | C8: 한국산학연협회 (산학연) | D8: =COUNTA('26년 LIST (산학연)'!$C$4:$C$1999) -> 160 | E8: =COUNTIF('26년 LIST (산학연)'!$E$4:$E$1999, "미착수") -> 0 | F8: =COUNTIF('26년 LIST (산학연)'!$E$4:$E$1999, "미완료")+COUNTIF('26년 LIST (산학연)'!$E$4:$E$1999, "금일신규") -> 0 | G8: =COUNTIF('26년 LIST (산학연)'!$E$4:$E$1999, "완료") -> 160 | H8: =COUNTIF('26년 LIST (산학연)'!$J$4:$J$1999,"<>") -> 75 | I8: =COUNTIF('26년 LIST (산학연)'!$E$4:$E$1999, "취소") -> 0 | J8: =COUNTIF('26년 LIST (산학연)'!I:I,TODAY()) -> 4 | K8: =COUNTIF('26년 LIST (산학연)'!H:H,TODAY()) -> 0 | L8: =D8-G8 -> 0 | U8: =G8+L8 -> 160 | V8: =D8=U8 -> TRUE | X8: 진행중=자료수령+금일신규-금일신규中당일완료
C9: (사)한국경영혁신 중소기업협회 (메인비즈) | U9: =G9+L9 -> 0 | V9: =D9=U9 -> TRUE | X9: 진행중=자료수령+금일신규-금일신규中당일완료
C10: 합계 | D10: =SUM(D8:D9) -> 160 | E10: =SUM(E8:E9) -> 0 | F10: =SUM(F8:F9) -> 0 | G10: =SUM(G8:G9) -> 160 | H10: =SUM(H8:H9) -> 75 | I10: =SUM(I8:I9) -> 0 | J10: =SUM(J8:J9) -> 4 | K10: =SUM(K8:K9) -> 0 | L10: =SUM(L8:L9) -> 0 | U10: =G10+L10 -> 160 | V10: =D10=U10 -> TRUE | X10: 진행중=자료수령+금일신규-금일신규中당일완료
B13: 애로사항
C14: ● 해당 없음
B16: 특이사항 | C16: ● 운영기관 산학연: 해당 없음
C17: ● 운영기관 메인비즈: 해당 없음
B20: 자료 보완요청
C21: ● 해당 없음
B23: 검 토 | C23: ●업체 제출 사업비 기준 8천만원 초과: 김민선 원장 5천만원 초과~8천만원 이하: 하은정 이사 5천만원 이하: 담당자 | I23: ●요청자료 검토방법: 플랫폼에 신규 건 올라오면 담당자 확인 후 추가 자료 요청
I24: ●검토라인 순서 지킬 것 (담당자 → 하은정 이사 → 품질관리실 → 김민선 원장)
I25: ●원장님께 검토 올릴 시, 수행계획서·견적서 등 증빙자료 출력해가기
B27: ○ 연간 진행현황 | I27: (단위: 건) | L27: 1. 한국산학협회(최혜리 연구원 / 044-410-3334)
B28: 원가감리기관 | C28: 운영기관 | D28: 2021 | F28: 2022 | G28: 2023~2024 | H28: 2025 | I28: 2026 | J28: 합계 | L28: - 모집완료, 5월 중 감리 요청 시작 예정
B29: (사)한국경영분석연구원 | C29: 한국산학연협회 | D29: - | F29: - | G29: - | H29: 336 | I29: =D8 -> 160 | J29: =SUM(D29:H29) -> 336 | L29: - 기업별 서류 준비시기 상이하여 나눠서 감리 요청 예상
C30: (사)한국경영혁신중소기업협회 | D30: 35 | F30: 604 | G30: 895 | H30: 355 | I30: =D9 -> 0 | J30: =SUM(D30:H30) -> 1889 | L30: 2. 메인비즈 협회(유원석 과장 / 02-2230-2112)
B31: (재)21세기경제연구소 | C31: 한국산학연협회 | D31: 52 | F31: 506 | G31: 519 | H31: - | I31: - | J31: =SUM(D31:H31) -> 1077 | L31: - 2026년도 운영기관 참여중
B32: 연간 합계 | D32: =SUM(D29:D31) -> 87 | F32: =SUM(F29:F31) -> 1110 | G32: =SUM(G29:G31) -> 1414 | H32: =SUM(H29:H31) -> 691 | I32: =SUM(I29:I31) -> 160 | J32: =SUM(J29:J31) -> 3302 | L32: - 중진고에서 운영기관 두 곳이 몰려 감리 요청시 마감 일정이 촉박하여 운영기관 별로 나우어 감리 요청으로 2026년도 메인비즈는 타연구원에 의뢰
B33: 주1) 2023~2024년은 계약기간 중 산학연 자체 플랫폼 사용으로 변경, 타 기관 일부만 집계됨
B34: 주2) 2023년~2024년은 계약서 1건으로 진행. 23년도 진행현황파일에 합산하여 정리

Sheet 26년 LIST (산학연)
B1: □ 26년 중소기업 혁신 바우처사업 원가감리 현황 회신요청 (한국산학연 협회(산학연)) | O1: https://mssmiv.com/portal/Main
B2: *파란칠: 감액
B3: 연번 | C3: 수요기업 | D3: 수행기관 | E3: system 현황 | F3: 총 투입공수 (HR) | G3: 최종 작성자 | H3: 의뢰일 | I3: 제출일 | J3: 대금청구일 | K3: 입금일 | L3: 자료누락여부 | M3: 특이사항 | N3: Prog.분류
A4: 1 | B4: 1 | C4: ㈜태린 | D4: ㈜리드경영기술원 | E4: 완료 | J4: 46120 | O4: =CONCATENATE(B4,". ",C4,"_",D4) -> 1. ㈜태린_㈜리드경영기술원
A5: 1 | B5: =B4+1 -> 2 | C5: 주식회사 인투앱 | D5: ㈜포어스딜라이트 | E5: 완료 | J5: 46120 | O5: =CONCATENATE(B5,". ",C5,"_",D5) -> 2. 주식회사 인투앱_㈜포어스딜라이트
A6: 1 | B6: =B5+1 -> 3 | C6: 사천편백림 | D6: 주식회사 대동씨엠씨 | E6: 완료 | J6: 46120 | O6: =CONCATENATE(B6,". ",C6,"_",D6) -> 3. 사천편백림_주식회사 대동씨엠씨
A7: 1 | B7: =B6+1 -> 4 | C7: ㈜라온솔루션 | D7: 주식회사 샘플피씨비 | E7: 완료 | J7: 46120 | L7: 자료없음 | O7: =CONCATENATE(B7,". ",C7,"_",D7) -> 4. ㈜라온솔루션_주식회사 샘플피씨비
A8: 1 | B8: =B7+1 -> 5 | C8: 씨엠아이주식회사 | D8: 주식회사 샘플피씨비 | E8: 완료 | J8: 46120 | O8: =CONCATENATE(B8,". ",C8,"_",D8) -> 5. 씨엠아이주식회사_주식회사 샘플피씨비
A9: 1 | B9: =B8+1 -> 6 | C9: 주식회사 아성정공 | D9: 제이디엘(JDL) | E9: 완료 | J9: 46120 | L9: 자료없음 | O9: =CONCATENATE(B9,". ",C9,"_",D9) -> 6. 주식회사 아성정공_제이디엘(JDL)
A10: 1 | B10: =B9+1 -> 7 | C10: (주)태성이엠씨 | D10: ㈜우영실업 | E10: 완료 | J10: 46120 | L10: 자료없음 | O10: =CONCATENATE(B10,". ",C10,"_",D10) -> 7. (주)태성이엠씨_㈜우영실업
A11: 1 | B11: =B10+1 -> 8 | C11: 프로인 주식회사 | D11: ㈜크레탐 | E11: 완료 | J11: 46120 | L11: 자료없음 | O11: =CONCATENATE(B11,". ",C11,"_",D11) -> 8. 프로인 주식회사_㈜크레탐
A12: 1 | B12: =B11+1 -> 9 | C12: 힐링스 | D12: ㈜포어스딜라이트 | E12: 완료 | J12: 46120 | L12: 자료없음 | O12: =CONCATENATE(B12,". ",C12,"_",D12) -> 9. 힐링스_㈜포어스딜라이트
A13: 1 | B13: =B12+1 -> 10 | C13: 삼화메디칼 | D13: ㈜루트아이템 | E13: 완료 | J13: 46120 | L13: 자료없음 | O13: =CONCATENATE(B13,". ",C13,"_",D13) -> 10. 삼화메디칼_㈜루트아이템
A14: 1 | B14: =B13+1 -> 11 | C14: ㈜소닉랩 | D14: 이에스플러스 | E14: 완료 | J14: 46120 | O14: =CONCATENATE(B14,". ",C14,"_",D14) -> 11. ㈜소닉랩_이에스플러스
A15: 1 | B15: =B14+1 -> 12 | C15: 주식회사 알파큐 | D15: 주식회사 로맨 | E15: 완료 | J15: 46120 | O15: =CONCATENATE(B15,". ",C15,"_",D15) -> 12. 주식회사 알파큐_주식회사 로맨
A16: 1 | B16: =B15+1 -> 13 | C16: 유니스파테크 주식회사 | D16: 주식회사 큐네스글로벌(QNES Global) | E16: 완료 | J16: 46120 | O16: =CONCATENATE(B16,". ",C16,"_",D16) -> 13. 유니스파테크 주식회사_주식회사 큐네스글로벌(QNES Global)
A17: 1 | B17: =B16+1 -> 14 | C17: 주식회사 브러쉬포유 | D17: 이에스플러스 | E17: 완료 | J17: 46120 | O17: =CONCATENATE(B17,". ",C17,"_",D17) -> 14. 주식회사 브러쉬포유_이에스플러스
A18: 1 | B18: =B17+1 -> 15 | C18: ㈜제이스 | D18: 온플러스 | E18: 완료 | J18: 46120 | O18: =CONCATENATE(B18,". ",C18,"_",D18) -> 15. ㈜제이스_온플러스
A19: 1 | B19: =B18+1 -> 16 | C19: ㈜성심메디케어 | D19: ㈜코엔 | E19: 완료 | J19: 46120 | O19: =CONCATENATE(B19,". ",C19,"_",D19) -> 16. ㈜성심메디케어_㈜코엔
A20: 1 | B20: =B19+1 -> 17 | C20: ㈜뉴돈테크 | D20: ㈜네이카 | E20: 완료 | J20: 46120 | L20: 자료없음 | O20: =CONCATENATE(B20,". ",C20,"_",D20) -> 17. ㈜뉴돈테크_㈜네이카
A21: 1 | B21: =B20+1 -> 18 | C21: 지니스㈜ | D21: ㈜포디믹스 | E21: 완료 | J21: 46120 | L21: 자료없음 | O21: =CONCATENATE(B21,". ",C21,"_",D21) -> 18. 지니스㈜_㈜포디믹스
A22: 1 | B22: =B21+1 -> 19 | C22: 대영금형정공사 | D22: ㈜포디믹스 | E22: 완료 | J22: 46120 | L22: 자료없음 | O22: =CONCATENATE(B22,". ",C22,"_",D22) -> 19. 대영금형정공사_㈜포디믹스
A23: 1 | B23: =B22+1 -> 20 | C23: ㈜에이티홀딩스 | D23: ㈜포디믹스 | E23: 완료 | J23: 46120 | L23: 자료없음 | O23: =CONCATENATE(B23,". ",C23,"_",D23) -> 20. ㈜에이티홀딩스_㈜포디믹스
A24: 1 | B24: =B23+1 -> 21 | C24: ㈜엡스코어 | D24: ㈜이앤비솔루션 | E24: 완료 | J24: 46120 | L24: 자료없음 | O24: =CONCATENATE(B24,". ",C24,"_",D24) -> 21. ㈜엡스코어_㈜이앤비솔루션
A25: 1 | B25: =B24+1 -> 22 | C25: ㈜포러스젠 | D25: ㈜씨넷 | E25: 완료 | J25: 46120 | L25: 자료없음 | O25: =CONCATENATE(B25,". ",C25,"_",D25) -> 22. ㈜포러스젠_㈜씨넷
A26: 1 | B26: =B25+1 -> 23 | C26: 이레테크 | D26: 온플러스 | E26: 완료 | J26: 46120 | L26: 자료없음 | O26: =CONCATENATE(B26,". ",C26,"_",D26) -> 23. 이레테크_온플러스
A27: 1 | B27: =B26+1 -> 24 | C27: 한빛이노텍 | D27: ㈜쓰리디플러스 | E27: 완료 | J27: 46120 | O27: =CONCATENATE(B27,". ",C27,"_",D27) -> 24. 한빛이노텍_㈜쓰리디플러스
A28: 1 | B28: =B27+1 -> 25 | C28: ㈜맨엔텔 | D28: ㈜하다 | E28: 완료 | J28: 46120 | L28: 자료없음 | O28: =CONCATENATE(B28,". ",C28,"_",D28) -> 25. ㈜맨엔텔_㈜하다
A29: 1 | B29: =B28+1 -> 26 | C29: 노바센㈜ | D29: ㈜크레탐 | E29: 완료 | J29: 46120 | L29: 자료없음 | O29: =CONCATENATE(B29,". ",C29,"_",D29) -> 26. 노바센㈜_㈜크레탐
A30: 1 | B30: =B29+1 -> 27 | C30: ㈜엑스오컴퍼니 | D30: ㈜이엘엠디 | E30: 완료 | J30: 46120 | L30: 자료없음 | O30: =CONCATENATE(B30,". ",C30,"_",D30) -> 27. ㈜엑스오컴퍼니_㈜이엘엠디
A31: 1 | B31: =B30+1 -> 28 | C31: ㈜엠티에스 | D31: ㈜파인에스텍 | E31: 완료 | J31: 46120 | L31: 자료없음 | O31: =CONCATENATE(B31,". ",C31,"_",D31) -> 28. ㈜엠티에스_㈜파인에스텍
A32: 1 | B32: =B31+1 -> 29 | C32: ㈜엘에이치바이오메드 | D32: ㈜파인디자인 | E32: 완료 | J32: 46120 | L32: 자료없음 | O32: =CONCATENATE(B32,". ",C32,"_",D32) -> 29. ㈜엘에이치바이오메드_㈜파인디자인
A33: 1 | B33: =B32+1 -> 30 | C33: 메디칼리서치 | D33: 한일정밀화학 | E33: 완료 | J33: 46120 | O33: =CONCATENATE(B33,". ",C33,"_",D33) -> 30. 메디칼리서치_한일정밀화학
A34: 1 | B34: =B33+1 -> 31 | C34: 농업회사법인 주식회사 드레스푸드 | D34: 유니드 | E34: 완료 | J34: 46120 | O34: =CONCATENATE(B34,". ",C34,"_",D34) -> 31. 농업회사법인 주식회사 드레스푸드_유니드
A35: 1 | B35: =B34+1 -> 32 | C35: 굿라이프 | D35: 온플러스 | E35: 완료 | J35: 46120 | O35: =CONCATENATE(B35,". ",C35,"_",D35) -> 32. 굿라이프_온플러스
A36: 1 | B36: =B35+1 -> 33 | C36: 주식회사 시어니스트 | D36: ㈜아주화장품 | E36: 완료 | J36: 46120 | O36: =CONCATENATE(B36,". ",C36,"_",D36) -> 33. 주식회사 시어니스트_㈜아주화장품
A37: 1 | B37: =B36+1 -> 34 | C37: ㈜셀드로우 | D37: 주식회사 로맨 | E37: 완료 | J37: 46120 | O37: =CONCATENATE(B37,". ",C37,"_",D37) -> 34. ㈜셀드로우_주식회사 로맨
A38: 1 | B38: =B37+1 -> 35 | C38: ㈜화진몰테크 | D38: ㈜우영실업 | E38: 완료 | J38: 46120 | O38: =CONCATENATE(B38,". ",C38,"_",D38) -> 35. ㈜화진몰테크_㈜우영실업
A39: 1 | B39: =B38+1 -> 36 | C39: ㈜대광에프앤지 | D39: 씨에프티 유한책임회사 | E39: 완료 | J39: 46120 | O39: =CONCATENATE(B39,". ",C39,"_",D39) -> 36. ㈜대광에프앤지_씨에프티 유한책임회사
A40: 1 | B40: =B39+1 -> 37 | C40: ㈜레피오 | D40: 온플러스 | E40: 완료 | J40: 46120 | L40: 자료없음 | O40: =CONCATENATE(B40,". ",C40,"_",D40) -> 37. ㈜레피오_온플러스
...

Sheet 수행
A1: 전체 수주현황
H2: (단위 : 건, 원)
A3: 구분 | B3: 2024년 미제출분 (12월 의뢰) | D3: 2025년 | F3: 24.12~2025 | H3: 비고
B4: 건수 | C4: 금액 | D4: 건수 | E4: 금액 | F4: 건수 | G4: 금액 | J4: 기준일
A5: 신규 | B5: =COUNTIFS(#REF!,"<"&수행!$J$5,#REF!,$A$5)+COUNTIFS(#REF!,"<="&수행!$J$5,#REF!,"자료수령") -> #REF! | C5: =B5*100000 -> #REF! | D5: =COUNTIFS(#REF!,">="&수행!$J$5,#REF!,수행!$A5)+COUNTIFS(#REF!,">="&수행!$J$5,#REF!,"자료수령") -> #REF! | E5: =D5*100000 -> #REF! | F5: =B5+D5 -> #REF! | G5: =C5+E5 -> #REF! | H5: 자료수령포함 | J5: 46023
A6: 완료 | B6: =COUNTIFS(#REF!,"<"&수행!$J$5,#REF!,수행!$A6) -> #REF! | C6: =B6*100000 -> #REF! | D6: =COUNTIFS(#REF!,">="&수행!$J$5,#REF!,수행!$A6) -> #REF! | E6: =D6*100000 -> #REF! | F6: =B6+D6 -> #REF! | G6: =C6+E6 -> #REF!
A7: 취소 | B7: =COUNTIFS(#REF!,"<"&수행!$J$5,#REF!,수행!$A7) -> #REF! | C7: =B7*100000 -> #REF! | D7: =COUNTIFS(#REF!,">="&수행!$J$5,#REF!,수행!$A7) -> #REF! | E7: =D7*100000 -> #REF! | F7: =B7+D7 -> #REF! | G7: =C7+E7 -> #REF!
A8: 합계 | B8: =SUM(B5:B7) -> #REF! | C8: =SUM(C5:C7) -> #REF! | D8: =SUM(D5:D7) -> #REF! | E8: =SUM(E5:E7) -> #REF! | F8: =SUM(F5:F7) -> #REF! | G8: =SUM(G5:G7) -> #REF!
A9: 수주건수 및 금액 | B9: =SUM(B8-B7) -> #REF! | C9: =SUM(C8-C7) -> #REF! | D9: =SUM(D8-D7) -> #REF! | E9: =SUM(E8-E7) -> #REF! | F9: =SUM(F8-F7) -> #REF! | G9: =SUM(G8-G7) -> #REF! | H9: 취소 제외
A11: 인원별 수행금액 집계표(완료건에 한함)
H12: (단위 : 건, 원)
A13: 구분 | B13: 2024년 미제출분 (12월 의뢰) | D13: 2026년 | H13: 비고
B14: 건수 | C14: 금액 | D14: 건수 | E14: 금액
A15: 김용전 | B15: =COUNTIFS(#REF!,"<"&수행!$J$5,#REF!,수행!$A15,#REF!,"완료") -> #REF! | C15: =B15*100000 -> #REF! | D15: =COUNTIFS(#REF!,">="&수행!$J$5,#REF!,수행!$A15,#REF!,"완료") -> #REF! | E15: =D15*100000 -> #REF!
B16: =COUNTIFS(#REF!,"<"&수행!$J$5,#REF!,수행!$A16,#REF!,"완료") -> #REF! | C16: =B16*100000 -> #REF! | D16: =COUNTIFS(#REF!,">="&수행!$J$5,#REF!,수행!$A16,#REF!,"완료") -> #REF! | E16: =D16*100000 -> #REF!
B17: =COUNTIFS(#REF!,"<"&수행!$J$5,#REF!,수행!$A17,#REF!,"완료") -> #REF! | C17: =B17*100000 -> #REF! | D17: =COUNTIFS(#REF!,">="&수행!$J$5,#REF!,수행!$A17,#REF!,"완료") -> #REF! | E17: =D17*100000 -> #REF!
B18: =B6-B15-B16-B17 -> #REF! | C18: =B18*100000 -> #REF! | D18: =D6-D15-D16 -> #REF! | E18: =D18*100000 -> #REF!
A19: 합계 | B19: =SUM(B15:B18) -> #REF! | C19: =SUM(C15:C18) -> #REF! | D19: =SUM(D15:D18) -> #REF! | E19: =SUM(E15:E18) -> #REF!

Sheet 도장, prg
F8: 결 재 | G8: 담당 | I8: 검토 | K8: 이사 | M8: 원장
G9: 김나경
G14: =TODAY() -> 46189
P16: 프로그램별 건수 분류
R17: 메인비즈 | S17: 산학연
P18: 일반 | Q18: 시제품제작 (정부한도 : 3천만원) | R18: =COUNTIF('26년 LIST (산학연)'!$N:$N,"일제") -> 0 | S18: =COUNTIF('26년 LIST (산학연)'!$N:$N,"일제") -> 0
Q19: 시스템 및 시설구축 (정부한도 : 2천만원) | R19: =COUNTIF('26년 LIST (산학연)'!$N:$N,"일구") -> 0 | S19: =COUNTIF('26년 LIST (산학연)'!$N:$N,"일구") -> 0
P20: 일반 계 | R20: =SUM(R18:R19) -> 0 | S20: =SUM(S18:S19) -> 0
P21: 탄소 | Q21: 시제품제작 (정부한도 : 5천만원) | R21: =COUNTIF('26년 LIST (산학연)'!$N:$N,"탄제") -> 0 | S21: =COUNTIF('26년 LIST (산학연)'!$N:$N,"탄제") -> 0
Q22: 에너지 효율 향상 시스템 및 시설구축 (정부한도 : 5천만원) | R22: =COUNTIF('26년 LIST (산학연)'!$N:$N,"탄구") -> 0 | S22: =COUNTIF('26년 LIST (산학연)'!$N:$N,"탄구") -> 0
P23: 탄소 계 | R23: =SUM(R21:R22) -> 0 | S23: =SUM(S21:S22) -> 0
P24: 누계 | R24: =R20+R23 -> 0 | S24: =S20+S23 -> 0
P25: ※ 지역별 특화산업 육성 및 현안해결 등의 사업목적 달성을 위한 총괄기관의 방침이 있을 경우 한시적으로 프로그램을 신설하거나 프로그램별 한도를 조정하여 운영할 수 있다. -['26.01.] 2026년_중소기업_혁신바우처사업_운영지침 6페이지 발췌

Sheet 담당자 연락처
B2: 구분 | D2: 이름 | E2: 직책 | F2: 전화번호 | G2: 이메일 | H2: 담당업무
B3: 운영기관 | C3: 메인비즈 | D3: 김한나 | E3: 과장 | F3: 02-2230-2157 | G3: khn37@mainbiz.or.kr | H3: 3자 협약 (원가감리 단계 포함)
B4: 운영기관 | C4: 산학연 | D4: 문지한 | E4: 선임 | F4: 044-410-3333 (010-6403-3207) | G4: mun@auri.go.kr voucher@auri.go.kr | H4: 3자 협약 (원가감리 단계 포함)
B5: 플랫폼 | C5: 퓨테크 | D5: 송석환 | E5: 과장 | F5: 02-735-2450 | G5: shsong@futechsoft.com | H5: 플랫폼 사용에 관한 응대 (오류 개선 요청 등이 있을 때 연락)
B6: 플랫폼 | C6: 퓨테크 | E6: 대리 | F6: 010-3939-6771 | G6: (과장님 연차일 때 연락)

Sheet 진행상황표
B1: <진행상황표> | V1: 구분 | W1: 김기태 | X1: 지승연 | Y1: 김연아
N2: 신규(수행계획서 수령 및 견적요청) | Q2: 0.1 | V2: 진행중 | W2: =COUNTIFS($B:$B,$V2,$Q:$Q,W$1) -> 0 | X2: =COUNTIFS($B:$B,$V2,$Q:$Q,X$1) -> 6 | Y2: =COUNTIFS($B:$B,$V2,$Q:$Q,Y$1) -> 0
N3: 견적서 수령(자료 다운) | Q3: 0.4 | V3: 완료 | W3: =COUNTIFS($B:$B,$V3,$Q:$Q,W$1) -> 0 | X3: =COUNTIFS($B:$B,$V3,$Q:$Q,X$1) -> 1 | Y3: =COUNTIFS($B:$B,$V3,$Q:$Q,Y$1) -> 0
N4: 검토 후 보완요청 완료 | Q4: 0.6
N5: 보고서 작성(감리 전) | Q5: 0.8
N6: 보고서 제출 | Q6: 0.95
B7: <메인비즈>
B8: ="○ 완료 : "&COUNTIF($B11:$B28,"완료")&"건, 진행중: "&COUNTIF($B11:$B28,"진행중")&"건" -> ○ 완료 : 1건, 진행중: 17건 | J8: =TODAY() -> 46189 | V8: 완료건->맨 위로
A9: # | B9: 구분 | C9: 폴더 번호 | D9: 수요기업 | E9: 수행기관 | F9: 의뢰일 | G9: 예상완료일 | H9: 진행상황 | I9: 일일 투입시간(h) | J9: 누적시간 (h) | K9: 現진행률 | L9: 진행률(%)별 수행일자 | Q9: 담당 | R9: 윤세준 | S9: 검토담당 | T9: 전날 누적 (값 복사) | V9: 60
B10: 구분 | C10: 폴더 번호 | D10: 수요기업 | E10: 수행기관 | F10: 의뢰일 | G10: 예상완료일 | H10: 진행상황 | I10: 일일 투입시간(h) | J10: 누적시간 (h) | K10: 現진행률 | L10: 0.1 | M10: 0.4 | N10: 0.6 | O10: 0.8 | P10: 0.95 | R10: 당일 | S10: 당일
B11: 진행중 | C11: 67 | D11: =VLOOKUP($C11,#REF!,2,FALSE) -> #REF! | E11: =VLOOKUP($C11,#REF!,3,FALSE) -> #REF! | F11: =VLOOKUP(C11,#REF!,7,FALSE) -> #REF! | G11: 45762 | H11: 비비에 기재 | J11: =I11+T11 -> 0.8 | K11: 0.6 | N11: 4.15 | Q11: 지승연 | T11: 0.8 | U11: =VLOOKUP(C11,#REF!, 12, FALSE) -> #REF!
B12: 진행중 | C12: 68 | D12: =VLOOKUP($C12,#REF!,2,FALSE) -> #REF! | E12: =VLOOKUP($C12,#REF!,3,FALSE) -> #REF! | F12: =VLOOKUP(C12,#REF!,7,FALSE) -> #REF! | G12: 45762 | H12: 비비에 기재 | J12: =I12+T12 -> 0.9 | K12: 0.6 | N12: 4.15 | Q12: 지승연 | T12: 0.9 | U12: =VLOOKUP(C12,#REF!, 12, FALSE) -> #REF!
B13: 진행중 | C13: 69 | D13: =VLOOKUP($C13,#REF!,2,FALSE) -> #REF! | E13: =VLOOKUP($C13,#REF!,3,FALSE) -> #REF! | F13: =VLOOKUP(C13,#REF!,7,FALSE) -> #REF! | G13: 45762 | H13: 비비에 기재 | J13: =I13+T13 -> 0.7 | K13: 0.6 | N13: 4.15 | Q13: 지승연 | T13: 0.7 | U13: =VLOOKUP(C13,#REF!, 12, FALSE) -> #REF!
B14: 진행중 | C14: 70 | D14: =VLOOKUP($C14,#REF!,2,FALSE) -> #REF! | E14: =VLOOKUP($C14,#REF!,3,FALSE) -> #REF! | F14: =VLOOKUP(C14,#REF!,7,FALSE) -> #REF! | G14: 45762 | H14: 비비에 기재 | J14: =I14+T14 -> 1 | K14: 0.4 | L14: 4.15 | M14: 4.15 | Q14: 지승연 | T14: 1 | U14: =VLOOKUP(C14,#REF!, 12, FALSE) -> #REF!
B15: 완료 | C15: 72 | D15: =VLOOKUP($C15,#REF!,2,FALSE) -> #REF! | E15: =VLOOKUP($C15,#REF!,3,FALSE) -> #REF! | F15: =VLOOKUP(C15,#REF!,7,FALSE) -> #REF! | G15: 45762 | H15: 비비에 기재 | J15: =I15+T15 -> 2 | K15: 0.95 | L15: 4.15 | M15: 4.15 | Q15: 지승연 | T15: 2 | U15: =VLOOKUP(C15,#REF!, 12, FALSE) -> #REF!
B16: 진행중 | C16: 78 | D16: =VLOOKUP($C16,#REF!,2,FALSE) -> #REF! | E16: =VLOOKUP($C16,#REF!,3,FALSE) -> #REF! | F16: =VLOOKUP(C16,#REF!,7,FALSE) -> #REF! | G16: 45762 | H16: 비비에 기재 | J16: =I16+T16 -> 0 | K16: 0.4 | T16: 0 | U16: =VLOOKUP(C16,#REF!, 12, FALSE) -> #REF!
B17: 진행중 | C17: 79 | D17: =VLOOKUP($C17,#REF!,2,FALSE) -> #REF! | E17: =VLOOKUP($C17,#REF!,3,FALSE) -> #REF! | F17: =VLOOKUP(C17,#REF!,7,FALSE) -> #REF! | G17: 45772 | H17: 비비에 기재 | J17: =I17+T17 -> 0 | T17: 0 | U17: =VLOOKUP(C17,#REF!, 12, FALSE) -> #REF!
B18: 진행중 | C18: 80 | D18: =VLOOKUP($C18,#REF!,2,FALSE) -> #REF! | E18: =VLOOKUP($C18,#REF!,3,FALSE) -> #REF! | F18: =VLOOKUP(C18,#REF!,7,FALSE) -> #REF! | G18: 45772 | H18: 비비에 기재 | J18: =I18+T18 -> 0 | T18: 0 | U18: =VLOOKUP(C18,#REF!, 12, FALSE) -> #REF!
B19: 진행중 | C19: 81 | D19: =VLOOKUP($C19,#REF!,2,FALSE) -> #REF! | E19: =VLOOKUP($C19,#REF!,3,FALSE) -> #REF! | F19: =VLOOKUP(C19,#REF!,7,FALSE) -> #REF! | G19: 45772 | H19: 비비에 기재 | J19: =I19+T19 -> 0 | T19: 0 | U19: =VLOOKUP(C19,#REF!, 12, FALSE) -> #REF!
B20: 진행중 | C20: 82 | D20: =VLOOKUP($C20,#REF!,2,FALSE) -> #REF! | E20: =VLOOKUP($C20,#REF!,3,FALSE) -> #REF! | F20: =VLOOKUP(C20,#REF!,7,FALSE) -> #REF! | G20: 45772 | H20: 비비에 기재 | J20: =I20+T20 -> 0 | T20: 0 | U20: =VLOOKUP(C20,#REF!, 12, FALSE) -> #REF!
B21: 진행중 | C21: 83 | D21: =VLOOKUP($C21,#REF!,2,FALSE) -> #REF! | E21: =VLOOKUP($C21,#REF!,3,FALSE) -> #REF! | F21: =VLOOKUP(C21,#REF!,7,FALSE) -> #REF! | G21: 45772 | H21: 비비에 기재 | J21: =I21+T21 -> 0 | T21: 0 | U21: =VLOOKUP(C21,#REF!, 12, FALSE) -> #REF!
B22: 진행중 | C22: 84 | D22: =VLOOKUP($C22,#REF!,2,FALSE) -> #REF! | E22: =VLOOKUP($C22,#REF!,3,FALSE) -> #REF! | F22: =VLOOKUP(C22,#REF!,7,FALSE) -> #REF! | G22: 45772 | H22: 비비에 기재 | J22: =I22+T22 -> 0 | T22: 0 | U22: =VLOOKUP(C22,#REF!, 12, FALSE) -> #REF!
B23: 진행중 | C23: 85 | D23: =VLOOKUP($C23,#REF!,2,FALSE) -> #REF! | E23: =VLOOKUP($C23,#REF!,3,FALSE) -> #REF! | F23: =VLOOKUP(C23,#REF!,7,FALSE) -> #REF! | G23: 45772 | H23: 비비에 기재 | J23: =I23+T23 -> 0 | T23: 0 | U23: =VLOOKUP(C23,#REF!, 12, FALSE) -> #REF!
B24: 진행중 | C24: 86 | D24: =VLOOKUP($C24,#REF!,2,FALSE) -> #REF! | E24: =VLOOKUP($C24,#REF!,3,FALSE) -> #REF! | F24: =VLOOKUP(C24,#REF!,7,FALSE) -> #REF! | G24: 45772 | H24: 비비에 기재 | J24: =I24+T24 -> 0 | T24: 0 | U24: =VLOOKUP(C24,#REF!, 12, FALSE) -> #REF!
B25: 진행중 | C25: 87 | D25: =VLOOKUP($C25,#REF!,2,FALSE) -> #REF! | E25: =VLOOKUP($C25,#REF!,3,FALSE) -> #REF! | F25: =VLOOKUP(C25,#REF!,7,FALSE) -> #REF! | G25: 45772 | H25: 신규 확인만 | J25: =I25+T25 -> 0 | T25: 0 | U25: =VLOOKUP(C25,#REF!, 12, FALSE) -> #REF!
B26: 진행중 | C26: 88 | D26: =VLOOKUP($C26,#REF!,2,FALSE) -> #REF! | E26: =VLOOKUP($C26,#REF!,3,FALSE) -> #REF! | F26: =VLOOKUP(C26,#REF!,7,FALSE) -> #REF! | G26: 45772 | H26: 신규 확인만 | J26: =I26+T26 -> 0 | T26: 0 | U26: =VLOOKUP(C26,#REF!, 12, FALSE) -> #REF!
B27: 진행중 | C27: 89 | D27: =VLOOKUP($C27,#REF!,2,FALSE) -> #REF! | E27: =VLOOKUP($C27,#REF!,3,FALSE) -> #REF! | F27: =VLOOKUP(C27,#REF!,7,FALSE) -> #REF! | G27: 45772 | H27: 신규 확인만 | J27: =I27+T27 -> 0 | T27: 0 | U27: =VLOOKUP(C27,#REF!, 12, FALSE) -> #REF!
B28: 진행중 | C28: 90 | D28: =VLOOKUP($C28,#REF!,2,FALSE) -> #REF! | E28: =VLOOKUP($C28,#REF!,3,FALSE) -> #REF! | F28: =VLOOKUP(C28,#REF!,7,FALSE) -> #REF! | G28: 45772 | H28: 신규 확인만 | J28: =I28+T28 -> 0 | T28: 0 | U28: =VLOOKUP(C28,#REF!, 12, FALSE) -> #REF!
S29: =SUM(#REF!) -> #REF! | U29: =SUM(#REF!) -> #REF!
B30: <산학연>
B31: ="○ 완료 : "&COUNTIF($B34:$B930,"완료")&"건, 진행중: "&COUNTIF($B34:$B930,"진행중")&"건" -> ○ 완료 : 1건, 진행중: 19건 | J31: =TODAY() -> 46189
B32: 구분 | C32: 폴더 번호 | D32: 수요기업 | E32: 수행기관 | F32: 의뢰일 | G32: 예상완료일 | H32: 진행상황 | I32: 일일 투입시간(h) | J32: 누적시간 (h) | K32: 現진행률 | L32: 진행률(%)별 수행일자 | Q32: 담당 | R32: 윤세준 | S32: 검토담당 | T32: 전날 누적 (값 복사)
L33: 0.1 | M33: 0.4 | N33: 0.6 | O33: 0.8 | P33: 0.95 | R33: 당일 | S33: 당일
B34: 진행중 | C34: 33 | D34: =VLOOKUP($C34,'26년 LIST (산학연)'!$B:$H,2,FALSE) -> 주식회사 시어니스트 | E34: =VLOOKUP($C34,'26년 LIST (산학연)'!$B:$H,3,FALSE) -> ㈜아주화장품 | F34: =VLOOKUP(C34,'26년 LIST (산학연)'!$B:$H,7,FALSE) -> 0 | G34: 45762 | H34: 비비에 기재 | J34: =I34+T34 -> 1 | K34: 0.6 | N34: 4.15 | Q34: 지승연 | T34: 1 | U34: =VLOOKUP(C34,'26년 LIST (산학연)'!$B:$N, 12, FALSE) -> 0
B35: 완료 | C35: 55 | D35: =VLOOKUP($C35,'26년 LIST (산학연)'!$B:$H,2,FALSE) -> 에이치에스테크㈜ | E35: =VLOOKUP($C35,'26년 LIST (산학연)'!$B:$H,3,FALSE) -> ㈜케이엠씨(KMC) | F35: =VLOOKUP(C35,'26년 LIST (산학연)'!$B:$H,7,FALSE) -> 0 | G35: 45762 | H35: 비비에 기재 | I35: 0.5 | J35: =I35+T35 -> 0.5 | K35: 0.95 | T35: 0 | U35: =VLOOKUP(C35,'26년 LIST (산학연)'!$B:$N, 12, FALSE) -> 0
B36: 진행중 | C36: 36 | D36: =VLOOKUP($C36,'26년 LIST (산학연)'!$B:$H,2,FALSE) -> ㈜대광에프앤지 | E36: =VLOOKUP($C36,'26년 LIST (산학연)'!$B:$H,3,FALSE) -> 씨에프티 유한책임회사 | F36: =VLOOKUP(C36,'26년 LIST (산학연)'!$B:$H,7,FALSE) -> 0 | G36: 45762 | H36: 비비에 기재 | J36: =I36+T36 -> 0.5 | K36: 0.4 | L36: 4.15 | Q36: 지승연 | T36: 0.5 | U36: =VLOOKUP(C36,'26년 LIST (산학연)'!$B:$N, 12, FALSE) -> 0
B37: 진행중 | C37: 40 | D37: =VLOOKUP($C37,'26년 LIST (산학연)'!$B:$H,2,FALSE) -> ㈜클린존 | E37: =VLOOKUP($C37,'26년 LIST (산학연)'!$B:$H,3,FALSE) -> ㈜씨넷 | F37: =VLOOKUP(C37,'26년 LIST (산학연)'!$B:$H,7,FALSE) -> 0 | G37: 45762 | H37: 비비에 기재 | J37: =I37+T37 -> 1 | T37: 1 | U37: =VLOOKUP(C37,'26년 LIST (산학연)'!$B:$N, 12, FALSE) -> 0
B38: 진행중 | C38: 41 | D38: =VLOOKUP($C38,'26년 LIST (산학연)'!$B:$H,2,FALSE) -> 주식회사 티나 | E38: =VLOOKUP($C38,'26년 LIST (산학연)'!$B:$H,3,FALSE) -> 주식회사 제이솔루션 | F38: =VLOOKUP(C38,'26년 LIST (산학연)'!$B:$H,7,FALSE) -> 0 | G38: 45762 | H38: 비비에 기재 | J38: =I38+T38 -> 1.5 | T38: 1.5 | U38: =VLOOKUP(C38,'26년 LIST (산학연)'!$B:$N, 12, FALSE) -> 0
B39: 진행중 | C39: 45 | D39: =VLOOKUP($C39,'26년 LIST (산학연)'!$B:$H,2,FALSE) -> 재융공업 | E39: =VLOOKUP($C39,'26년 LIST (산학연)'!$B:$H,3,FALSE) -> ㈜엠아이씨유 | F39: =VLOOKUP(C39,'26년 LIST (산학연)'!$B:$H,7,FALSE) -> 0 | G39: 45762 | H39: 비비에 기재 | J39: =I39+T39 -> 0.5 | T39: 0.5 | U39: =VLOOKUP(C39,'26년 LIST (산학연)'!$B:$N, 12, FALSE) -> 0
B40: 진행중 | C40: 46 | D40: =VLOOKUP($C40,'26년 LIST (산학연)'!$B:$H,2,FALSE) -> ㈜멀티밸런스(사업비: 30,000,000원) | E40: =VLOOKUP($C40,'26년 LIST (산학연)'!$B:$H,3,FALSE) -> ㈜아이토프 | F40: =VLOOKUP(C40,'26년 LIST (산학연)'!$B:$H,7,FALSE) -> 0 | G40: 45762 | H40: 비비에 기재 | J40: =I40+T40 -> 0 | T40: 0 | U40: =VLOOKUP(C40,'26년 LIST (산학연)'!$B:$N, 12, FALSE) -> 0
...
