Workbook

Sheet 종합
B1: 견적서 현황 | F1: 수주 및 입금 현황 | L1: 물가변동 프로젝트 현황
B2: 데이터 수 | C2: =COUNTA('견적서 진행현황'!A:A)-1 -> 507 | F2: 데이터 수 | G2: =COUNTA('수주 및 입금 진행현황'!A:A) -> 115 | L2: 마지막 행번호 | M2: =MATCH(E1+308,'물가변동 진행현황'!A:A,1) -> 20
B3: 진행 형황 | C3: 건수 | D3: 합계 | F3: 구분 | G3: 진행 현황 | I3: 건수 | J3: 합계 | L3: 진행 현황 | M3: 건수
B4: 연단가 | C4: {=COUNTIF(INDIRECT("'견적서 진행현황'!L7:L"&C2+5),B4)} -> 28 | D4: =C4+C5 -> 255 | F4: 수주건 | G4: 수주 | I4: {=COUNTIF(INDIRECT("'수주 및 입금 진행현황'!L7:L" &G2+4), "수주")} -> 97 | J4: =I4+I5 -> 113 | L4: 견적제출 | M4: {=COUNTIF(INDIRECT("'견적서 진행현황'!D7:D"&C2+5),"공사-물가변동")} -> 30
B5: 수주 | C5: {=COUNTIF(INDIRECT("'견적서 진행현황'!L7:L"&C2+5),B5)} -> 227 | G5: 연단가 | I5: {=COUNTIF(INDIRECT("'수주 및 입금 진행현황'!L7:L" &G2+4), G5)} -> 16 | L5: 미수주 | M5: {=COUNTIFS(INDIRECT("'견적서 진행현황'!D7:D"&C2+5), "공사-물가변동", INDIRECT("'견적서 진행현황'!L7:L"&C2+5), "미수주")} -> 9
B6: 진행 중 | C6: {=COUNTA(INDIRECT("'견적서 진행현황'!M7:M"&C2+5))-(C7+C8+C9)} -> 33 | D6: =C6+C7+C8+C9 -> 250 | F6: 진행 현황 | G6: 보고서 작성 중 | I6: =J4-I7 -> 26 | J6: =I6+I7 -> 113 | L6: 수주 | M6: {=COUNTIFS(INDIRECT("'견적서 진행현황'!D7:D"&C2+5), "공사-물가변동", INDIRECT("'견적서 진행현황'!L7:L"&C2+5), "수주")} -> 14
B7: 완료 | C7: {=COUNTIF(INDIRECT("'견적서 진행현황'!N7:N"&C2+5),B7)-(C8+C9)} -> -1 | G7: 완료 | I7: {=COUNTIF(INDIRECT("'수주 및 입금 진행현황'!N7:N" &G2+4), "<>")} -> 87 | L7: 진행중 | M7: {=COUNTIF(INDIRECT("'물가변동 진행현황'!K7:K"&$M$2),L7)} -> 2
B8: 보고서 제출 | C8: {=COUNTIF(INDIRECT("'견적서 진행현황'!P7:P"&C2+5),"<>")-C9} -> 154 | F8: 수금 현황 | G8: 세금계산서 미발행 | I8: =I7-(I9+I10) -> 48 | J8: =I8+I9+I10 -> 87 | L8: 1차완료 | M8: =COUNTIF(INDIRECT("'물가변동 진행현황'!J7:J"&$M$2),L8) -> 3
B9: 입금 완료 | C9: {=COUNTIF(INDIRECT("'견적서 진행현황'!S7:S"&C2+5),"<>")} -> 64 | G9: 세금계산서 발행 | I9: {=COUNTIF(INDIRECT("'수주 및 입금 진행현황'!Q7:Q" &G2+4), "<>")-I10} -> 24 | L9: 완료 | M9: =COUNTIF(INDIRECT("'물가변동 진행현황'!J7:J"&$M$2),L9) -> 9
B10: 견적제출 | C10: {=COUNTIF(INDIRECT("'견적서 진행현황'!L7:L"&C2+5),B10)} -> 45 | D10: - | G10: 입금 완료 | I10: {=COUNTIF(INDIRECT("'수주 및 입금 진행현황'!S7:S" &G2+4), "<>")} -> 15 | L10: 합계 | M10: =M7+M8+M9 -> 14
L11: ※ 수주대기 7건임
B12: LH 프로젝트 현황 | F12: LH외 프로젝트 현황 | I12: 원가 프로젝트 현황 | L12: 혁신바우처 사업
B13: 마지막 행번호 | D13: =MATCH(1E+308, '일정(LH)'!A:A, 1) -> 248 | F13: 마지막 행번호 | G13: =MATCH(1E+308,'일정(LH외 공사)'!A:A,1) -> 203 | I13: 마지막 행번호 | J13: =MATCH(1E+308,'일정(원가 등)'!A:A,1) -> 53
B14: 진행현황 | D14: 건수 | F14: 진행 현황 | G14: 건수 | I14: 진행 현황 | J14: 건수 | L14: 진행 현황 | M14: 건수
B15: 견적 및 제안서 | C15: : 견적 / 제안서 제출 | D15: =COUNTIF(INDIRECT("'일정(LH)'!B3:B"&$D$13),B15) -> 0 | F15: 견적 및 제안서 | G15: =COUNTIF(INDIRECT("'일정(LH외 공사)'!B3:B"&$G$13),F15) -> 1 | I15: 견적 및 제안서 | J15: =COUNTIF(INDIRECT("'일정(원가 등)'!B4:B"&$J$13),I15) -> 0 | L15: 누계(2026년) | M15: ='혁신바우처 사업 진행현황'!D11 -> 160
B16: Ⅰ-1 | C16: : 1차 체크 | D16: =COUNTIF(INDIRECT("'일정(LH)'!B3:B"&$D$13),B16) -> 0 | F16: 진행 | G16: =COUNTIF(INDIRECT("'일정(LH외 공사)'!B3:B"&$G$13),F16) -> 4 | I16: 진행 | J16: =COUNTIF(INDIRECT("'일정(원가 등)'!B4:B"&$J$13),I16) -> 1 | L16: 미 착수 | M16: ='혁신바우처 사업 진행현황'!F11 -> 0
B17: Ⅰ-2 | C17: : 물량산출 내역작성 | D17: =COUNTIF(INDIRECT("'일정(LH)'!B3:B"&$D$13),B17) -> 0 | F17: 보고서 제출 | G17: =COUNTIF(INDIRECT("'일정(LH외 공사)'!B3:B"&$G$13),F17) -> 6 | I17: 보고서 제출 | J17: =COUNTIF(INDIRECT("'일정(원가 등)'!B4:B"&$J$13),I17) -> 3 | L17: 미 완료 | M17: ='혁신바우처 사업 진행현황'!F11 -> 0
B18: Ⅱ-1 | C18: : 2차 체크 내역비교 | D18: =COUNTIF(INDIRECT("'일정(LH)'!B3:B"&$D$13),B18) -> 1 | F18: 보고서 승인 | G18: =COUNTIF(INDIRECT("'일정(LH외 공사)'!B3:B"&$G$13),F18) -> 0 | I18: 보고서 승인 | J18: =COUNTIF(INDIRECT("'일정(원가 등)'!B4:B"&$J$13),I18) -> 0 | L18: 완료 | M18: ='혁신바우처 사업 진행현황'!H11 -> 75
B19: Ⅱ-2 | C19: : 보고서/기준표 작성 | D19: =COUNTIF(INDIRECT("'일정(LH)'!B3:B"&$D$13),B19) -> 8 | F19: 세금계산서 발행 | G19: =COUNTIF(INDIRECT("'일정(LH외 공사)'!B3:B"&$G$13),F19) -> 5 | I19: 세금계산서 발행 | J19: =COUNTIF(INDIRECT("'일정(원가 등)'!B4:B"&$J$13),I19) -> 1 | L19: 세금계산서 미발행 | M19: ='혁신바우처 사업 진행현황'!H11 -> 75
B20: 1차기성 | C20: : 1차기성 신청 | D20: =COUNTIF(INDIRECT("'일정(LH)'!B3:B"&$D$13),B20) -> 0 | F20: 입금 완료 | G20: =COUNTIF(INDIRECT("'일정(LH외 공사)'!B3:B"&$G$13),F20) -> 6 | I20: 입금 완료 | J20: =COUNTIF(INDIRECT("'일정(원가 등)'!B4:B"&$J$13),I20) -> 2
B21: 1차기성 완료 | C21: : 1차기성 입금완료 | D21: =COUNTIF(INDIRECT("'일정(LH)'!B3:B"&$D$13),B21) -> 9 | F21: 합계 | G21: =SUM(G15:G20) -> 22 | I21: 합계 | J21: =SUM(J15:J20) -> 7
B22: Ⅲ-1 | C22: : 기준표 검토 | D22: =COUNTIF(INDIRECT("'일정(LH)'!B3:B"&$D$13),B22) -> 0
B23: Ⅲ-2 | C23: : 공정표 검토 | D23: =COUNTIF(INDIRECT("'일정(LH)'!B3:B"&$D$13),B23) -> 0 | F23: 스마트공장 진행현황 | I23: 납품대금연동제 현황 | L23: 안전동행지원 사업
B24: 2차기성 | C24: : 2차기성 신청 | D24: =COUNTIF(INDIRECT("'일정(LH)'!B3:B"&$D$13),B24) -> 0 | F24: 진행 현황 | G24: 건수 | I24: 진행 현황 | J24: 건수 | L24: 진행 현황 | M24: 건수
B25: Ⅳ-1 | C25: : 설계변경 | D25: =COUNTIF(INDIRECT("'일정(LH)'!B3:B"&$D$13),B25) -> 0 | F25: 누계(2026년) | G25: ='스마트공장 진행현황'!J48 -> 116 | I25: 누계(2026년) | J25: 3 | L25: 누계(2026년) | M25: 0
B26: Ⅳ-2 | C26: : E.S | D26: =COUNTIF(INDIRECT("'일정(LH)'!B3:B"&$D$13),B26) -> 0 | F26: 진행중 | G26: ='스마트공장 진행현황'!K48 -> 41 | I26: 진행중 | J26: 3 | L26: 진행중 | M26: 0
B27: Ⅴ-1 | C27: : 원가검증 | D27: =COUNTIF(INDIRECT("'일정(LH)'!B3:B"&$D$13),B27) -> 0 | F27: 보고서 제출 | G27: ='스마트공장 진행현황'!M48 -> 75 | I27: 보고서 제출 | J27: 0 | L27: 보고서 제출 | M27: 0
B28: 3차기성 | C28: : 3차기성 신청 | D28: =COUNTIF(INDIRECT("'일정(LH)'!B3:B"&$D$13),B28) -> 0 | F28: 세금계산서 발행 | G28: ='스마트공장 진행현황'!O48 -> 0 | I28: 세금계산서 발행 | J28: 0 | L28: 세금계산서 발행 | M28: 0
B29: 입금 완료 | C29: : 프로젝트 완료 | D29: =COUNTIF(INDIRECT("'일정(LH)'!B3:B"&$D$13),B29) -> 0
B30: 합계 | D30: =SUM(D15:D29) -> 18

Sheet 보고서 검토일지(26년)
B1: 762 | C1: 일자 | D1: 담당 | E1: 코드 (세부분류) | F1: 업무분류 (과업명 기준) | G1: 발주처 | H1: 과업명 (견적서 및 계약서 과업명 그대로 작성) | I1: 구분 | J1: 검토완료 희망시간 | K1: 검토사항(수정,보완 등) 오류 등급 : 상 - (중대오류 -계산 오류, 항목오류, 누락 등) - 재검토 중 - (오타, 단순 오기등)- 수정필수 하 - 상세내역서, 업체견적서 등 오타 ,오기 - 수정권고 | L1: 검토 시간 | M1: 요청담당자 검토사항 반영 확인 | N1: 견적서, 수주, 입금진행현황 시트로 이동
B2: 767
B3: 766
B4: 765
B5: 764
B6: 763
B7: 762 | C7: 46189 | D7: 하은정 | E7: CB-211 | F7: 공사-공사원가 | G7: 한국에너지공단 | H7: 2026년 산업계 에너지관리시스템(EMS) 보급 지원사업 원가계산 | I7: 최종보고서 | J7: 46189.583 | K7: 상 : '제시되 제반자료를' → '제시된 제반자료를'. 'ThinkSytem' → 'ThinkSystem' <표 2-8> '일반관리 비율표' 비고란 수치 누락 | L7: 0.5 | M7: 0 | N7: {=LET(행번호, MATCH(1, INDEX(('수주 및 입금 진행현황'!$F:$F=G7) * ('수주 및 입금 진행현황'!$G:$G=H7) * ('수주 및 입금 진행현황'!$F:$F<>""), 0), 0), IF(ISNUMBER(행번호), HYPERLINK("#gid=" & "1759022251" & "&range=A" & 행번호, "이동"), "X"))} -> X
B8: 761 | C8: 46189 | D8: 장연주 | E8: CC-311 | F8: 학술용역-연구 | G8: 소상공인시장진흥공단 | H8: 2026년 소상공인 재기지원사업 성과분석 용역 원가계산 | I8: 완료계 | J8: 46189.417 | K8: 완료계, 공문 검토 → 첨부서류 확인, 문제 없음 | L8: 0.2 | M8: 0 | N8: 이동
B9: 760 | C9: 46189 | D9: 장연주 | E9: CC-311 | F9: 학술용역-연구 | G9: 소상공인시장진흥공단 | H9: 2026년 소상공인 재기지원사업 성과분석 용역 원가계산 | I9: 최종보고서 | J9: 46189.417 | K9: 상 : 총괄표에 <부가세> 누락 → 확인요 | L9: 0.5 | M9: 0 | N9: 이동
B10: 759 | C10: 46188 | D10: 장연주 | E10: CC-311 | F10: 학술용역-연구 | G10: 한국산업기술진흥원 | H10: 산업기술기반구축 관리 및 활용도 제고 연구용역 원가계산 | I10: 완료계 | J10: 46188.479 | K10: 완료계, 공문 검토 → 첨부서류 확인, 문제 없음 | L10: 0.2 | M10: 0 | N10: 이동
B11: 758 | C11: 46188 | D11: 장연주 | E11: CC-311 | F11: 학술용역-연구 | G11: 한국산업기술진흥원 | H11: 산업기술기반구축 관리 및 활용도 제고 연구용역 원가계산 | I11: 최종보고서 | J11: 46188.479 | K11: 최종보고서 검토 → 문제 없음 | L11: 0.5 | M11: 0 | N11: 이동
B12: 757 | C12: 46188 | D12: 장연주 | E12: CC-311 | F12: 학술용역-연구 | G12: 한국산업기술진흥원 | H12: 산업기술기반구축 관리 및 활용도 제고 연구용역 원가계산 | I12: 청구서 | J12: 46188.479 | K12: 청구서, 공문 검토 → 수신인 확인 ~원, ~원장 | L12: 0.2 | M12: 0 | N12: 이동
B13: 756 | C13: 46188 | D13: 하은정 | E13: CB-211 | F13: 공사-공사원가 | G13: 한국에너지공단 | H13: 2026년 산업계 에너지관리시스템(EMS) 보급 지원사업 원가계산 | I13: 최종보고서 | J13: 46188.042 | K13: 상 : <표3-1> 비고란 : 경비 <표 3-2> → <표 3-4> 일반관리비 <표 3-2> → <표 3-9> 이윤 <표 2-19> → <표 3-11> 하 : 인건비 집계표의 구분란에 "#REF!" → 수정요 "에너경영 절차서 작성" → "에너지경영" | L13: 0.5
B14: 755 | C14: 46188 | D14: 장연주 | E14: CC-321 | F14: 학술용역-행사, 운영(대행) | G14: 한국산업기술기획평가원 | H14: 2026 코리아테크페스티벌(가칭) 종합운영·홍보 및 전시설치 용역 원가계산 | I14: 완료계 | J14: 2026. 06.15 11:00 | K14: 완료계, 공문 검토 → 첨부서류 확인, 문제 없음 | L14: 0.2 | M14: 0 | N14: 이동
B15: 754 | C15: 46188 | D15: 장연주 | E15: CC-321 | F15: 학술용역-행사, 운영(대행) | G15: 한국산업기술기획평가원 | H15: 2026 코리아테크페스티벌(가칭) 종합운영·홍보 및 전시설치 용역 원가계산 | I15: 최종보고서 | J15: 2026. 06.15 11:00 | K15: 하: '캐치프라이즈' -> '캐치프레이즈(Catchphrase)' | L15: 0.5 | M15: 0 | N15: 이동
B16: 753 | C16: 46188 | D16: 장연주 | E16: CC-321 | F16: 학술용역-행사, 운영(대행) | G16: 한국산업기술기획평가원 | H16: 2026 코리아테크페스티벌(가칭) 종합운영·홍보 및 전시설치 용역 원가계산 | I16: 청구서 | J16: 2026. 06.15 11:00 | K16: 청구서, 공문 검토 → 첨부서류 확인, 문제 없음 | L16: 0.2 | M16: 0 | N16: 이동
B17: 752 | C17: 46184 | D17: 장연주 | E17: CC-341 | F17: 일반용역-S/W | G17: 한국방사선진흥협회 | H17: RATIS AI 도입을 위한 DB 정비 및 AI 챗봇 서비스 개발(시범운영) 원가계산 | I17: 완료계 | J17: 2026. 06.11 17:30 | K17: 완료계, 공문 검토 → 첨부서류 확인, 문제 없음 | L17: 0.25 | M17: 0 | N17: 이동
B18: 751 | C18: 46184 | D18: 장연주 | E18: CC-341 | F18: 일반용역-S/W | G18: 한국방사선진흥협회 | H18: RATIS AI 도입을 위한 DB 정비 및 AI 챗봇 서비스 개발(시범운영) 원가계산 | I18: 청구서 | J18: 2026. 06.11 17:30 | K18: 청구서, 공문 검토 → 첨부서류 확인, 문제 없음 | L18: 0.25 | M18: 0 | N18: 이동
B19: 750 | C19: 46184 | D19: 장연주 | E19: CC-341 | F19: 일반용역-S/W | G19: 한국방사선진흥협회 | H19: RATIS AI 도입을 위한 DB 정비 및 AI 챗봇 서비스 개발(시범운영) 원가계산 | I19: 최종보고서 | J19: 2026. 06.11 17:30 | K19: 상 : 'Ⅳ. 원가계산서'에서는 제경비를 <표 6>, 기술료를 <표 7>, 직접경비를 <표 10>으로 참조 <표 8>과 <표 9>가 완전히 누락 <표 3> 투입공수 산출표를 보면 'UI/UX기획/개발자'의 공수(M/M) 소계는 정확히 1.000이며 4개 직무(IT PM, 데이터분석가, 응용SW개발자, UI/UX기획/개발자)의 전체 합계가 2.000 → 확인요 하 : <표 5> 직무체계 및 정의 중 3번 '업무분석가'의 직무 정의 란에 "업무 요구사항을 도출하고 분석1)하여 → 1) 삭제 | L19: 0.5 | M19: 0 | N19: 이동
B20: 749 | C20: 46184 | D20: 최재운 | E20: CB-202 | F20: 공사-공사원가 | G20: LH경기남부지역본부 | H20: 세류동 1155-4 오피스텔 신축공사 | I20: 중간보고서 | J20: 2026. 06. 11. 12:00 | K20: 상 : p11 관련 근거 부분에 "기회재정부" → "기획재정부" p17 원가계산서 간접노무비 표에서 원가계산기관(B)의 금액 "10,30" → "1,030". p28 강관동바리 검토내용 중 "2026녀 품셈을 기준으로" → "2026년 품셈" p38 타일공사 검토내용에서 "적용하였으고,원가증기관 산정내역의..." → "적용하였고, 원가계산기관(또는 검증기관) 산정내역의..." p41 알루미늄폼 검토의견 중 "원가기간 알루미늄폼 자재비는" → "원가기관" p47 판넬히팅 검토의견에 "시멘트 비용이 포함외어 있고" → "포함되어" p70 공종별 직접공사비 목차 번호 (5) 통신, (5) 소방 → (6) 통신, (7) 소방 p74 (소방공사 직접공사비 종합의견) 보고서에는 "LH기준에 의해 기계소방공사는 사업자의 산정금액이 원가기관의 산정금액보다 적어 --." 수치표를 보면 전기소방공사가 사업자(329백만) < 원가기관(576백만) "기계소방공사" → "전기소방공사" | L20: 0.7
B21: 748 | C21: 46183 | D21: 장연주 | E21: CC-321 | F21: 학술용역-행사, 운영(대행) | G21: 창업진흥원 | H21: 몽골 스타트업 지원인력 초청연수 위탁용역 원가계산 | I21: 완료계 | J21: 46183.688 | K21: 완료계, 공문 검토 → 첨부서류 확인, 문제 없음 | L21: 0.25 | M21: 0 | N21: 이동
B22: 747 | C22: 46183 | D22: 장연주 | E22: CC-321 | F22: 학술용역-행사, 운영(대행) | G22: 창업진흥원 | H22: 몽골 스타트업 지원인력 초청연수 위탁용역 원가계산 | I22: 청구서 | J22: 46183.688 | K22: 청구서, 공문 검토 → 첨부서류 확인, 문제 없음 | L22: 0.25 | M22: 0 | N22: 이동
B23: 746 | C23: 46183 | D23: 장연주 | E23: CC-341 | F23: 일반용역-S/W | G23: 대한상공회의소 | H23: 2024년도 부처협업형(방산) 스마트공장 구축 지원사업 원가계산 | I23: 청구서 | J23: 46183.625 | K23: 청구서, 공문 검토 → 첨부서류 확인, 문제 없음 | L23: 0.25 | M23: 0 | N23: {=LET(행번호, MATCH(1, INDEX(('수주 및 입금 진행현황'!$F:$F=G23) * ('수주 및 입금 진행현황'!$G:$G=H23) * ('수주 및 입금 진행현황'!$F:$F<>""), 0), 0), IF(ISNUMBER(행번호), HYPERLINK("#gid=" & "1759022251" & "&range=A" & 행번호, "이동"), "X"))} -> X
B24: 745 | C24: 46183 | D24: 장연주 | E24: CC-341 | F24: 일반용역-S/W | G24: 대한상공회의소 | H24: 2025년 부처협업형 스마트공장 (방위산업) 스마트공장 구축 지원사업 원가계산 | I24: 청구서 | J24: 46183.625 | K24: 청구서, 공문 검토 → 첨부서류 확인, 문제 없음 | L24: 0.25 | M24: 0 | N24: {=LET(행번호, MATCH(1, INDEX(('수주 및 입금 진행현황'!$F:$F=G24) * ('수주 및 입금 진행현황'!$G:$G=H24) * ('수주 및 입금 진행현황'!$F:$F<>""), 0), 0), IF(ISNUMBER(행번호), HYPERLINK("#gid=" & "1759022251" & "&range=A" & 행번호, "이동"), "X"))} -> X
B25: 744 | C25: 46183 | D25: 장연주 | E25: CC-311 | F25: 학술용역-연구 | G25: 한국산업기술진흥원 | H25: 2026년 기후에너지환경부 ODA 종료평가 용역 원가계산 | I25: 완료계 | J25: 46183.604 | K25: 완료계, 공문 검토 → 첨부서류 확인, 문제 없음 | L25: 0.25 | M25: 0 | N25: 이동
B26: 743 | C26: 46183 | D26: 장연주 | E26: CC-311 | F26: 학술용역-연구 | G26: 한국산업기술진흥원 | H26: 2026년 기후에너지환경부 ODA 종료평가 용역 원가계산 | I26: 최종보고서 | J26: 46183.604 | K26: 상 : 'Ⅱ. 원가계산의 개요' "2026년 기후에너지환경부 ODA 종료평가" 'Ⅳ. 용역원가계산서' 상단표의 건명 "2025년 산업 및 에너지협력개발지원(ODA) 자체성과 평가" → 확인요 | L26: 0.5 | M26: 0 | N26: 이동
B27: 742 | C27: 46183 | D27: 장연주 | E27: CC-321 | F27: 학술용역-행사, 운영(대행) | G27: 소상공인시장진흥공단 | H27: 2026년 디지털닥터 교육과정 개선 및 운영대행 용역 원가계산 | I27: 최종보고서 | J27: 46183.604 | K27: 최종보고서 검토 → 문제 없음 | L27: 0.5 | M27: 0 | N27: 이동
B28: 741 | C28: 46183 | D28: 하은정 | E28: CB-211 | F28: 공사-공사원가 | G28: (주)재원테크 | H28: 산업용 리프트 제작설치공사 | I28: 최종보고서 | J28: 46183.5 | K28: 하 : '낙하벨브': <표 2> 공사내역서, <표 5> 단가대비표 → '밸브' '압력벨브': <표 2> 공사내역서, <표 5> 단가대비표 → '밸브' '유압류' → 유'압유' | L28: 0.5 | N28: {=LET(행번호, MATCH(1, INDEX(('수주 및 입금 진행현황'!$F:$F=G28) * ('수주 및 입금 진행현황'!$G:$G=H28) * ('수주 및 입금 진행현황'!$F:$F<>""), 0), 0), IF(ISNUMBER(행번호), HYPERLINK("#gid=" & "1759022251" & "&range=A" & 행번호, "이동"), "X"))} -> X
B29: 740 | C29: 46183 | D29: 하은정 | E29: CB-211 | F29: 공사-공사원가 | G29: (주)신양플레이팅 | H29: 2026년 화학안전 사업장 조성 지원사업 | I29: 최종보고서 | J29: 46183.5 | K29: 최종보고서 검토 → 문제 없음 | L29: 0.5 | N29: {=LET(행번호, MATCH(1, INDEX(('수주 및 입금 진행현황'!$F:$F=G29) * ('수주 및 입금 진행현황'!$G:$G=H29) * ('수주 및 입금 진행현황'!$F:$F<>""), 0), 0), IF(ISNUMBER(행번호), HYPERLINK("#gid=" & "1759022251" & "&range=A" & 행번호, "이동"), "X"))} -> X
B30: 739 | C30: 46183 | D30: 이길훈 | E30: CB-252 | F30: 공사-기부채납 | G30: 엔에이디벨롭먼트 | H30: 동작 보라매역 프리센트 기부채납 설치비용 검증용역 | I30: 중간보고서 | J30: 46183.438 | K30: 상 : 총괄집계표의 21번 부대비용 항목 명칭 "건축물에너지 효육등급 예비인증 수수료" → "---효율등급---" 단위 누락: 공공임대오피스 면적을 구분하는 항목 "② 공공임대오피스 전용면적 : 502.802 (64.18%) → 단위 'm2(㎡)' 추가 "기부채납 시설 연면적(전용면적+전용외 면적) : 1,357.117m2" 실제 하단의 전용면적(796.023m2)+ 전용외 면적(557.094m2)=1,353.117m2 → 확인요 | L30: 0.5 | M30: 0 | N30: {=LET(행번호, MATCH(1, INDEX(('수주 및 입금 진행현황'!$F:$F=G30) * ('수주 및 입금 진행현황'!$G:$G=H30) * ('수주 및 입금 진행현황'!$F:$F<>""), 0), 0), IF(ISNUMBER(행번호), HYPERLINK("#gid=" & "1759022251" & "&range=A" & 행번호, "이동"), "X"))} -> X
B31: 738 | C31: 46181 | D31: 장연주 | E31: CC-321 | F31: 학술용역-행사, 운영(대행) | G31: 인천창조경제혁신센터 | H31: 모두의 창업 프로젝트 출범식 및 오리엔테이션 운영 용역 원가계산 | I31: 최종보고서 | J31: 46181.688 | K31: 최종보고서 검토 → 문제 없음 | L31: 0.5 | M31: 0 | N31: 이동
B32: 737 | C32: 46181 | D32: 장연주 | E32: CC-321 | F32: 학술용역-행사, 운영(대행) | G32: 인천창조경제혁신센터 | H32: 모두의 창업 프로젝트 출범식 및 오리엔테이션 운영 용역 원가계산 | I32: 청구서 | J32: 46181.688 | K32: 청구서, 공문 검토 → 첨부서류 확인, 문제 없음 | L32: 0.25 | M32: 0 | N32: 이동
B33: 736 | C33: 46181 | D33: 이길훈 | E33: CB-251 | F33: 공사-기부채납 | G33: 해조건설 | H33: 안양시 평촌 C10-3 공공기여시설 기부채납 공사비 산정용역 | I33: 중간보고서 | J33: 46181.708 | K33: 최종보고서 검토 → 문제 없음 | L33: 0.5 | N33: {=LET(행번호, MATCH(1, INDEX(('수주 및 입금 진행현황'!$F:$F=G33) * ('수주 및 입금 진행현황'!$G:$G=H33) * ('수주 및 입금 진행현황'!$F:$F<>""), 0), 0), IF(ISNUMBER(행번호), HYPERLINK("#gid=" & "1759022251" & "&range=A" & 행번호, "이동"), "X"))} -> X
B34: 735 | C34: 46181 | D34: 하은정 | E34: CB-211 | F34: 공사-공사원가 | G34: 법원행정처 | H34: 서울회생법원 청사 이전에 따른 전산망 구축을 위한 네트워크 공사 원가계산 | I34: 최종보고서 | J34: 46181.479 | K34: 상 : <표 5> 단가대비표에서는 '통신내선공'의 일 노임단가를 284,880원 → <표 4> 일위대가표의 '15. OUTLET(AMP)' 항목 통신내선공의 노임단가 450,000원 확인요 | L34: 0.5 | N34: {=LET(행번호, MATCH(1, INDEX(('수주 및 입금 진행현황'!$F:$F=G34) * ('수주 및 입금 진행현황'!$G:$G=H34) * ('수주 및 입금 진행현황'!$F:$F<>""), 0), 0), IF(ISNUMBER(행번호), HYPERLINK("#gid=" & "1759022251" & "&range=A" & 행번호, "이동"), "X"))} -> X
B35: 734 | C35: 46181 | D35: 장연주 | E35: CC-321 | F35: 학술용역-행사, 운영(대행) | G35: 소상공인시장진흥공단 | H35: 소상공인 보건관리 위탁 용역 원가계산 | I35: 최종보고서 | J35: 46181.458 | K35: 상 : "Ⅰ. 원가계산의 결과" → "Ⅰ. 원가계산 결과" <표 5> 재료비 산출표에서 세부 항목명 '구 금 함' → '구급함' 'Ⅲ. 원가요소별 계산기준' 이윤 산출 시 "인건비, 경비 및 일반관리비 합계액"의 10% 'Ⅴ. 산출내역'의 <표 8> 이윤 산출표 하단 주석(주2)에는 '<표 4> 경비 집계표 참조, 재료비 제외' → 경비와 재료비 분리 확인요 | L35: 0.5 | M35: 0 | N35: 이동
B36: 733 | C36: 46181 | D36: 하은정 | E36: CB-211 | F36: 공사-공사원가 | G36: (주)대웅케미칼 | H36: 대웅케미칼 탱크 설비 원가계산 | I36: 최종보고서 | J36: 46181.417 | K36: 상 : '이윤 산출표'가 <표 19> '이윤 비율표'가 <표 120> → <표 20> 수정요 IV. 공사원가계산서 노무비 항목 '건접노무비' → '간접노무비' <표 16> 하단 (주4) 각주에 '총공사금액 2천만원 이상 건설공사에만 적용하므로 본 보고서에서는 제외함' → 확인요 하 : <표 2> 공사내역서 자재비 항목 'INSULATIN ANGLE' → 'INSULATION ANGLE' | L36: 0.5 | N36: {=LET(행번호, MATCH(1, INDEX(('수주 및 입금 진행현황'!$F:$F=G36) * ('수주 및 입금 진행현황'!$G:$G=H36) * ('수주 및 입금 진행현황'!$F:$F<>""), 0), 0), IF(ISNUMBER(행번호), HYPERLINK("#gid=" & "1759022251" & "&range=A" & 행번호, "이동"), "X"))} -> X
B37: 732 | C37: 46178 | D37: 장연주 | E37: CC-311 | F37: 학술용역-연구 | G37: 한국산업기술기획평가원 | H37: KEIT(한국산업기술기획평가원) R&D지원 효과 종합분석 용역 원가계산 | I37: 완료계 | J37: 46178.667 | K37: 완료계, 공문 검토 → 첨부서류 확인, 문제 없음 | L37: 0.2 | M37: 0 | N37: 이동
B38: 731 | C38: 46178 | D38: 장연주 | E38: CC-311 | F38: 학술용역-연구 | G38: 한국산업기술기획평가원 | H38: KEIT(한국산업기술기획평가원) R&D지원 효과 종합분석 용역 원가계산 | I38: 최종보고서 | J38: 46178.667 | K38: 최종보고서 검토 → 문제 없음 | L38: 0.4 | M38: 0 | N38: 이동
B39: 730 | C39: 46178 | D39: 장연주 | E39: CC-311 | F39: 학술용역-연구 | G39: 한국산업기술기획평가원 | H39: KEIT(한국산업기술기획평가원) R&D지원 효과 종합분석 용역 원가계산 | I39: 청구서 | J39: 46178.667 | K39: 청구서, 공문 검토 → 첨부서류 확인, 문제 없음 | L39: 0.2 | M39: 0 | N39: 이동
B40: 729 | C40: 46178 | D40: 최재운 | E40: CB-202 | F40: 공사-공사원가 | G40: LH경기남부지역본부 | H40: 세교동 591-2 오피스텔 신축공사 | I40: 최종보고서 | J40: 2026. 06. 05. 16:00 | K40: 최종보고서 검토 → 문제 없음 | L40: 0.4 | M40: 0 | N40: {=LET(행번호, MATCH(1, INDEX(('수주 및 입금 진행현황'!$F:$F=G40) * ('수주 및 입금 진행현황'!$G:$G=H40) * ('수주 및 입금 진행현황'!$F:$F<>""), 0), 0), IF(ISNUMBER(행번호), HYPERLINK("#gid=" & "1759022251" & "&range=A" & 행번호, "이동"), "X"))} -> X
...

Sheet 견적서 진행현황
A1: 2026년 견적서 진행현황
T3: : 변동사항이 있는 행
T4: : 견적서 제출하지 않고 용역 수행 중인 행
T5: : 견적X
A6: 견적일자 | B6: 계약기간 | C6: 업무코드 (세부코드) | D6: 업무분류 | E6: 업무분류 | F6: 발주처 | G6: 과업명 | H6: 수주방식 | I6: 견적금액 (VAT포함) | J6: 사업비 규모 | K6: 견적 유/무 | L6: 진행상태 | M6: 담당자 | N6: 완료여부 | O6: 품질 관리실 확인여부 | P6: 보고서제출일 | Q6: 세금계산서 발행일자 | R6: 세금계산서 발행금액 (VAT 포함) | S6: 입금일 | T6: 비고
A9: 45803 | C9: CB-222 | D9: 공사-물가변동 | F9: 조달청/해양수산부 포항지방해양수산청 | G9: 수영만 자연재해위험개선지구 정비사업 물가변동 용역(동아건설) | H9: 견적-최저 | I9: 9020000 | J9: 사업비 확인불가 | K9: 유 | L9: 수주 | M9: 하은정 | N9: 1차완료 | P9: 45812
A10: 45663 | C10: CB-222 | D10: 공사-물가변동 | F10: 조달청/해양수산부 포항지방해양수산청 | G10: 포항 영일대지구 연안정비사업 중 물가변동(E/S) 용역 (동아건설) | H10: 견적-최저 | I10: 12500000 | J10: 사업비 확인불가 | K10: 유 | L10: 수주 | M10: 하은정 | N10: 1차완료 | P10: 45663
A11: 45714 | C11: CB-222 | D11: 공사-물가변동 | F11: 주식회사 송림 | G11: 하남교산 공공주택지구 지장물 해체공사 중 물가변동 용역(송림)_1차 | H11: 견적-최저 | I11: 5280000 | J11: 사업비 확인불가 | K11: 유 | L11: 수주 | M11: 하은정 | N11: 완료 | P11: 45673 | Q11: 46127 | R11: 5280000
A12: 46189.625 | C12: CC-341 | D12: 일반용역-S/W | F12: 데이터얼라이언스(주) | G12: 광주지역거점형 사업의 원가검증 | H12: 견적-최저 | I12: 1100000 | J12: 사업비 확인불가 | K12: 유 | L12: 견적제출
A13: 46189.471 | C13: CC-311 | D13: 학술용역-연구 | F13: 한국산업기술진흥원 | G13: 산업기술개발장비 성과분석 원가계산 | H13: 견적-최저 | I13: 550000 | J13: 70000000 | K13: 유 | L13: 견적제출
A14: 46189.441 | C14: CB-222 | D14: 공사-물가변동 | F14: 인천경제자유구역청 | G14: 송도 11-1공구 기반시설 건설 신호등 설치공사(2구역) 물가변동으로 인한 계약금액 조정 검토 용역 (지수조정 2회) | H14: 견적-최저 | I14: 1650000 | J14: 1355097650 | K14: 유 | L14: 견적제출
A15: 46188 | C15: CH-801 | D15: 비교견적 | F15: 한국식품산업클러스터진흥원 | G15: 국가식품클러스터 테스트베드 고도화 및 시뮬레이션 연동체계 구성 용역 | H15: 견적-비교견적 | I15: 1320000 | J15: 사업비 확인불가 | K15: 유 | L15: 견적제출 | T15: (사)도우경제정책연구원
A16: 46188 | C16: CH-801 | D16: 비교견적 | F16: 한국식품산업클러스터진흥원 | G16: 테스트베드(미러월드) 고도화 및 시뮬레이션 연동체계 구성 용역 | H16: 견적-비교견적 | I16: 1320000 | J16: 사업비 확인불가 | K16: 유 | L16: 견적제출 | T16: (사)도우경제정책연구원
A17: 46189.4 | C17: CH-801 | D17: 비교견적 | F17: 주식회사 동명기술공단종합건축사사무소 | G17: 남원처리구역 하수관로 정비사업(2단계) 건설사업관리용역 물가변동 품목조정 용역 | H17: 견적-비교견적 | I17: 1650000 | J17: 사업비 확인불가 | K17: 유 | L17: 견적제출 | T17: (사)도우경제정책연구원
A18: 46189.4 | C18: CB-212 | D18: 공사-공사원가 | F18: (주)대우건설 | G18: 월성 1호기 해체(1·2단계) 공사비 산정 및 설계용역 | H18: 견적-최저 | I18: 380000000 | J18: 사업비 확인불가 | K18: 유 | L18: 견적준비
A19: 46188.662 | C19: CB-211 | D19: 공사-공사원가 | F19: (주)장수티엔시 | G19: 원형사다리 소운반, 설치 및 철거 공사 원가계산 | H19: 견적-최저 | I19: 1100000 | J19: 사업비 확인불가 | K19: 유 | L19: 견적제출
A20: 46188 | C20: CA-111 | D20: 제조-제조(제작설치포함) | F20: 주식회사 아트필 | G20: 테이프롤러가 적용된 승강구동 무대장치 조달우수제품 신청 관련 원가계산 | H20: 견적-최저 | I20: 2200000 | J20: 사업비 확인불가 | K20: 유 | L20: 견적제출
F21: 국가철도공단 | G21: 연결선인터페이스장치 외 4개 품목 원가계산 용역 | H21: 견적-최저 | K21: 무 | L21: 견적준비
A22: 46185.735 | C22: CH-801 | D22: 비교견적 | F22: 금강종합건설(주) | G22: 서화지구 풍수해생활권종합정비사업 물가변동으로 인한 계약금액조정 | H22: 견적-비교견적 | I22: 2750000 | J22: 사업비 확인불가 | K22: 유 | L22: 비교견적
A23: 46185.734 | C23: CH-801 | D23: 비교견적 | F23: 하남도시공사 | G23: 위례복합체육센터 인테리어 공사에 대한 원가계산 | H23: 견적-비교견적 | I23: 1000000 | J23: 사업비 확인불가 | K23: 유 | L23: 비교견적 | T23: (사)동양경제정보연구소
A24: 46185.705 | C24: CB-222 | D24: 공사-물가변동 | F24: 인천경제자유구역청 | G24: 송도 11-1공구 기반시설 건설(2구역) 가로등 설치공사 물가변동으로 인한 계약금액 조정 | H24: 견적-최저 | I24: 1650000 | J24: 사업비 확인불가 | K24: 유 | L24: 견적제출
A25: 46185.704 | C25: CC-341 | D25: 일반용역-S/W | F25: 소상공인시장진흥공단 | G25: 26년 스마트상점 사업관리시스템 고도화 용역 원가계산 | H25: 견적-최저 | I25: 880000 | J25: 사업비 확인불가 | K25: 유 | L25: 견적제출
A26: 46185.546 | C26: CC-321 | D26: 학술용역-행사, 운영(대행) | F26: 한국산업기술진흥원 | G26: 2026 인공지능 분야 부트캠프 라운드업 운영 용역 원가계산 | H26: 견적-최저 | I26: 1320000 | J26: 220000000 | K26: 유 | L26: 견적제출
A27: 46185 | C27: CC-311 | D27: 학술용역-연구 | F27: 한국에너지기술평가원 | G27: 2026년 ESG 경영체계 고도화 및 지속가능경영보고서 발간 | H27: 견적-최저 | I27: 440000 | J27: 55000000 | K27: 유 | L27: 수주 | M27: 장연주
A28: 46184 | B28: 계약일로부터 20일 | C28: CC-331 | D28: 일반용역-시설 | F28: c-market 전남지방우정청 | G28: 전남지방우정청 무인경비 용역 원가계산 | H28: 가격투찰 | I28: 9900000 | J28: 사업비 확인불가 | K28: 유 | L28: 견적제출
A29: 46183.488 | C29: CH-801 | D29: 비교견적 | F29: 대한체육회선수촌 | G29: 올림픽의 집 냉방기(EHP) 구매 설치 원가계산 | H29: 견적-비교견적 | I29: 3800000 | J29: 사업비 확인불가 | K29: 유 | L29: 비교견적 | T29: (사)동양경제정보연구소
A30: 46183.472 | C30: CC-341 | D30: 일반용역-S/W | F30: 혜성산업(주) | G30: 2026년 산업계 에너지관리시스템(EMS) 보급 지원사업 원가계산 | H30: 견적-최저 | I30: 880000 | J30: 사업비 확인불가 | K30: 유 | L30: 견적제출
A31: 46182.475 | C31: CC-311 | D31: 학술용역-연구 | F31: 창업진흥원 | G31: 몽골 스타트업 지원인력 초청연수 위탁용역 원가계산 | H31: 견적-최저 | I31: 550000 | J31: 90000000 | K31: 유 | L31: 수주 | M31: 장연주 | N31: 완료 | O31: =IF(COUNTIFS('보고서 검토일지(26년)'!$H:$H, $G31, '보고서 검토일지(26년)'!$M:$M, "0", '보고서 검토일지(26년)'!$G:$G, $F31)>0, "완료", "") -> 완료 | P31: 46183
A32: 46182.373 | C32: CC-321 | D32: 학술용역-행사, 운영(대행) | F32: 경북문화재단 콘텐츠진흥원 | G32: 2026년 [광역] 청년크리에이티브 양성 및 창업 지원사업 운영 용역 원가계산 | H32: 견적-최저 | I32: 660000 | J32: 119000000 | K32: 유 | L32: 견적제출
A33: 46181.647 | C33: CC-321 | D33: 학술용역-행사, 운영(대행) | F33: 한국산업기술기획평가원 | G33: 2026 코리아테크페스티벌(가칭) 종합운영·홍보 및 전시설치 용역 원가계산 | H33: 견적-최저 | I33: 660000 | J33: 900000000 | K33: 유 | L33: 수주 | M33: 장연주 | N33: 완료 | O33: =IF(COUNTIFS('보고서 검토일지(26년)'!$H:$H, $G33, '보고서 검토일지(26년)'!$M:$M, "0", '보고서 검토일지(26년)'!$G:$G, $F33)>0, "완료", "") -> 완료 | P33: 46188 | Q33: 46188 | R33: 660000
A34: 46181.647 | C34: CH-801 | D34: 비교견적 | F34: 한국에너지기술평가원 | G34: 에너지 국제공동연구 로드맵 수립 연구용역 원가계산 | H34: 견적-비교견적 | I34: 770000 | J34: 사업비 확인불가 | K34: 유 | L34: 비교견적
A35: 46181.647 | C35: CC-311 | D35: 학술용역-연구 | F35: 소상공인시장진흥공단 | G35: 2026년 소상공인 재기지원사업 성과분석 용역 원가계산 | H35: 견적-최저 | I35: 990000 | J35: 사업비 확인불가 | K35: 유 | L35: 수주 | M35: 장연주 | N35: 완료 | O35: =IF(COUNTIFS('보고서 검토일지(26년)'!$H:$H, $G35, '보고서 검토일지(26년)'!$M:$M, "0", '보고서 검토일지(26년)'!$G:$G, $F35)>0, "완료", "") -> 완료 | P35: 46189
A36: 46181.647 | C36: CB-222 | D36: 공사-물가변동 | F36: 인천광역시 | G36: 드림로~원당대로간 도로개설공사 물가변동(5회) 검토 용역 | H36: 견적-최저 | I36: 2200000 | J36: 사업비 확인불가 | K36: 유 | L36: 견적제출
A37: 46181.647 | C37: CB-222 | D37: 공사-물가변동 | F37: 인천경제자유구역청 | G37: 송도 11-1공구 기반시설 건설 신호등 설치공사(1구역) 물가변동으로 인한 계약금액 조정 검토 용역(지수조정 2회) | H37: 견적-최저 | I37: 1650000 | J37: 사업비 확인불가 | K37: 유 | L37: 견적제출
A38: 46181.647 | C38: CB-211 | D38: 공사-공사원가 | F38: (주)금강패키지 | G38: 금강패키지 리프트 시설 교체 공사 원가계산 | H38: 견적-최저 | I38: 660000 | J38: 사업비 확인불가 | K38: 유 | L38: 견적제출
A39: 46177.687 | C39: CH-801 | D39: 비교견적 | F39: 리베라종합건설㈜ | G39: 대전체육고 복합체육관 증축공사 ESC 1차 | H39: 견적-비교견적 | I39: 4000000 | J39: 사업비 확인불가 | K39: 유 | L39: 비교견적
A40: 46177.687 | C40: CB-212 | D40: 공사-공사원가 | F40: 한국토지주택공사 | G40: 인천계양 국도39호선(벌말로) 확장공사 가스관로 및 열배관 이설비 적정성 검토 용역 | H40: 견적-최저 | I40: 18700000 | J40: 사업비 확인불가 | K40: 유 | L40: 견적제출
A41: 46177.47 | C41: CC-311 | D41: 학술용역-연구 | F41: 한국산업기술진흥원 | G41: 산업기술기반구축 관리 및 활용도 제고 연구용역 원가계산 | H41: 견적-최저 | I41: 440000 | J41: 50000000 | K41: 유 | L41: 수주 | M41: 장연주
A42: 46175.744 | C42: CC-321 | D42: 학술용역-행사, 운영(대행) | F42: 인천창조경제혁신센터 | G42: 모두의 창업 프로젝트 출범식 및 오리엔테이션 운영 용역 원가계산 | H42: 견적-최저 | I42: 440000 | J42: 사업비 확인불가 | K42: 유 | L42: 수주 | M42: 장연주 | N42: 완료 | O42: =IF(COUNTIFS('보고서 검토일지(26년)'!$H:$H, $G42, '보고서 검토일지(26년)'!$M:$M, "0", '보고서 검토일지(26년)'!$G:$G, $F42)>0, "완료", "") -> 완료 | P42: 46181
A43: 46175.714 | C43: CC-311 | D43: 학술용역-연구 | F43: 한국산업기술진흥원 | G43: 중견기업-공공연구기관 공동기획 성과조사 및 개편방안 마련 용역 원가계산 | H43: 견적-최저 | I43: 330000 | J43: 40000000 | K43: 유 | L43: 수주 | M43: 장연주
...

Sheet 제안서 진행현황
A1: 회의자료 | I1: 계약면적 | K1: 계약기간 | M1: 내역서 | O1: 보고서 | R1: 누계공정률 | W1: 도급금액(A) (V.A.T 별도) | AA1: 계약서 관리 | AF1: 외주금액 (B) (V.A.T 별도) | AP1: 현재공정 | AS1: 2026년 1월 | BZ1: 2026년 2월 | DC1: 2026년 3월 | FN1: 2026년 5월 | GS1: Ⅰ-1 | GT1: Ⅰ-2 | GU1: Ⅱ-1 | GV1: Ⅱ-2 | GW1: Ⅲ | GX1: Ⅳ | GY1: Ⅴ
A2: No. | B2: 진행상황 | D2: 업무코드 (세부코드) | E2: 업무분류 | F2: 발주처 | G2: 과업명 | H2: 업무구분 | I2: ㎡ | J2: 평 | K2: 시작일 | L2: 종료일 | M2: 착수일 (재착수일) | N2: 종료일 | O2: 착수일 (재착수일) | P2: 종료일 | Q2: 품질관리실 확인 | R2: 전주계획 | S2: 전주실적 | T2: 금주계획 | V2: 항목 | W2: 내용 | X2: 금액 | Y2: 세금계산서 확인 | Z2: 입금확인 | AA2: 작업구분 품의서 | AB2: 업체선정 품의서 | AC2: 발주 및 계약서 | AD2: 결제 여부 | AE2: 비고 | AF2: 내용 | AG2: 금액 | AH2: 집행 여부 | AI2: 외주집행금액 (V.A.T 별도) | AJ2: 잔금 (V.A.T 별도) | AL2: 참여자 | AM2: 구분 | AN2: 주업무 | AO2: 특이사항 | AP2: 시작일 | AQ2: 종료일 | AS2: 46023 | AT2: 46024 | AU2: 46025 | AV2: 46026 | AW2: 46027 | AX2: 46028 | AY2: 46029 | AZ2: 46030 | BA2: 46031 | BB2: 46032 | BC2: 46033 | BD2: 46034 | BE2: 46035 | BF2: 46036 | BG2: 46037 | BH2: 46038 | BI2: 46039 | BJ2: 46040 | BK2: 46041 | BL2: 46042 | BM2: 46043 | BN2: 46044 | BO2: 46045 | BP2: 46046 | BQ2: 46047 | BR2: 46048 | BS2: 46049 | BT2: 46050 | BU2: 46051 | BV2: 46052 | BW2: 46053 | BZ2: 46054 | CA2: 46055 | CB2: 46056 | CC2: 46057 | CD2: 46058 | CE2: 46059 | CF2: 46060 | CG2: 46061 | CH2: 46062 | CI2: 46063 | CJ2: 46064 | CK2: 46065 | CL2: 46066 | CM2: 46067 | CN2: 46068 | CO2: 46069 | CP2: 46070 | CQ2: 46071 | CR2: 46072 | CS2: 46073 | CT2: 46074 | CU2: 46075 | CV2: 46076 | CW2: 46077 | CX2: 46078 | CY2: 46079 | CZ2: 46080 | DA2: 46081 | DC2: 46082 | DD2: 46083 | DE2: 46084 | DF2: 46085 | DG2: 46086 | DH2: 46087 | DI2: 46088 | DJ2: 46089 | DK2: 46090 | DL2: 46091 | DM2: 46092 | DN2: 46093 | DO2: 46094 | DP2: 46095 | DQ2: 46096 | DR2: 46097 | DS2: 46098 | DT2: 46099 | DU2: 46100 | DV2: 46101 | DW2: 46102 | DX2: 46103 | DY2: 46104 | DZ2: 46105 | EA2: 46106 | EB2: 46107 | EC2: 46108 | ED2: 46109 | EE2: 46110 | EF2: 46111 | EG2: 46112 | EI2: 46113 | EJ2: 46114 | EK2: 46115 | EL2: 46116 | EM2: 46117 | EN2: 46118 | EO2: 46119 | EP2: 46120 | EQ2: 46121 | ER2: 46122 | ES2: 46123 | ET2: 46124 | EU2: 46125 | EV2: 46126 | EW2: 46127 | EX2: 46128 | EY2: 46129 | EZ2: 46130 | FA2: 46131 | FB2: 46132 | FC2: 46133 | FD2: 46134 | FE2: 46135 | FF2: 46136 | FG2: 46137 | FH2: 46138 | FI2: 46139 | FJ2: 46140 | FK2: 46141 | FL2: 46142 | FN2: 46143 | FO2: 46144 | FP2: 46145 | FQ2: 46146 | FR2: 46147 | FS2: 46148 | FT2: 46149 | FU2: 46150 | FV2: 46151 | FW2: 46152 | FX2: 46153 | FY2: 46154 | FZ2: 46155 | GA2: 46156 | GB2: 46157 | GC2: 46158 | GD2: 46159 | GE2: 46160 | GF2: 46161 | GG2: 46162 | GH2: 46163 | GI2: 46164 | GJ2: 46165 | GK2: 46166 | GL2: 46167 | GM2: 46168 | GN2: 46169 | GO2: 46170 | GP2: 46171 | GQ2: 46172 | GR2: 46173 | GS2: 1차체크 | GT2: 물량산출 | GU2: 2차체크 | GV2: 내역비교 | GW2: 기준표 검토 | GX2: 설계변경 | GY2: 원가검증
A3: 12 | B3: 현장 발표 완료 | D3: {=INDEX('코드분류표(보조)'!$G$5:$G$72,MATCH(E3,'코드분류표(보조)'!$F$5:$F$72,0))} -> CC-311 | E3: 학술용역-연구_산정 | F3: 국가공무원노동조합 | G3: 공무원 근무시간 면제제도의 운영실태 및 개선방안 관련 정책연구
A4: 11 | B4: 현장 발표 완료 | D4: {=INDEX('코드분류표(보조)'!$G$5:$G$72,MATCH(E4,'코드분류표(보조)'!$F$5:$F$72,0))} -> CC-311 | E4: 학술용역-연구_산정 | F4: 한국발명진흥회 | G4: 2026년~2027년 한국발명진흥회 원가계산 전문용역 기관 선정

Sheet 수주 및 입금 진행현황
A1: 2026년 수주, 세금계산서 및 입금진행현황
V5: 품질관리실 검토여부 및 이동버튼
A6: 견적일자 | B6: 계약기간 | C6: 업무코드 (세부코드) | D6: 업무분류 | F6: 발주처 | G6: 과업명 | H6: 수주방식 | I6: 견적금액 (VAT포함) | J6: 사업비 규모 | K6: 견적 유/무 | L6: 진행상태 | M6: 담당자 | N6: 완료 여부 | O6: 품질 관리실 확인여부 | P6: 보고서 제출일 | Q6: 세금계산서 발행일자 | R6: 세금계산서 발행금액 (VAT 포함) | S6: 입금일 | T6: 잔금 여부 | U6: 비고 | V6: 제안서 | W6: 최종보고서 | X6: 완료계 | Y6: 청구서
A7: 46182.475 | C7: CC-311 | D7: 학술용역-연구 | F7: 창업진흥원 | G7: 몽골 스타트업 지원인력 초청연수 위탁용역 원가계산 | H7: 견적-최저 | I7: 550000 | J7: 90000000 | K7: 유 | L7: 수주 | M7: 장연주 | N7: 완료 | O7: =IF(COUNTIFS('보고서 검토일지(26년)'!$H:$H, $G7, '보고서 검토일지(26년)'!$M:$M, "0", '보고서 검토일지(26년)'!$G:$G, $F7)>0, "완료", "") -> 완료 | P7: 46183
A8: 46182.373 | C8: CC-311 | D8: 학술용역-연구 | F8: 한국에너지기술평가원 | G8: ESG경영 체계 고도화 및 ESG경영보고서 발간 원가계산 | H8: 견적-최저 | I8: 440000 | J8: 55000000 | K8: 유 | L8: 수주 | M8: 장연주
A9: 46181.647 | C9: CC-321 | D9: 학술용역-행사, 운영(대행) | F9: 한국산업기술기획평가원 | G9: 2026 코리아테크페스티벌(가칭) 종합운영·홍보 및 전시설치 용역 원가계산 | H9: 견적-최저 | I9: 660000 | J9: 900000000 | K9: 유 | L9: 수주 | M9: 장연주 | N9: 완료 | O9: =IF(COUNTIFS('보고서 검토일지(26년)'!$H:$H, $G9, '보고서 검토일지(26년)'!$M:$M, "0", '보고서 검토일지(26년)'!$G:$G, $F9)>0, "완료", "") -> 완료 | P9: 46188 | Q9: 46188 | R9: 660000
A10: 46181.647 | C10: CC-311 | D10: 학술용역-연구 | F10: 소상공인시장진흥공단 | G10: 2026년 소상공인 재기지원사업 성과분석 용역 원가계산 | H10: 견적-최저 | I10: 990000 | J10: 사업비 확인불가 | K10: 유 | L10: 수주 | M10: 장연주 | N10: 완료 | O10: =IF(COUNTIFS('보고서 검토일지(26년)'!$H:$H, $G10, '보고서 검토일지(26년)'!$M:$M, "0", '보고서 검토일지(26년)'!$G:$G, $F10)>0, "완료", "") -> 완료 | P10: 46189
A11: 46177.47 | C11: CC-311 | D11: 학술용역-연구 | F11: 한국산업기술진흥원 | G11: 산업기술기반구축 관리 및 활용도 제고 연구용역 원가계산 | H11: 견적-최저 | I11: 440000 | J11: 50000000 | K11: 유 | L11: 수주 | M11: 장연주
A12: 46175.714 | C12: CC-311 | D12: 학술용역-연구 | F12: 한국산업기술진흥원 | G12: 중견기업-공공연구기관 공동기획 성과조사 및 개편방안 마련 용역 원가계산 | H12: 견적-최저 | I12: 330000 | J12: 40000000 | K12: 유 | L12: 수주 | M12: 장연주
A13: 46160.417 | B13: 26.05.29~26.06.12 (착수일로부터 14일) | C13: CB-232 | D13: 공사-개발비용 | F13: 영등포구청 | G13: 양평동 1가 243-1 일대 개발비용 산출명세서 검증용역 | H13: 견적-최저 | I13: 1320000 | J13: 사업비 확인불가 | K13: 유 | L13: 수주
A14: 46175.744 | C14: CC-321 | D14: 학술용역-행사, 운영(대행) | F14: 인천창조경제혁신센터 | G14: 모두의 창업 프로젝트 출범식 및 오리엔테이션 운영 용역 원가계산 | H14: 견적-최저 | I14: 440000 | J14: 사업비 확인불가 | K14: 유 | L14: 수주 | M14: 장연주 | N14: 완료 | O14: =IF(COUNTIFS('보고서 검토일지(26년)'!$H:$H, $G14, '보고서 검토일지(26년)'!$M:$M, "0", '보고서 검토일지(26년)'!$G:$G, $F14)>0, "완료", "") -> 완료
A15: 46174.561 | C15: CC-311 | D15: 학술용역-연구 | F15: (재)장애인기업종합지원센터 | G15: 2026년 창업사업화 지원사업 수혜자 집행 내역 회계점검 원가계산 | H15: 견적-최저 | I15: 330000 | J15: 11000000 | K15: 유 | L15: 수주 | M15: 장연주 | N15: 완료 | O15: =IF(COUNTIFS('보고서 검토일지(26년)'!$H:$H, $G15, '보고서 검토일지(26년)'!$M:$M, "0", '보고서 검토일지(26년)'!$G:$G, $F15)>0, "완료", "") -> 완료 | P15: 46178 | Q15: 46178 | R15: 330000
A16: 46171 | C16: CC-311 | D16: 학술용역-연구 | F16: 한국산업기술진흥원 | G16: 첨단산업 인재혁신 촉진제도 홍보 용역 원가계산 | H16: 견적-최저 | I16: 880000 | J16: 104000000 | K16: 유 | L16: 수주 | M16: 장연주 | N16: 완료 | O16: =IF(COUNTIFS('보고서 검토일지(26년)'!$H:$H, $G16, '보고서 검토일지(26년)'!$M:$M, "0", '보고서 검토일지(26년)'!$G:$G, $F16)>0, "완료", "") -> 완료 | P16: 46171 | Q16: 46178 | R16: 880000 | V16: {=LET(행번호, MATCH(1, INDEX(('보고서 검토일지(26년)'!$G:$G=F16) * ('보고서 검토일지(26년)'!$H:$H=G16) * ('보고서 검토일지(26년)'!$I:$I="제안서"), 0), 0), IF(ISNUMBER(행번호), HYPERLINK("#gid=" & "0" & "&range=A" & 행번호, "완료"), "-"))} -> - | W16: 완료 | X16: 완료 | Y16: 완료
A17: 46170.428 | C17: CC-311 | D17: 학술용역-연구 | F17: 한국산업기술기획평가원 | G17: KEIT(한국산업기술기획평가원) R&D지원 효과 종합분석 용역 원가계산 | H17: 견적-최저 | I17: 660000 | J17: 105000000 | K17: 유 | L17: 수주 | M17: 장연주 | N17: 완료 | O17: =IF(COUNTIFS('보고서 검토일지(26년)'!$H:$H, $G17, '보고서 검토일지(26년)'!$M:$M, "0", '보고서 검토일지(26년)'!$G:$G, $F17)>0, "완료", "") -> 완료 | P17: 46178
A18: 46170.462 | C18: CC-321 | D18: 학술용역-행사, 운영(대행) | F18: 한국의료기기안전정보원 | G18: MDSAP 평가자 양성 교육 운영 원가계산 | H18: 견적-최저 | I18: 440000 | J18: 6000000 | K18: 유 | L18: 수주 | M18: 장연주 | N18: 완료 | O18: =IF(COUNTIFS('보고서 검토일지(26년)'!$H:$H, $G18, '보고서 검토일지(26년)'!$M:$M, "0", '보고서 검토일지(26년)'!$G:$G, $F18)>0, "완료", "") -> 완료 | P18: 46175 | Q18: 46178 | R18: 440000 | V18: {=LET(행번호, MATCH(1, INDEX(('보고서 검토일지(26년)'!$G:$G=F18) * ('보고서 검토일지(26년)'!$H:$H=G18) * ('보고서 검토일지(26년)'!$I:$I="제안서"), 0), 0), IF(ISNUMBER(행번호), HYPERLINK("#gid=" & "0" & "&range=A" & 행번호, "완료"), "-"))} -> - | W18: 완료 | X18: {=LET(행번호, MATCH(1, INDEX(('보고서 검토일지(26년)'!$G:$G=F18) * ('보고서 검토일지(26년)'!$H:$H=G18) * ('보고서 검토일지(26년)'!$I:$I="완료계"), 0), 0), IF(ISNUMBER(행번호), HYPERLINK("#gid=" & "0" & "&range=A" & 행번호, "완료"), "-"))} -> - | Y18: 완료
A19: 46170.424 | C19: CB-211 | D19: 공사-공사원가 | F19: 스이레이 | G19: 2026년 안전동행 지원사업 원가계산 | H19: 연단가-견적 | I19: 880000 | J19: 사업비 확인불가 | K19: 유 | L19: 연단가 | M19: 하은정 | N19: 완료 | O19: =IF(COUNTIFS('보고서 검토일지(26년)'!$H:$H, $G19, '보고서 검토일지(26년)'!$M:$M, "0", '보고서 검토일지(26년)'!$G:$G, $F19)>0, "완료", "") -> 완료 | P19: 46170 | V19: {=LET(행번호, MATCH(1, INDEX(('보고서 검토일지(26년)'!$G:$G=F19) * ('보고서 검토일지(26년)'!$H:$H=G19) * ('보고서 검토일지(26년)'!$I:$I="제안서"), 0), 0), IF(ISNUMBER(행번호), HYPERLINK("#gid=" & "0" & "&range=A" & 행번호, "완료"), "-"))} -> - | W19: 완료 | X19: {=LET(행번호, MATCH(1, INDEX(('보고서 검토일지(26년)'!$G:$G=F19) * ('보고서 검토일지(26년)'!$H:$H=G19) * ('보고서 검토일지(26년)'!$I:$I="완료계"), 0), 0), IF(ISNUMBER(행번호), HYPERLINK("#gid=" & "0" & "&range=A" & 행번호, "완료"), "-"))} -> - | Y19: {=LET(행번호, MATCH(1, INDEX(('보고서 검토일지(26년)'!$G:$G=F19) * ('보고서 검토일지(26년)'!$H:$H=G19) * ('보고서 검토일지(26년)'!$I:$I="청구서"), 0), 0), IF(ISNUMBER(행번호), HYPERLINK("#gid=" & "0" & "&range=A" & 행번호, "완료"), "-"))} -> -
A20: 46170.424 | C20: CB-211 | D20: 공사-공사원가 | F20: 엠탑 | G20: 2026년 안전동행 지원사업 원가계산 | H20: 연단가-견적 | I20: 880000 | J20: 사업비 확인불가 | K20: 유 | L20: 연단가 | M20: 하은정 | N20: 완료 | O20: =IF(COUNTIFS('보고서 검토일지(26년)'!$H:$H, $G20, '보고서 검토일지(26년)'!$M:$M, "0", '보고서 검토일지(26년)'!$G:$G, $F20)>0, "완료", "") -> 완료 | P20: 46170 | V20: {=LET(행번호, MATCH(1, INDEX(('보고서 검토일지(26년)'!$G:$G=F20) * ('보고서 검토일지(26년)'!$H:$H=G20) * ('보고서 검토일지(26년)'!$I:$I="제안서"), 0), 0), IF(ISNUMBER(행번호), HYPERLINK("#gid=" & "0" & "&range=A" & 행번호, "완료"), "-"))} -> - | W20: 완료 | X20: {=LET(행번호, MATCH(1, INDEX(('보고서 검토일지(26년)'!$G:$G=F20) * ('보고서 검토일지(26년)'!$H:$H=G20) * ('보고서 검토일지(26년)'!$I:$I="완료계"), 0), 0), IF(ISNUMBER(행번호), HYPERLINK("#gid=" & "0" & "&range=A" & 행번호, "완료"), "-"))} -> - | Y20: {=LET(행번호, MATCH(1, INDEX(('보고서 검토일지(26년)'!$G:$G=F20) * ('보고서 검토일지(26년)'!$H:$H=G20) * ('보고서 검토일지(26년)'!$I:$I="청구서"), 0), 0), IF(ISNUMBER(행번호), HYPERLINK("#gid=" & "0" & "&range=A" & 행번호, "완료"), "-"))} -> -
A21: 46170.424 | C21: CB-211 | D21: 공사-공사원가 | F21: 신양플레이팅 | G21: 2026년 안전동행 지원사업 원가계산 | H21: 연단가-견적 | I21: 880000 | J21: 사업비 확인불가 | K21: 유 | L21: 연단가 | M21: 하은정 | N21: 완료 | O21: =IF(COUNTIFS('보고서 검토일지(26년)'!$H:$H, $G21, '보고서 검토일지(26년)'!$M:$M, "0", '보고서 검토일지(26년)'!$G:$G, $F21)>0, "완료", "") -> 완료 | P21: 46170 | V21: {=LET(행번호, MATCH(1, INDEX(('보고서 검토일지(26년)'!$G:$G=F21) * ('보고서 검토일지(26년)'!$H:$H=G21) * ('보고서 검토일지(26년)'!$I:$I="제안서"), 0), 0), IF(ISNUMBER(행번호), HYPERLINK("#gid=" & "0" & "&range=A" & 행번호, "완료"), "-"))} -> - | W21: 완료 | X21: {=LET(행번호, MATCH(1, INDEX(('보고서 검토일지(26년)'!$G:$G=F21) * ('보고서 검토일지(26년)'!$H:$H=G21) * ('보고서 검토일지(26년)'!$I:$I="완료계"), 0), 0), IF(ISNUMBER(행번호), HYPERLINK("#gid=" & "0" & "&range=A" & 행번호, "완료"), "-"))} -> - | Y21: {=LET(행번호, MATCH(1, INDEX(('보고서 검토일지(26년)'!$G:$G=F21) * ('보고서 검토일지(26년)'!$H:$H=G21) * ('보고서 검토일지(26년)'!$I:$I="청구서"), 0), 0), IF(ISNUMBER(행번호), HYPERLINK("#gid=" & "0" & "&range=A" & 행번호, "완료"), "-"))} -> -
A22: 46169.611 | C22: CC-311 | D22: 학술용역-연구 | F22: 한국산업기술진흥원 | G22: 2026년 기후에너지환경부 ODA 종료평가 용역 원가계산 | H22: 견적-최저 | I22: 880000 | J22: 230000000 | K22: 유 | L22: 수주 | M22: 장연주
A23: 46164.714 | C23: CC-321 | D23: 학술용역-행사, 운영(대행) | F23: 정보통신기획평가원 | G23: CES 2027 디지털 청년인재 토크콘서트 행사 기획 및 운영 용역 원가계산 | H23: 견적-최저 | I23: 1100000 | J23: 170000000 | K23: 유 | L23: 수주 | M23: 장연주 | N23: 완료 | O23: =IF(COUNTIFS('보고서 검토일지(26년)'!$H:$H, $G23, '보고서 검토일지(26년)'!$M:$M, "0", '보고서 검토일지(26년)'!$G:$G, $F23)>0, "완료", "") -> 완료 | P23: 46171 | V23: {=LET(행번호, MATCH(1, INDEX(('보고서 검토일지(26년)'!$G:$G=F23) * ('보고서 검토일지(26년)'!$H:$H=G23) * ('보고서 검토일지(26년)'!$I:$I="제안서"), 0), 0), IF(ISNUMBER(행번호), HYPERLINK("#gid=" & "0" & "&range=A" & 행번호, "완료"), "-"))} -> - | W23: 완료 | X23: 완료 | Y23: {=LET(행번호, MATCH(1, INDEX(('보고서 검토일지(26년)'!$G:$G=F23) * ('보고서 검토일지(26년)'!$H:$H=G23) * ('보고서 검토일지(26년)'!$I:$I="청구서"), 0), 0), IF(ISNUMBER(행번호), HYPERLINK("#gid=" & "0" & "&range=A" & 행번호, "완료"), "-"))} -> -
A24: 46164.464 | C24: CC-321 | D24: 학술용역-행사, 운영(대행) | F24: 인천창조경제혁신센터 | G24: 모두의 창업 프로젝트 선배 창업자 인사이트 강연 운영 용역 원가계산 | H24: 견적-최저 | I24: 330000 | J24: 13700000 | K24: 유 | L24: 수주 | M24: 장연주 | N24: 완료 | O24: =IF(COUNTIFS('보고서 검토일지(26년)'!$H:$H, $G24, '보고서 검토일지(26년)'!$M:$M, "0", '보고서 검토일지(26년)'!$G:$G, $F24)>0, "완료", "") -> 완료 | P24: 46169 | Q24: 46169 | R24: 330000 | V24: {=LET(행번호, MATCH(1, INDEX(('보고서 검토일지(26년)'!$G:$G=F24) * ('보고서 검토일지(26년)'!$H:$H=G24) * ('보고서 검토일지(26년)'!$I:$I="제안서"), 0), 0), IF(ISNUMBER(행번호), HYPERLINK("#gid=" & "0" & "&range=A" & 행번호, "완료"), "-"))} -> - | W24: 완료 | X24: {=LET(행번호, MATCH(1, INDEX(('보고서 검토일지(26년)'!$G:$G=F24) * ('보고서 검토일지(26년)'!$H:$H=G24) * ('보고서 검토일지(26년)'!$I:$I="완료계"), 0), 0), IF(ISNUMBER(행번호), HYPERLINK("#gid=" & "0" & "&range=A" & 행번호, "완료"), "-"))} -> - | Y24: 완료
A25: 46162.569 | C25: CC-341 | D25: 일반용역-S/W | F25: 한국방사선진흥협회 | G25: RATIS AI 도입을 위한 DB 정비 및 AI 챗봇 서비스 개발(시범운영) 원가계산 | H25: 견적-최저 | I25: 1650000 | J25: 170000000 | K25: 유 | L25: 수주 | M25: 장연주 | N25: 완료 | O25: =IF(COUNTIFS('보고서 검토일지(26년)'!$H:$H, $G25, '보고서 검토일지(26년)'!$M:$M, "0", '보고서 검토일지(26년)'!$G:$G, $F25)>0, "완료", "") -> 완료 | P25: 46184 | Q25: 46184 | R25: 1650000 | V25: {=LET(행번호, MATCH(1, INDEX(('보고서 검토일지(26년)'!$G:$G=F25) * ('보고서 검토일지(26년)'!$H:$H=G25) * ('보고서 검토일지(26년)'!$I:$I="제안서"), 0), 0), IF(ISNUMBER(행번호), HYPERLINK("#gid=" & "0" & "&range=A" & 행번호, "완료"), "-"))} -> - | W25: 완료 | X25: 완료 | Y25: 완료
A26: 46161.579 | C26: CC-311 | D26: 학술용역-연구 | F26: 소상공인시장진흥공단 | G26: 2026년 스마트상점 기술보급사업 홍보전략 수립 및 운영 용역 원가계산 | H26: 견적-최저 | I26: 1650000 | J26: 250000000 | K26: 유 | L26: 수주 | M26: 장연주 | N26: 완료 | O26: =IF(COUNTIFS('보고서 검토일지(26년)'!$H:$H, $G26, '보고서 검토일지(26년)'!$M:$M, "0", '보고서 검토일지(26년)'!$G:$G, $F26)>0, "완료", "") -> 완료 | P26: 46170 | V26: {=LET(행번호, MATCH(1, INDEX(('보고서 검토일지(26년)'!$G:$G=F26) * ('보고서 검토일지(26년)'!$H:$H=G26) * ('보고서 검토일지(26년)'!$I:$I="제안서"), 0), 0), IF(ISNUMBER(행번호), HYPERLINK("#gid=" & "0" & "&range=A" & 행번호, "완료"), "-"))} -> - | W26: 완료 | X26: 완료 | Y26: {=LET(행번호, MATCH(1, INDEX(('보고서 검토일지(26년)'!$G:$G=F26) * ('보고서 검토일지(26년)'!$H:$H=G26) * ('보고서 검토일지(26년)'!$I:$I="청구서"), 0), 0), IF(ISNUMBER(행번호), HYPERLINK("#gid=" & "0" & "&range=A" & 행번호, "완료"), "-"))} -> -
A27: 46161.579 | C27: CC-321 | D27: 학술용역-행사, 운영(대행) | F27: (재)경남창조경제혁신센터 | G27: 2026 경남 창업기업 역량강화 A.C.E경진대회 프로그램 운영 용역 원가계산 | H27: 견적-최저 | I27: 900000 | J27: 74000000 | K27: 유 | L27: 수주 | M27: 장연주 | N27: 완료 | O27: =IF(COUNTIFS('보고서 검토일지(26년)'!$H:$H, $G27, '보고서 검토일지(26년)'!$M:$M, "0", '보고서 검토일지(26년)'!$G:$G, $F27)>0, "완료", "") -> 완료 | P27: 46169 | Q27: 46174 | R27: 900000 | V27: {=LET(행번호, MATCH(1, INDEX(('보고서 검토일지(26년)'!$G:$G=F27) * ('보고서 검토일지(26년)'!$H:$H=G27) * ('보고서 검토일지(26년)'!$I:$I="제안서"), 0), 0), IF(ISNUMBER(행번호), HYPERLINK("#gid=" & "0" & "&range=A" & 행번호, "완료"), "-"))} -> - | W27: 완료 | X27: {=LET(행번호, MATCH(1, INDEX(('보고서 검토일지(26년)'!$G:$G=F27) * ('보고서 검토일지(26년)'!$H:$H=G27) * ('보고서 검토일지(26년)'!$I:$I="완료계"), 0), 0), IF(ISNUMBER(행번호), HYPERLINK("#gid=" & "0" & "&range=A" & 행번호, "완료"), "-"))} -> - | Y27: 완료
A28: 46157.447 | C28: CC-341 | D28: 일반용역-S/W | F28: 창업진흥원 | G28: 원스톱 지원센터 상담플랫폼 기능개선 용역 원가계산 | H28: 견적-최저 | I28: 1100000 | J28: 198000000 | K28: 유 | L28: 수주 | M28: 장연주 | N28: 완료 | O28: =IF(COUNTIFS('보고서 검토일지(26년)'!$H:$H, $G28, '보고서 검토일지(26년)'!$M:$M, "0", '보고서 검토일지(26년)'!$G:$G, $F28)>0, "완료", "") -> 완료 | P28: 46164 | Q28: 46168 | R28: 1100000 | V28: {=LET(행번호, MATCH(1, INDEX(('보고서 검토일지(26년)'!$G:$G=F28) * ('보고서 검토일지(26년)'!$H:$H=G28) * ('보고서 검토일지(26년)'!$I:$I="제안서"), 0), 0), IF(ISNUMBER(행번호), HYPERLINK("#gid=" & "0" & "&range=A" & 행번호, "완료"), "-"))} -> - | W28: 완료 | X28: 완료 | Y28: {=LET(행번호, MATCH(1, INDEX(('보고서 검토일지(26년)'!$G:$G=F28) * ('보고서 검토일지(26년)'!$H:$H=G28) * ('보고서 검토일지(26년)'!$I:$I="청구서"), 0), 0), IF(ISNUMBER(행번호), HYPERLINK("#gid=" & "0" & "&range=A" & 행번호, "완료"), "-"))} -> -
A29: 46157.447 | C29: CA-111 | D29: 제조-제조(제작설치포함) | F29: (주)위즈윙 | G29: AI기반 순찰용 배터리 자동교체식 드론시스템 원가계산 | H29: 견적-최저 | I29: 990000 | J29: 사업비 확인불가 | K29: 유 | L29: 수주 | M29: 하은정 | N29: 완료 | O29: =IF(COUNTIFS('보고서 검토일지(26년)'!$H:$H, $G29, '보고서 검토일지(26년)'!$M:$M, "0", '보고서 검토일지(26년)'!$G:$G, $F29)>0, "완료", "") | P29: 46157 | V29: {=LET(행번호, MATCH(1, INDEX(('보고서 검토일지(26년)'!$G:$G=F29) * ('보고서 검토일지(26년)'!$H:$H=G29) * ('보고서 검토일지(26년)'!$I:$I="제안서"), 0), 0), IF(ISNUMBER(행번호), HYPERLINK("#gid=" & "0" & "&range=A" & 행번호, "완료"), "-"))} -> - | W29: {=LET(행번호, MATCH(1, INDEX(('보고서 검토일지(26년)'!$G:$G=F29) * ('보고서 검토일지(26년)'!$H:$H=G29) * ('보고서 검토일지(26년)'!$I:$I="최종보고서"), 0), 0), IF(ISNUMBER(행번호), HYPERLINK("#gid=" & "0" & "&range=A" & 행번호, "완료"), "-"))} -> - | X29: {=LET(행번호, MATCH(1, INDEX(('보고서 검토일지(26년)'!$G:$G=F29) * ('보고서 검토일지(26년)'!$H:$H=G29) * ('보고서 검토일지(26년)'!$I:$I="완료계"), 0), 0), IF(ISNUMBER(행번호), HYPERLINK("#gid=" & "0" & "&range=A" & 행번호, "완료"), "-"))} -> - | Y29: {=LET(행번호, MATCH(1, INDEX(('보고서 검토일지(26년)'!$G:$G=F29) * ('보고서 검토일지(26년)'!$H:$H=G29) * ('보고서 검토일지(26년)'!$I:$I="청구서"), 0), 0), IF(ISNUMBER(행번호), HYPERLINK("#gid=" & "0" & "&range=A" & 행번호, "완료"), "-"))} -> -
A30: 46157.447 | C30: CC-311 | D30: 학술용역-연구 | F30: 한국산업기술진흥원 | G30: 2026년도 글로벌 산업기술정책 동향조사분석 원가계산 | H30: 견적-최저 | I30: 770000 | J30: 140000000 | K30: 유 | L30: 수주 | M30: 장연주 | N30: 완료 | O30: =IF(COUNTIFS('보고서 검토일지(26년)'!$H:$H, $G30, '보고서 검토일지(26년)'!$M:$M, "0", '보고서 검토일지(26년)'!$G:$G, $F30)>0, "완료", "") -> 완료 | P30: 46162 | Q30: 46163 | R30: 770000 | V30: {=LET(행번호, MATCH(1, INDEX(('보고서 검토일지(26년)'!$G:$G=F30) * ('보고서 검토일지(26년)'!$H:$H=G30) * ('보고서 검토일지(26년)'!$I:$I="제안서"), 0), 0), IF(ISNUMBER(행번호), HYPERLINK("#gid=" & "0" & "&range=A" & 행번호, "완료"), "-"))} -> - | W30: 완료 | X30: 완료 | Y30: {=LET(행번호, MATCH(1, INDEX(('보고서 검토일지(26년)'!$G:$G=F30) * ('보고서 검토일지(26년)'!$H:$H=G30) * ('보고서 검토일지(26년)'!$I:$I="청구서"), 0), 0), IF(ISNUMBER(행번호), HYPERLINK("#gid=" & "0" & "&range=A" & 행번호, "완료"), "-"))} -> -
A31: 46157.684 | C31: CC-321 | D31: 학술용역-행사, 운영(대행) | F31: 소상공인시장진흥공단 | G31: ‘26년 로컬창업기업 육성 성과확산 용역 원가계산 | H31: 견적-최저 | I31: 1980000 | J31: 420000000 | K31: 유 | L31: 수주 | M31: 장연주 | N31: 완료 | O31: =IF(COUNTIFS('보고서 검토일지(26년)'!$H:$H, $G31, '보고서 검토일지(26년)'!$M:$M, "0", '보고서 검토일지(26년)'!$G:$G, $F31)>0, "완료", "") -> 완료 | P31: 46161 | V31: {=LET(행번호, MATCH(1, INDEX(('보고서 검토일지(26년)'!$G:$G=F31) * ('보고서 검토일지(26년)'!$H:$H=G31) * ('보고서 검토일지(26년)'!$I:$I="제안서"), 0), 0), IF(ISNUMBER(행번호), HYPERLINK("#gid=" & "0" & "&range=A" & 행번호, "완료"), "-"))} -> - | W31: 완료 | X31: 완료 | Y31: {=LET(행번호, MATCH(1, INDEX(('보고서 검토일지(26년)'!$G:$G=F31) * ('보고서 검토일지(26년)'!$H:$H=G31) * ('보고서 검토일지(26년)'!$I:$I="청구서"), 0), 0), IF(ISNUMBER(행번호), HYPERLINK("#gid=" & "0" & "&range=A" & 행번호, "완료"), "-"))} -> -
A32: 46160.632 | C32: CC-311 | D32: 학술용역-연구 | F32: 건설근로자공제회 | G32: 건설근로자 인력수급전망 모형 구축 연구용역 원가계산 | H32: 연단가-견적 | I32: 550000 | J32: 84500000 | K32: 유 | L32: 연단가 | M32: 장연주 | N32: 완료 | O32: =IF(COUNTIFS('보고서 검토일지(26년)'!$H:$H, $G32, '보고서 검토일지(26년)'!$M:$M, "0", '보고서 검토일지(26년)'!$G:$G, $F32)>0, "완료", "") -> 완료 | P32: 46160 | Q32: 46160 | R32: 550000 | V32: {=LET(행번호, MATCH(1, INDEX(('보고서 검토일지(26년)'!$G:$G=F32) * ('보고서 검토일지(26년)'!$H:$H=G32) * ('보고서 검토일지(26년)'!$I:$I="제안서"), 0), 0), IF(ISNUMBER(행번호), HYPERLINK("#gid=" & "0" & "&range=A" & 행번호, "완료"), "-"))} -> - | W32: 완료 | X32: 완료 | Y32: {=LET(행번호, MATCH(1, INDEX(('보고서 검토일지(26년)'!$G:$G=F32) * ('보고서 검토일지(26년)'!$H:$H=G32) * ('보고서 검토일지(26년)'!$I:$I="청구서"), 0), 0), IF(ISNUMBER(행번호), HYPERLINK("#gid=" & "0" & "&range=A" & 행번호, "완료"), "-"))} -> -
A33: 46155.774 | C33: CC-311 | D33: 학술용역-연구 | F33: 한국방사선진흥협회 | G33: 방사선 계측 방법별 교육 가상환경 구축을 위한 VR 교육 자료 콘텐츠 제작 및 UI/UX 제작 원가계산 | H33: 견적-최저 | I33: 1650000 | J33: 150000000 | K33: 유 | L33: 수주 | M33: 장연주 | N33: 완료 | O33: =IF(COUNTIFS('보고서 검토일지(26년)'!$H:$H, $G33, '보고서 검토일지(26년)'!$M:$M, "0", '보고서 검토일지(26년)'!$G:$G, $F33)>0, "완료", "") -> 완료 | P33: 46169 | Q33: 46169 | R33: 1650000 | V33: {=LET(행번호, MATCH(1, INDEX(('보고서 검토일지(26년)'!$G:$G=F33) * ('보고서 검토일지(26년)'!$H:$H=G33) * ('보고서 검토일지(26년)'!$I:$I="제안서"), 0), 0), IF(ISNUMBER(행번호), HYPERLINK("#gid=" & "0" & "&range=A" & 행번호, "완료"), "-"))} -> - | W33: 완료 | X33: 완료 | Y33: 완료
A34: 46155.773 | C34: CC-311 | D34: 학술용역-연구 | F34: 한국방사선진흥협회 | G34: 이러닝플랫폼 AI Agent 개발 용역 원가계산 | H34: 견적-최저 | I34: 1650000 | J34: 104000000 | K34: 유 | L34: 수주 | M34: 장연주 | N34: 완료 | O34: =IF(COUNTIFS('보고서 검토일지(26년)'!$H:$H, $G34, '보고서 검토일지(26년)'!$M:$M, "0", '보고서 검토일지(26년)'!$G:$G, $F34)>0, "완료", "") -> 완료 | P34: 46169 | Q34: 46169 | R34: 1650000 | V34: {=LET(행번호, MATCH(1, INDEX(('보고서 검토일지(26년)'!$G:$G=F34) * ('보고서 검토일지(26년)'!$H:$H=G34) * ('보고서 검토일지(26년)'!$I:$I="제안서"), 0), 0), IF(ISNUMBER(행번호), HYPERLINK("#gid=" & "0" & "&range=A" & 행번호, "완료"), "-"))} -> - | W34: 완료 | X34: 완료 | Y34: 완료
A35: 46154.745 | C35: CB-211 | D35: 공사-공사원가 | F35: 한국자산관리공사 | G35: 용인통합청사 신축 전기, 통신, 소방 원가검증 | H35: 견적-최저 | I35: 330000 | J35: 사업비 확인불가 | K35: 유 | L35: 수주 | M35: 하은정 | V35: {=LET(행번호, MATCH(1, INDEX(('보고서 검토일지(26년)'!$G:$G=F35) * ('보고서 검토일지(26년)'!$H:$H=G35) * ('보고서 검토일지(26년)'!$I:$I="제안서"), 0), 0), IF(ISNUMBER(행번호), HYPERLINK("#gid=" & "0" & "&range=A" & 행번호, "완료"), "-"))} -> - | W35: {=LET(행번호, MATCH(1, INDEX(('보고서 검토일지(26년)'!$G:$G=F35) * ('보고서 검토일지(26년)'!$H:$H=G35) * ('보고서 검토일지(26년)'!$I:$I="최종보고서"), 0), 0), IF(ISNUMBER(행번호), HYPERLINK("#gid=" & "0" & "&range=A" & 행번호, "완료"), "-"))} -> - | X35: {=LET(행번호, MATCH(1, INDEX(('보고서 검토일지(26년)'!$G:$G=F35) * ('보고서 검토일지(26년)'!$H:$H=G35) * ('보고서 검토일지(26년)'!$I:$I="완료계"), 0), 0), IF(ISNUMBER(행번호), HYPERLINK("#gid=" & "0" & "&range=A" & 행번호, "완료"), "-"))} -> - | Y35: {=LET(행번호, MATCH(1, INDEX(('보고서 검토일지(26년)'!$G:$G=F35) * ('보고서 검토일지(26년)'!$H:$H=G35) * ('보고서 검토일지(26년)'!$I:$I="청구서"), 0), 0), IF(ISNUMBER(행번호), HYPERLINK("#gid=" & "0" & "&range=A" & 행번호, "완료"), "-"))} -> -
A36: 46154.739 | C36: CC-321 | D36: 학술용역-행사, 운영(대행) | F36: 포방터시장 문화관광형시장 육성사업단 | G36: 2026년 포방터시장 특화 디자인 거리 조성 사업 원가계산 | H36: 견적-최저 | I36: 550000 | J36: 39450000 | K36: 유 | L36: 수주 | M36: 하은정 | N36: 완료 | O36: =IF(COUNTIFS('보고서 검토일지(26년)'!$H:$H, $G36, '보고서 검토일지(26년)'!$M:$M, "0", '보고서 검토일지(26년)'!$G:$G, $F36)>0, "완료", "") -> 완료 | P36: 46163 | V36: {=LET(행번호, MATCH(1, INDEX(('보고서 검토일지(26년)'!$G:$G=F36) * ('보고서 검토일지(26년)'!$H:$H=G36) * ('보고서 검토일지(26년)'!$I:$I="제안서"), 0), 0), IF(ISNUMBER(행번호), HYPERLINK("#gid=" & "0" & "&range=A" & 행번호, "완료"), "-"))} -> - | W36: 완료 | X36: {=LET(행번호, MATCH(1, INDEX(('보고서 검토일지(26년)'!$G:$G=F36) * ('보고서 검토일지(26년)'!$H:$H=G36) * ('보고서 검토일지(26년)'!$I:$I="완료계"), 0), 0), IF(ISNUMBER(행번호), HYPERLINK("#gid=" & "0" & "&range=A" & 행번호, "완료"), "-"))} -> - | Y36: {=LET(행번호, MATCH(1, INDEX(('보고서 검토일지(26년)'!$G:$G=F36) * ('보고서 검토일지(26년)'!$H:$H=G36) * ('보고서 검토일지(26년)'!$I:$I="청구서"), 0), 0), IF(ISNUMBER(행번호), HYPERLINK("#gid=" & "0" & "&range=A" & 행번호, "완료"), "-"))} -> -
A37: 46154.739 | C37: CC-311 | D37: 학술용역-연구 | F37: 한국장애인고용공단 | G37: 장애인 고용컨설팅 포털 콘텐츠 수집‧구성 연구용역 원가계산 | H37: 견적-최저 | I37: 550000 | J37: 120000000 | K37: 유 | L37: 수주 | M37: 장연주 | N37: 완료 | O37: =IF(COUNTIFS('보고서 검토일지(26년)'!$H:$H, $G37, '보고서 검토일지(26년)'!$M:$M, "0", '보고서 검토일지(26년)'!$G:$G, $F37)>0, "완료", "") -> 완료 | P37: 46169 | V37: {=LET(행번호, MATCH(1, INDEX(('보고서 검토일지(26년)'!$G:$G=F37) * ('보고서 검토일지(26년)'!$H:$H=G37) * ('보고서 검토일지(26년)'!$I:$I="제안서"), 0), 0), IF(ISNUMBER(행번호), HYPERLINK("#gid=" & "0" & "&range=A" & 행번호, "완료"), "-"))} -> - | W37: 완료 | X37: 완료 | Y37: {=LET(행번호, MATCH(1, INDEX(('보고서 검토일지(26년)'!$G:$G=F37) * ('보고서 검토일지(26년)'!$H:$H=G37) * ('보고서 검토일지(26년)'!$I:$I="청구서"), 0), 0), IF(ISNUMBER(행번호), HYPERLINK("#gid=" & "0" & "&range=A" & 행번호, "완료"), "-"))} -> -
A38: 46154.739 | C38: CC-321 | D38: 학술용역-행사, 운영(대행) | F38: 인천창조경제혁신센터 | G38: 2026년 창업-BuS 연합IR 행사 운영(미래산업 및 투자활성화 세미나) 원가계산 | H38: 견적-최저 | I38: 330000 | J38: 20000000 | K38: 유 | L38: 수주 | M38: 장연주 | N38: 완료 | O38: =IF(COUNTIFS('보고서 검토일지(26년)'!$H:$H, $G38, '보고서 검토일지(26년)'!$M:$M, "0", '보고서 검토일지(26년)'!$G:$G, $F38)>0, "완료", "") -> 완료 | P38: 46156 | Q38: 46163 | R38: 330000 | V38: {=LET(행번호, MATCH(1, INDEX(('보고서 검토일지(26년)'!$G:$G=F38) * ('보고서 검토일지(26년)'!$H:$H=G38) * ('보고서 검토일지(26년)'!$I:$I="제안서"), 0), 0), IF(ISNUMBER(행번호), HYPERLINK("#gid=" & "0" & "&range=A" & 행번호, "완료"), "-"))} -> - | W38: 완료 | X38: {=LET(행번호, MATCH(1, INDEX(('보고서 검토일지(26년)'!$G:$G=F38) * ('보고서 검토일지(26년)'!$H:$H=G38) * ('보고서 검토일지(26년)'!$I:$I="완료계"), 0), 0), IF(ISNUMBER(행번호), HYPERLINK("#gid=" & "0" & "&range=A" & 행번호, "완료"), "-"))} -> - | Y38: 완료
A39: 46155.475 | C39: CG-712 | D39: 클레임-사감정 | F39: 한국공항공사 | G39: 한국공항공사 간접비 청구 감정 | I39: 7300000 | J39: 사업비 확인불가 | K39: 유 | L39: 수주 | V39: {=LET(행번호, MATCH(1, INDEX(('보고서 검토일지(26년)'!$G:$G=F39) * ('보고서 검토일지(26년)'!$H:$H=G39) * ('보고서 검토일지(26년)'!$I:$I="제안서"), 0), 0), IF(ISNUMBER(행번호), HYPERLINK("#gid=" & "0" & "&range=A" & 행번호, "완료"), "-"))} -> - | W39: {=LET(행번호, MATCH(1, INDEX(('보고서 검토일지(26년)'!$G:$G=F39) * ('보고서 검토일지(26년)'!$H:$H=G39) * ('보고서 검토일지(26년)'!$I:$I="최종보고서"), 0), 0), IF(ISNUMBER(행번호), HYPERLINK("#gid=" & "0" & "&range=A" & 행번호, "완료"), "-"))} -> - | X39: {=LET(행번호, MATCH(1, INDEX(('보고서 검토일지(26년)'!$G:$G=F39) * ('보고서 검토일지(26년)'!$H:$H=G39) * ('보고서 검토일지(26년)'!$I:$I="완료계"), 0), 0), IF(ISNUMBER(행번호), HYPERLINK("#gid=" & "0" & "&range=A" & 행번호, "완료"), "-"))} -> - | Y39: {=LET(행번호, MATCH(1, INDEX(('보고서 검토일지(26년)'!$G:$G=F39) * ('보고서 검토일지(26년)'!$H:$H=G39) * ('보고서 검토일지(26년)'!$I:$I="청구서"), 0), 0), IF(ISNUMBER(행번호), HYPERLINK("#gid=" & "0" & "&range=A" & 행번호, "완료"), "-"))} -> -
A40: 46153.735 | C40: CA-111 | D40: 제조-제조(제작설치포함) | F40: 주식회사 닷 | G40: 신규 제품 원가계산 | H40: 견적-최저 | I40: 550000 | J40: 사업비 확인불가 | K40: 유 | L40: 수주 | M40: 하은정 | V40: {=LET(행번호, MATCH(1, INDEX(('보고서 검토일지(26년)'!$G:$G=F40) * ('보고서 검토일지(26년)'!$H:$H=G40) * ('보고서 검토일지(26년)'!$I:$I="제안서"), 0), 0), IF(ISNUMBER(행번호), HYPERLINK("#gid=" & "0" & "&range=A" & 행번호, "완료"), "-"))} -> - | W40: {=LET(행번호, MATCH(1, INDEX(('보고서 검토일지(26년)'!$G:$G=F40) * ('보고서 검토일지(26년)'!$H:$H=G40) * ('보고서 검토일지(26년)'!$I:$I="최종보고서"), 0), 0), IF(ISNUMBER(행번호), HYPERLINK("#gid=" & "0" & "&range=A" & 행번호, "완료"), "-"))} -> - | X40: {=LET(행번호, MATCH(1, INDEX(('보고서 검토일지(26년)'!$G:$G=F40) * ('보고서 검토일지(26년)'!$H:$H=G40) * ('보고서 검토일지(26년)'!$I:$I="완료계"), 0), 0), IF(ISNUMBER(행번호), HYPERLINK("#gid=" & "0" & "&range=A" & 행번호, "완료"), "-"))} -> - | Y40: {=LET(행번호, MATCH(1, INDEX(('보고서 검토일지(26년)'!$G:$G=F40) * ('보고서 검토일지(26년)'!$H:$H=G40) * ('보고서 검토일지(26년)'!$I:$I="청구서"), 0), 0), IF(ISNUMBER(행번호), HYPERLINK("#gid=" & "0" & "&range=A" & 행번호, "완료"), "-"))} -> -
A41: 46153.735 | C41: CC-311 | D41: 학술용역-연구 | F41: 한국문화예술회관연합회 | G41: 2026 KoCACA아트페스티벌 평가연구 용역 원가계산 | H41: 견적-최저 | I41: 300000 | J41: 18000000 | K41: 유 | L41: 수주 | M41: 장연주 | N41: 완료 | O41: =IF(COUNTIFS('보고서 검토일지(26년)'!$H:$H, $G41, '보고서 검토일지(26년)'!$M:$M, "0", '보고서 검토일지(26년)'!$G:$G, $F41)>0, "완료", "") -> 완료 | P41: 46160 | V41: {=LET(행번호, MATCH(1, INDEX(('보고서 검토일지(26년)'!$G:$G=F41) * ('보고서 검토일지(26년)'!$H:$H=G41) * ('보고서 검토일지(26년)'!$I:$I="제안서"), 0), 0), IF(ISNUMBER(행번호), HYPERLINK("#gid=" & "0" & "&range=A" & 행번호, "완료"), "-"))} -> - | W41: 완료 | X41: 완료 | Y41: {=LET(행번호, MATCH(1, INDEX(('보고서 검토일지(26년)'!$G:$G=F41) * ('보고서 검토일지(26년)'!$H:$H=G41) * ('보고서 검토일지(26년)'!$I:$I="청구서"), 0), 0), IF(ISNUMBER(행번호), HYPERLINK("#gid=" & "0" & "&range=A" & 행번호, "완료"), "-"))} -> -
A42: 46149 | C42: CC-321 | D42: 학술용역-행사, 운영(대행) | F42: 소상공인시장진흥공단 | G42: 외국인 관광객 전통시장 방문 연계 홍보 용역 원가계산 | H42: 견적-최저 | I42: 770000 | J42: 110000000 | K42: 유 | L42: 수주 | M42: 장연주 | N42: 완료 | O42: =IF(COUNTIFS('보고서 검토일지(26년)'!$H:$H, $G42, '보고서 검토일지(26년)'!$M:$M, "0", '보고서 검토일지(26년)'!$G:$G, $F42)>0, "완료", "") -> 완료 | P42: 46153 | V42: {=LET(행번호, MATCH(1, INDEX(('보고서 검토일지(26년)'!$G:$G=F42) * ('보고서 검토일지(26년)'!$H:$H=G42) * ('보고서 검토일지(26년)'!$I:$I="제안서"), 0), 0), IF(ISNUMBER(행번호), HYPERLINK("#gid=" & "0" & "&range=A" & 행번호, "완료"), "-"))} -> - | W42: 완료 | X42: 완료 | Y42: {=LET(행번호, MATCH(1, INDEX(('보고서 검토일지(26년)'!$G:$G=F42) * ('보고서 검토일지(26년)'!$H:$H=G42) * ('보고서 검토일지(26년)'!$I:$I="청구서"), 0), 0), IF(ISNUMBER(행번호), HYPERLINK("#gid=" & "0" & "&range=A" & 행번호, "완료"), "-"))} -> -
A43: 46149 | C43: CC-341 | D43: 일반용역-S/W | F43: 창업진흥원 | G43: 창업기업 성장 이력(포트폴리오) 자동 생성 AI 모델 개발 원가계산 | H43: 견적-최저 | I43: 660000 | J43: 100000000 | K43: 유 | L43: 수주 | M43: 장연주 | N43: 완료 | O43: =IF(COUNTIFS('보고서 검토일지(26년)'!$H:$H, $G43, '보고서 검토일지(26년)'!$M:$M, "0", '보고서 검토일지(26년)'!$G:$G, $F43)>0, "완료", "") -> 완료 | P43: 46161 | Q43: 46161 | R43: 660000 | V43: {=LET(행번호, MATCH(1, INDEX(('보고서 검토일지(26년)'!$G:$G=F43) * ('보고서 검토일지(26년)'!$H:$H=G43) * ('보고서 검토일지(26년)'!$I:$I="제안서"), 0), 0), IF(ISNUMBER(행번호), HYPERLINK("#gid=" & "0" & "&range=A" & 행번호, "완료"), "-"))} -> - | W43: 완료 | X43: 완료 | Y43: 완료
...

Sheet 입찰정보(원가분석본부)
A1: 입찰정보
Z2: 결 재 | AA2: 담당 | AC2: 관리 | AE2: 원장
AA3: 김현진
A4: ="기준일자 : "&TEXT(TODAY(),"yyyy-mm-dd") -> 기준일자 : 2026-06-17 | E4: KIBD 서비스종료 : 2026-11-12 | V4: 출력일 : | W4: =TEXT(TODAY(),"yyyy-mm-dd") -> 2026-06-17
A5: * 투찰의견 : O (참여), △ (재검토), X (미참여) _ 해당 도형 기재 후 하단 "( )"안에 간략히 사유 기재 | AA5: =TODAY() -> 46190 | AC5: =TODAY() -> 46190 | AE5: =TODAY() -> 46190
A6: * ① 원가계산 / ② 학술, 경영 외/ ③건설
A7: 날짜 | B7: 번호 | C7: 구분 | D7: 공고명 | E7: 공고기관 | F7: 입찰 개시일 | G7: 참가신청 마감일 | H7: 투찰 마감일시 | I7: 개찰 일시 | J7: 구 분 | K7: 지역제한 | L7: 업종제한 | M7: 기초금액 | N7: 추정가격 | O7: 예가 변동폭 | P7: 투찰 하한율 | Q7: 제안서 / 가격 | R7: 투찰의견 | V7: 투찰금액 | W7: 투찰 일자 | X7: 투찰 여부 | Y7: 총괄본부 | AB7: 담당자 | AE7: 개찰 결과 | AF7: 비고
R8: 원가 분석본부 | S8: 기획실 등 | T8: 하은정 이사 | U8: 원장 | Y8: 진행 | Z8: 검토 | AA8: 투찰 | AB8: 확인 | AC8: 검토 | AD8: 승인
A9: 46188 | B9: 169 | C9: ① | D9: 무인경비 위탁 원가계산용역 | E9: c-market 전북지방우정청 | F9: 46185.667 | G9: 46189.625 | H9: 46189.625 | I9: 46189.625 | J9: 전자,견적 | K9: [전국] | L9: [원가계산] | M9: 0 | N9: 0 | O9: 공고문참조 | P9: 공고문참조 | Q9: 가격 | T9: - | U9: O
A10: 46188 | B10: 168 | C10: ① | D10: 부산광역시 대중교통 운영체계 전면 재검토 용역 | E10: 부산광역시 | F10: 46199.375 | G10: 46202.75 | H10: 46203.417 | I10: 46203.458 | J10: 전자,공동도급,협상 | K10: [전국] | L10: [건설ENG][연구/학술][원가계산][기술사사무소][세무/회계/법무] | M10: 700000000 | N10: 636363636 | O10: 공고문참조 | P10: 공고문참조 | Q10: 제안서 | T10: X | U10: X
A11: 46184 | B11: 167 | C11: ③ | D11: 공사비 검증 신청 용역 협력업체 선정 입찰 공고 | E11: 서금사재정비촉진A구역 주택재개발정비사업조합 | F11: 46184.583 | G11: 46197.75 | H11: 46198.625 | I11: 46199.75 | J11: 전자 | K11: [전국] | L11: [정비산업][기타] | M11: 0 | N11: 0 | O11: 공고문참조 | P11: 가격 | Q11: 제안서 | T11: - | U11: O
A12: 46183 | B12: 166 | C12: ① | D12: 2026년 생활폐기물 수집운반 운영체계 개선방안 연구용역 | E12: 강원특별자치도 홍천군 | F12: 46183.625 | G12: 46188.75 | H12: 46189.625 | I12: 46189.667 | J12: 전자,수의 | K12: [강원] | L12: [연구/학술][원가계산] | M12: 60000000 | N12: 54545455 | O12: -3% ~ 3% | P12: 0.88 | Q12: 가격 | T12: X | U12: X | AF12: 지역제한
A13: 46183 | B13: 165 | C13: ① | D13: (중요)2026년 스마트제조지원사업 및 클린제조환경조성 사업 원가계산기관 모집 공고 | E13: 소상공인시장진흥공단 | F13: 46181.75 | G13: 46195.75 | H13: 46195.75 | I13: 46195.792 | J13: 일반 | O13: 공고문참조 | P13: 공고문참조 | Q13: 가격 | U13: - | AF13: 서류제출
A14: 46182 | B14: 164 | C14: ① | D14: (취소)공사비 검증 업무 대행 업체 선정 입찰 공고 | E14: 청솔아파트 주택재건축정비사업조합 | F14: 46182.625 | G14: 46189.583 | H14: 46189.583 | I14: 46189.583 | J14: 일반,전자 | O14: 공고문참조 | P14: 공고문참조 | Q14: 가격 | AF14: 적격심사
A15: 46178 | B15: 163 | C15: ① | D15: (유찰공고) 원전 기전공사 원가조사·표준품셈 제정 용역 | E15: 한국수력원자력(주) 조달처 계약실 신규건설계약부 | F15: 46178.667 | G15: 46178.75 | H15: 46178.75 | I15: 46178.75 | J15: 일반 | K15: [전국] | L15: [원가계산] | M15: 0 | N15: 0 | O15: 공고문참조 | P15: 공고문참조 | Q15: 견적서 (유찰공고) | T15: X | U15: X
A16: 46178 | B16: 162 | C16: ① | D16: 무인경비용역(청사, 숙소, 365 등) 원가산정을 위한 견적 요청 | E16: c-market 전남지방우정청 | F16: 46177.583 | G16: 46184.583 | H16: 46184.583 | I16: 46184.583 | J16: 전자,견적 | K16: [전국] | L16: [원가계산] | M16: 0 | N16: 0 | O16: 공고문참조 | P16: 공고문참조 | Q16: 가격 | T16: O | U16: O | V16: 9900000 | W16: 46184 | X16: 완료
A17: 46178 | B17: 161 | C17: ① | D17: 「2026년 속초시 시내버스 비수익 노선 손실액 산정 용역」소액수의 전자견적 제출안내 | E17: 강원특별자치도 속초시 | F17: 46178.417 | G17: 46182.75 | H17: 46183.417 | I17: 46183.458 | J17: 전자,수의 | K17: [강원] | L17: [연구/학술][원가계산] | M17: 25000000 | N17: 22727273 | O17: -3% ~ 3% | P17: 0.88 | Q17: 가격 | T17: X | U17: X | AF17: 지역제한
A18: 46178 | B18: 160 | C18: ① | D18: 태양광발전장치 115종 원가계산 용역 계약 의뢰 | E18: 조달청 | F18: 46182.417 | G18: 46181.75 | H18: 46182.5 | I18: 46182.542 | J18: 수의,일반,시담 | K18: [전국] | L18: [원가계산] | M18: 0 | N18: 9545455 | O18: 공고문참조 | P18: 공고문참조 | Q18: 수의시담 | T18: X | U18: X
A19: 46178 | B19: 159 | C19: ① | D19: 공공지원 민간임대주택 공사비 검증을 위한 원가조사용역 | E19: 조달청 부산지방조달청 | F19: 46183.417 | G19: 46184.75 | H19: 46185.417 | I19: 46185.458 | J19: 전자 | K19: [전국] | L19: [연구/학술][원가계산] | M19: 119823000 | N19: 108979091 | O19: -2% ~ 2% | P19: 0.86245 | Q19: 가격 | T19: O | U19: O | V19: 106442000 | W19: 46183 | X19: 완료 | AE19: 미수주 (22위)
A20: 46177 | B20: 158 | C20: ① | D20: 26년 5차 방위사업 원가계산 외부용역 | E20: 국방부 국방조달 방위사업청(운영지원과) | F20: 0000-00-00 00:00:00 | G20: 46191.583 | H20: 46192.583 | I20: 46192.625 | J20: 긴급,전자 | K20: [전국] | L20: [원가계산] | M20: 0 | N20: 413636364 | O20: 공고문참조 | P20: 공고문참조 | Q20: 제안서 | T20: X | U20: X
A21: 46174 | B21: 157 | C21: ① | D21: 「BIXPO2026 행사대행 용역」사후원가계산 | E21: 한국전력공사 | F21: 46174.75 | G21: 46181.75 | H21: 46182.583 | I21: 46182.625 | J21: 전자 | K21: [전국] | L21: [원가계산][세무/회계/법무] | M21: 25243900 | N21: 22949000 | O21: -2% ~ 2% | P21: 0.84245 | Q21: 가격 | U21: X
A22: 46170 | B22: 155 | C22: ① | D22: 원자로면허갱신을 위한 경력인정시험 응시수수료 산정분석 | E22: 한국원자력안전기술원 | F22: 46182.417 | G22: 46183.75 | H22: 46184.417 | I22: 46184.458 | J22: 정정,전자 | K22: [전국] | L22: [연구/학술][원가계산] | M22: 0 | N22: 27272727 | O22: -2% ~ 2% | P22: 0.86245 | Q22: 가격 | U22: X
A23: 46169 | B23: 154 | C23: ① | D23: [정책,156] 2026년 두창 및 탄저백신 원가 산정 용역 | E23: 질병관리청 | F23: 46171.417 | G23: 46170.75 | H23: 46171.458 | I23: 46171.5 | J23: 수의,일반,시담 | K23: [전국] | L23: [원가계산] | M23: 0 | N23: 36363636 | O23: 공고문참조 | P23: 공고문참조 | Q23: 수의시담 | U23: X
A24: 46169 | B24: 153 | C24: ① | D24: 원자로면허갱신을 위한 경력인정시험 응시수수료 산정분석 | E24: 한국원자력안전기술원 | F24: 46175.417 | G24: 46177.75 | H24: 46178.417 | I24: 46178.458 | J24: 전자 | K24: [전국] | L24: [연구/학술][원가계산] | M24: 0 | N24: 27272727 | O24: -2% ~ 2% | P24: 0.86245 | Q24: 가격 | U24: X
A25: 46169 | B25: 152 | C25: ① | D25: 2026년 반려동물 연관산업 해외수출화산업화 정산용역 | E25: 한국농수산식품유통공사 | F25: 46177.417 | G25: 46180.75 | H25: 46181.417 | I25: 46181.458 | J25: 전자,공동도급,협상 | K25: [전국] | L25: [원가계산][세무/회계/법무] | M25: 35000000 | N25: 31818182 | O25: 공고문참조 | P25: 공고문참조 | Q25: 제안서 | U25: X
A26: 46168 | B26: 151 | C26: ① | D26: 26년 외주정비 사후조건부 원가검증 용역 | E26: 국방부 국방조달 육군항공사령부 | F26: 0000-00-00 00:00:00 | G26: 46174.458 | H26: 46174.458 | I26: 46174.479 | J26: 전자,수의 | K26: [전국] | L26: [원가계산] | M26: 7742120 | N26: 7038291 | O26: -2% ~ 2% | P26: 0.88 | Q26: 가격 | U26: X
A27: 46163 | B27: 150 | C27: ① | D27: 2026년 무진장 농어촌 고속버스 회계감사, 손실보상 실차조사 및 성과연동 평가 용역 | E27: 전북특별자치도 무주군 | F27: 46168.417 | G27: 46169.75 | H27: 46170.417 | I27: 46170.458 | J27: 전자,수의 | K27: [전북] | L27: [연구/학술][원가계산] | M27: 90000000 | N27: 81818182 | O27: -3% ~ 3% | P27: 0.88 | Q27: 가격 | U27: X | AF27: 지역제한
A28: 46163 | B28: 149 | C28: ① | D28: 우체국 자,과초금 및 점외365코너 자금 위탁운송 원가계산 용역 | E28: c-market 경북지방우정청 | F28: 46162.708 | G28: 46169.417 | H28: 46169.417 | I28: 46169.458 | J28: 전자 | K28: [전국] | L28: [원가계산] | M28: 0 | N28: 0 | O28: 공고문참조 | P28: 공고문참조 | Q28: 가격 | U28: X
A29: 46163 | B29: 148 | C29: ① | D29: 새울3,4호기 주설비공사 공기연장(IPS R.6) 간접비 산정 원가분석 | E29: 한국수력원자력(주) 새울원자력본부 대외협력처 노무자재팀 | F29: 46162.708 | G29: 46170.458 | H29: 46170.458 | I29: 46170.583 | J29: 전자 | K29: [부산][울산] | L29: [원가계산] | M29: 38742000 | N29: 35220000 | O29: -2.5% ~ 2.5% | P29: 0.84245 | Q29: 가격 | U29: X | AF29: 지역제한
A30: 46162 | B30: 147 | C30: ① | D30: [공공] 2026년 보조기기 등록제(상반기) 접수 제품 원가계산 | E30: 보건복지부 국립재활원 | F30: 46168.417 | G30: 46169.75 | H30: 46170.5 | I30: 46170.625 | J30: 정정,전자 | K30: [전국] | L30: [원가계산] | M30: 0 | N30: 1363636 | O30: 공고문참조 | P30: 0.84245 | Q30: 가격 | U30: X
A31: 46162 | B31: 146 | C31: ① | D31: 낙동강하굿둑 rubber seal 제조원가 계산 용역 | E31: 한국수자원공사 | F31: 46162.542 | G31: 46162.708 | H31: 46162.708 | I31: 46162.708 | J31: 전자,수의,시담 | K31: [전국] | L31: [원가계산] | M31: 0 | N31: 0 | O31: 공고문참조 | P31: 공고문참조 | Q31: 수의시담 | U31: X
A32: 46162 | B32: 145 | C32: ① | D32: 부산광역시 대중교통 운영체계 전면 재검토 용역 | E32: 부산광역시 | F32: 46181.375 | G32: 46182.75 | H32: 46183.417 | I32: 46183.458 | J32: 전자,공동도급,협상 | K32: [전국] | L32: [건설ENG][연구/학술][원가계산][기술사사무소][세무/회계/법무] | M32: 700000000 | N32: 636363636 | O32: 공고문참조 | P32: 공고문참조 | Q32: 제안서 | U32: X
A33: 46162 | B33: 144 | C33: ① | D33: 26년 4차 방위사업 원가계산 외부용역 | E33: 국방부 국방조달 방위사업청(운영지원과) | F33: 0000-00-00 00:00:00 | G33: 46174.583 | H33: 46175.583 | I33: 46175.625 | J33: 긴급,전자 | K33: [전국] | L33: [원가계산] | M33: 0 | N33: 469090909 | O33: 공고문참조 | P33: 공고문참조 | Q33: 제안서 | U33: X
A34: 46161 | B34: 143 | C34: ① | D34: 공간정보 품질관리 기술컨설팅 강화 연구 | E34: (재)공간정보품질관리원 | F34: 46161.667 | G34: 46173.75 | H34: 46174.583 | I34: 46174.625 | J34: 전자,협상 | K34: [전국] | L34: [연구/학술][원가계산] | M34: 0 | N34: 40000000 | O34: 공고문참조 | P34: 공고문참조 | Q34: 제안서 | U34: X
A35: 46154 | B35: 142 | C35: ① | D35: 전력거래소 서비스 기반 원가분석 및 중기 재무전망 용역 | E35: 한국전력거래소 | F35: 46154.438 | G35: 46164.583 | H35: 46168.583 | I35: 46168.625 | J35: 전자 | K35: [전국] | L35: [원가계산] | M35: 112685000 | N35: 104531987 | O35: -2% ~ 2% | P35: 공고문참조 | Q35: 제안서 | U35: X
