Workbook

Sheet 현황
B2: 수문정보 인프라 확충 관련 현황 | K2: 수문정보 인프라 확충 관련 현황
B3: [단위 : 개소] | K3: [단위 : 개소]
B4: 구분 | C4: 항목 | D4: 2021년 | E4: 2022년 | F4: 2023년 | G4: 2024년 | H4: 2025년 | I4: 2026년 | K4: 구분 | L4: 항목 | M4: 2021년 | N4: 2022년 | O4: 2023년 | P4: 2024년 | Q4: 2025년 | R4: 2026년
B5: 수문조사 | C5: 유량 | D5: 194 | E5: 244 | F5: 244 | G5: 284 | H5: 186 | I5: 144 | K5: 수문조사 | L5: 유량 | M5: 194 | N5: 244 | O5: 244 | P5: 284 | Q5: 186 | R5: 144
C6: 유사량 | D6: 24 | E6: 25 | F6: 25 | G6: 25 | H6: 25 | I6: 30 | L6: 유사량 | M6: 27 | N6: 25 | O6: 25 | P6: 26 | Q6: 27 | R6: 30
C7: 토양수분량 | D7: 2 | E7: 2 | F7: 2 | G7: 2 | H7: 2 | I7: 2 | L7: 토양수분량 | M7: 2 | N7: 2 | O7: 2 | P7: 2 | Q7: 2 | R7: 2
C8: 증발산량 | D8: 2 | E8: 2 | F8: 2 | G8: 2 | H8: 2 | I8: 2 | L8: 증발산량 | M8: 2 | N8: 2 | O8: 2 | P8: 2 | Q8: 2 | R8: 2
B9: 자동유량 | C9: 운영 | D9: 64 | E9: 67 | F9: 71 | G9: 76 | H9: 176 | I9: 218 | K9: 자동유량 | L9: 운영 | M9: 64 | N9: 67 | O9: 72 | P9: 76 | Q9: 176 | R9: 218
C10: 설치 | D10: 0 | E10: 4 | F10: 3 | G10: 10 | H10: 75 | I10: 42 | L10: 설치 | M10: 0 | N10: 4 | O10: 4 | P10: 25 | Q10: 75 | R10: 42
C11: 유지관리 | D11: 0 | E11: 10 | F11: 10 | G11: 17 | H11: 25 | I11: 25 | L11: 유지관리 | M11: 10 | N11: 10 | O11: 10 | P11: 17 | Q11: 25 | R11: 25
B12: * [출처] 세부시행계획서(수문정보 인프라확충 사업)_변경전 | K12: * [출처] 세부시행계획서(수문정보 인프라확충 사업)_변경후
C14: 설치 | G14: 25 | H14: 75 | I14: 42 | L14: 설치 | P14: 25 | Q14: 75 | R14: 42
C15: 유지보수 | E15: 20 | F15: 4 | G15: 16 | H15: 16 | I15: 7 | L15: 유지보수 | N15: 20 | O15: 4 | P15: 16 | Q15: 16 | R15: 7

Sheet 단가
B2: 수문정보 인프라 확충 관련 단가 현황
B3: [단위 : 백만원]
B4: 구분 | C4: 항목 | D4: 2021년 | E4: 2022년 | F4: 2023년 | G4: 2024년 | H4: 2025년 | I4: 2026년
B5: 수문조사 | C5: 유량 | D5: 84 | E5: 84 | F5: 84 | G5: 84 | H5: 84 | I5: 84
C6: 유사량 | D6: 50 | E6: 50 | F6: 50 | G6: 50 | H6: 50 | I6: 50
C7: 토양수분량 | D7: 50 | E7: 50 | F7: 50 | G7: 50 | H7: 50 | I7: 50
C8: 증발산량 | D8: 50 | E8: 50 | F8: 50 | G8: 50 | H8: 50 | I8: 50
B9: 자동유량 | C9: 운영 | D9: 49 | E9: 49 | F9: 49 | G9: 49 | H9: 49 | I9: 51
C10: 설치 | D10: 420 | E10: 420 | F10: 420 | G10: 420 | H10: 373 | I10: 299
C11: 유지관리 | D11: 120 | E11: 120 | F11: 120 | G11: 120 | H11: 120 | I11: 120

Sheet 항목별예산
B2: 수문조사 항목별 예산 현황 | J2: 수문조사 항목별 예산 현황(전년도 잔액 예산 반영)
B3: [단위 : 원] | J3: [단위 : 원]
B4: 구분 | C4: 2021년 | D4: 2022년 | E4: 2023년 | F4: 2024년 | G4: 2025년 | H4: 2026년 | J4: 구분 | K4: 2021년 | L4: 2022년 | M4: 2023년 | N4: 2024년 | O4: 2025년 | P4: 2026년
B5: 계 | C5: =SUM(C6:C10) -> 2487456225 | D5: =SUM(D6:D10) -> 9520000000 | E5: =SUM(E6:E10) -> 8475000000 | F5: =SUM(F6:F10) -> 10985000000 | G5: =SUM(G6:G10) -> 35704000000 | H5: =SUM(H6:H10) -> 18488000000 | J5: 계 | K5: =SUM(K6:K10) -> 2487456225 | L5: =SUM(L6:L10) -> 9943740153 | M5: =SUM(M6:M10) -> 8590082000 | N5: =SUM(N6:N10) -> 11195749215 | O5: =SUM(O6:O10) -> 36607548900 | P5: =SUM(P6:P10) -> 18488000000
B6: 유량 | C6: 1190182077 | D6: 3490000000 | E6: 2588664990 | F6: 3791790577 | G6: 2628000000 | H6: 2039920000 | J6: 유량 | K6: 1190182077 | L6: 3770139873 | M6: 2594604990 | N6: 3950363432 | O6: 3097893500 | P6: 2039920000
B7: 자동유량 | C7: 922911768 | D7: 5618000000 | E7: 5377336970 | F7: 6912209423 | G7: 32861000000 | H7: 16249080000 | J7: 자동유량 | K7: 922911768 | L7: 5659525000 | M7: 5377336970 | N7: 6929601543 | O7: 32905136330 | P7: 16249080000
B8: 유사량 | C8: 337965730 | D8: 356000000 | E8: 416083240 | F8: 221000000 | G8: 175000000 | H8: 159000000 | J8: 유사량 | K8: 337965730 | L8: 375025280 | M8: 525225240 | N8: 221000000 | O8: 476246410 | P8: 159000000
B9: 토양수분량 | C9: 20453200 | D9: 26700000 | E9: 55206400 | F9: 30000000 | G9: 20000000 | H9: 20000000 | J9: 토양수분량 | K9: 20453200 | L9: 68225000 | M9: 55206400 | N9: 47392120 | O9: 64136330 | P9: 20000000
B10: 증발산량 | C10: 15943450 | D10: 29300000 | E10: 37708400 | F10: 30000000 | G10: 20000000 | H10: 20000000 | J10: 증발산량 | K10: 15943450 | L10: 70825000 | M10: 37708400 | N10: 47392120 | O10: 64136330 | P10: 20000000
B12: [단위 : 백만원] | J12: [단위 : 백만원]
B13: 구분 | C13: 2021년 | D13: 2022년 | E13: 2023년 | F13: 2024년 | G13: 2025년 | H13: 2026년 | J13: 구분 | K13: 2021년 | L13: 2022년 | M13: 2023년 | N13: 2024년 | O13: 2025년 | P13: 2026년
B14: 계 | C14: =SUM(C15:C19) -> 2487 | D14: =SUM(D15:D19) -> 9520 | E14: =SUM(E15:E19) -> 8475 | F14: =SUM(F15:F19) -> 10985 | G14: =SUM(G15:G19) -> 35704 | H14: =SUM(H15:H19) -> 18488 | J14: 계 | K14: =SUM(K15:K19) -> 2487 | L14: =SUM(L15:L19) -> 9944 | M14: =SUM(M15:M19) -> 8590 | N14: =SUM(N15:N19) -> 11195 | O14: =SUM(O15:O19) -> 36607 | P14: =SUM(P15:P19) -> 18488
B15: 유량 | C15: =ROUND(C6/1000000,0) -> 1190 | D15: =ROUND(D6/1000000,0) -> 3490 | E15: =ROUND(E6/1000000,0) -> 2589 | F15: =ROUND(F6/1000000,0) -> 3792 | G15: =ROUND(G6/1000000,0) -> 2628 | H15: =ROUND(H6/1000000,0) -> 2040 | J15: 유량 | K15: =ROUND(K6/1000000,0) -> 1190 | L15: =ROUND(L6/1000000,0) -> 3770 | M15: =ROUND(M6/1000000,0) -> 2595 | N15: =ROUND(N6/1000000,0) -> 3950 | O15: =ROUND(O6/1000000,0) -> 3098 | P15: =ROUND(P6/1000000,0) -> 2040
B16: 자동유량 | C16: =ROUND(C7/1000000,0) -> 923 | D16: =ROUND(D7/1000000,0) -> 5618 | E16: =ROUND(E7/1000000,0) -> 5377 | F16: =ROUND(F7/1000000,0) -> 6912 | G16: =ROUND(G7/1000000,0) -> 32861 | H16: =ROUND(H7/1000000,0) -> 16249 | J16: 자동유량 | K16: =ROUND(K7/1000000,0) -> 923 | L16: =ROUND(L7/1000000,0) -> 5660 | M16: =ROUND(M7/1000000,0) -> 5377 | N16: =ROUND(N7/1000000,0) -> 6930 | O16: =ROUND(O7/1000000,0) -> 32905 | P16: =ROUND(P7/1000000,0) -> 16249
B17: 유사량 | C17: =ROUND(C8/1000000,0) -> 338 | D17: =ROUND(D8/1000000,0) -> 356 | E17: =ROUND(E8/1000000,0) -> 416 | F17: =ROUND(F8/1000000,0) -> 221 | G17: =ROUND(G8/1000000,0) -> 175 | H17: =ROUND(H8/1000000,0) -> 159 | J17: 유사량 | K17: =ROUND(K8/1000000,0) -> 338 | L17: =ROUND(L8/1000000,0) -> 375 | M17: =ROUND(M8/1000000,0) -> 525 | N17: =ROUND(N8/1000000,0) -> 221 | O17: =ROUND(O8/1000000,0) -> 476 | P17: =ROUND(P8/1000000,0) -> 159
B18: 토양수분량 | C18: =ROUND(C9/1000000,0) -> 20 | D18: =ROUND(D9/1000000,0) -> 27 | E18: =ROUND(E9/1000000,0) -> 55 | F18: =ROUND(F9/1000000,0) -> 30 | G18: =ROUND(G9/1000000,0) -> 20 | H18: =ROUND(H9/1000000,0) -> 20 | J18: 토양수분량 | K18: =ROUND(K9/1000000,0) -> 20 | L18: =ROUND(L9/1000000,0) -> 68 | M18: =ROUND(M9/1000000,0) -> 55 | N18: =ROUND(N9/1000000,0) -> 47 | O18: =ROUND(O9/1000000,0) -> 64 | P18: =ROUND(P9/1000000,0) -> 20
B19: 증발산량 | C19: =ROUND(C10/1000000,0) -> 16 | D19: =ROUND(D10/1000000,0) -> 29 | E19: =ROUND(E10/1000000,0) -> 38 | F19: =ROUND(F10/1000000,0) -> 30 | G19: =ROUND(G10/1000000,0) -> 20 | H19: =ROUND(H10/1000000,0) -> 20 | J19: 증발산량 | K19: =ROUND(K10/1000000,0) -> 16 | L19: =ROUND(L10/1000000,0) -> 71 | M19: =ROUND(M10/1000000,0) -> 38 | N19: =ROUND(N10/1000000,0) -> 47 | O19: =ROUND(O10/1000000,0) -> 64 | P19: =ROUND(P10/1000000,0) -> 20

Sheet 유량
B2: =B3&"조사 항목 예산 현황" -> 유량조사 항목 예산 현황
B3: 유량 | C3: (단위 : 개소, 백만원)
B4: 구분 | C4: 수량 | D4: 단가 | E4: 총계 | F4: 실행예산 | J4: 실행예산 (잔액 포함)
F5: 기관운영 | H5: 사업 | J5: 기관운영 | L5: 사업
B6: 2021년 | C6: =INDEX(지점현황[[2021년]:[2026년]],MATCH($B$3,지점현황[항목],0),MATCH(B6,지점현황[[#Headers],[2021년]:[2026년]],0)) -> 194 | D6: =INDEX(단가[[2021년]:[2026년]],MATCH($B$3,단가[항목],0),MATCH($B6,단가[[#Headers],[2021년]:[2026년]],0)) -> 84 | E6: =$C6*$D6 -> 16296 | F6: =$E6-H6 -> 15106 | G6: =ROUND(F6/$E6*100,2) -> 92.7 | H6: =INDEX(실행예산[[2021년]:[2026년]],MATCH($B$3,실행예산[구분],0),MATCH($B6,실행예산[[#Headers],[2021년]:[2026년]],0)) -> 1190 | I6: =ROUND(H6/$E6*100,2) -> 7.3 | J6: =$E6-L6 -> 15106 | K6: =ROUND(J6/$E6*100,2) -> 92.7 | L6: =INDEX(예산[[2021년]:[2026년]],MATCH($B$3,예산[구분],0),MATCH($B6,예산[[#Headers],[2021년]:[2026년]],0)) -> 1190 | M6: =ROUND(L6/$E6*100,2) -> 7.3
B7: 2022년 | C7: =INDEX(지점현황[[2021년]:[2026년]],MATCH($B$3,지점현황[항목],0),MATCH(B7,지점현황[[#Headers],[2021년]:[2026년]],0)) -> 244 | D7: =INDEX(단가[[2021년]:[2026년]],MATCH($B$3,단가[항목],0),MATCH($B7,단가[[#Headers],[2021년]:[2026년]],0)) -> 84 | E7: =$C7*$D7 -> 20496 | F7: =E7-H7 -> 17006 | G7: =ROUND(F7/$E7*100,2) -> 82.97 | H7: =INDEX(실행예산[[2021년]:[2026년]],MATCH($B$3,실행예산[구분],0),MATCH($B7,실행예산[[#Headers],[2021년]:[2026년]],0)) -> 3490 | I7: =ROUND(H7/$E7*100,2) -> 17.03 | J7: =$E7-L7 -> 16726 | K7: =ROUND(J7/$E7*100,2) -> 81.61 | L7: =INDEX(예산[[2021년]:[2026년]],MATCH($B$3,예산[구분],0),MATCH($B7,예산[[#Headers],[2021년]:[2026년]],0)) -> 3770 | M7: =ROUND(L7/$E7*100,2) -> 18.39
B8: 2023년 | C8: =INDEX(지점현황[[2021년]:[2026년]],MATCH($B$3,지점현황[항목],0),MATCH(B8,지점현황[[#Headers],[2021년]:[2026년]],0)) -> 244 | D8: =INDEX(단가[[2021년]:[2026년]],MATCH($B$3,단가[항목],0),MATCH($B8,단가[[#Headers],[2021년]:[2026년]],0)) -> 84 | E8: =$C8*$D8 -> 20496 | F8: =E8-H8 -> 17907 | G8: =ROUND(F8/$E8*100,2) -> 87.37 | H8: =INDEX(실행예산[[2021년]:[2026년]],MATCH($B$3,실행예산[구분],0),MATCH($B8,실행예산[[#Headers],[2021년]:[2026년]],0)) -> 2589 | I8: =ROUND(H8/$E8*100,2) -> 12.63 | J8: =$E8-L8 -> 17901 | K8: =ROUND(J8/$E8*100,2) -> 87.34 | L8: =INDEX(예산[[2021년]:[2026년]],MATCH($B$3,예산[구분],0),MATCH($B8,예산[[#Headers],[2021년]:[2026년]],0)) -> 2595 | M8: =ROUND(L8/$E8*100,2) -> 12.66
B9: 2024년 | C9: =INDEX(지점현황[[2021년]:[2026년]],MATCH($B$3,지점현황[항목],0),MATCH(B9,지점현황[[#Headers],[2021년]:[2026년]],0)) -> 284 | D9: =INDEX(단가[[2021년]:[2026년]],MATCH($B$3,단가[항목],0),MATCH($B9,단가[[#Headers],[2021년]:[2026년]],0)) -> 84 | E9: =$C9*$D9 -> 23856 | F9: =E9-H9 -> 20064 | G9: =ROUND(F9/$E9*100,2) -> 84.1 | H9: =INDEX(실행예산[[2021년]:[2026년]],MATCH($B$3,실행예산[구분],0),MATCH($B9,실행예산[[#Headers],[2021년]:[2026년]],0)) -> 3792 | I9: =ROUND(H9/$E9*100,2) -> 15.9 | J9: =$E9-L9 -> 19906 | K9: =ROUND(J9/$E9*100,2) -> 83.44 | L9: =INDEX(예산[[2021년]:[2026년]],MATCH($B$3,예산[구분],0),MATCH($B9,예산[[#Headers],[2021년]:[2026년]],0)) -> 3950 | M9: =ROUND(L9/$E9*100,2) -> 16.56
B10: 2025년 | C10: =INDEX(지점현황[[2021년]:[2026년]],MATCH($B$3,지점현황[항목],0),MATCH(B10,지점현황[[#Headers],[2021년]:[2026년]],0)) -> 186 | D10: =INDEX(단가[[2021년]:[2026년]],MATCH($B$3,단가[항목],0),MATCH($B10,단가[[#Headers],[2021년]:[2026년]],0)) -> 84 | E10: =$C10*$D10 -> 15624 | F10: =E10-H10 -> 12996 | G10: =ROUND(F10/$E10*100,2) -> 83.18 | H10: =INDEX(실행예산[[2021년]:[2026년]],MATCH($B$3,실행예산[구분],0),MATCH($B10,실행예산[[#Headers],[2021년]:[2026년]],0)) -> 2628 | I10: =ROUND(H10/$E10*100,2) -> 16.82 | J10: =$E10-L10 -> 12526 | K10: =ROUND(J10/$E10*100,2) -> 80.17 | L10: =INDEX(예산[[2021년]:[2026년]],MATCH($B$3,예산[구분],0),MATCH($B10,예산[[#Headers],[2021년]:[2026년]],0)) -> 3098 | M10: =ROUND(L10/$E10*100,2) -> 19.83
B11: 2026년 | C11: =INDEX(지점현황[[2021년]:[2026년]],MATCH($B$3,지점현황[항목],0),MATCH(B11,지점현황[[#Headers],[2021년]:[2026년]],0)) -> 144 | D11: =INDEX(단가[[2021년]:[2026년]],MATCH($B$3,단가[항목],0),MATCH($B11,단가[[#Headers],[2021년]:[2026년]],0)) -> 84 | E11: =$C11*$D11 -> 12096 | F11: =E11-H11 -> 10056 | G11: =ROUND(F11/$E11*100,2) -> 83.13 | H11: =INDEX(실행예산[[2021년]:[2026년]],MATCH($B$3,실행예산[구분],0),MATCH($B11,실행예산[[#Headers],[2021년]:[2026년]],0)) -> 2040 | I11: =ROUND(H11/$E11*100,2) -> 16.87 | J11: =$E11-L11 -> 10056 | K11: =ROUND(J11/$E11*100,2) -> 83.13 | L11: =INDEX(예산[[2021년]:[2026년]],MATCH($B$3,예산[구분],0),MATCH($B11,예산[[#Headers],[2021년]:[2026년]],0)) -> 2040 | M11: =ROUND(L11/$E11*100,2) -> 16.87
B12: 평균 (전체) | E12: =SUM($F12,$H12) -> 18145 | F12: =ROUND(AVERAGE(F$6:F$11),0) -> 15523 | G12: =ROUND(F12/$E12*100,2) -> 85.55 | H12: =ROUND(AVERAGE(H$6:H$11),0) -> 2622 | I12: =ROUND(H12/$E12*100,2) -> 14.45 | J12: =ROUND(AVERAGE(J$6:J$11),0) -> 15370 | K12: =ROUND(J12/$E12*100,2) -> 84.71 | L12: =ROUND(AVERAGE(L$6:L$11),0) -> 2774 | M12: =ROUND(L12/$E12*100,2) -> 15.29
B13: 평균 ('22년~'25년) | E13: =SUM($F13,$H13) -> 20118 | F13: =ROUND(AVERAGE(F$7:F$10),0) -> 16993 | G13: =ROUND(F13/$E13*100,2) -> 84.47 | H13: =ROUND(AVERAGE(H$7:H$10),0) -> 3125 | I13: =ROUND(H13/$E13*100,2) -> 15.53 | J13: =ROUND(AVERAGE(J$7:J$10),0) -> 16765 | K13: =ROUND(J13/$E13*100,2) -> 83.33 | L13: =ROUND(AVERAGE(L$7:L$10),0) -> 3353 | M13: =ROUND(L13/$E13*100,2) -> 16.67
B14: =INDEX(단가[[2021년]:[2026년]],MATCH($B$3,단가[항목],0),MATCH($B11,단가[[#Headers],[2021년]:[2026년]],0)) -> 84

Sheet 유사량
B2: =B3&"조사 항목 예산 현황" -> 유사량조사 항목 예산 현황
B3: 유사량 | C3: (단위 : 개소, 백만원)
B4: 구분 | C4: 수량 | D4: 단가 | E4: 총계 | F4: 실행예산 | J4: 실행예산 (잔액 포함)
F5: 기관운영 | H5: 사업 | J5: 기관운영 | L5: 사업
B6: 2021년 | C6: =INDEX(지점현황[[2021년]:[2026년]],MATCH($B$3,지점현황[항목],0),MATCH(B6,지점현황[[#Headers],[2021년]:[2026년]],0)) -> 24 | D6: =INDEX(단가[[2021년]:[2026년]],MATCH($B$3,단가[항목],0),MATCH($B6,단가[[#Headers],[2021년]:[2026년]],0)) -> 50 | E6: =$C6*$D6 -> 1200 | F6: =$E6-H6 -> 862 | G6: =ROUND(F6/$E6*100,2) -> 71.83 | H6: =INDEX(실행예산[[2021년]:[2026년]],MATCH($B$3,실행예산[구분],0),MATCH($B6,실행예산[[#Headers],[2021년]:[2026년]],0)) -> 338 | I6: =ROUND(H6/$E6*100,2) -> 28.17 | J6: =$E6-L6 -> 862 | K6: =ROUND(J6/$E6*100,2) -> 71.83 | L6: =INDEX(예산[[2021년]:[2026년]],MATCH($B$3,예산[구분],0),MATCH($B6,예산[[#Headers],[2021년]:[2026년]],0)) -> 338 | M6: =ROUND(L6/$E6*100,2) -> 28.17
B7: 2022년 | C7: =INDEX(지점현황[[2021년]:[2026년]],MATCH($B$3,지점현황[항목],0),MATCH(B7,지점현황[[#Headers],[2021년]:[2026년]],0)) -> 25 | D7: =INDEX(단가[[2021년]:[2026년]],MATCH($B$3,단가[항목],0),MATCH($B7,단가[[#Headers],[2021년]:[2026년]],0)) -> 50 | E7: =$C7*$D7 -> 1250 | F7: =E7-H7 -> 894 | G7: =ROUND(F7/$E7*100,2) -> 71.52 | H7: =INDEX(실행예산[[2021년]:[2026년]],MATCH($B$3,실행예산[구분],0),MATCH($B7,실행예산[[#Headers],[2021년]:[2026년]],0)) -> 356 | I7: =ROUND(H7/$E7*100,2) -> 28.48 | J7: =$E7-L7 -> 875 | K7: =ROUND(J7/$E7*100,2) -> 70 | L7: =INDEX(예산[[2021년]:[2026년]],MATCH($B$3,예산[구분],0),MATCH($B7,예산[[#Headers],[2021년]:[2026년]],0)) -> 375 | M7: =ROUND(L7/$E7*100,2) -> 30
B8: 2023년 | C8: =INDEX(지점현황[[2021년]:[2026년]],MATCH($B$3,지점현황[항목],0),MATCH(B8,지점현황[[#Headers],[2021년]:[2026년]],0)) -> 25 | D8: =INDEX(단가[[2021년]:[2026년]],MATCH($B$3,단가[항목],0),MATCH($B8,단가[[#Headers],[2021년]:[2026년]],0)) -> 50 | E8: =$C8*$D8 -> 1250 | F8: =E8-H8 -> 834 | G8: =ROUND(F8/$E8*100,2) -> 66.72 | H8: =INDEX(실행예산[[2021년]:[2026년]],MATCH($B$3,실행예산[구분],0),MATCH($B8,실행예산[[#Headers],[2021년]:[2026년]],0)) -> 416 | I8: =ROUND(H8/$E8*100,2) -> 33.28 | J8: =$E8-L8 -> 725 | K8: =ROUND(J8/$E8*100,2) -> 58 | L8: =INDEX(예산[[2021년]:[2026년]],MATCH($B$3,예산[구분],0),MATCH($B8,예산[[#Headers],[2021년]:[2026년]],0)) -> 525 | M8: =ROUND(L8/$E8*100,2) -> 42
B9: 2024년 | C9: =INDEX(지점현황[[2021년]:[2026년]],MATCH($B$3,지점현황[항목],0),MATCH(B9,지점현황[[#Headers],[2021년]:[2026년]],0)) -> 25 | D9: =INDEX(단가[[2021년]:[2026년]],MATCH($B$3,단가[항목],0),MATCH($B9,단가[[#Headers],[2021년]:[2026년]],0)) -> 50 | E9: =$C9*$D9 -> 1250 | F9: =E9-H9 -> 1029 | G9: =ROUND(F9/$E9*100,2) -> 82.32 | H9: =INDEX(실행예산[[2021년]:[2026년]],MATCH($B$3,실행예산[구분],0),MATCH($B9,실행예산[[#Headers],[2021년]:[2026년]],0)) -> 221 | I9: =ROUND(H9/$E9*100,2) -> 17.68 | J9: =$E9-L9 -> 1029 | K9: =ROUND(J9/$E9*100,2) -> 82.32 | L9: =INDEX(예산[[2021년]:[2026년]],MATCH($B$3,예산[구분],0),MATCH($B9,예산[[#Headers],[2021년]:[2026년]],0)) -> 221 | M9: =ROUND(L9/$E9*100,2) -> 17.68
B10: 2025년 | C10: =INDEX(지점현황[[2021년]:[2026년]],MATCH($B$3,지점현황[항목],0),MATCH(B10,지점현황[[#Headers],[2021년]:[2026년]],0)) -> 25 | D10: =INDEX(단가[[2021년]:[2026년]],MATCH($B$3,단가[항목],0),MATCH($B10,단가[[#Headers],[2021년]:[2026년]],0)) -> 50 | E10: =$C10*$D10 -> 1250 | F10: =E10-H10 -> 1075 | G10: =ROUND(F10/$E10*100,2) -> 86 | H10: =INDEX(실행예산[[2021년]:[2026년]],MATCH($B$3,실행예산[구분],0),MATCH($B10,실행예산[[#Headers],[2021년]:[2026년]],0)) -> 175 | I10: =ROUND(H10/$E10*100,2) -> 14 | J10: =$E10-L10 -> 774 | K10: =ROUND(J10/$E10*100,2) -> 61.92 | L10: =INDEX(예산[[2021년]:[2026년]],MATCH($B$3,예산[구분],0),MATCH($B10,예산[[#Headers],[2021년]:[2026년]],0)) -> 476 | M10: =ROUND(L10/$E10*100,2) -> 38.08
B11: 2026년 | C11: =INDEX(지점현황[[2021년]:[2026년]],MATCH($B$3,지점현황[항목],0),MATCH(B11,지점현황[[#Headers],[2021년]:[2026년]],0)) -> 30 | D11: =INDEX(단가[[2021년]:[2026년]],MATCH($B$3,단가[항목],0),MATCH($B11,단가[[#Headers],[2021년]:[2026년]],0)) -> 50 | E11: =$C11*$D11 -> 1500 | F11: =E11-H11 -> 1341 | G11: =ROUND(F11/$E11*100,2) -> 89.4 | H11: =INDEX(실행예산[[2021년]:[2026년]],MATCH($B$3,실행예산[구분],0),MATCH($B11,실행예산[[#Headers],[2021년]:[2026년]],0)) -> 159 | I11: =ROUND(H11/$E11*100,2) -> 10.6 | J11: =$E11-L11 -> 1341 | K11: =ROUND(J11/$E11*100,2) -> 89.4 | L11: =INDEX(예산[[2021년]:[2026년]],MATCH($B$3,예산[구분],0),MATCH($B11,예산[[#Headers],[2021년]:[2026년]],0)) -> 159 | M11: =ROUND(L11/$E11*100,2) -> 10.6
B12: 평균 (전체) | E12: =SUM($F12,$H12) -> 1284 | F12: =ROUND(AVERAGE(F$6:F$11),0) -> 1006 | G12: =ROUND(F12/$E12*100,2) -> 78.35 | H12: =ROUND(AVERAGE(H$6:H$11),0) -> 278 | I12: =ROUND(H12/$E12*100,2) -> 21.65 | J12: =ROUND(AVERAGE(J$6:J$11),0) -> 934 | K12: =ROUND(J12/$E12*100,2) -> 72.74 | L12: =ROUND(AVERAGE(L$6:L$11),0) -> 349 | M12: =ROUND(L12/$E12*100,2) -> 27.18
B13: 평균 ('22년~'25년) | E13: =SUM($F13,$H13) -> 1250 | F13: =ROUND(AVERAGE(F$7:F$10),0) -> 958 | G13: =ROUND(F13/$E13*100,2) -> 76.64 | H13: =ROUND(AVERAGE(H$7:H$10),0) -> 292 | I13: =ROUND(H13/$E13*100,2) -> 23.36 | J13: =ROUND(AVERAGE(J$7:J$10),0) -> 851 | K13: =ROUND(J13/$E13*100,2) -> 68.08 | L13: =ROUND(AVERAGE(L$7:L$10),0) -> 399 | M13: =ROUND(L13/$E13*100,2) -> 31.92
B14: =INDEX(단가[[2021년]:[2026년]],MATCH($B$3,단가[항목],0),MATCH($B11,단가[[#Headers],[2021년]:[2026년]],0)) -> 50

Sheet 토양수분량
B2: =B3&"조사 항목 예산 현황" -> 토양수분량조사 항목 예산 현황
B3: 토양수분량 | C3: (단위 : 개소, 백만원)
B4: 구분 | C4: 수량 | D4: 단가 | E4: 총계 | F4: 실행예산 | J4: 실행예산 (잔액 포함)
F5: 기관운영 | H5: 사업 | J5: 기관운영 | L5: 사업
B6: 2021년 | C6: =INDEX(지점현황[[2021년]:[2026년]],MATCH($B$3,지점현황[항목],0),MATCH(B6,지점현황[[#Headers],[2021년]:[2026년]],0)) -> 2 | D6: =INDEX(단가[[2021년]:[2026년]],MATCH($B$3,단가[항목],0),MATCH($B6,단가[[#Headers],[2021년]:[2026년]],0)) -> 50 | E6: =$C6*$D6 -> 100 | F6: =$E6-H6 -> 80 | G6: =ROUND(F6/$E6*100,2) -> 80 | H6: =INDEX(실행예산[[2021년]:[2026년]],MATCH($B$3,실행예산[구분],0),MATCH($B6,실행예산[[#Headers],[2021년]:[2026년]],0)) -> 20 | I6: =ROUND(H6/$E6*100,2) -> 20 | J6: =$E6-L6 -> 80 | K6: =ROUND(J6/$E6*100,2) -> 80 | L6: =INDEX(예산[[2021년]:[2026년]],MATCH($B$3,예산[구분],0),MATCH($B6,예산[[#Headers],[2021년]:[2026년]],0)) -> 20 | M6: =ROUND(L6/$E6*100,2) -> 20
B7: 2022년 | C7: =INDEX(지점현황[[2021년]:[2026년]],MATCH($B$3,지점현황[항목],0),MATCH(B7,지점현황[[#Headers],[2021년]:[2026년]],0)) -> 2 | D7: =INDEX(단가[[2021년]:[2026년]],MATCH($B$3,단가[항목],0),MATCH($B7,단가[[#Headers],[2021년]:[2026년]],0)) -> 50 | E7: =$C7*$D7 -> 100 | F7: =E7-H7 -> 73 | G7: =ROUND(F7/$E7*100,2) -> 73 | H7: =INDEX(실행예산[[2021년]:[2026년]],MATCH($B$3,실행예산[구분],0),MATCH($B7,실행예산[[#Headers],[2021년]:[2026년]],0)) -> 27 | I7: =ROUND(H7/$E7*100,2) -> 27 | J7: =$E7-L7 -> 32 | K7: =ROUND(J7/$E7*100,2) -> 32 | L7: =INDEX(예산[[2021년]:[2026년]],MATCH($B$3,예산[구분],0),MATCH($B7,예산[[#Headers],[2021년]:[2026년]],0)) -> 68 | M7: =ROUND(L7/$E7*100,2) -> 68
B8: 2023년 | C8: =INDEX(지점현황[[2021년]:[2026년]],MATCH($B$3,지점현황[항목],0),MATCH(B8,지점현황[[#Headers],[2021년]:[2026년]],0)) -> 2 | D8: =INDEX(단가[[2021년]:[2026년]],MATCH($B$3,단가[항목],0),MATCH($B8,단가[[#Headers],[2021년]:[2026년]],0)) -> 50 | E8: =$C8*$D8 -> 100 | F8: =E8-H8 -> 45 | G8: =ROUND(F8/$E8*100,2) -> 45 | H8: =INDEX(실행예산[[2021년]:[2026년]],MATCH($B$3,실행예산[구분],0),MATCH($B8,실행예산[[#Headers],[2021년]:[2026년]],0)) -> 55 | I8: =ROUND(H8/$E8*100,2) -> 55 | J8: =$E8-L8 -> 45 | K8: =ROUND(J8/$E8*100,2) -> 45 | L8: =INDEX(예산[[2021년]:[2026년]],MATCH($B$3,예산[구분],0),MATCH($B8,예산[[#Headers],[2021년]:[2026년]],0)) -> 55 | M8: =ROUND(L8/$E8*100,2) -> 55
B9: 2024년 | C9: =INDEX(지점현황[[2021년]:[2026년]],MATCH($B$3,지점현황[항목],0),MATCH(B9,지점현황[[#Headers],[2021년]:[2026년]],0)) -> 2 | D9: =INDEX(단가[[2021년]:[2026년]],MATCH($B$3,단가[항목],0),MATCH($B9,단가[[#Headers],[2021년]:[2026년]],0)) -> 50 | E9: =$C9*$D9 -> 100 | F9: =E9-H9 -> 70 | G9: =ROUND(F9/$E9*100,2) -> 70 | H9: =INDEX(실행예산[[2021년]:[2026년]],MATCH($B$3,실행예산[구분],0),MATCH($B9,실행예산[[#Headers],[2021년]:[2026년]],0)) -> 30 | I9: =ROUND(H9/$E9*100,2) -> 30 | J9: =$E9-L9 -> 53 | K9: =ROUND(J9/$E9*100,2) -> 53 | L9: =INDEX(예산[[2021년]:[2026년]],MATCH($B$3,예산[구분],0),MATCH($B9,예산[[#Headers],[2021년]:[2026년]],0)) -> 47 | M9: =ROUND(L9/$E9*100,2) -> 47
B10: 2025년 | C10: =INDEX(지점현황[[2021년]:[2026년]],MATCH($B$3,지점현황[항목],0),MATCH(B10,지점현황[[#Headers],[2021년]:[2026년]],0)) -> 2 | D10: =INDEX(단가[[2021년]:[2026년]],MATCH($B$3,단가[항목],0),MATCH($B10,단가[[#Headers],[2021년]:[2026년]],0)) -> 50 | E10: =$C10*$D10 -> 100 | F10: =E10-H10 -> 80 | G10: =ROUND(F10/$E10*100,2) -> 80 | H10: =INDEX(실행예산[[2021년]:[2026년]],MATCH($B$3,실행예산[구분],0),MATCH($B10,실행예산[[#Headers],[2021년]:[2026년]],0)) -> 20 | I10: =ROUND(H10/$E10*100,2) -> 20 | J10: =$E10-L10 -> 36 | K10: =ROUND(J10/$E10*100,2) -> 36 | L10: =INDEX(예산[[2021년]:[2026년]],MATCH($B$3,예산[구분],0),MATCH($B10,예산[[#Headers],[2021년]:[2026년]],0)) -> 64 | M10: =ROUND(L10/$E10*100,2) -> 64
B11: 2026년 | C11: =INDEX(지점현황[[2021년]:[2026년]],MATCH($B$3,지점현황[항목],0),MATCH(B11,지점현황[[#Headers],[2021년]:[2026년]],0)) -> 2 | D11: =INDEX(단가[[2021년]:[2026년]],MATCH($B$3,단가[항목],0),MATCH($B11,단가[[#Headers],[2021년]:[2026년]],0)) -> 50 | E11: =$C11*$D11 -> 100 | F11: =E11-H11 -> 80 | G11: =ROUND(F11/$E11*100,2) -> 80 | H11: =INDEX(실행예산[[2021년]:[2026년]],MATCH($B$3,실행예산[구분],0),MATCH($B11,실행예산[[#Headers],[2021년]:[2026년]],0)) -> 20 | I11: =ROUND(H11/$E11*100,2) -> 20 | J11: =$E11-L11 -> 80 | K11: =ROUND(J11/$E11*100,2) -> 80 | L11: =INDEX(예산[[2021년]:[2026년]],MATCH($B$3,예산[구분],0),MATCH($B11,예산[[#Headers],[2021년]:[2026년]],0)) -> 20 | M11: =ROUND(L11/$E11*100,2) -> 20
B12: 평균 (전체) | E12: =SUM($F12,$H12) -> 100 | F12: =ROUND(AVERAGE(F$6:F$11),0) -> 71 | G12: =ROUND(F12/$E12*100,2) -> 71 | H12: =ROUND(AVERAGE(H$6:H$11),0) -> 29 | I12: =ROUND(H12/$E12*100,2) -> 29 | J12: =ROUND(AVERAGE(J$6:J$11),0) -> 54 | K12: =ROUND(J12/$E12*100,2) -> 54 | L12: =ROUND(AVERAGE(L$6:L$11),0) -> 46 | M12: =ROUND(L12/$E12*100,2) -> 46
B13: 평균 ('22년~'25년) | E13: =SUM($F13,$H13) -> 100 | F13: =ROUND(AVERAGE(F$7:F$10),0) -> 67 | G13: =ROUND(F13/$E13*100,2) -> 67 | H13: =ROUND(AVERAGE(H$7:H$10),0) -> 33 | I13: =ROUND(H13/$E13*100,2) -> 33 | J13: =ROUND(AVERAGE(J$7:J$10),0) -> 42 | K13: =ROUND(J13/$E13*100,2) -> 42 | L13: =ROUND(AVERAGE(L$7:L$10),0) -> 59 | M13: =ROUND(L13/$E13*100,2) -> 59
B14: =INDEX(단가[[2021년]:[2026년]],MATCH($B$3,단가[항목],0),MATCH($B11,단가[[#Headers],[2021년]:[2026년]],0)) -> 50

Sheet 증발산량
B2: =B3&"조사 항목 예산 현황" -> 증발산량조사 항목 예산 현황
B3: 증발산량 | C3: (단위 : 개소, 백만원)
B4: 구분 | C4: 수량 | D4: 단가 | E4: 총계 | F4: 실행예산 | J4: 실행예산 (잔액 포함)
F5: 기관운영 | H5: 사업 | J5: 기관운영 | L5: 사업
B6: 2021년 | C6: =INDEX(지점현황[[2021년]:[2026년]],MATCH($B$3,지점현황[항목],0),MATCH(B6,지점현황[[#Headers],[2021년]:[2026년]],0)) -> 2 | D6: =INDEX(단가[[2021년]:[2026년]],MATCH($B$3,단가[항목],0),MATCH($B6,단가[[#Headers],[2021년]:[2026년]],0)) -> 50 | E6: =$C6*$D6 -> 100 | F6: =$E6-H6 -> 84 | G6: =ROUND(F6/$E6*100,2) -> 84 | H6: =INDEX(실행예산[[2021년]:[2026년]],MATCH($B$3,실행예산[구분],0),MATCH($B6,실행예산[[#Headers],[2021년]:[2026년]],0)) -> 16 | I6: =ROUND(H6/$E6*100,2) -> 16 | J6: =$E6-L6 -> 84 | K6: =ROUND(J6/$E6*100,2) -> 84 | L6: =INDEX(예산[[2021년]:[2026년]],MATCH($B$3,예산[구분],0),MATCH($B6,예산[[#Headers],[2021년]:[2026년]],0)) -> 16 | M6: =ROUND(L6/$E6*100,2) -> 16
B7: 2022년 | C7: =INDEX(지점현황[[2021년]:[2026년]],MATCH($B$3,지점현황[항목],0),MATCH(B7,지점현황[[#Headers],[2021년]:[2026년]],0)) -> 2 | D7: =INDEX(단가[[2021년]:[2026년]],MATCH($B$3,단가[항목],0),MATCH($B7,단가[[#Headers],[2021년]:[2026년]],0)) -> 50 | E7: =$C7*$D7 -> 100 | F7: =E7-H7 -> 71 | G7: =ROUND(F7/$E7*100,2) -> 71 | H7: =INDEX(실행예산[[2021년]:[2026년]],MATCH($B$3,실행예산[구분],0),MATCH($B7,실행예산[[#Headers],[2021년]:[2026년]],0)) -> 29 | I7: =ROUND(H7/$E7*100,2) -> 29 | J7: =$E7-L7 -> 29 | K7: =ROUND(J7/$E7*100,2) -> 29 | L7: =INDEX(예산[[2021년]:[2026년]],MATCH($B$3,예산[구분],0),MATCH($B7,예산[[#Headers],[2021년]:[2026년]],0)) -> 71 | M7: =ROUND(L7/$E7*100,2) -> 71
B8: 2023년 | C8: =INDEX(지점현황[[2021년]:[2026년]],MATCH($B$3,지점현황[항목],0),MATCH(B8,지점현황[[#Headers],[2021년]:[2026년]],0)) -> 2 | D8: =INDEX(단가[[2021년]:[2026년]],MATCH($B$3,단가[항목],0),MATCH($B8,단가[[#Headers],[2021년]:[2026년]],0)) -> 50 | E8: =$C8*$D8 -> 100 | F8: =E8-H8 -> 62 | G8: =ROUND(F8/$E8*100,2) -> 62 | H8: =INDEX(실행예산[[2021년]:[2026년]],MATCH($B$3,실행예산[구분],0),MATCH($B8,실행예산[[#Headers],[2021년]:[2026년]],0)) -> 38 | I8: =ROUND(H8/$E8*100,2) -> 38 | J8: =$E8-L8 -> 62 | K8: =ROUND(J8/$E8*100,2) -> 62 | L8: =INDEX(예산[[2021년]:[2026년]],MATCH($B$3,예산[구분],0),MATCH($B8,예산[[#Headers],[2021년]:[2026년]],0)) -> 38 | M8: =ROUND(L8/$E8*100,2) -> 38
B9: 2024년 | C9: =INDEX(지점현황[[2021년]:[2026년]],MATCH($B$3,지점현황[항목],0),MATCH(B9,지점현황[[#Headers],[2021년]:[2026년]],0)) -> 2 | D9: =INDEX(단가[[2021년]:[2026년]],MATCH($B$3,단가[항목],0),MATCH($B9,단가[[#Headers],[2021년]:[2026년]],0)) -> 50 | E9: =$C9*$D9 -> 100 | F9: =E9-H9 -> 70 | G9: =ROUND(F9/$E9*100,2) -> 70 | H9: =INDEX(실행예산[[2021년]:[2026년]],MATCH($B$3,실행예산[구분],0),MATCH($B9,실행예산[[#Headers],[2021년]:[2026년]],0)) -> 30 | I9: =ROUND(H9/$E9*100,2) -> 30 | J9: =$E9-L9 -> 53 | K9: =ROUND(J9/$E9*100,2) -> 53 | L9: =INDEX(예산[[2021년]:[2026년]],MATCH($B$3,예산[구분],0),MATCH($B9,예산[[#Headers],[2021년]:[2026년]],0)) -> 47 | M9: =ROUND(L9/$E9*100,2) -> 47
B10: 2025년 | C10: =INDEX(지점현황[[2021년]:[2026년]],MATCH($B$3,지점현황[항목],0),MATCH(B10,지점현황[[#Headers],[2021년]:[2026년]],0)) -> 2 | D10: =INDEX(단가[[2021년]:[2026년]],MATCH($B$3,단가[항목],0),MATCH($B10,단가[[#Headers],[2021년]:[2026년]],0)) -> 50 | E10: =$C10*$D10 -> 100 | F10: =E10-H10 -> 80 | G10: =ROUND(F10/$E10*100,2) -> 80 | H10: =INDEX(실행예산[[2021년]:[2026년]],MATCH($B$3,실행예산[구분],0),MATCH($B10,실행예산[[#Headers],[2021년]:[2026년]],0)) -> 20 | I10: =ROUND(H10/$E10*100,2) -> 20 | J10: =$E10-L10 -> 36 | K10: =ROUND(J10/$E10*100,2) -> 36 | L10: =INDEX(예산[[2021년]:[2026년]],MATCH($B$3,예산[구분],0),MATCH($B10,예산[[#Headers],[2021년]:[2026년]],0)) -> 64 | M10: =ROUND(L10/$E10*100,2) -> 64
B11: 2026년 | C11: =INDEX(지점현황[[2021년]:[2026년]],MATCH($B$3,지점현황[항목],0),MATCH(B11,지점현황[[#Headers],[2021년]:[2026년]],0)) -> 2 | D11: =INDEX(단가[[2021년]:[2026년]],MATCH($B$3,단가[항목],0),MATCH($B11,단가[[#Headers],[2021년]:[2026년]],0)) -> 50 | E11: =$C11*$D11 -> 100 | F11: =E11-H11 -> 80 | G11: =ROUND(F11/$E11*100,2) -> 80 | H11: =INDEX(실행예산[[2021년]:[2026년]],MATCH($B$3,실행예산[구분],0),MATCH($B11,실행예산[[#Headers],[2021년]:[2026년]],0)) -> 20 | I11: =ROUND(H11/$E11*100,2) -> 20 | J11: =$E11-L11 -> 80 | K11: =ROUND(J11/$E11*100,2) -> 80 | L11: =INDEX(예산[[2021년]:[2026년]],MATCH($B$3,예산[구분],0),MATCH($B11,예산[[#Headers],[2021년]:[2026년]],0)) -> 20 | M11: =ROUND(L11/$E11*100,2) -> 20
B12: 평균 (전체) | E12: =SUM($F12,$H12) -> 101 | F12: =ROUND(AVERAGE(F$6:F$11),0) -> 75 | G12: =ROUND(F12/$E12*100,2) -> 74.26 | H12: =ROUND(AVERAGE(H$6:H$11),0) -> 26 | I12: =ROUND(H12/$E12*100,2) -> 25.74 | J12: =ROUND(AVERAGE(J$6:J$11),0) -> 57 | K12: =ROUND(J12/$E12*100,2) -> 56.44 | L12: =ROUND(AVERAGE(L$6:L$11),0) -> 43 | M12: =ROUND(L12/$E12*100,2) -> 42.57
B13: 평균 ('22년~'25년) | E13: =SUM($F13,$H13) -> 100 | F13: =ROUND(AVERAGE(F$7:F$10),0) -> 71 | G13: =ROUND(F13/$E13*100,2) -> 71 | H13: =ROUND(AVERAGE(H$7:H$10),0) -> 29 | I13: =ROUND(H13/$E13*100,2) -> 29 | J13: =ROUND(AVERAGE(J$7:J$10),0) -> 45 | K13: =ROUND(J13/$E13*100,2) -> 45 | L13: =ROUND(AVERAGE(L$7:L$10),0) -> 55 | M13: =ROUND(L13/$E13*100,2) -> 55
B14: =INDEX(단가[[2021년]:[2026년]],MATCH($B$3,단가[항목],0),MATCH($B11,단가[[#Headers],[2021년]:[2026년]],0)) -> 50

Sheet 자동유량
B2: =B3&"조사 항목 예산 현황" -> 자동유량조사 항목 예산 현황
B3: 자동유량 | D3: (단위 : 개소, 백만원)
B4: 구분 | D4: 수량 | E4: 단가 | F4: 총계 | G4: 실행예산 | K4: 실행예산 (잔액 포함)
G5: 기관운영 | I5: 사업 | K5: 기관운영 | M5: 사업
B6: 2021년 | C6: 소계 | F6: =SUM(F7:F9) -> 3136 | G6: =$F6-I6 -> 2213 | H6: =IF($F6=0,0,ROUND(G6/$F6*100,2)) -> 70.57 | I6: =INDEX(실행예산[[2021년]:[2026년]],MATCH($B$3,실행예산[구분],0),MATCH($B6,실행예산[[#Headers],[2021년]:[2026년]],0)) -> 923 | J6: =IF($F6=0,0,ROUND(I6/$F6*100,2)) -> 29.43 | K6: =$F6-M6 -> 2213 | L6: =IF($F6=0,0,ROUND(K6/$F6*100,2)) -> 70.57 | M6: =INDEX(예산[[2021년]:[2026년]],MATCH($B$3,예산[구분],0),MATCH($B6,예산[[#Headers],[2021년]:[2026년]],0)) -> 923 | N6: =IF($F6=0,0,ROUND(M6/$F6*100,2)) -> 29.43
C7: 운영 | D7: =INDEX(지점현황[[2021년]:[2026년]],MATCH($C7,지점현황[항목],0),MATCH(B6,지점현황[[#Headers],[2021년]:[2026년]],0)) -> 64 | E7: =INDEX(단가[[2021년]:[2026년]],MATCH($C7,단가[항목],0),MATCH(B6,단가[[#Headers],[2021년]:[2026년]],0)) -> 49 | F7: =$D7*$E7 -> 3136 | G7: =G6 -> 2213 | H7: =IF($F7=0,0,ROUND(G7/$F7*100,2)) -> 70.57 | I7: =I6-SUM(I8:I9) -> 923 | J7: =IF($F7=0,0,ROUND(I7/$F7*100,2)) -> 29.43 | K7: =K6 -> 2213 | L7: =IF($F7=0,0,ROUND(K7/$F7*100,2)) -> 70.57 | M7: =M6-SUM(M8:M9) -> 923 | N7: =IF($F7=0,0,ROUND(M7/$F7*100,2)) -> 29.43
C8: 설치 | D8: =INDEX(지점현황[[2021년]:[2026년]],MATCH($C8,지점현황[항목],0),MATCH(B6,지점현황[[#Headers],[2021년]:[2026년]],0)) -> 0 | E8: =INDEX(단가[[2021년]:[2026년]],MATCH($C8,단가[항목],0),MATCH(B6,단가[[#Headers],[2021년]:[2026년]],0)) -> 420 | F8: =$D8*$E8 -> 0 | G8: 0 | H8: =IF($F8=0,0,ROUND(G8/$F8*100,2)) -> 0 | I8: =$F8 -> 0 | J8: =IF($F8=0,0,ROUND(I8/$F8*100,2)) -> 0 | K8: 0 | L8: =IF($F8=0,0,ROUND(K8/$F8*100,2)) -> 0 | M8: =$F8 -> 0 | N8: =IF($F8=0,0,ROUND(M8/$F8*100,2)) -> 0
C9: 유지관리 | D9: =INDEX(지점현황[[2021년]:[2026년]],MATCH($C9,지점현황[항목],0),MATCH(B6,지점현황[[#Headers],[2021년]:[2026년]],0)) -> 0 | E9: =INDEX(단가[[2021년]:[2026년]],MATCH($C9,단가[항목],0),MATCH(B6,단가[[#Headers],[2021년]:[2026년]],0)) -> 120 | F9: =$D9*$E9 -> 0 | G9: 0 | H9: =IF($F9=0,0,ROUND(G9/$F9*100,2)) -> 0 | I9: =$F9 -> 0 | J9: =IF($F9=0,0,ROUND(I9/$F9*100,2)) -> 0 | K9: 0 | L9: =IF($F9=0,0,ROUND(K9/$F9*100,2)) -> 0 | M9: =$F9 -> 0 | N9: =IF($F9=0,0,ROUND(M9/$F9*100,2)) -> 0
B10: 2022년 | C10: 소계 | F10: =SUM(F11:F13) -> 6163 | G10: =$F10-I10 -> 545 | H10: =IF($F10=0,0,ROUND(G10/$F10*100,2)) -> 8.84 | I10: =INDEX(실행예산[[2021년]:[2026년]],MATCH($B$3,실행예산[구분],0),MATCH($B10,실행예산[[#Headers],[2021년]:[2026년]],0)) -> 5618 | J10: =IF($F10=0,0,ROUND(I10/$F10*100,2)) -> 91.16 | K10: =$F10-M10 -> 503 | L10: =IF($F10=0,0,ROUND(K10/$F10*100,2)) -> 8.16 | M10: =INDEX(예산[[2021년]:[2026년]],MATCH($B$3,예산[구분],0),MATCH($B10,예산[[#Headers],[2021년]:[2026년]],0)) -> 5660 | N10: =IF($F10=0,0,ROUND(M10/$F10*100,2)) -> 91.84
C11: 운영 | D11: =INDEX(지점현황[[2021년]:[2026년]],MATCH($C11,지점현황[항목],0),MATCH(B10,지점현황[[#Headers],[2021년]:[2026년]],0)) -> 67 | E11: =INDEX(단가[[2021년]:[2026년]],MATCH($C11,단가[항목],0),MATCH(B10,단가[[#Headers],[2021년]:[2026년]],0)) -> 49 | F11: =$D11*$E11 -> 3283 | G11: =G10 -> 545 | H11: =IF($F11=0,0,ROUND(G11/$F11*100,2)) -> 16.6 | I11: =I10-SUM(I12:I13) -> 2738 | J11: =IF($F11=0,0,ROUND(I11/$F11*100,2)) -> 83.4 | K11: =K10 -> 503 | L11: =IF($F11=0,0,ROUND(K11/$F11*100,2)) -> 15.32 | M11: =M10-SUM(M12:M13) -> 2780 | N11: =IF($F11=0,0,ROUND(M11/$F11*100,2)) -> 84.68
C12: 설치 | D12: =INDEX(지점현황[[2021년]:[2026년]],MATCH($C12,지점현황[항목],0),MATCH(B10,지점현황[[#Headers],[2021년]:[2026년]],0)) -> 4 | E12: =INDEX(단가[[2021년]:[2026년]],MATCH($C12,단가[항목],0),MATCH(B10,단가[[#Headers],[2021년]:[2026년]],0)) -> 420 | F12: =$D12*$E12 -> 1680 | G12: 0 | H12: =IF($F12=0,0,ROUND(G12/$F12*100,2)) -> 0 | I12: =$F12 -> 1680 | J12: =IF($F12=0,0,ROUND(I12/$F12*100,2)) -> 100 | K12: 0 | L12: =IF($F12=0,0,ROUND(K12/$F12*100,2)) -> 0 | M12: =$F12 -> 1680 | N12: =IF($F12=0,0,ROUND(M12/$F12*100,2)) -> 100
C13: 유지관리 | D13: =INDEX(지점현황[[2021년]:[2026년]],MATCH($C13,지점현황[항목],0),MATCH(B10,지점현황[[#Headers],[2021년]:[2026년]],0)) -> 10 | E13: =INDEX(단가[[2021년]:[2026년]],MATCH($C13,단가[항목],0),MATCH(B10,단가[[#Headers],[2021년]:[2026년]],0)) -> 120 | F13: =$D13*$E13 -> 1200 | G13: 0 | H13: =IF($F13=0,0,ROUND(G13/$F13*100,2)) -> 0 | I13: =$F13 -> 1200 | J13: =IF($F13=0,0,ROUND(I13/$F13*100,2)) -> 100 | K13: 0 | L13: =IF($F13=0,0,ROUND(K13/$F13*100,2)) -> 0 | M13: =$F13 -> 1200 | N13: =IF($F13=0,0,ROUND(M13/$F13*100,2)) -> 100
B14: 2023년 | C14: 소계 | F14: =SUM(F15:F17) -> 5939 | G14: =$F14-I14 -> 562 | H14: =IF($F14=0,0,ROUND(G14/$F14*100,2)) -> 9.46 | I14: =INDEX(실행예산[[2021년]:[2026년]],MATCH($B$3,실행예산[구분],0),MATCH($B14,실행예산[[#Headers],[2021년]:[2026년]],0)) -> 5377 | J14: =IF($F14=0,0,ROUND(I14/$F14*100,2)) -> 90.54 | K14: =$F14-M14 -> 562 | L14: =IF($F14=0,0,ROUND(K14/$F14*100,2)) -> 9.46 | M14: =INDEX(예산[[2021년]:[2026년]],MATCH($B$3,예산[구분],0),MATCH($B14,예산[[#Headers],[2021년]:[2026년]],0)) -> 5377 | N14: =IF($F14=0,0,ROUND(M14/$F14*100,2)) -> 90.54
C15: 운영 | D15: =INDEX(지점현황[[2021년]:[2026년]],MATCH($C15,지점현황[항목],0),MATCH(B14,지점현황[[#Headers],[2021년]:[2026년]],0)) -> 71 | E15: =INDEX(단가[[2021년]:[2026년]],MATCH($C15,단가[항목],0),MATCH(B14,단가[[#Headers],[2021년]:[2026년]],0)) -> 49 | F15: =$D15*$E15 -> 3479 | G15: =G14 -> 562 | H15: =IF($F15=0,0,ROUND(G15/$F15*100,2)) -> 16.15 | I15: =I14-SUM(I16:I17) -> 2917 | J15: =IF($F15=0,0,ROUND(I15/$F15*100,2)) -> 83.85 | K15: =K14 -> 562 | L15: =IF($F15=0,0,ROUND(K15/$F15*100,2)) -> 16.15 | M15: =M14-SUM(M16:M17) -> 2917 | N15: =IF($F15=0,0,ROUND(M15/$F15*100,2)) -> 83.85
C16: 설치 | D16: =INDEX(지점현황[[2021년]:[2026년]],MATCH($C16,지점현황[항목],0),MATCH(B14,지점현황[[#Headers],[2021년]:[2026년]],0)) -> 3 | E16: =INDEX(단가[[2021년]:[2026년]],MATCH($C16,단가[항목],0),MATCH(B14,단가[[#Headers],[2021년]:[2026년]],0)) -> 420 | F16: =$D16*$E16 -> 1260 | G16: 0 | H16: =IF($F16=0,0,ROUND(G16/$F16*100,2)) -> 0 | I16: =$F16 -> 1260 | J16: =IF($F16=0,0,ROUND(I16/$F16*100,2)) -> 100 | K16: 0 | L16: =IF($F16=0,0,ROUND(K16/$F16*100,2)) -> 0 | M16: =$F16 -> 1260 | N16: =IF($F16=0,0,ROUND(M16/$F16*100,2)) -> 100
C17: 유지관리 | D17: =INDEX(지점현황[[2021년]:[2026년]],MATCH($C17,지점현황[항목],0),MATCH(B14,지점현황[[#Headers],[2021년]:[2026년]],0)) -> 10 | E17: =INDEX(단가[[2021년]:[2026년]],MATCH($C17,단가[항목],0),MATCH(B14,단가[[#Headers],[2021년]:[2026년]],0)) -> 120 | F17: =$D17*$E17 -> 1200 | G17: 0 | H17: =IF($F17=0,0,ROUND(G17/$F17*100,2)) -> 0 | I17: =$F17 -> 1200 | J17: =IF($F17=0,0,ROUND(I17/$F17*100,2)) -> 100 | K17: 0 | L17: =IF($F17=0,0,ROUND(K17/$F17*100,2)) -> 0 | M17: =$F17 -> 1200 | N17: =IF($F17=0,0,ROUND(M17/$F17*100,2)) -> 100
B18: 2024년 | C18: 소계 | F18: =SUM(F19:F21) -> 9964 | G18: =$F18-I18 -> 3052 | H18: =IF($F18=0,0,ROUND(G18/$F18*100,2)) -> 30.63 | I18: =INDEX(실행예산[[2021년]:[2026년]],MATCH($B$3,실행예산[구분],0),MATCH($B18,실행예산[[#Headers],[2021년]:[2026년]],0)) -> 6912 | J18: =IF($F18=0,0,ROUND(I18/$F18*100,2)) -> 69.37 | K18: =$F18-M18 -> 3034 | L18: =IF($F18=0,0,ROUND(K18/$F18*100,2)) -> 30.45 | M18: =INDEX(예산[[2021년]:[2026년]],MATCH($B$3,예산[구분],0),MATCH($B18,예산[[#Headers],[2021년]:[2026년]],0)) -> 6930 | N18: =IF($F18=0,0,ROUND(M18/$F18*100,2)) -> 69.55
C19: 운영 | D19: =INDEX(지점현황[[2021년]:[2026년]],MATCH($C19,지점현황[항목],0),MATCH(B18,지점현황[[#Headers],[2021년]:[2026년]],0)) -> 76 | E19: =INDEX(단가[[2021년]:[2026년]],MATCH($C19,단가[항목],0),MATCH(B18,단가[[#Headers],[2021년]:[2026년]],0)) -> 49 | F19: =$D19*$E19 -> 3724 | G19: =G18 -> 3052 | H19: =IF($F19=0,0,ROUND(G19/$F19*100,2)) -> 81.95 | I19: =I18-SUM(I20:I21) -> 672 | J19: =IF($F19=0,0,ROUND(I19/$F19*100,2)) -> 18.05 | K19: =K18 -> 3034 | L19: =IF($F19=0,0,ROUND(K19/$F19*100,2)) -> 81.47 | M19: =M18-SUM(M20:M21) -> 690 | N19: =IF($F19=0,0,ROUND(M19/$F19*100,2)) -> 18.53
C20: 설치 | D20: =INDEX(지점현황[[2021년]:[2026년]],MATCH($C20,지점현황[항목],0),MATCH(B18,지점현황[[#Headers],[2021년]:[2026년]],0)) -> 10 | E20: =INDEX(단가[[2021년]:[2026년]],MATCH($C20,단가[항목],0),MATCH(B18,단가[[#Headers],[2021년]:[2026년]],0)) -> 420 | F20: =$D20*$E20 -> 4200 | G20: 0 | H20: =IF($F20=0,0,ROUND(G20/$F20*100,2)) -> 0 | I20: =$F20 -> 4200 | J20: =IF($F20=0,0,ROUND(I20/$F20*100,2)) -> 100 | K20: 0 | L20: =IF($F20=0,0,ROUND(K20/$F20*100,2)) -> 0 | M20: =$F20 -> 4200 | N20: =IF($F20=0,0,ROUND(M20/$F20*100,2)) -> 100
C21: 유지관리 | D21: =INDEX(지점현황[[2021년]:[2026년]],MATCH($C21,지점현황[항목],0),MATCH(B18,지점현황[[#Headers],[2021년]:[2026년]],0)) -> 17 | E21: =INDEX(단가[[2021년]:[2026년]],MATCH($C21,단가[항목],0),MATCH(B18,단가[[#Headers],[2021년]:[2026년]],0)) -> 120 | F21: =$D21*$E21 -> 2040 | G21: 0 | H21: =IF($F21=0,0,ROUND(G21/$F21*100,2)) -> 0 | I21: =$F21 -> 2040 | J21: =IF($F21=0,0,ROUND(I21/$F21*100,2)) -> 100 | K21: 0 | L21: =IF($F21=0,0,ROUND(K21/$F21*100,2)) -> 0 | M21: =$F21 -> 2040 | N21: =IF($F21=0,0,ROUND(M21/$F21*100,2)) -> 100
B22: 2025년 | C22: 소계 | F22: =SUM(F23:F25) -> 39549 | G22: =$F22-I22 -> 6688 | H22: =IF($F22=0,0,ROUND(G22/$F22*100,2)) -> 16.91 | I22: =INDEX(실행예산[[2021년]:[2026년]],MATCH($B$3,실행예산[구분],0),MATCH($B22,실행예산[[#Headers],[2021년]:[2026년]],0)) -> 32861 | J22: =IF($F22=0,0,ROUND(I22/$F22*100,2)) -> 83.09 | K22: =$F22-M22 -> 6644 | L22: =IF($F22=0,0,ROUND(K22/$F22*100,2)) -> 16.8 | M22: =INDEX(예산[[2021년]:[2026년]],MATCH($B$3,예산[구분],0),MATCH($B22,예산[[#Headers],[2021년]:[2026년]],0)) -> 32905 | N22: =IF($F22=0,0,ROUND(M22/$F22*100,2)) -> 83.2
C23: 운영 | D23: =INDEX(지점현황[[2021년]:[2026년]],MATCH($C23,지점현황[항목],0),MATCH(B22,지점현황[[#Headers],[2021년]:[2026년]],0)) -> 176 | E23: =INDEX(단가[[2021년]:[2026년]],MATCH($C23,단가[항목],0),MATCH(B22,단가[[#Headers],[2021년]:[2026년]],0)) -> 49 | F23: =$D23*$E23 -> 8624 | G23: =G22 -> 6688 | H23: =IF($F23=0,0,ROUND(G23/$F23*100,2)) -> 77.55 | I23: =I22-SUM(I24:I25) -> 1936 | J23: =IF($F23=0,0,ROUND(I23/$F23*100,2)) -> 22.45 | K23: =K22 -> 6644 | L23: =IF($F23=0,0,ROUND(K23/$F23*100,2)) -> 77.04 | M23: =M22-SUM(M24:M25) -> 1980 | N23: =IF($F23=0,0,ROUND(M23/$F23*100,2)) -> 22.96
C24: 설치 | D24: =INDEX(지점현황[[2021년]:[2026년]],MATCH($C24,지점현황[항목],0),MATCH(B22,지점현황[[#Headers],[2021년]:[2026년]],0)) -> 75 | E24: =INDEX(단가[[2021년]:[2026년]],MATCH($C24,단가[항목],0),MATCH(B22,단가[[#Headers],[2021년]:[2026년]],0)) -> 373 | F24: =$D24*$E24 -> 27975 | G24: 0 | H24: =IF($F24=0,0,ROUND(G24/$F24*100,2)) -> 0 | I24: =$F24 -> 27975 | J24: =IF($F24=0,0,ROUND(I24/$F24*100,2)) -> 100 | K24: 0 | L24: =IF($F24=0,0,ROUND(K24/$F24*100,2)) -> 0 | M24: =$F24 -> 27975 | N24: =IF($F24=0,0,ROUND(M24/$F24*100,2)) -> 100
C25: 유지관리 | D25: =INDEX(지점현황[[2021년]:[2026년]],MATCH($C25,지점현황[항목],0),MATCH(B22,지점현황[[#Headers],[2021년]:[2026년]],0)) -> 25 | E25: =INDEX(단가[[2021년]:[2026년]],MATCH($C25,단가[항목],0),MATCH(B22,단가[[#Headers],[2021년]:[2026년]],0)) -> 120 | F25: =$D25*$E25-50 -> 2950 | G25: 0 | H25: =IF($F25=0,0,ROUND(G25/$F25*100,2)) -> 0 | I25: =$F25 -> 2950 | J25: =IF($F25=0,0,ROUND(I25/$F25*100,2)) -> 100 | K25: 0 | L25: =IF($F25=0,0,ROUND(K25/$F25*100,2)) -> 0 | M25: =$F25 -> 2950 | N25: =IF($F25=0,0,ROUND(M25/$F25*100,2)) -> 100
B26: 2026년 | C26: 소계 | F26: =SUM(F27:F29) -> 26681 | G26: =$F26-I26 -> 10432 | H26: =IF($F26=0,0,ROUND(G26/$F26*100,2)) -> 39.1 | I26: =INDEX(실행예산[[2021년]:[2026년]],MATCH($B$3,실행예산[구분],0),MATCH($B26,실행예산[[#Headers],[2021년]:[2026년]],0)) -> 16249 | J26: =IF($F26=0,0,ROUND(I26/$F26*100,2)) -> 60.9 | K26: =$F26-M26 -> 10432 | L26: =IF($F26=0,0,ROUND(K26/$F26*100,2)) -> 39.1 | M26: =INDEX(예산[[2021년]:[2026년]],MATCH($B$3,예산[구분],0),MATCH($B26,예산[[#Headers],[2021년]:[2026년]],0)) -> 16249 | N26: =IF($F26=0,0,ROUND(M26/$F26*100,2)) -> 60.9
C27: 운영 | D27: =INDEX(지점현황[[2021년]:[2026년]],MATCH($C27,지점현황[항목],0),MATCH(B26,지점현황[[#Headers],[2021년]:[2026년]],0)) -> 218 | E27: =INDEX(단가[[2021년]:[2026년]],MATCH($C27,단가[항목],0),MATCH(B26,단가[[#Headers],[2021년]:[2026년]],0)) -> 51 | F27: =$D27*$E27+15 -> 11133 | G27: =G26 -> 10432 | H27: =IF($F27=0,0,ROUND(G27/$F27*100,2)) -> 93.7 | I27: =I26-SUM(I28:I29) -> 701 | J27: =IF($F27=0,0,ROUND(I27/$F27*100,2)) -> 6.3 | K27: =K26 -> 10432 | L27: =IF($F27=0,0,ROUND(K27/$F27*100,2)) -> 93.7 | M27: =M26-SUM(M28:M29) -> 701 | N27: =IF($F27=0,0,ROUND(M27/$F27*100,2)) -> 6.3
C28: 설치 | D28: =INDEX(지점현황[[2021년]:[2026년]],MATCH($C28,지점현황[항목],0),MATCH(B26,지점현황[[#Headers],[2021년]:[2026년]],0)) -> 42 | E28: =INDEX(단가[[2021년]:[2026년]],MATCH($C28,단가[항목],0),MATCH(B26,단가[[#Headers],[2021년]:[2026년]],0)) -> 299 | F28: =$D28*$E28+40 -> 12598 | G28: 0 | H28: =IF($F28=0,0,ROUND(G28/$F28*100,2)) -> 0 | I28: =$F28 -> 12598 | J28: =IF($F28=0,0,ROUND(I28/$F28*100,2)) -> 100 | K28: 0 | L28: =IF($F28=0,0,ROUND(K28/$F28*100,2)) -> 0 | M28: =$F28 -> 12598 | N28: =IF($F28=0,0,ROUND(M28/$F28*100,2)) -> 100
C29: 유지관리 | D29: =INDEX(지점현황[[2021년]:[2026년]],MATCH($C29,지점현황[항목],0),MATCH(B26,지점현황[[#Headers],[2021년]:[2026년]],0)) -> 25 | E29: =INDEX(단가[[2021년]:[2026년]],MATCH($C29,단가[항목],0),MATCH(B26,단가[[#Headers],[2021년]:[2026년]],0)) -> 120 | F29: =$D29*$E29-50 -> 2950 | G29: 0 | H29: =IF($F29=0,0,ROUND(G29/$F29*100,2)) -> 0 | I29: =$F29 -> 2950 | J29: =IF($F29=0,0,ROUND(I29/$F29*100,2)) -> 100 | K29: 0 | L29: =IF($F29=0,0,ROUND(K29/$F29*100,2)) -> 0 | M29: =$F29 -> 2950 | N29: =IF($F29=0,0,ROUND(M29/$F29*100,2)) -> 100
B30: 평균 (전체) | C30: 소계 | F30: =SUM(G30,I30) -> 15238 | G30: =ROUND(AVERAGE(G6,G10,G14,G18,G22,G26),0) -> 3915 | H30: =IF($F30=0,0,ROUND(G30/$F30*100,2)) -> 25.69 | I30: =ROUND(AVERAGE(I6,I10,I14,I18,I22,I26),0) -> 11323 | J30: =IF($F30=0,0,ROUND(I30/$F30*100,2)) -> 74.31 | K30: =ROUND(AVERAGE(K6,K10,K14,K18,K22,K26),0) -> 3898 | L30: =IF($F30=0,0,ROUND(K30/$F30*100,2)) -> 25.58 | M30: =ROUND(AVERAGE(M6,M10,M14,M18,M22,M26),0) -> 11341 | N30: =IF($F30=0,0,ROUND(M30/$F30*100,2)) -> 74.43
C31: 운영 | F31: =SUM(G31,I31) -> 5563 | G31: =ROUND(AVERAGE(G7,G11,G15,G19,G23,G27),0) -> 3915 | H31: =IF($F31=0,0,ROUND(G31/$F31*100,2)) -> 70.38 | I31: =ROUND(AVERAGE(I7,I11,I15,I19,I23,I27),0) -> 1648 | J31: =IF($F31=0,0,ROUND(I31/$F31*100,2)) -> 29.62 | K31: =ROUND(AVERAGE(K7,K11,K15,K19,K23,K27),0) -> 3898 | L31: =IF($F31=0,0,ROUND(K31/$F31*100,2)) -> 70.07 | M31: =ROUND(AVERAGE(M7,M11,M15,M19,M23,M27),0) -> 1665 | N31: =IF($F31=0,0,ROUND(M31/$F31*100,2)) -> 29.93
C32: 설치 | F32: =SUM(G32,I32) -> 7952 | G32: =ROUND(AVERAGE(G8,G12,G16,G20,G24,G28),0) -> 0 | H32: =IF($F32=0,0,ROUND(G32/$F32*100,2)) -> 0 | I32: =ROUND(AVERAGE(I8,I12,I16,I20,I24,I28),0) -> 7952 | J32: =IF($F32=0,0,ROUND(I32/$F32*100,2)) -> 100 | K32: =ROUND(AVERAGE(K8,K12,K16,K20,K24,K28),0) -> 0 | L32: =IF($F32=0,0,ROUND(K32/$F32*100,2)) -> 0 | M32: =ROUND(AVERAGE(M8,M12,M16,M20,M24,M28),0) -> 7952 | N32: =IF($F32=0,0,ROUND(M32/$F32*100,2)) -> 100
C33: 유지관리 | F33: =SUM(G33,I33) -> 1723 | G33: =ROUND(AVERAGE(G9,G13,G17,G21,G25,G29),0) -> 0 | H33: =IF($F33=0,0,ROUND(G33/$F33*100,2)) -> 0 | I33: =ROUND(AVERAGE(I9,I13,I17,I21,I25,I29),0) -> 1723 | J33: =IF($F33=0,0,ROUND(I33/$F33*100,2)) -> 100 | K33: =ROUND(AVERAGE(K9,K13,K17,K21,K25,K29),0) -> 0 | L33: =IF($F33=0,0,ROUND(K33/$F33*100,2)) -> 0 | M33: =ROUND(AVERAGE(M9,M13,M17,M21,M25,M29),0) -> 1723 | N33: =IF($F33=0,0,ROUND(M33/$F33*100,2)) -> 100
B34: 평균 ('22년~'25년) | C34: 소계 | F34: =SUM(G34,I34) -> 15404 | G34: =ROUND(AVERAGE(G10,G14,G18,G22),0) -> 2712 | H34: =IF($F34=0,0,ROUND(G34/$F34*100,2)) -> 17.61 | I34: =ROUND(AVERAGE(I10,I14,I18,I22),0) -> 12692 | J34: =IF($F34=0,0,ROUND(I34/$F34*100,2)) -> 82.39 | K34: =ROUND(AVERAGE(K10,K14,K18,K22),0) -> 2686 | L34: =IF($F34=0,0,ROUND(K34/$F34*100,2)) -> 17.44 | M34: =ROUND(AVERAGE(M10,M14,M18,M22),0) -> 12718 | N34: =IF($F34=0,0,ROUND(M34/$F34*100,2)) -> 82.56
C35: 운영 | F35: =SUM(G35,I35) -> 4778 | G35: =ROUND(AVERAGE(G11,G15,G19,G23),0) -> 2712 | H35: =IF($F35=0,0,ROUND(G35/$F35*100,2)) -> 56.76 | I35: =ROUND(AVERAGE(I11,I15,I19,I23),0) -> 2066 | J35: =IF($F35=0,0,ROUND(I35/$F35*100,2)) -> 43.24 | K35: =ROUND(AVERAGE(K11,K15,K19,K23),0) -> 2686 | L35: =IF($F35=0,0,ROUND(K35/$F35*100,2)) -> 56.22 | M35: =ROUND(AVERAGE(M11,M15,M19,M23),0) -> 2092 | N35: =IF($F35=0,0,ROUND(M35/$F35*100,2)) -> 43.78
C36: 설치 | F36: =SUM(G36,I36) -> 8779 | G36: =ROUND(AVERAGE(G12,G16,G20,G24),0) -> 0 | H36: =IF($F36=0,0,ROUND(G36/$F36*100,2)) -> 0 | I36: =ROUND(AVERAGE(I12,I16,I20,I24),0) -> 8779 | J36: =IF($F36=0,0,ROUND(I36/$F36*100,2)) -> 100 | K36: =ROUND(AVERAGE(K12,K16,K20,K24),0) -> 0 | L36: =IF($F36=0,0,ROUND(K36/$F36*100,2)) -> 0 | M36: =ROUND(AVERAGE(M12,M16,M20,M24),0) -> 8779 | N36: =IF($F36=0,0,ROUND(M36/$F36*100,2)) -> 100
C37: 유지관리 | F37: =SUM(G37,I37) -> 1848 | G37: =ROUND(AVERAGE(G13,G17,G21,G25),0) -> 0 | H37: =IF($F37=0,0,ROUND(G37/$F37*100,2)) -> 0 | I37: =ROUND(AVERAGE(I13,I17,I21,I25),0) -> 1848 | J37: =IF($F37=0,0,ROUND(I37/$F37*100,2)) -> 100 | K37: =ROUND(AVERAGE(K13,K17,K21,K25),0) -> 0 | L37: =IF($F37=0,0,ROUND(K37/$F37*100,2)) -> 0 | M37: =ROUND(AVERAGE(M13,M17,M21,M25),0) -> 1848 | N37: =IF($F37=0,0,ROUND(M37/$F37*100,2)) -> 100
B38: =INDEX(단가[[2021년]:[2026년]],MATCH($C$7,단가[항목],0),MATCH($B26,단가[[#Headers],[2021년]:[2026년]],0)) -> 51
B39: =INDEX(단가[[2021년]:[2026년]],MATCH($C$8,단가[항목],0),MATCH($B26,단가[[#Headers],[2021년]:[2026년]],0)) -> 299
B40: =INDEX(단가[[2021년]:[2026년]],MATCH($C$9,단가[항목],0),MATCH($B26,단가[[#Headers],[2021년]:[2026년]],0)) -> 120

Sheet 총예산_01
B2: 수문정보 인프라 확충 관련 예산 현황 | M2: 수문정보 인프라 확충 관련 예산 현황(전년도 잔액 예산 반영)
B3: (단위 : 개소, 백만원) | M3: (단위 : 개소, 백만원)
B4: 구분 | D4: 계 | E4: 유량조사 등 수문조사 | I4: 자동유량 운영 및 설치 등 | M4: 구분 | O4: 계 | P4: 유량조사 등 수문조사 | T4: 자동유량 운영 및 설치 등
E5: 유량 | F5: 유사량 | G5: 토양수분량 | H5: 증발산량 | I5: 운영 | J5: 설치 | K5: 유지관리 | P5: 유량 | Q5: 유사량 | R5: 토양수분량 | S5: 증발산량 | T5: 운영 | U5: 설치 | V5: 유지관리
B6: 2021년 | C6: 소계 | D6: =SUM(D7:D8) -> 20832 | E6: =SUM(E7:E8) -> 16296 | F6: =SUM(F7:F8) -> 1200 | G6: =SUM(G7:G8) -> 100 | H6: =SUM(H7:H8) -> 100 | I6: =SUM(I7:I8) -> 3136 | J6: =SUM(J7:J8) -> 0 | K6: =SUM(K7:K8) -> 0 | M6: 2021년 | N6: 소계 | O6: =SUM(O7:O8) -> 20832 | P6: =SUM(P7:P8) -> 16296 | Q6: =SUM(Q7:Q8) -> 1200 | R6: =SUM(R7:R8) -> 100 | S6: =SUM(S7:S8) -> 100 | T6: =SUM(T7:T8) -> 3136 | U6: =SUM(U7:U8) -> 0 | V6: =SUM(V7:V8) -> 0
C7: 기관운영 | D7: =SUM(E7:K7) -> 18345 | E7: =INDEX(유량!$F$6:$I$11,MATCH($B6,유량!$B$6:$B$11,0),MATCH($C7,유량!$F$5:$I$5,0)) -> 15106 | F7: =INDEX(유사량!$F$6:$I$11,MATCH($B6,유사량!$B$6:$B$11,0),MATCH($C7,유사량!$F$5:$I$5,0)) -> 862 | G7: =INDEX(토양수분량!$F$6:$I$11,MATCH($B6,토양수분량!$B$6:$B$11,0),MATCH($C7,토양수분량!$F$5:$I$5,0)) -> 80 | H7: =INDEX(증발산량!$F$6:$I$11,MATCH($B6,증발산량!$B$6:$B$11,0),MATCH($C7,증발산량!$F$5:$I$5,0)) -> 84 | I7: =INDEX(자동유량!$G$6:$J$9,MATCH(I$5,자동유량!$C$6:$C$9,0),MATCH($C7,자동유량!$G$5:$J$5,0)) -> 2213 | J7: =INDEX(자동유량!$G$6:$J$9,MATCH(J$5,자동유량!$C$6:$C$9,0),MATCH($C7,자동유량!$G$5:$J$5,0)) -> 0 | K7: =INDEX(자동유량!$G$6:$J$9,MATCH(K$5,자동유량!$C$6:$C$9,0),MATCH($C7,자동유량!$G$5:$J$5,0)) -> 0 | N7: 기관운영 | O7: =SUM(P7:V7) -> 18345 | P7: =INDEX(유량!$J$6:$M$11,MATCH($M6,유량!$B$6:$B$11,0),MATCH($N7,유량!$J$5:$M$5,0)) -> 15106 | Q7: =INDEX(유사량!$J$6:$M$11,MATCH($M6,유사량!$B$6:$B$11,0),MATCH($N7,유사량!$J$5:$M$5,0)) -> 862 | R7: =INDEX(토양수분량!$J$6:$M$11,MATCH($M6,토양수분량!$B$6:$B$11,0),MATCH($N7,토양수분량!$J$5:$M$5,0)) -> 80 | S7: =INDEX(증발산량!$J$6:$M$11,MATCH($M6,증발산량!$B$6:$B$11,0),MATCH($N7,증발산량!$J$5:$M$5,0)) -> 84 | T7: =INDEX(자동유량!$K$6:$N$9,MATCH(T$5,자동유량!$C$6:$C$9,0),MATCH($N7,자동유량!$K$5:$N$5,0)) -> 2213 | U7: =INDEX(자동유량!$K$6:$N$9,MATCH(U$5,자동유량!$C$6:$C$9,0),MATCH($N7,자동유량!$K$5:$N$5,0)) -> 0 | V7: =INDEX(자동유량!$K$6:$N$9,MATCH(V$5,자동유량!$C$6:$C$9,0),MATCH($N7,자동유량!$K$5:$N$5,0)) -> 0
C8: 사업 | D8: =SUM(E8:K8) -> 2487 | E8: =INDEX(유량!$F$6:$I$11,MATCH($B6,유량!$B$6:$B$11,0),MATCH($C8,유량!$F$5:$I$5,0)) -> 1190 | F8: =INDEX(유사량!$F$6:$I$11,MATCH($B6,유사량!$B$6:$B$11,0),MATCH($C8,유사량!$F$5:$I$5,0)) -> 338 | G8: =INDEX(토양수분량!$F$6:$I$11,MATCH($B6,토양수분량!$B$6:$B$11,0),MATCH($C8,토양수분량!$F$5:$I$5,0)) -> 20 | H8: =INDEX(증발산량!$F$6:$I$11,MATCH($B6,증발산량!$B$6:$B$11,0),MATCH($C8,증발산량!$F$5:$I$5,0)) -> 16 | I8: =INDEX(자동유량!$G$6:$J$9,MATCH(I$5,자동유량!$C$6:$C$9,0),MATCH($C8,자동유량!$G$5:$J$5,0)) -> 923 | J8: =INDEX(자동유량!$G$6:$J$9,MATCH(J$5,자동유량!$C$6:$C$9,0),MATCH($C8,자동유량!$G$5:$J$5,0)) -> 0 | K8: =INDEX(자동유량!$G$6:$J$9,MATCH(K$5,자동유량!$C$6:$C$9,0),MATCH($C8,자동유량!$G$5:$J$5,0)) -> 0 | N8: 사업 | O8: =SUM(P8:V8) -> 2487 | P8: =INDEX(유량!$J$6:$M$11,MATCH($M6,유량!$B$6:$B$11,0),MATCH($N8,유량!$J$5:$M$5,0)) -> 1190 | Q8: =INDEX(유사량!$J$6:$M$11,MATCH($M6,유사량!$B$6:$B$11,0),MATCH($N8,유사량!$J$5:$M$5,0)) -> 338 | R8: =INDEX(토양수분량!$J$6:$M$11,MATCH($M6,토양수분량!$B$6:$B$11,0),MATCH($N8,토양수분량!$J$5:$M$5,0)) -> 20 | S8: =INDEX(증발산량!$J$6:$M$11,MATCH($M6,증발산량!$B$6:$B$11,0),MATCH($N8,증발산량!$J$5:$M$5,0)) -> 16 | T8: =INDEX(자동유량!$K$6:$N$9,MATCH(T$5,자동유량!$C$6:$C$9,0),MATCH($N8,자동유량!$K$5:$N$5,0)) -> 923 | U8: =INDEX(자동유량!$K$6:$N$9,MATCH(U$5,자동유량!$C$6:$C$9,0),MATCH($N8,자동유량!$K$5:$N$5,0)) -> 0 | V8: =INDEX(자동유량!$K$6:$N$9,MATCH(V$5,자동유량!$C$6:$C$9,0),MATCH($N8,자동유량!$K$5:$N$5,0)) -> 0
B9: 2022년 | C9: 소계 | D9: =SUM(D10:D11) -> 28109 | E9: =SUM(E10:E11) -> 20496 | F9: =SUM(F10:F11) -> 1250 | G9: =SUM(G10:G11) -> 100 | H9: =SUM(H10:H11) -> 100 | I9: =SUM(I10:I11) -> 3283 | J9: =SUM(J10:J11) -> 1680 | K9: =SUM(K10:K11) -> 1200 | M9: 2022년 | N9: 소계 | O9: =SUM(O10:O11) -> 28109 | P9: =SUM(P10:P11) -> 20496 | Q9: =SUM(Q10:Q11) -> 1250 | R9: =SUM(R10:R11) -> 100 | S9: =SUM(S10:S11) -> 100 | T9: =SUM(T10:T11) -> 3283 | U9: =SUM(U10:U11) -> 1680 | V9: =SUM(V10:V11) -> 1200
C10: 기관운영 | D10: =SUM(E10:K10) -> 18589 | E10: =INDEX(유량!$F$6:$I$11,MATCH($B9,유량!$B$6:$B$11,0),MATCH($C10,유량!$F$5:$I$5,0)) -> 17006 | F10: =INDEX(유사량!$F$6:$I$11,MATCH($B9,유사량!$B$6:$B$11,0),MATCH($C10,유사량!$F$5:$I$5,0)) -> 894 | G10: =INDEX(토양수분량!$F$6:$I$11,MATCH($B9,토양수분량!$B$6:$B$11,0),MATCH($C10,토양수분량!$F$5:$I$5,0)) -> 73 | H10: =INDEX(증발산량!$F$6:$I$11,MATCH($B9,증발산량!$B$6:$B$11,0),MATCH($C10,증발산량!$F$5:$I$5,0)) -> 71 | I10: =INDEX(자동유량!$G$10:$J$13,MATCH(I$5,자동유량!$C$10:$C$13,0),MATCH($C10,자동유량!$G$5:$J$5,0)) -> 545 | J10: =INDEX(자동유량!$G$10:$J$13,MATCH(J$5,자동유량!$C$10:$C$13,0),MATCH($C10,자동유량!$G$5:$J$5,0)) -> 0 | K10: =INDEX(자동유량!$G$10:$J$13,MATCH(K$5,자동유량!$C$10:$C$13,0),MATCH($C10,자동유량!$G$5:$J$5,0)) -> 0 | N10: 기관운영 | O10: =SUM(P10:V10) -> 18165 | P10: =INDEX(유량!$J$6:$M$11,MATCH($M9,유량!$B$6:$B$11,0),MATCH($N10,유량!$J$5:$M$5,0)) -> 16726 | Q10: =INDEX(유사량!$J$6:$M$11,MATCH($M9,유사량!$B$6:$B$11,0),MATCH($N10,유사량!$J$5:$M$5,0)) -> 875 | R10: =INDEX(토양수분량!$J$6:$M$11,MATCH($M9,토양수분량!$B$6:$B$11,0),MATCH($N10,토양수분량!$J$5:$M$5,0)) -> 32 | S10: =INDEX(증발산량!$J$6:$M$11,MATCH($M9,증발산량!$B$6:$B$11,0),MATCH($N10,증발산량!$J$5:$M$5,0)) -> 29 | T10: =INDEX(자동유량!$K$10:$N$13,MATCH(T$5,자동유량!$C$10:$C$13,0),MATCH($N10,자동유량!$K$5:$N$5,0)) -> 503 | U10: =INDEX(자동유량!$K$10:$N$13,MATCH(U$5,자동유량!$C$10:$C$13,0),MATCH($N10,자동유량!$K$5:$N$5,0)) -> 0 | V10: =INDEX(자동유량!$K$10:$N$13,MATCH(V$5,자동유량!$C$10:$C$13,0),MATCH($N10,자동유량!$K$5:$N$5,0)) -> 0
C11: 사업 | D11: =SUM(E11:K11) -> 9520 | E11: =INDEX(유량!$F$6:$I$11,MATCH($B9,유량!$B$6:$B$11,0),MATCH($C11,유량!$F$5:$I$5,0)) -> 3490 | F11: =INDEX(유사량!$F$6:$I$11,MATCH($B9,유사량!$B$6:$B$11,0),MATCH($C11,유사량!$F$5:$I$5,0)) -> 356 | G11: =INDEX(토양수분량!$F$6:$I$11,MATCH($B9,토양수분량!$B$6:$B$11,0),MATCH($C11,토양수분량!$F$5:$I$5,0)) -> 27 | H11: =INDEX(증발산량!$F$6:$I$11,MATCH($B9,증발산량!$B$6:$B$11,0),MATCH($C11,증발산량!$F$5:$I$5,0)) -> 29 | I11: =INDEX(자동유량!$G$10:$J$13,MATCH(I$5,자동유량!$C$10:$C$13,0),MATCH($C11,자동유량!$G$5:$J$5,0)) -> 2738 | J11: =INDEX(자동유량!$G$10:$J$13,MATCH(J$5,자동유량!$C$10:$C$13,0),MATCH($C11,자동유량!$G$5:$J$5,0)) -> 1680 | K11: =INDEX(자동유량!$G$10:$J$13,MATCH(K$5,자동유량!$C$10:$C$13,0),MATCH($C11,자동유량!$G$5:$J$5,0)) -> 1200 | N11: 사업 | O11: =SUM(P11:V11) -> 9944 | P11: =INDEX(유량!$J$6:$M$11,MATCH($M9,유량!$B$6:$B$11,0),MATCH($N11,유량!$J$5:$M$5,0)) -> 3770 | Q11: =INDEX(유사량!$J$6:$M$11,MATCH($M9,유사량!$B$6:$B$11,0),MATCH($N11,유사량!$J$5:$M$5,0)) -> 375 | R11: =INDEX(토양수분량!$J$6:$M$11,MATCH($M9,토양수분량!$B$6:$B$11,0),MATCH($N11,토양수분량!$J$5:$M$5,0)) -> 68 | S11: =INDEX(증발산량!$J$6:$M$11,MATCH($M9,증발산량!$B$6:$B$11,0),MATCH($N11,증발산량!$J$5:$M$5,0)) -> 71 | T11: =INDEX(자동유량!$K$10:$N$13,MATCH(T$5,자동유량!$C$10:$C$13,0),MATCH($N11,자동유량!$K$5:$N$5,0)) -> 2780 | U11: =INDEX(자동유량!$K$10:$N$13,MATCH(U$5,자동유량!$C$10:$C$13,0),MATCH($N11,자동유량!$K$5:$N$5,0)) -> 1680 | V11: =INDEX(자동유량!$K$10:$N$13,MATCH(V$5,자동유량!$C$10:$C$13,0),MATCH($N11,자동유량!$K$5:$N$5,0)) -> 1200
B12: 2023년 | C12: 소계 | D12: =SUM(D13:D14) -> 27885 | E12: =SUM(E13:E14) -> 20496 | F12: =SUM(F13:F14) -> 1250 | G12: =SUM(G13:G14) -> 100 | H12: =SUM(H13:H14) -> 100 | I12: =SUM(I13:I14) -> 3479 | J12: =SUM(J13:J14) -> 1260 | K12: =SUM(K13:K14) -> 1200 | M12: 2023년 | N12: 소계 | O12: =SUM(O13:O14) -> 27885 | P12: =SUM(P13:P14) -> 20496 | Q12: =SUM(Q13:Q14) -> 1250 | R12: =SUM(R13:R14) -> 100 | S12: =SUM(S13:S14) -> 100 | T12: =SUM(T13:T14) -> 3479 | U12: =SUM(U13:U14) -> 1260 | V12: =SUM(V13:V14) -> 1200
C13: 기관운영 | D13: =SUM(E13:K13) -> 19410 | E13: =INDEX(유량!$F$6:$I$11,MATCH($B12,유량!$B$6:$B$11,0),MATCH($C13,유량!$F$5:$I$5,0)) -> 17907 | F13: =INDEX(유사량!$F$6:$I$11,MATCH($B12,유사량!$B$6:$B$11,0),MATCH($C13,유사량!$F$5:$I$5,0)) -> 834 | G13: =INDEX(토양수분량!$F$6:$I$11,MATCH($B12,토양수분량!$B$6:$B$11,0),MATCH($C13,토양수분량!$F$5:$I$5,0)) -> 45 | H13: =INDEX(증발산량!$F$6:$I$11,MATCH($B12,증발산량!$B$6:$B$11,0),MATCH($C13,증발산량!$F$5:$I$5,0)) -> 62 | I13: =INDEX(자동유량!$G$14:$J$17,MATCH(I$5,자동유량!$C$14:$C$17,0),MATCH($C13,자동유량!$G$5:$J$5,0)) -> 562 | J13: =INDEX(자동유량!$G$14:$J$17,MATCH(J$5,자동유량!$C$14:$C$17,0),MATCH($C13,자동유량!$G$5:$J$5,0)) -> 0 | K13: =INDEX(자동유량!$G$14:$J$17,MATCH(K$5,자동유량!$C$14:$C$17,0),MATCH($C13,자동유량!$G$5:$J$5,0)) -> 0 | N13: 기관운영 | O13: =SUM(P13:V13) -> 19295 | P13: =INDEX(유량!$J$6:$M$11,MATCH($M12,유량!$B$6:$B$11,0),MATCH($N13,유량!$J$5:$M$5,0)) -> 17901 | Q13: =INDEX(유사량!$J$6:$M$11,MATCH($M12,유사량!$B$6:$B$11,0),MATCH($N13,유사량!$J$5:$M$5,0)) -> 725 | R13: =INDEX(토양수분량!$J$6:$M$11,MATCH($M12,토양수분량!$B$6:$B$11,0),MATCH($N13,토양수분량!$J$5:$M$5,0)) -> 45 | S13: =INDEX(증발산량!$J$6:$M$11,MATCH($M12,증발산량!$B$6:$B$11,0),MATCH($N13,증발산량!$J$5:$M$5,0)) -> 62 | T13: =INDEX(자동유량!$K$14:$N$17,MATCH(T$5,자동유량!$C$14:$C$17,0),MATCH($N13,자동유량!$K$5:$N$5,0)) -> 562 | U13: =INDEX(자동유량!$K$14:$N$17,MATCH(U$5,자동유량!$C$14:$C$17,0),MATCH($N13,자동유량!$K$5:$N$5,0)) -> 0 | V13: =INDEX(자동유량!$K$14:$N$17,MATCH(V$5,자동유량!$C$14:$C$17,0),MATCH($N13,자동유량!$K$5:$N$5,0)) -> 0
C14: 사업 | D14: =SUM(E14:K14) -> 8475 | E14: =INDEX(유량!$F$6:$I$11,MATCH($B12,유량!$B$6:$B$11,0),MATCH($C14,유량!$F$5:$I$5,0)) -> 2589 | F14: =INDEX(유사량!$F$6:$I$11,MATCH($B12,유사량!$B$6:$B$11,0),MATCH($C14,유사량!$F$5:$I$5,0)) -> 416 | G14: =INDEX(토양수분량!$F$6:$I$11,MATCH($B12,토양수분량!$B$6:$B$11,0),MATCH($C14,토양수분량!$F$5:$I$5,0)) -> 55 | H14: =INDEX(증발산량!$F$6:$I$11,MATCH($B12,증발산량!$B$6:$B$11,0),MATCH($C14,증발산량!$F$5:$I$5,0)) -> 38 | I14: =INDEX(자동유량!$G$14:$J$17,MATCH(I$5,자동유량!$C$14:$C$17,0),MATCH($C14,자동유량!$G$5:$J$5,0)) -> 2917 | J14: =INDEX(자동유량!$G$14:$J$17,MATCH(J$5,자동유량!$C$14:$C$17,0),MATCH($C14,자동유량!$G$5:$J$5,0)) -> 1260 | K14: =INDEX(자동유량!$G$14:$J$17,MATCH(K$5,자동유량!$C$14:$C$17,0),MATCH($C14,자동유량!$G$5:$J$5,0)) -> 1200 | N14: 사업 | O14: =SUM(P14:V14) -> 8590 | P14: =INDEX(유량!$J$6:$M$11,MATCH($M12,유량!$B$6:$B$11,0),MATCH($N14,유량!$J$5:$M$5,0)) -> 2595 | Q14: =INDEX(유사량!$J$6:$M$11,MATCH($M12,유사량!$B$6:$B$11,0),MATCH($N14,유사량!$J$5:$M$5,0)) -> 525 | R14: =INDEX(토양수분량!$J$6:$M$11,MATCH($M12,토양수분량!$B$6:$B$11,0),MATCH($N14,토양수분량!$J$5:$M$5,0)) -> 55 | S14: =INDEX(증발산량!$J$6:$M$11,MATCH($M12,증발산량!$B$6:$B$11,0),MATCH($N14,증발산량!$J$5:$M$5,0)) -> 38 | T14: =INDEX(자동유량!$K$14:$N$17,MATCH(T$5,자동유량!$C$14:$C$17,0),MATCH($N14,자동유량!$K$5:$N$5,0)) -> 2917 | U14: =INDEX(자동유량!$K$14:$N$17,MATCH(U$5,자동유량!$C$14:$C$17,0),MATCH($N14,자동유량!$K$5:$N$5,0)) -> 1260 | V14: =INDEX(자동유량!$K$14:$N$17,MATCH(V$5,자동유량!$C$14:$C$17,0),MATCH($N14,자동유량!$K$5:$N$5,0)) -> 1200
B15: 2024년 | C15: 소계 | D15: =SUM(D16:D17) -> 35270 | E15: =SUM(E16:E17) -> 23856 | F15: =SUM(F16:F17) -> 1250 | G15: =SUM(G16:G17) -> 100 | H15: =SUM(H16:H17) -> 100 | I15: =SUM(I16:I17) -> 3724 | J15: =SUM(J16:J17) -> 4200 | K15: =SUM(K16:K17) -> 2040 | M15: 2024년 | N15: 소계 | O15: =SUM(O16:O17) -> 35270 | P15: =SUM(P16:P17) -> 23856 | Q15: =SUM(Q16:Q17) -> 1250 | R15: =SUM(R16:R17) -> 100 | S15: =SUM(S16:S17) -> 100 | T15: =SUM(T16:T17) -> 3724 | U15: =SUM(U16:U17) -> 4200 | V15: =SUM(V16:V17) -> 2040
C16: 기관운영 | D16: =SUM(E16:K16) -> 24285 | E16: =INDEX(유량!$F$6:$I$11,MATCH($B15,유량!$B$6:$B$11,0),MATCH($C16,유량!$F$5:$I$5,0)) -> 20064 | F16: =INDEX(유사량!$F$6:$I$11,MATCH($B15,유사량!$B$6:$B$11,0),MATCH($C16,유사량!$F$5:$I$5,0)) -> 1029 | G16: =INDEX(토양수분량!$F$6:$I$11,MATCH($B15,토양수분량!$B$6:$B$11,0),MATCH($C16,토양수분량!$F$5:$I$5,0)) -> 70 | H16: =INDEX(증발산량!$F$6:$I$11,MATCH($B15,증발산량!$B$6:$B$11,0),MATCH($C16,증발산량!$F$5:$I$5,0)) -> 70 | I16: =INDEX(자동유량!$G$18:$J$21,MATCH(I$5,자동유량!$C$18:$C$21,0),MATCH($C16,자동유량!$G$5:$J$5,0)) -> 3052 | J16: =INDEX(자동유량!$G$18:$J$21,MATCH(J$5,자동유량!$C$18:$C$21,0),MATCH($C16,자동유량!$G$5:$J$5,0)) -> 0 | K16: =INDEX(자동유량!$G$18:$J$21,MATCH(K$5,자동유량!$C$18:$C$21,0),MATCH($C16,자동유량!$G$5:$J$5,0)) -> 0 | N16: 기관운영 | O16: =SUM(P16:V16) -> 24075 | P16: =INDEX(유량!$J$6:$M$11,MATCH($M15,유량!$B$6:$B$11,0),MATCH($N16,유량!$J$5:$M$5,0)) -> 19906 | Q16: =INDEX(유사량!$J$6:$M$11,MATCH($M15,유사량!$B$6:$B$11,0),MATCH($N16,유사량!$J$5:$M$5,0)) -> 1029 | R16: =INDEX(토양수분량!$J$6:$M$11,MATCH($M15,토양수분량!$B$6:$B$11,0),MATCH($N16,토양수분량!$J$5:$M$5,0)) -> 53 | S16: =INDEX(증발산량!$J$6:$M$11,MATCH($M15,증발산량!$B$6:$B$11,0),MATCH($N16,증발산량!$J$5:$M$5,0)) -> 53 | T16: =INDEX(자동유량!$K$18:$N$21,MATCH(T$5,자동유량!$C$18:$C$21,0),MATCH($N13,자동유량!$K$5:$N$5,0)) -> 3034 | U16: =INDEX(자동유량!$K$18:$N$21,MATCH(U$5,자동유량!$C$18:$C$21,0),MATCH($N13,자동유량!$K$5:$N$5,0)) -> 0 | V16: =INDEX(자동유량!$K$18:$N$21,MATCH(V$5,자동유량!$C$18:$C$21,0),MATCH($N13,자동유량!$K$5:$N$5,0)) -> 0
C17: 사업 | D17: =SUM(E17:K17) -> 10985 | E17: =INDEX(유량!$F$6:$I$11,MATCH($B15,유량!$B$6:$B$11,0),MATCH($C17,유량!$F$5:$I$5,0)) -> 3792 | F17: =INDEX(유사량!$F$6:$I$11,MATCH($B15,유사량!$B$6:$B$11,0),MATCH($C17,유사량!$F$5:$I$5,0)) -> 221 | G17: =INDEX(토양수분량!$F$6:$I$11,MATCH($B15,토양수분량!$B$6:$B$11,0),MATCH($C17,토양수분량!$F$5:$I$5,0)) -> 30 | H17: =INDEX(증발산량!$F$6:$I$11,MATCH($B15,증발산량!$B$6:$B$11,0),MATCH($C17,증발산량!$F$5:$I$5,0)) -> 30 | I17: =INDEX(자동유량!$G$18:$J$21,MATCH(I$5,자동유량!$C$18:$C$21,0),MATCH($C17,자동유량!$G$5:$J$5,0)) -> 672 | J17: =INDEX(자동유량!$G$18:$J$21,MATCH(J$5,자동유량!$C$18:$C$21,0),MATCH($C17,자동유량!$G$5:$J$5,0)) -> 4200 | K17: =INDEX(자동유량!$G$18:$J$21,MATCH(K$5,자동유량!$C$18:$C$21,0),MATCH($C17,자동유량!$G$5:$J$5,0)) -> 2040 | N17: 사업 | O17: =SUM(P17:V17) -> 11195 | P17: =INDEX(유량!$J$6:$M$11,MATCH($M15,유량!$B$6:$B$11,0),MATCH($N17,유량!$J$5:$M$5,0)) -> 3950 | Q17: =INDEX(유사량!$J$6:$M$11,MATCH($M15,유사량!$B$6:$B$11,0),MATCH($N17,유사량!$J$5:$M$5,0)) -> 221 | R17: =INDEX(토양수분량!$J$6:$M$11,MATCH($M15,토양수분량!$B$6:$B$11,0),MATCH($N17,토양수분량!$J$5:$M$5,0)) -> 47 | S17: =INDEX(증발산량!$J$6:$M$11,MATCH($M15,증발산량!$B$6:$B$11,0),MATCH($N17,증발산량!$J$5:$M$5,0)) -> 47 | T17: =INDEX(자동유량!$K$18:$N$21,MATCH(T$5,자동유량!$C$18:$C$21,0),MATCH($N14,자동유량!$K$5:$N$5,0)) -> 690 | U17: =INDEX(자동유량!$K$18:$N$21,MATCH(U$5,자동유량!$C$18:$C$21,0),MATCH($N14,자동유량!$K$5:$N$5,0)) -> 4200 | V17: =INDEX(자동유량!$K$18:$N$21,MATCH(V$5,자동유량!$C$18:$C$21,0),MATCH($N14,자동유량!$K$5:$N$5,0)) -> 2040
B18: 2025년 | C18: 소계 | D18: =SUM(D19:D20) -> 56623 | E18: =SUM(E19:E20) -> 15624 | F18: =SUM(F19:F20) -> 1250 | G18: =SUM(G19:G20) -> 100 | H18: =SUM(H19:H20) -> 100 | I18: =SUM(I19:I20) -> 8624 | J18: =SUM(J19:J20) -> 27975 | K18: =SUM(K19:K20) -> 2950 | M18: 2025년 | N18: 소계 | O18: =SUM(O19:O20) -> 56623 | P18: =SUM(P19:P20) -> 15624 | Q18: =SUM(Q19:Q20) -> 1250 | R18: =SUM(R19:R20) -> 100 | S18: =SUM(S19:S20) -> 100 | T18: =SUM(T19:T20) -> 8624 | U18: =SUM(U19:U20) -> 27975 | V18: =SUM(V19:V20) -> 2950
C19: 기관운영 | D19: =SUM(E19:K19) -> 20919 | E19: =INDEX(유량!$F$6:$I$11,MATCH($B18,유량!$B$6:$B$11,0),MATCH($C19,유량!$F$5:$I$5,0)) -> 12996 | F19: =INDEX(유사량!$F$6:$I$11,MATCH($B18,유사량!$B$6:$B$11,0),MATCH($C19,유사량!$F$5:$I$5,0)) -> 1075 | G19: =INDEX(토양수분량!$F$6:$I$11,MATCH($B18,토양수분량!$B$6:$B$11,0),MATCH($C19,토양수분량!$F$5:$I$5,0)) -> 80 | H19: =INDEX(증발산량!$F$6:$I$11,MATCH($B18,증발산량!$B$6:$B$11,0),MATCH($C19,증발산량!$F$5:$I$5,0)) -> 80 | I19: =INDEX(자동유량!$G$22:$J$25,MATCH(I$5,자동유량!$C$22:$C$25,0),MATCH($C19,자동유량!$G$5:$J$5,0)) -> 6688 | J19: =INDEX(자동유량!$G$22:$J$25,MATCH(J$5,자동유량!$C$22:$C$25,0),MATCH($C19,자동유량!$G$5:$J$5,0)) -> 0 | K19: =INDEX(자동유량!$G$22:$J$25,MATCH(K$5,자동유량!$C$22:$C$25,0),MATCH($C19,자동유량!$G$5:$J$5,0)) -> 0 | N19: 기관운영 | O19: =SUM(P19:V19) -> 20016 | P19: =INDEX(유량!$J$6:$M$11,MATCH($M18,유량!$B$6:$B$11,0),MATCH($N19,유량!$J$5:$M$5,0)) -> 12526 | Q19: =INDEX(유사량!$J$6:$M$11,MATCH($M18,유사량!$B$6:$B$11,0),MATCH($N19,유사량!$J$5:$M$5,0)) -> 774 | R19: =INDEX(토양수분량!$J$6:$M$11,MATCH($M18,토양수분량!$B$6:$B$11,0),MATCH($N19,토양수분량!$J$5:$M$5,0)) -> 36 | S19: =INDEX(증발산량!$J$6:$M$11,MATCH($M18,증발산량!$B$6:$B$11,0),MATCH($N19,증발산량!$J$5:$M$5,0)) -> 36 | T19: =INDEX(자동유량!$K$22:$N$25,MATCH(T$5,자동유량!$C$22:$C$25,0),MATCH($N13,자동유량!$K$5:$N$5,0)) -> 6644 | U19: =INDEX(자동유량!$K$22:$N$25,MATCH(U$5,자동유량!$C$22:$C$25,0),MATCH($N13,자동유량!$K$5:$N$5,0)) -> 0 | V19: =INDEX(자동유량!$K$22:$N$25,MATCH(V$5,자동유량!$C$22:$C$25,0),MATCH($N13,자동유량!$K$5:$N$5,0)) -> 0
