Workbook

Sheet 항목별예산
B2: 수문조사 항목별 예산 현황 | J2: 수문조사 항목별 예산 현황(전년도 잔액 예산 반영)
B4: 구분 | C4: 2021년 | D4: 2022년 | E4: 2023년 | F4: 2024년 | G4: 2025년 | H4: 2026년 | J4: 구분 | K4: 2021년 | L4: 2022년 | M4: 2023년 | N4: 2024년 | O4: 2025년 | P4: 2026년
B5: 계 | C5: =SUM(C6:C10) -> 2487456225 | D5: =SUM(D6:D10) -> 9520000000 | E5: =SUM(E6:E10) -> 8475000000 | F5: =SUM(F6:F10) -> 10985000000 | G5: =SUM(G6:G10) -> 35704000000 | H5: =SUM(H6:H10) -> 18488000000 | J5: 계 | K5: =SUM(K6:K10) -> 2487456225 | L5: =SUM(L6:L10) -> 9943740153 | M5: =SUM(M6:M10) -> 8590082000 | N5: =SUM(N6:N10) -> 11195749215 | O5: =SUM(O6:O10) -> 36607548900 | P5: =SUM(P6:P10) -> 18488000000
B6: 유량 | C6: =유량!$D$4 -> 1190182077 | D6: =유량!$F$4 -> 3490000000 | E6: =유량!$H$4 -> 2588664990 | F6: =유량!$J$4 -> 3791790577 | G6: =유량!$L$4 -> 2628000000 | H6: =유량!$N$4 -> 2039920000 | J6: 유량 | K6: =SUM(유량!D$4:E$4) -> 1190182077 | L6: =SUM(유량!F$4:G$4) -> 3770139873 | M6: =SUM(유량!H$4:I$4) -> 2594604990 | N6: =SUM(유량!J$4:K$4) -> 3950363432 | O6: =SUM(유량!L$4:M$4) -> 3097893500 | P6: =SUM(유량!N$4:O$4) -> 2039920000
B7: 자동유량 | C7: =자동유량!$D$4 -> 922911768 | D7: =자동유량!$F$4 -> 5618000000 | E7: =자동유량!$H$4 -> 5377336970 | F7: =자동유량!$J$4 -> 6912209423 | G7: =자동유량!$L$4 -> 32861000000 | H7: =자동유량!$N$4 -> 16249080000 | J7: 자동유량 | K7: =SUM(자동유량!D$4:E$4) -> 922911768 | L7: =SUM(자동유량!F$4:G$4) -> 5659525000 | M7: =SUM(자동유량!H$4:I$4) -> 5377336970 | N7: =SUM(자동유량!J$4:K$4) -> 6929601543 | O7: =SUM(자동유량!L$4:M$4) -> 32905136330 | P7: =SUM(자동유량!N$4:O$4) -> 16249080000
B8: 유사량 | C8: =유사량!$D$4 -> 337965730 | D8: =유사량!$F$4 -> 356000000 | E8: =유사량!$H$4 -> 416083240 | F8: =유사량!$J$4 -> 221000000 | G8: =유사량!$L$4 -> 175000000 | H8: =유사량!$N$4 -> 159000000 | J8: 유사량 | K8: =SUM(유사량!D$4:E$4) -> 337965730 | L8: =SUM(유사량!F$4:G$4) -> 375025280 | M8: =SUM(유사량!H$4:I$4) -> 525225240 | N8: =SUM(유사량!J$4:K$4) -> 221000000 | O8: =SUM(유사량!L$4:M$4) -> 476246410 | P8: =SUM(유사량!N$4:O$4) -> 159000000
B9: 토양수분량 | C9: =토양수분량!$D$4 -> 20453200 | D9: =토양수분량!$F$4 -> 26700000 | E9: =토양수분량!$H$4 -> 55206400 | F9: =토양수분량!$J$4 -> 30000000 | G9: =토양수분량!$L$4 -> 20000000 | H9: =토양수분량!$N$4 -> 20000000 | J9: 토양수분량 | K9: =SUM(토양수분량!D$4:E$4) -> 20453200 | L9: =SUM(토양수분량!F$4:G$4) -> 68225000 | M9: =SUM(토양수분량!H$4:I$4) -> 55206400 | N9: =SUM(토양수분량!J$4:K$4) -> 47392120 | O9: =SUM(토양수분량!L$4:M$4) -> 64136330 | P9: =SUM(토양수분량!N$4:O$4) -> 20000000
B10: 증발산량 | C10: =증발산량!$D$4 -> 15943450 | D10: =증발산량!$F$4 -> 29300000 | E10: =증발산량!$H$4 -> 37708400 | F10: =증발산량!$J$4 -> 30000000 | G10: =증발산량!$L$4 -> 20000000 | H10: =증발산량!$N$4 -> 20000000 | J10: 증발산량 | K10: =SUM(증발산량!D$4:E$4) -> 15943450 | L10: =SUM(증발산량!F$4:G$4) -> 70825000 | M10: =SUM(증발산량!H$4:I$4) -> 37708400 | N10: =SUM(증발산량!J$4:K$4) -> 47392120 | O10: =SUM(증발산량!L$4:M$4) -> 64136330 | P10: =SUM(증발산량!N$4:O$4) -> 20000000

Sheet 유량
B1: 유량
B2: 편성목 | C2: 통계목 | D2: 2021년 | F2: 2022년 | H2: 2023년 | J2: 2024년 | L2: 2025년 | N2: 2026년
D3: 실행예산 | E3: 잔액 예산 | F3: 실행예산 | G3: 잔액 예산 | H3: 실행예산 | I3: 잔액 예산 | J3: 실행예산 | K3: 잔액 예산 | L3: 실행예산 | M3: 잔액 예산 | N3: 실행예산 | O3: 잔액 예산
B4: 합계 | D4: =SUM(D5,D10,D23,D26,D29,D32,D34,D40,D42,D44,D46) -> 1190182077 | E4: =SUM(E5,E10,E23,E26,E29,E32,E34,E40,E42,E44,E46) -> 0 | F4: =SUM(F5,F10,F23,F26,F29,F32,F34,F40,F42,F44,F46) -> 3490000000 | G4: =SUM(G5,G10,G23,G26,G29,G32,G34,G40,G42,G44,G46) -> 280139873 | H4: =SUM(H5,H10,H23,H26,H29,H32,H34,H40,H42,H44,H46) -> 2588664990 | I4: =SUM(I5,I10,I23,I26,I29,I32,I34,I40,I42,I44,I46) -> 5940000 | J4: =SUM(J5,J10,J23,J26,J29,J32,J34,J40,J42,J44,J46) -> 3791790577 | K4: =SUM(K5,K10,K23,K26,K29,K32,K34,K40,K42,K44,K46) -> 158572855 | ... O4: =SUM(O5,O10,O23,O26,O29,O32,O34,O40,O42,O44,O46) -> 0
B5: 인건비 | C5: 소계 | D5: =SUM(D6:D9) -> 123200000 | E5: =SUM(E6:E9) -> 0 | F5: =SUM(F6:F9) -> 443000000 | G5: =SUM(G6:G9) -> 0 | H5: =SUM(H6:H9) -> 747380000 | I5: =SUM(I6:I9) -> 0 | J5: =SUM(J6:J9) -> 572951413 | K5: =SUM(K6:K9) -> 0 | ... O5: =SUM(O6:O9) -> 0
C6: 보수 | G6: =IF(SUMIFS(잔액_2022[결의금액],잔액_2022[통계목],$C6,잔액_2022[분류 항목],"유량")=0,"",SUMIFS(잔액_2022[결의금액],잔액_2022[통계목],$C6,잔액_2022[분류 항목],"유량")) | I6: =IF(SUMIFS(잔액_2023[결의금액],잔액_2023[통계목],$C6,잔액_2023[분류 항목],"유량")=0,"",SUMIFS(잔액_2023[결의금액],잔액_2023[통계목],$C6,잔액_2023[분류 항목],"유량")) | K6: =IF(SUMIFS(잔액_2024[결의금액],잔액_2024[통계목],$C6,잔액_2024[분류 항목],"유량")=0,"",SUMIFS(잔액_2024[결의금액],잔액_2024[통계목],$C6,잔액_2024[분류 항목],"유량")) | M6: =IF(SUMIFS(잔액_2025[결의금액],잔액_2025[통계목],$C6,잔액_2025[분류 항목],"유량")=0,"",SUMIFS(잔액_2025[결의금액],잔액_2025[통계목],$C6,잔액_2025[분류 항목],"유량"))
C7: 기타직보수 | G7: =IF(SUMIFS(잔액_2022[결의금액],잔액_2022[통계목],$C7,잔액_2022[분류 항목],"유량")=0,"",SUMIFS(잔액_2022[결의금액],잔액_2022[통계목],$C7,잔액_2022[분류 항목],"유량")) | I7: =IF(SUMIFS(잔액_2023[결의금액],잔액_2023[통계목],$C7,잔액_2023[분류 항목],"유량")=0,"",SUMIFS(잔액_2023[결의금액],잔액_2023[통계목],$C7,잔액_2023[분류 항목],"유량")) | K7: =IF(SUMIFS(잔액_2024[결의금액],잔액_2024[통계목],$C7,잔액_2024[분류 항목],"유량")=0,"",SUMIFS(잔액_2024[결의금액],잔액_2024[통계목],$C7,잔액_2024[분류 항목],"유량")) | M7: =IF(SUMIFS(잔액_2025[결의금액],잔액_2025[통계목],$C7,잔액_2025[분류 항목],"유량")=0,"",SUMIFS(잔액_2025[결의금액],잔액_2025[통계목],$C7,잔액_2025[분류 항목],"유량")) | N7: 12800000
C8: 상용임금 | F8: 443000000 | G8: =IF(SUMIFS(잔액_2022[결의금액],잔액_2022[통계목],$C8,잔액_2022[분류 항목],"유량")=0,"",SUMIFS(잔액_2022[결의금액],잔액_2022[통계목],$C8,잔액_2022[분류 항목],"유량")) | H8: 747380000 | I8: =IF(SUMIFS(잔액_2023[결의금액],잔액_2023[통계목],$C8,잔액_2023[분류 항목],"유량")=0,"",SUMIFS(잔액_2023[결의금액],잔액_2023[통계목],$C8,잔액_2023[분류 항목],"유량")) | J8: 572951413 | K8: =IF(SUMIFS(잔액_2024[결의금액],잔액_2024[통계목],$C8,잔액_2024[분류 항목],"유량")=0,"",SUMIFS(잔액_2024[결의금액],잔액_2024[통계목],$C8,잔액_2024[분류 항목],"유량")) | L8: 342209542 | M8: =IF(SUMIFS(잔액_2025[결의금액],잔액_2025[통계목],$C8,잔액_2025[분류 항목],"유량")=0,"",SUMIFS(잔액_2025[결의금액],잔액_2025[통계목],$C8,잔액_2025[분류 항목],"유량"))
C9: 일용임금 | D9: 123200000 | G9: =IF(SUMIFS(잔액_2022[결의금액],잔액_2022[통계목],$C9,잔액_2022[분류 항목],"유량")=0,"",SUMIFS(잔액_2022[결의금액],잔액_2022[통계목],$C9,잔액_2022[분류 항목],"유량")) | I9: =IF(SUMIFS(잔액_2023[결의금액],잔액_2023[통계목],$C9,잔액_2023[분류 항목],"유량")=0,"",SUMIFS(잔액_2023[결의금액],잔액_2023[통계목],$C9,잔액_2023[분류 항목],"유량")) | K9: =IF(SUMIFS(잔액_2024[결의금액],잔액_2024[통계목],$C9,잔액_2024[분류 항목],"유량")=0,"",SUMIFS(잔액_2024[결의금액],잔액_2024[통계목],$C9,잔액_2024[분류 항목],"유량")) | M9: =IF(SUMIFS(잔액_2025[결의금액],잔액_2025[통계목],$C9,잔액_2025[분류 항목],"유량")=0,"",SUMIFS(잔액_2025[결의금액],잔액_2025[통계목],$C9,잔액_2025[분류 항목],"유량"))
B10: 운영비 | C10: 소계 | D10: =SUM(D11:D22) -> 515397177 | E10: =SUM(E11:E22) -> 0 | F10: =SUM(F11:F22) -> 874000000 | G10: =SUM(G11:G22) -> 0 | H10: =SUM(H11:H22) -> 827554990 | I10: =SUM(I11:I22) -> 0 | J10: =SUM(J11:J22) -> 945626566 | K10: =SUM(K11:K22) -> 0 | ... O10: =SUM(O11:O22) -> 0
C11: 일반수용비 | D11: 472624256 | F11: 318000000 | G11: =IF(SUMIFS(잔액_2022[결의금액],잔액_2022[통계목],$C11,잔액_2022[분류 항목],"유량")=0,"",SUMIFS(잔액_2022[결의금액],잔액_2022[통계목],$C11,잔액_2022[분류 항목],"유량")) | H11: 234927550 | I11: =IF(SUMIFS(잔액_2023[결의금액],잔액_2023[통계목],$C11,잔액_2023[분류 항목],"유량")=0,"",SUMIFS(잔액_2023[결의금액],잔액_2023[통계목],$C11,잔액_2023[분류 항목],"유량")) | J11: 119515600 | K11: =IF(SUMIFS(잔액_2024[결의금액],잔액_2024[통계목],$C11,잔액_2024[분류 항목],"유량")=0,"",SUMIFS(잔액_2024[결의금액],잔액_2024[통계목],$C11,잔액_2024[분류 항목],"유량")) | L11: 153020400 | M11: =IF(SUMIFS(잔액_2025[결의금액],잔액_2025[통계목],$C11,잔액_2025[분류 항목],"유량")=0,"",SUMIFS(잔액_2025[결의금액],잔액_2025[통계목],$C11,잔액_2025[분류 항목],"유량")) | N11: 63420000
C12: 공공요금 및 제세 | F12: 10000000 | G12: =IF(SUMIFS(잔액_2022[결의금액],잔액_2022[통계목],$C12,잔액_2022[분류 항목],"유량")=0,"",SUMIFS(잔액_2022[결의금액],잔액_2022[통계목],$C12,잔액_2022[분류 항목],"유량")) | H12: 14250440 | I12: =IF(SUMIFS(잔액_2023[결의금액],잔액_2023[통계목],$C12,잔액_2023[분류 항목],"유량")=0,"",SUMIFS(잔액_2023[결의금액],잔액_2023[통계목],$C12,잔액_2023[분류 항목],"유량")) | J12: 10020000 | K12: =IF(SUMIFS(잔액_2024[결의금액],잔액_2024[통계목],$C12,잔액_2024[분류 항목],"유량")=0,"",SUMIFS(잔액_2024[결의금액],잔액_2024[통계목],$C12,잔액_2024[분류 항목],"유량")) | L12: 9040000 | M12: =IF(SUMIFS(잔액_2025[결의금액],잔액_2025[통계목],$C12,잔액_2025[분류 항목],"유량")=0,"",SUMIFS(잔액_2025[결의금액],잔액_2025[통계목],$C12,잔액_2025[분류 항목],"유량")) | N12: 8860000
C13: 피복비 | G13: =IF(SUMIFS(잔액_2022[결의금액],잔액_2022[통계목],$C13,잔액_2022[분류 항목],"유량")=0,"",SUMIFS(잔액_2022[결의금액],잔액_2022[통계목],$C13,잔액_2022[분류 항목],"유량")) | I13: =IF(SUMIFS(잔액_2023[결의금액],잔액_2023[통계목],$C13,잔액_2023[분류 항목],"유량")=0,"",SUMIFS(잔액_2023[결의금액],잔액_2023[통계목],$C13,잔액_2023[분류 항목],"유량")) | K13: =IF(SUMIFS(잔액_2024[결의금액],잔액_2024[통계목],$C13,잔액_2024[분류 항목],"유량")=0,"",SUMIFS(잔액_2024[결의금액],잔액_2024[통계목],$C13,잔액_2024[분류 항목],"유량")) | M13: =IF(SUMIFS(잔액_2025[결의금액],잔액_2025[통계목],$C13,잔액_2025[분류 항목],"유량")=0,"",SUMIFS(잔액_2025[결의금액],잔액_2025[통계목],$C13,잔액_2025[분류 항목],"유량"))
C14: 특근매식비 | G14: =IF(SUMIFS(잔액_2022[결의금액],잔액_2022[통계목],$C14,잔액_2022[분류 항목],"유량")=0,"",SUMIFS(잔액_2022[결의금액],잔액_2022[통계목],$C14,잔액_2022[분류 항목],"유량")) | I14: =IF(SUMIFS(잔액_2023[결의금액],잔액_2023[통계목],$C14,잔액_2023[분류 항목],"유량")=0,"",SUMIFS(잔액_2023[결의금액],잔액_2023[통계목],$C14,잔액_2023[분류 항목],"유량")) | K14: =IF(SUMIFS(잔액_2024[결의금액],잔액_2024[통계목],$C14,잔액_2024[분류 항목],"유량")=0,"",SUMIFS(잔액_2024[결의금액],잔액_2024[통계목],$C14,잔액_2024[분류 항목],"유량")) | M14: =IF(SUMIFS(잔액_2025[결의금액],잔액_2025[통계목],$C14,잔액_2025[분류 항목],"유량")=0,"",SUMIFS(잔액_2025[결의금액],잔액_2025[통계목],$C14,잔액_2025[분류 항목],"유량"))
C15: 임차료 | F15: 388000000 | G15: =IF(SUMIFS(잔액_2022[결의금액],잔액_2022[통계목],$C15,잔액_2022[분류 항목],"유량")=0,"",SUMIFS(잔액_2022[결의금액],잔액_2022[통계목],$C15,잔액_2022[분류 항목],"유량")) | H15: 469311000 | I15: =IF(SUMIFS(잔액_2023[결의금액],잔액_2023[통계목],$C15,잔액_2023[분류 항목],"유량")=0,"",SUMIFS(잔액_2023[결의금액],잔액_2023[통계목],$C15,잔액_2023[분류 항목],"유량")) | J15: 567318105 | K15: =IF(SUMIFS(잔액_2024[결의금액],잔액_2024[통계목],$C15,잔액_2024[분류 항목],"유량")=0,"",SUMIFS(잔액_2024[결의금액],잔액_2024[통계목],$C15,잔액_2024[분류 항목],"유량")) | L15: 663210000 | M15: =IF(SUMIFS(잔액_2025[결의금액],잔액_2025[통계목],$C15,잔액_2025[분류 항목],"유량")=0,"",SUMIFS(잔액_2025[결의금액],잔액_2025[통계목],$C15,잔액_2025[분류 항목],"유량")) | N15: 553740000
C16: 유류비 | D16: 42772921 | F16: 95000000 | G16: =IF(SUMIFS(잔액_2022[결의금액],잔액_2022[통계목],$C16,잔액_2022[분류 항목],"유량")=0,"",SUMIFS(잔액_2022[결의금액],잔액_2022[통계목],$C16,잔액_2022[분류 항목],"유량")) | H16: 78866000 | I16: =IF(SUMIFS(잔액_2023[결의금액],잔액_2023[통계목],$C16,잔액_2023[분류 항목],"유량")=0,"",SUMIFS(잔액_2023[결의금액],잔액_2023[통계목],$C16,잔액_2023[분류 항목],"유량")) | J16: 78800000 | K16: =IF(SUMIFS(잔액_2024[결의금액],잔액_2024[통계목],$C16,잔액_2024[분류 항목],"유량")=0,"",SUMIFS(잔액_2024[결의금액],잔액_2024[통계목],$C16,잔액_2024[분류 항목],"유량")) | L16: 78800000 | M16: =IF(SUMIFS(잔액_2025[결의금액],잔액_2025[통계목],$C16,잔액_2025[분류 항목],"유량")=0,"",SUMIFS(잔액_2025[결의금액],잔액_2025[통계목],$C16,잔액_2025[분류 항목],"유량")) | N16: 33000000
C17: 시설장비유지비 | F17: 54000000 | G17: =IF(SUMIFS(잔액_2022[결의금액],잔액_2022[통계목],$C17,잔액_2022[분류 항목],"유량")=0,"",SUMIFS(잔액_2022[결의금액],잔액_2022[통계목],$C17,잔액_2022[분류 항목],"유량")) | H17: 30200000 | I17: =IF(SUMIFS(잔액_2023[결의금액],잔액_2023[통계목],$C17,잔액_2023[분류 항목],"유량")=0,"",SUMIFS(잔액_2023[결의금액],잔액_2023[통계목],$C17,잔액_2023[분류 항목],"유량")) | J17: 25000000 | K17: =IF(SUMIFS(잔액_2024[결의금액],잔액_2024[통계목],$C17,잔액_2024[분류 항목],"유량")=0,"",SUMIFS(잔액_2024[결의금액],잔액_2024[통계목],$C17,잔액_2024[분류 항목],"유량")) | L17: 93350000 | M17: =IF(SUMIFS(잔액_2025[결의금액],잔액_2025[통계목],$C17,잔액_2025[분류 항목],"유량")=0,"",SUMIFS(잔액_2025[결의금액],잔액_2025[통계목],$C17,잔액_2025[분류 항목],"유량")) | N17: 28000000
C18: 재료비 | F18: 9000000 | G18: =IF(SUMIFS(잔액_2022[결의금액],잔액_2022[통계목],$C18,잔액_2022[분류 항목],"유량")=0,"",SUMIFS(잔액_2022[결의금액],잔액_2022[통계목],$C18,잔액_2022[분류 항목],"유량")) | I18: =IF(SUMIFS(잔액_2023[결의금액],잔액_2023[통계목],$C18,잔액_2023[분류 항목],"유량")=0,"",SUMIFS(잔액_2023[결의금액],잔액_2023[통계목],$C18,잔액_2023[분류 항목],"유량")) | J18: 134972861 | K18: =IF(SUMIFS(잔액_2024[결의금액],잔액_2024[통계목],$C18,잔액_2024[분류 항목],"유량")=0,"",SUMIFS(잔액_2024[결의금액],잔액_2024[통계목],$C18,잔액_2024[분류 항목],"유량")) | L18: 108481560 | M18: =IF(SUMIFS(잔액_2025[결의금액],잔액_2025[통계목],$C18,잔액_2025[분류 항목],"유량")=0,"",SUMIFS(잔액_2025[결의금액],잔액_2025[통계목],$C18,잔액_2025[분류 항목],"유량")) | N18: 28000000
C19: 복리후생비 | G19: =IF(SUMIFS(잔액_2022[결의금액],잔액_2022[통계목],$C19,잔액_2022[분류 항목],"유량")=0,"",SUMIFS(잔액_2022[결의금액],잔액_2022[통계목],$C19,잔액_2022[분류 항목],"유량")) | I19: =IF(SUMIFS(잔액_2023[결의금액],잔액_2023[통계목],$C19,잔액_2023[분류 항목],"유량")=0,"",SUMIFS(잔액_2023[결의금액],잔액_2023[통계목],$C19,잔액_2023[분류 항목],"유량")) | K19: =IF(SUMIFS(잔액_2024[결의금액],잔액_2024[통계목],$C19,잔액_2024[분류 항목],"유량")=0,"",SUMIFS(잔액_2024[결의금액],잔액_2024[통계목],$C19,잔액_2024[분류 항목],"유량")) | M19: =IF(SUMIFS(잔액_2025[결의금액],잔액_2025[통계목],$C19,잔액_2025[분류 항목],"유량")=0,"",SUMIFS(잔액_2025[결의금액],잔액_2025[통계목],$C19,잔액_2025[분류 항목],"유량"))
C20: 일반용역비 | G20: =IF(SUMIFS(잔액_2022[결의금액],잔액_2022[통계목],$C20,잔액_2022[분류 항목],"유량")=0,"",SUMIFS(잔액_2022[결의금액],잔액_2022[통계목],$C20,잔액_2022[분류 항목],"유량")) | I20: =IF(SUMIFS(잔액_2023[결의금액],잔액_2023[통계목],$C20,잔액_2023[분류 항목],"유량")=0,"",SUMIFS(잔액_2023[결의금액],잔액_2023[통계목],$C20,잔액_2023[분류 항목],"유량")) | J20: 10000000 | K20: =IF(SUMIFS(잔액_2024[결의금액],잔액_2024[통계목],$C20,잔액_2024[분류 항목],"유량")=0,"",SUMIFS(잔액_2024[결의금액],잔액_2024[통계목],$C20,잔액_2024[분류 항목],"유량")) | L20: 78000000 | M20: =IF(SUMIFS(잔액_2025[결의금액],잔액_2025[통계목],$C20,잔액_2025[분류 항목],"유량")=0,"",SUMIFS(잔액_2025[결의금액],잔액_2025[통계목],$C20,잔액_2025[분류 항목],"유량")) | N20: 30000000
C21: 관리용역비 | G21: =IF(SUMIFS(잔액_2022[결의금액],잔액_2022[통계목],$C21,잔액_2022[분류 항목],"유량")=0,"",SUMIFS(잔액_2022[결의금액],잔액_2022[통계목],$C21,잔액_2022[분류 항목],"유량")) | I21: =IF(SUMIFS(잔액_2023[결의금액],잔액_2023[통계목],$C21,잔액_2023[분류 항목],"유량")=0,"",SUMIFS(잔액_2023[결의금액],잔액_2023[통계목],$C21,잔액_2023[분류 항목],"유량")) | K21: =IF(SUMIFS(잔액_2024[결의금액],잔액_2024[통계목],$C21,잔액_2024[분류 항목],"유량")=0,"",SUMIFS(잔액_2024[결의금액],잔액_2024[통계목],$C21,잔액_2024[분류 항목],"유량")) | L21: 175500000 | M21: =IF(SUMIFS(잔액_2025[결의금액],잔액_2025[통계목],$C21,잔액_2025[분류 항목],"유량")=0,"",SUMIFS(잔액_2025[결의금액],잔액_2025[통계목],$C21,잔액_2025[분류 항목],"유량"))
C22: 기타운영비 | G22: =IF(SUMIFS(잔액_2022[결의금액],잔액_2022[통계목],$C22,잔액_2022[분류 항목],"유량")=0,"",SUMIFS(잔액_2022[결의금액],잔액_2022[통계목],$C22,잔액_2022[분류 항목],"유량")) | I22: =IF(SUMIFS(잔액_2023[결의금액],잔액_2023[통계목],$C22,잔액_2023[분류 항목],"유량")=0,"",SUMIFS(잔액_2023[결의금액],잔액_2023[통계목],$C22,잔액_2023[분류 항목],"유량")) | K22: =IF(SUMIFS(잔액_2024[결의금액],잔액_2024[통계목],$C22,잔액_2024[분류 항목],"유량")=0,"",SUMIFS(잔액_2024[결의금액],잔액_2024[통계목],$C22,잔액_2024[분류 항목],"유량")) | M22: =IF(SUMIFS(잔액_2025[결의금액],잔액_2025[통계목],$C22,잔액_2025[분류 항목],"유량")=0,"",SUMIFS(잔액_2025[결의금액],잔액_2025[통계목],$C22,잔액_2025[분류 항목],"유량"))
B23: 여비 | C23: 소계 | D23: =SUM(D24:D25) -> 551584900 | E23: =SUM(E24:E25) -> 0 | F23: =SUM(F24:F25) -> 878000000 | G23: =SUM(G24:G25) -> 0 | H23: =SUM(H24:H25) -> 990470000 | I23: =SUM(I24:I25) -> 0 | J23: =SUM(J24:J25) -> 874270000 | K23: =SUM(K24:K25) -> 0 | ... O23: =SUM(O24:O25) -> 0
C24: 국내여비 | D24: 551584900 | F24: 878000000 | G24: =IF(SUMIFS(잔액_2022[결의금액],잔액_2022[통계목],$C24,잔액_2022[분류 항목],"유량")=0,"",SUMIFS(잔액_2022[결의금액],잔액_2022[통계목],$C24,잔액_2022[분류 항목],"유량")) | H24: 990470000 | I24: =IF(SUMIFS(잔액_2023[결의금액],잔액_2023[통계목],$C24,잔액_2023[분류 항목],"유량")=0,"",SUMIFS(잔액_2023[결의금액],잔액_2023[통계목],$C24,잔액_2023[분류 항목],"유량")) | J24: 874270000 | K24: =IF(SUMIFS(잔액_2024[결의금액],잔액_2024[통계목],$C24,잔액_2024[분류 항목],"유량")=0,"",SUMIFS(잔액_2024[결의금액],잔액_2024[통계목],$C24,잔액_2024[분류 항목],"유량")) | L24: 799020000 | M24: =IF(SUMIFS(잔액_2025[결의금액],잔액_2025[통계목],$C24,잔액_2025[분류 항목],"유량")=0,"",SUMIFS(잔액_2025[결의금액],잔액_2025[통계목],$C24,잔액_2025[분류 항목],"유량")) | N24: 622000000
C25: 국외업무여비 | G25: =IF(SUMIFS(잔액_2022[결의금액],잔액_2022[통계목],$C25,잔액_2022[분류 항목],"유량")=0,"",SUMIFS(잔액_2022[결의금액],잔액_2022[통계목],$C25,잔액_2022[분류 항목],"유량")) | I25: =IF(SUMIFS(잔액_2023[결의금액],잔액_2023[통계목],$C25,잔액_2023[분류 항목],"유량")=0,"",SUMIFS(잔액_2023[결의금액],잔액_2023[통계목],$C25,잔액_2023[분류 항목],"유량")) | K25: =IF(SUMIFS(잔액_2024[결의금액],잔액_2024[통계목],$C25,잔액_2024[분류 항목],"유량")=0,"",SUMIFS(잔액_2024[결의금액],잔액_2024[통계목],$C25,잔액_2024[분류 항목],"유량")) | M25: =IF(SUMIFS(잔액_2025[결의금액],잔액_2025[통계목],$C25,잔액_2025[분류 항목],"유량")=0,"",SUMIFS(잔액_2025[결의금액],잔액_2025[통계목],$C25,잔액_2025[분류 항목],"유량"))
B26: 업무추진비 | C26: 소계 | D26: =SUM(D27:D28) -> 0 | E26: =SUM(E27:E28) -> 0 | F26: =SUM(F27:F28) -> 0 | G26: =SUM(G27:G28) -> 0 | H26: =SUM(H27:H28) -> 23260000 | I26: =SUM(I27:I28) -> 0 | J26: =SUM(J27:J28) -> 74100000 | K26: =SUM(K27:K28) -> 0 | ... O26: =SUM(O27:O28) -> 0
C27: 사업추진비 | G27: =IF(SUMIFS(잔액_2022[결의금액],잔액_2022[통계목],$C27,잔액_2022[분류 항목],"유량")=0,"",SUMIFS(잔액_2022[결의금액],잔액_2022[통계목],$C27,잔액_2022[분류 항목],"유량")) | H27: 23260000 | I27: =IF(SUMIFS(잔액_2023[결의금액],잔액_2023[통계목],$C27,잔액_2023[분류 항목],"유량")=0,"",SUMIFS(잔액_2023[결의금액],잔액_2023[통계목],$C27,잔액_2023[분류 항목],"유량")) | J27: 74100000 | K27: =IF(SUMIFS(잔액_2024[결의금액],잔액_2024[통계목],$C27,잔액_2024[분류 항목],"유량")=0,"",SUMIFS(잔액_2024[결의금액],잔액_2024[통계목],$C27,잔액_2024[분류 항목],"유량")) | L27: 74100000 | M27: =IF(SUMIFS(잔액_2025[결의금액],잔액_2025[통계목],$C27,잔액_2025[분류 항목],"유량")=0,"",SUMIFS(잔액_2025[결의금액],잔액_2025[통계목],$C27,잔액_2025[분류 항목],"유량")) | N27: 60100000
C28: 관서업무추진비 | G28: =IF(SUMIFS(잔액_2022[결의금액],잔액_2022[통계목],$C28,잔액_2022[분류 항목],"유량")=0,"",SUMIFS(잔액_2022[결의금액],잔액_2022[통계목],$C28,잔액_2022[분류 항목],"유량")) | I28: =IF(SUMIFS(잔액_2023[결의금액],잔액_2023[통계목],$C28,잔액_2023[분류 항목],"유량")=0,"",SUMIFS(잔액_2023[결의금액],잔액_2023[통계목],$C28,잔액_2023[분류 항목],"유량")) | K28: =IF(SUMIFS(잔액_2024[결의금액],잔액_2024[통계목],$C28,잔액_2024[분류 항목],"유량")=0,"",SUMIFS(잔액_2024[결의금액],잔액_2024[통계목],$C28,잔액_2024[분류 항목],"유량")) | M28: =IF(SUMIFS(잔액_2025[결의금액],잔액_2025[통계목],$C28,잔액_2025[분류 항목],"유량")=0,"",SUMIFS(잔액_2025[결의금액],잔액_2025[통계목],$C28,잔액_2025[분류 항목],"유량"))
B29: 연구용역비 | C29: 소계 | D29: =SUM(D30:D31) -> 0 | E29: =SUM(E30:E31) -> 0 | F29: =SUM(F30:F31) -> 46000000 | G29: =SUM(G30:G31) -> 205195000 | H29: =SUM(H30:H31) -> 0 | I29: =SUM(I30:I31) -> 5940000 | J29: =SUM(J30:J31) -> 100000000 | K29: =SUM(K30:K31) -> 0 | ... O29: =SUM(O30:O31) -> 0
C30: 일반연구비 | F30: 46000000 | G30: =IF(SUMIFS(잔액_2022[결의금액],잔액_2022[통계목],$C30,잔액_2022[분류 항목],"유량")=0,"",SUMIFS(잔액_2022[결의금액],잔액_2022[통계목],$C30,잔액_2022[분류 항목],"유량")) -> 205195000 | I30: {=IFERROR(INDEX(잔액_2023[결의금액],MATCH(1,(잔액_2023[통계목]=$C30)*(잔액_2023[분류 항목]="유량"),0)),"")} -> 5940000 | J30: 100000000 | K30: =IF(SUMIFS(잔액_2024[결의금액],잔액_2024[통계목],$C30,잔액_2024[분류 항목],"유량")=0,"",SUMIFS(잔액_2024[결의금액],잔액_2024[통계목],$C30,잔액_2024[분류 항목],"유량")) | M30: =IF(SUMIFS(잔액_2025[결의금액],잔액_2025[통계목],$C30,잔액_2025[분류 항목],"유량")=0,"",SUMIFS(잔액_2025[결의금액],잔액_2025[통계목],$C30,잔액_2025[분류 항목],"유량"))
C31: 정책연구비 | G31: =IF(SUMIFS(잔액_2022[결의금액],잔액_2022[통계목],$C31,잔액_2022[분류 항목],"유량")=0,"",SUMIFS(잔액_2022[결의금액],잔액_2022[통계목],$C31,잔액_2022[분류 항목],"유량")) | I31: =IF(SUMIFS(잔액_2023[결의금액],잔액_2023[통계목],$C31,잔액_2023[분류 항목],"유량")=0,"",SUMIFS(잔액_2023[결의금액],잔액_2023[통계목],$C31,잔액_2023[분류 항목],"유량")) | K31: =IF(SUMIFS(잔액_2024[결의금액],잔액_2024[통계목],$C31,잔액_2024[분류 항목],"유량")=0,"",SUMIFS(잔액_2024[결의금액],잔액_2024[통계목],$C31,잔액_2024[분류 항목],"유량")) | M31: =IF(SUMIFS(잔액_2025[결의금액],잔액_2025[통계목],$C31,잔액_2025[분류 항목],"유량")=0,"",SUMIFS(잔액_2025[결의금액],잔액_2025[통계목],$C31,잔액_2025[분류 항목],"유량"))
B32: 민간이전 | C32: 소계 | D32: =D33 -> 0 | E32: =E33 -> 0 | F32: =F33 -> 0 | G32: =G33 | H32: =H33 -> 0 | I32: =I33 | J32: =J33 -> 92420395 | K32: =K33 | ... O32: =O33 -> 0
C33: 고용부담금 | G33: =IF(SUMIFS(잔액_2022[결의금액],잔액_2022[통계목],$C33,잔액_2022[분류 항목],"유량")=0,"",SUMIFS(잔액_2022[결의금액],잔액_2022[통계목],$C33,잔액_2022[분류 항목],"유량")) | I33: =IF(SUMIFS(잔액_2023[결의금액],잔액_2023[통계목],$C33,잔액_2023[분류 항목],"유량")=0,"",SUMIFS(잔액_2023[결의금액],잔액_2023[통계목],$C33,잔액_2023[분류 항목],"유량")) | J33: 92420395 | K33: =IF(SUMIFS(잔액_2024[결의금액],잔액_2024[통계목],$C33,잔액_2024[분류 항목],"유량")=0,"",SUMIFS(잔액_2024[결의금액],잔액_2024[통계목],$C33,잔액_2024[분류 항목],"유량")) | L33: 43268498 | M33: =IF(SUMIFS(잔액_2025[결의금액],잔액_2025[통계목],$C33,잔액_2025[분류 항목],"유량")=0,"",SUMIFS(잔액_2025[결의금액],잔액_2025[통계목],$C33,잔액_2025[분류 항목],"유량"))
B34: 건설비 | C34: 소계 | D34: =SUM(D35:D39) -> 0 | E34: =SUM(E35:E39) -> 0 | F34: =SUM(F35:F39) -> 0 | G34: =SUM(G35:G39) -> 0 | H34: =SUM(H35:H39) -> 0 | I34: =SUM(I35:I39) -> 0 | J34: =SUM(J35:J39) -> 691055018 | K34: =SUM(K35:K39) -> 0 | ... O34: =SUM(O35:O39) -> 0
C35: 기본조사설계비 | G35: =IF(SUMIFS(잔액_2022[결의금액],잔액_2022[통계목],$C35,잔액_2022[분류 항목],"유량")=0,"",SUMIFS(잔액_2022[결의금액],잔액_2022[통계목],$C35,잔액_2022[분류 항목],"유량")) | I35: =IF(SUMIFS(잔액_2023[결의금액],잔액_2023[통계목],$C35,잔액_2023[분류 항목],"유량")=0,"",SUMIFS(잔액_2023[결의금액],잔액_2023[통계목],$C35,잔액_2023[분류 항목],"유량")) | K35: =IF(SUMIFS(잔액_2024[결의금액],잔액_2024[통계목],$C35,잔액_2024[분류 항목],"유량")=0,"",SUMIFS(잔액_2024[결의금액],잔액_2024[통계목],$C35,잔액_2024[분류 항목],"유량")) | M35: =IF(SUMIFS(잔액_2025[결의금액],잔액_2025[통계목],$C35,잔액_2025[분류 항목],"유량")=0,"",SUMIFS(잔액_2025[결의금액],잔액_2025[통계목],$C35,잔액_2025[분류 항목],"유량"))
C36: 실시설계비 | G36: =IF(SUMIFS(잔액_2022[결의금액],잔액_2022[통계목],$C36,잔액_2022[분류 항목],"유량")=0,"",SUMIFS(잔액_2022[결의금액],잔액_2022[통계목],$C36,잔액_2022[분류 항목],"유량")) | I36: =IF(SUMIFS(잔액_2023[결의금액],잔액_2023[통계목],$C36,잔액_2023[분류 항목],"유량")=0,"",SUMIFS(잔액_2023[결의금액],잔액_2023[통계목],$C36,잔액_2023[분류 항목],"유량")) | K36: =IF(SUMIFS(잔액_2024[결의금액],잔액_2024[통계목],$C36,잔액_2024[분류 항목],"유량")=0,"",SUMIFS(잔액_2024[결의금액],잔액_2024[통계목],$C36,잔액_2024[분류 항목],"유량")) | M36: =IF(SUMIFS(잔액_2025[결의금액],잔액_2025[통계목],$C36,잔액_2025[분류 항목],"유량")=0,"",SUMIFS(잔액_2025[결의금액],잔액_2025[통계목],$C36,잔액_2025[분류 항목],"유량"))
C37: 공사비 | G37: =IF(SUMIFS(잔액_2022[결의금액],잔액_2022[통계목],$C37,잔액_2022[분류 항목],"유량")=0,"",SUMIFS(잔액_2022[결의금액],잔액_2022[통계목],$C37,잔액_2022[분류 항목],"유량")) | I37: =IF(SUMIFS(잔액_2023[결의금액],잔액_2023[통계목],$C37,잔액_2023[분류 항목],"유량")=0,"",SUMIFS(잔액_2023[결의금액],잔액_2023[통계목],$C37,잔액_2023[분류 항목],"유량")) | J37: 691055018 | K37: =IF(SUMIFS(잔액_2024[결의금액],잔액_2024[통계목],$C37,잔액_2024[분류 항목],"유량")=0,"",SUMIFS(잔액_2024[결의금액],잔액_2024[통계목],$C37,잔액_2024[분류 항목],"유량")) | L37: 10000000 | M37: =IF(SUMIFS(잔액_2025[결의금액],잔액_2025[통계목],$C37,잔액_2025[분류 항목],"유량")=0,"",SUMIFS(잔액_2025[결의금액],잔액_2025[통계목],$C37,잔액_2025[분류 항목],"유량"))
C38: 감리비 | G38: =IF(SUMIFS(잔액_2022[결의금액],잔액_2022[통계목],$C38,잔액_2022[분류 항목],"유량")=0,"",SUMIFS(잔액_2022[결의금액],잔액_2022[통계목],$C38,잔액_2022[분류 항목],"유량")) | I38: =IF(SUMIFS(잔액_2023[결의금액],잔액_2023[통계목],$C38,잔액_2023[분류 항목],"유량")=0,"",SUMIFS(잔액_2023[결의금액],잔액_2023[통계목],$C38,잔액_2023[분류 항목],"유량")) | K38: =IF(SUMIFS(잔액_2024[결의금액],잔액_2024[통계목],$C38,잔액_2024[분류 항목],"유량")=0,"",SUMIFS(잔액_2024[결의금액],잔액_2024[통계목],$C38,잔액_2024[분류 항목],"유량")) | M38: =IF(SUMIFS(잔액_2025[결의금액],잔액_2025[통계목],$C38,잔액_2025[분류 항목],"유량")=0,"",SUMIFS(잔액_2025[결의금액],잔액_2025[통계목],$C38,잔액_2025[분류 항목],"유량"))
C39: 시설부대비 | G39: =IF(SUMIFS(잔액_2022[결의금액],잔액_2022[통계목],$C39,잔액_2022[분류 항목],"유량")=0,"",SUMIFS(잔액_2022[결의금액],잔액_2022[통계목],$C39,잔액_2022[분류 항목],"유량")) | I39: =IF(SUMIFS(잔액_2023[결의금액],잔액_2023[통계목],$C39,잔액_2023[분류 항목],"유량")=0,"",SUMIFS(잔액_2023[결의금액],잔액_2023[통계목],$C39,잔액_2023[분류 항목],"유량")) | K39: =IF(SUMIFS(잔액_2024[결의금액],잔액_2024[통계목],$C39,잔액_2024[분류 항목],"유량")=0,"",SUMIFS(잔액_2024[결의금액],잔액_2024[통계목],$C39,잔액_2024[분류 항목],"유량")) | M39: =IF(SUMIFS(잔액_2025[결의금액],잔액_2025[통계목],$C39,잔액_2025[분류 항목],"유량")=0,"",SUMIFS(잔액_2025[결의금액],잔액_2025[통계목],$C39,잔액_2025[분류 항목],"유량"))
B40: 유형자산 | C40: 소계 | D40: =D41 -> 0 | E40: =E41 -> 0 | F40: =F41 -> 1249000000 | G40: =G41 -> 74944873 | H40: =H41 -> 0 | I40: =I41 | J40: =J41 -> 428867185 | K40: =K41 -> 158572855 | ... O40: =O41 -> 0
...

Sheet 유사량
B1: 유사량
B2: 편성목 | C2: 통계목 | D2: 2021년 | F2: 2022년 | H2: 2023년 | J2: 2024년 | L2: 2025년 | N2: 2026년
D3: 실행예산 | E3: 잔액 예산 | F3: 실행예산 | G3: 잔액 예산 | H3: 실행예산 | I3: 잔액 예산 | J3: 실행예산 | K3: 잔액 예산 | L3: 실행예산 | M3: 잔액 예산 | N3: 실행예산 | O3: 잔액 예산
B4: 합계 | D4: =SUM(D5,D10,D23,D26,D29,D32,D34,D40,D42,D44,D46) -> 337965730 | E4: =SUM(E5,E10,E23,E26,E29,E32,E34,E40,E42,E44,E46) -> 0 | F4: =SUM(F5,F10,F23,F26,F29,F32,F34,F40,F42,F44,F46) -> 356000000 | G4: =SUM(G5,G10,G23,G26,G29,G32,G34,G40,G42,G44,G46) -> 19025280 | H4: =SUM(H5,H10,H23,H26,H29,H32,H34,H40,H42,H44,H46) -> 416083240 | I4: =SUM(I5,I10,I23,I26,I29,I32,I34,I40,I42,I44,I46) -> 109142000 | J4: =SUM(J5,J10,J23,J26,J29,J32,J34,J40,J42,J44,J46) -> 221000000 | K4: =SUM(K5,K10,K23,K26,K29,K32,K34,K40,K42,K44,K46) -> 0 | ... O4: =SUM(O5,O10,O23,O26,O29,O32,O34,O40,O42,O44,O46) -> 0
B5: 인건비 | C5: 소계 | D5: =SUM(D6:D9) -> 88000000 | E5: =SUM(E6:E9) -> 0 | F5: =SUM(F6:F9) -> 164000000 | G5: =SUM(G6:G9) -> 0 | H5: =SUM(H6:H9) -> 213508440 | I5: =SUM(I6:I9) -> 0 | J5: =SUM(J6:J9) -> 52067667 | K5: =SUM(K6:K9) -> 0 | ... O5: =SUM(O6:O9) -> 0
C6: 보수 | G6: =IF(SUMIFS(잔액_2022[결의금액],잔액_2022[통계목],$C6,잔액_2022[분류 항목],"유사량")=0,"",SUMIFS(잔액_2022[결의금액],잔액_2022[통계목],$C6,잔액_2022[분류 항목],"유사량")) | I6: =IF(SUMIFS(잔액_2023[결의금액],잔액_2023[통계목],$C6,잔액_2023[분류 항목],"유사량")=0,"",SUMIFS(잔액_2023[결의금액],잔액_2023[통계목],$C6,잔액_2023[분류 항목],"유사량")) | K6: =IF(SUMIFS(잔액_2024[결의금액],잔액_2024[통계목],$C6,잔액_2024[분류 항목],"유사량")=0,"",SUMIFS(잔액_2024[결의금액],잔액_2024[통계목],$C6,잔액_2024[분류 항목],"유사량")) | M6: =IF(SUMIFS(잔액_2025[결의금액],잔액_2025[통계목],$C6,잔액_2025[분류 항목],"유사량")=0,"",SUMIFS(잔액_2025[결의금액],잔액_2025[통계목],$C6,잔액_2025[분류 항목],"유사량"))
C7: 기타직보수 | G7: =IF(SUMIFS(잔액_2022[결의금액],잔액_2022[통계목],$C7,잔액_2022[분류 항목],"유사량")=0,"",SUMIFS(잔액_2022[결의금액],잔액_2022[통계목],$C7,잔액_2022[분류 항목],"유사량")) | I7: =IF(SUMIFS(잔액_2023[결의금액],잔액_2023[통계목],$C7,잔액_2023[분류 항목],"유사량")=0,"",SUMIFS(잔액_2023[결의금액],잔액_2023[통계목],$C7,잔액_2023[분류 항목],"유사량")) | K7: =IF(SUMIFS(잔액_2024[결의금액],잔액_2024[통계목],$C7,잔액_2024[분류 항목],"유사량")=0,"",SUMIFS(잔액_2024[결의금액],잔액_2024[통계목],$C7,잔액_2024[분류 항목],"유사량")) | M7: =IF(SUMIFS(잔액_2025[결의금액],잔액_2025[통계목],$C7,잔액_2025[분류 항목],"유사량")=0,"",SUMIFS(잔액_2025[결의금액],잔액_2025[통계목],$C7,잔액_2025[분류 항목],"유사량"))
C8: 상용임금 | F8: 164000000 | G8: =IF(SUMIFS(잔액_2022[결의금액],잔액_2022[통계목],$C8,잔액_2022[분류 항목],"유사량")=0,"",SUMIFS(잔액_2022[결의금액],잔액_2022[통계목],$C8,잔액_2022[분류 항목],"유사량")) | H8: 213508440 | I8: =IF(SUMIFS(잔액_2023[결의금액],잔액_2023[통계목],$C8,잔액_2023[분류 항목],"유사량")=0,"",SUMIFS(잔액_2023[결의금액],잔액_2023[통계목],$C8,잔액_2023[분류 항목],"유사량")) | J8: 52067667 | K8: =IF(SUMIFS(잔액_2024[결의금액],잔액_2024[통계목],$C8,잔액_2024[분류 항목],"유사량")=0,"",SUMIFS(잔액_2024[결의금액],잔액_2024[통계목],$C8,잔액_2024[분류 항목],"유사량")) | L8: 70200000 | M8: =IF(SUMIFS(잔액_2025[결의금액],잔액_2025[통계목],$C8,잔액_2025[분류 항목],"유사량")=0,"",SUMIFS(잔액_2025[결의금액],잔액_2025[통계목],$C8,잔액_2025[분류 항목],"유사량")) | N8: 79015500
C9: 일용임금 | D9: 88000000 | G9: =IF(SUMIFS(잔액_2022[결의금액],잔액_2022[통계목],$C9,잔액_2022[분류 항목],"유사량")=0,"",SUMIFS(잔액_2022[결의금액],잔액_2022[통계목],$C9,잔액_2022[분류 항목],"유사량")) | I9: =IF(SUMIFS(잔액_2023[결의금액],잔액_2023[통계목],$C9,잔액_2023[분류 항목],"유사량")=0,"",SUMIFS(잔액_2023[결의금액],잔액_2023[통계목],$C9,잔액_2023[분류 항목],"유사량")) | K9: =IF(SUMIFS(잔액_2024[결의금액],잔액_2024[통계목],$C9,잔액_2024[분류 항목],"유사량")=0,"",SUMIFS(잔액_2024[결의금액],잔액_2024[통계목],$C9,잔액_2024[분류 항목],"유사량")) | M9: =IF(SUMIFS(잔액_2025[결의금액],잔액_2025[통계목],$C9,잔액_2025[분류 항목],"유사량")=0,"",SUMIFS(잔액_2025[결의금액],잔액_2025[통계목],$C9,잔액_2025[분류 항목],"유사량"))
B10: 운영비 | C10: 소계 | D10: =SUM(D11:D22) -> 215513530 | E10: =SUM(E11:E22) -> 0 | F10: =SUM(F11:F22) -> 139000000 | G10: =SUM(G11:G22) -> 0 | H10: =SUM(H11:H22) -> 150414800 | I10: =SUM(I11:I22) -> 0 | J10: =SUM(J11:J22) -> 81296743 | K10: =SUM(K11:K22) -> 0 | ... O10: =SUM(O11:O22) -> 0
C11: 일반수용비 | D11: 211694530 | F11: 32000000 | G11: =IF(SUMIFS(잔액_2022[결의금액],잔액_2022[통계목],$C11,잔액_2022[분류 항목],"유사량")=0,"",SUMIFS(잔액_2022[결의금액],잔액_2022[통계목],$C11,잔액_2022[분류 항목],"유사량")) | H11: 29160000 | I11: =IF(SUMIFS(잔액_2023[결의금액],잔액_2023[통계목],$C11,잔액_2023[분류 항목],"유사량")=0,"",SUMIFS(잔액_2023[결의금액],잔액_2023[통계목],$C11,잔액_2023[분류 항목],"유사량")) | J11: 38800000 | K11: =IF(SUMIFS(잔액_2024[결의금액],잔액_2024[통계목],$C11,잔액_2024[분류 항목],"유사량")=0,"",SUMIFS(잔액_2024[결의금액],잔액_2024[통계목],$C11,잔액_2024[분류 항목],"유사량")) | L11: 41660000 | M11: =IF(SUMIFS(잔액_2025[결의금액],잔액_2025[통계목],$C11,잔액_2025[분류 항목],"유사량")=0,"",SUMIFS(잔액_2025[결의금액],잔액_2025[통계목],$C11,잔액_2025[분류 항목],"유사량")) | N11: 25853570
C12: 공공요금 및 제세 | G12: =IF(SUMIFS(잔액_2022[결의금액],잔액_2022[통계목],$C12,잔액_2022[분류 항목],"유사량")=0,"",SUMIFS(잔액_2022[결의금액],잔액_2022[통계목],$C12,잔액_2022[분류 항목],"유사량")) | H12: 100000 | I12: =IF(SUMIFS(잔액_2023[결의금액],잔액_2023[통계목],$C12,잔액_2023[분류 항목],"유사량")=0,"",SUMIFS(잔액_2023[결의금액],잔액_2023[통계목],$C12,잔액_2023[분류 항목],"유사량")) | K12: =IF(SUMIFS(잔액_2024[결의금액],잔액_2024[통계목],$C12,잔액_2024[분류 항목],"유사량")=0,"",SUMIFS(잔액_2024[결의금액],잔액_2024[통계목],$C12,잔액_2024[분류 항목],"유사량")) | L12: 100000 | M12: =IF(SUMIFS(잔액_2025[결의금액],잔액_2025[통계목],$C12,잔액_2025[분류 항목],"유사량")=0,"",SUMIFS(잔액_2025[결의금액],잔액_2025[통계목],$C12,잔액_2025[분류 항목],"유사량"))
C13: 피복비 | G13: =IF(SUMIFS(잔액_2022[결의금액],잔액_2022[통계목],$C13,잔액_2022[분류 항목],"유사량")=0,"",SUMIFS(잔액_2022[결의금액],잔액_2022[통계목],$C13,잔액_2022[분류 항목],"유사량")) | I13: =IF(SUMIFS(잔액_2023[결의금액],잔액_2023[통계목],$C13,잔액_2023[분류 항목],"유사량")=0,"",SUMIFS(잔액_2023[결의금액],잔액_2023[통계목],$C13,잔액_2023[분류 항목],"유사량")) | K13: =IF(SUMIFS(잔액_2024[결의금액],잔액_2024[통계목],$C13,잔액_2024[분류 항목],"유사량")=0,"",SUMIFS(잔액_2024[결의금액],잔액_2024[통계목],$C13,잔액_2024[분류 항목],"유사량")) | M13: =IF(SUMIFS(잔액_2025[결의금액],잔액_2025[통계목],$C13,잔액_2025[분류 항목],"유사량")=0,"",SUMIFS(잔액_2025[결의금액],잔액_2025[통계목],$C13,잔액_2025[분류 항목],"유사량"))
C14: 특근매식비 | G14: =IF(SUMIFS(잔액_2022[결의금액],잔액_2022[통계목],$C14,잔액_2022[분류 항목],"유사량")=0,"",SUMIFS(잔액_2022[결의금액],잔액_2022[통계목],$C14,잔액_2022[분류 항목],"유사량")) | I14: =IF(SUMIFS(잔액_2023[결의금액],잔액_2023[통계목],$C14,잔액_2023[분류 항목],"유사량")=0,"",SUMIFS(잔액_2023[결의금액],잔액_2023[통계목],$C14,잔액_2023[분류 항목],"유사량")) | K14: =IF(SUMIFS(잔액_2024[결의금액],잔액_2024[통계목],$C14,잔액_2024[분류 항목],"유사량")=0,"",SUMIFS(잔액_2024[결의금액],잔액_2024[통계목],$C14,잔액_2024[분류 항목],"유사량")) | M14: =IF(SUMIFS(잔액_2025[결의금액],잔액_2025[통계목],$C14,잔액_2025[분류 항목],"유사량")=0,"",SUMIFS(잔액_2025[결의금액],잔액_2025[통계목],$C14,잔액_2025[분류 항목],"유사량"))
C15: 임차료 | F15: 87000000 | G15: =IF(SUMIFS(잔액_2022[결의금액],잔액_2022[통계목],$C15,잔액_2022[분류 항목],"유사량")=0,"",SUMIFS(잔액_2022[결의금액],잔액_2022[통계목],$C15,잔액_2022[분류 항목],"유사량")) | H15: 67354800 | I15: =IF(SUMIFS(잔액_2023[결의금액],잔액_2023[통계목],$C15,잔액_2023[분류 항목],"유사량")=0,"",SUMIFS(잔액_2023[결의금액],잔액_2023[통계목],$C15,잔액_2023[분류 항목],"유사량")) | J15: 31000000 | K15: =IF(SUMIFS(잔액_2024[결의금액],잔액_2024[통계목],$C15,잔액_2024[분류 항목],"유사량")=0,"",SUMIFS(잔액_2024[결의금액],잔액_2024[통계목],$C15,잔액_2024[분류 항목],"유사량")) | L15: 21600000 | M15: =IF(SUMIFS(잔액_2025[결의금액],잔액_2025[통계목],$C15,잔액_2025[분류 항목],"유사량")=0,"",SUMIFS(잔액_2025[결의금액],잔액_2025[통계목],$C15,잔액_2025[분류 항목],"유사량")) | N15: 18000000
C16: 유류비 | D16: 3819000 | F16: 7000000 | G16: =IF(SUMIFS(잔액_2022[결의금액],잔액_2022[통계목],$C16,잔액_2022[분류 항목],"유사량")=0,"",SUMIFS(잔액_2022[결의금액],잔액_2022[통계목],$C16,잔액_2022[분류 항목],"유사량")) | H16: 6000000 | I16: =IF(SUMIFS(잔액_2023[결의금액],잔액_2023[통계목],$C16,잔액_2023[분류 항목],"유사량")=0,"",SUMIFS(잔액_2023[결의금액],잔액_2023[통계목],$C16,잔액_2023[분류 항목],"유사량")) | J16: 10000000 | K16: =IF(SUMIFS(잔액_2024[결의금액],잔액_2024[통계목],$C16,잔액_2024[분류 항목],"유사량")=0,"",SUMIFS(잔액_2024[결의금액],잔액_2024[통계목],$C16,잔액_2024[분류 항목],"유사량")) | L16: 3000000 | M16: =IF(SUMIFS(잔액_2025[결의금액],잔액_2025[통계목],$C16,잔액_2025[분류 항목],"유사량")=0,"",SUMIFS(잔액_2025[결의금액],잔액_2025[통계목],$C16,잔액_2025[분류 항목],"유사량")) | N16: 1500000
C17: 시설장비유지비 | G17: =IF(SUMIFS(잔액_2022[결의금액],잔액_2022[통계목],$C17,잔액_2022[분류 항목],"유사량")=0,"",SUMIFS(잔액_2022[결의금액],잔액_2022[통계목],$C17,잔액_2022[분류 항목],"유사량")) | I17: =IF(SUMIFS(잔액_2023[결의금액],잔액_2023[통계목],$C17,잔액_2023[분류 항목],"유사량")=0,"",SUMIFS(잔액_2023[결의금액],잔액_2023[통계목],$C17,잔액_2023[분류 항목],"유사량")) | K17: =IF(SUMIFS(잔액_2024[결의금액],잔액_2024[통계목],$C17,잔액_2024[분류 항목],"유사량")=0,"",SUMIFS(잔액_2024[결의금액],잔액_2024[통계목],$C17,잔액_2024[분류 항목],"유사량")) | M17: =IF(SUMIFS(잔액_2025[결의금액],잔액_2025[통계목],$C17,잔액_2025[분류 항목],"유사량")=0,"",SUMIFS(잔액_2025[결의금액],잔액_2025[통계목],$C17,잔액_2025[분류 항목],"유사량")) | N17: 8000000
C18: 재료비 | F18: 13000000 | G18: =IF(SUMIFS(잔액_2022[결의금액],잔액_2022[통계목],$C18,잔액_2022[분류 항목],"유사량")=0,"",SUMIFS(잔액_2022[결의금액],잔액_2022[통계목],$C18,잔액_2022[분류 항목],"유사량")) | H18: 47800000 | I18: =IF(SUMIFS(잔액_2023[결의금액],잔액_2023[통계목],$C18,잔액_2023[분류 항목],"유사량")=0,"",SUMIFS(잔액_2023[결의금액],잔액_2023[통계목],$C18,잔액_2023[분류 항목],"유사량")) | J18: 1496743 | K18: =IF(SUMIFS(잔액_2024[결의금액],잔액_2024[통계목],$C18,잔액_2024[분류 항목],"유사량")=0,"",SUMIFS(잔액_2024[결의금액],잔액_2024[통계목],$C18,잔액_2024[분류 항목],"유사량")) | L18: 7000000 | M18: =IF(SUMIFS(잔액_2025[결의금액],잔액_2025[통계목],$C18,잔액_2025[분류 항목],"유사량")=0,"",SUMIFS(잔액_2025[결의금액],잔액_2025[통계목],$C18,잔액_2025[분류 항목],"유사량")) | N18: 3628000
C19: 복리후생비 | G19: =IF(SUMIFS(잔액_2022[결의금액],잔액_2022[통계목],$C19,잔액_2022[분류 항목],"유사량")=0,"",SUMIFS(잔액_2022[결의금액],잔액_2022[통계목],$C19,잔액_2022[분류 항목],"유사량")) | I19: =IF(SUMIFS(잔액_2023[결의금액],잔액_2023[통계목],$C19,잔액_2023[분류 항목],"유사량")=0,"",SUMIFS(잔액_2023[결의금액],잔액_2023[통계목],$C19,잔액_2023[분류 항목],"유사량")) | K19: =IF(SUMIFS(잔액_2024[결의금액],잔액_2024[통계목],$C19,잔액_2024[분류 항목],"유사량")=0,"",SUMIFS(잔액_2024[결의금액],잔액_2024[통계목],$C19,잔액_2024[분류 항목],"유사량")) | M19: =IF(SUMIFS(잔액_2025[결의금액],잔액_2025[통계목],$C19,잔액_2025[분류 항목],"유사량")=0,"",SUMIFS(잔액_2025[결의금액],잔액_2025[통계목],$C19,잔액_2025[분류 항목],"유사량"))
C20: 일반용역비 | G20: =IF(SUMIFS(잔액_2022[결의금액],잔액_2022[통계목],$C20,잔액_2022[분류 항목],"유사량")=0,"",SUMIFS(잔액_2022[결의금액],잔액_2022[통계목],$C20,잔액_2022[분류 항목],"유사량")) | I20: =IF(SUMIFS(잔액_2023[결의금액],잔액_2023[통계목],$C20,잔액_2023[분류 항목],"유사량")=0,"",SUMIFS(잔액_2023[결의금액],잔액_2023[통계목],$C20,잔액_2023[분류 항목],"유사량")) | K20: =IF(SUMIFS(잔액_2024[결의금액],잔액_2024[통계목],$C20,잔액_2024[분류 항목],"유사량")=0,"",SUMIFS(잔액_2024[결의금액],잔액_2024[통계목],$C20,잔액_2024[분류 항목],"유사량")) | M20: =IF(SUMIFS(잔액_2025[결의금액],잔액_2025[통계목],$C20,잔액_2025[분류 항목],"유사량")=0,"",SUMIFS(잔액_2025[결의금액],잔액_2025[통계목],$C20,잔액_2025[분류 항목],"유사량"))
C21: 관리용역비 | G21: =IF(SUMIFS(잔액_2022[결의금액],잔액_2022[통계목],$C21,잔액_2022[분류 항목],"유사량")=0,"",SUMIFS(잔액_2022[결의금액],잔액_2022[통계목],$C21,잔액_2022[분류 항목],"유사량")) | I21: =IF(SUMIFS(잔액_2023[결의금액],잔액_2023[통계목],$C21,잔액_2023[분류 항목],"유사량")=0,"",SUMIFS(잔액_2023[결의금액],잔액_2023[통계목],$C21,잔액_2023[분류 항목],"유사량")) | K21: =IF(SUMIFS(잔액_2024[결의금액],잔액_2024[통계목],$C21,잔액_2024[분류 항목],"유사량")=0,"",SUMIFS(잔액_2024[결의금액],잔액_2024[통계목],$C21,잔액_2024[분류 항목],"유사량")) | M21: =IF(SUMIFS(잔액_2025[결의금액],잔액_2025[통계목],$C21,잔액_2025[분류 항목],"유사량")=0,"",SUMIFS(잔액_2025[결의금액],잔액_2025[통계목],$C21,잔액_2025[분류 항목],"유사량")) | N21: 7392000
C22: 기타운영비 | G22: =IF(SUMIFS(잔액_2022[결의금액],잔액_2022[통계목],$C22,잔액_2022[분류 항목],"유사량")=0,"",SUMIFS(잔액_2022[결의금액],잔액_2022[통계목],$C22,잔액_2022[분류 항목],"유사량")) | I22: =IF(SUMIFS(잔액_2023[결의금액],잔액_2023[통계목],$C22,잔액_2023[분류 항목],"유사량")=0,"",SUMIFS(잔액_2023[결의금액],잔액_2023[통계목],$C22,잔액_2023[분류 항목],"유사량")) | K22: =IF(SUMIFS(잔액_2024[결의금액],잔액_2024[통계목],$C22,잔액_2024[분류 항목],"유사량")=0,"",SUMIFS(잔액_2024[결의금액],잔액_2024[통계목],$C22,잔액_2024[분류 항목],"유사량")) | M22: =IF(SUMIFS(잔액_2025[결의금액],잔액_2025[통계목],$C22,잔액_2025[분류 항목],"유사량")=0,"",SUMIFS(잔액_2025[결의금액],잔액_2025[통계목],$C22,잔액_2025[분류 항목],"유사량"))
B23: 여비 | C23: 소계 | D23: =SUM(D24:D25) -> 34452200 | E23: =SUM(E24:E25) -> 0 | F23: =SUM(F24:F25) -> 45000000 | G23: =SUM(G24:G25) -> 0 | H23: =SUM(H24:H25) -> 52160000 | I23: =SUM(I24:I25) -> 0 | J23: =SUM(J24:J25) -> 33160000 | K23: =SUM(K24:K25) -> 0 | ... O23: =SUM(O24:O25) -> 0
C24: 국내여비 | D24: 34452200 | F24: 45000000 | G24: =IF(SUMIFS(잔액_2022[결의금액],잔액_2022[통계목],$C24,잔액_2022[분류 항목],"유사량")=0,"",SUMIFS(잔액_2022[결의금액],잔액_2022[통계목],$C24,잔액_2022[분류 항목],"유사량")) | H24: 52160000 | I24: =IF(SUMIFS(잔액_2023[결의금액],잔액_2023[통계목],$C24,잔액_2023[분류 항목],"유사량")=0,"",SUMIFS(잔액_2023[결의금액],잔액_2023[통계목],$C24,잔액_2023[분류 항목],"유사량")) | J24: 33160000 | K24: =IF(SUMIFS(잔액_2024[결의금액],잔액_2024[통계목],$C24,잔액_2024[분류 항목],"유사량")=0,"",SUMIFS(잔액_2024[결의금액],잔액_2024[통계목],$C24,잔액_2024[분류 항목],"유사량")) | L24: 24630600 | M24: =IF(SUMIFS(잔액_2025[결의금액],잔액_2025[통계목],$C24,잔액_2025[분류 항목],"유사량")=0,"",SUMIFS(잔액_2025[결의금액],잔액_2025[통계목],$C24,잔액_2025[분류 항목],"유사량")) | N24: 10870000
C25: 국외업무여비 | G25: =IF(SUMIFS(잔액_2022[결의금액],잔액_2022[통계목],$C25,잔액_2022[분류 항목],"유사량")=0,"",SUMIFS(잔액_2022[결의금액],잔액_2022[통계목],$C25,잔액_2022[분류 항목],"유사량")) | I25: =IF(SUMIFS(잔액_2023[결의금액],잔액_2023[통계목],$C25,잔액_2023[분류 항목],"유사량")=0,"",SUMIFS(잔액_2023[결의금액],잔액_2023[통계목],$C25,잔액_2023[분류 항목],"유사량")) | K25: =IF(SUMIFS(잔액_2024[결의금액],잔액_2024[통계목],$C25,잔액_2024[분류 항목],"유사량")=0,"",SUMIFS(잔액_2024[결의금액],잔액_2024[통계목],$C25,잔액_2024[분류 항목],"유사량")) | M25: =IF(SUMIFS(잔액_2025[결의금액],잔액_2025[통계목],$C25,잔액_2025[분류 항목],"유사량")=0,"",SUMIFS(잔액_2025[결의금액],잔액_2025[통계목],$C25,잔액_2025[분류 항목],"유사량"))
B26: 업무추진비 | C26: 소계 | D26: =SUM(D27:D28) -> 0 | E26: =SUM(E27:E28) -> 0 | F26: =SUM(F27:F28) -> 0 | G26: =SUM(G27:G28) -> 0 | H26: =SUM(H27:H28) -> 0 | I26: =SUM(I27:I28) -> 0 | J26: =SUM(J27:J28) -> 0 | K26: =SUM(K27:K28) -> 0 | ... O26: =SUM(O27:O28) -> 0
C27: 사업추진비 | G27: =IF(SUMIFS(잔액_2022[결의금액],잔액_2022[통계목],$C27,잔액_2022[분류 항목],"유사량")=0,"",SUMIFS(잔액_2022[결의금액],잔액_2022[통계목],$C27,잔액_2022[분류 항목],"유사량")) | I27: =IF(SUMIFS(잔액_2023[결의금액],잔액_2023[통계목],$C27,잔액_2023[분류 항목],"유사량")=0,"",SUMIFS(잔액_2023[결의금액],잔액_2023[통계목],$C27,잔액_2023[분류 항목],"유사량")) | K27: =IF(SUMIFS(잔액_2024[결의금액],잔액_2024[통계목],$C27,잔액_2024[분류 항목],"유사량")=0,"",SUMIFS(잔액_2024[결의금액],잔액_2024[통계목],$C27,잔액_2024[분류 항목],"유사량")) | M27: =IF(SUMIFS(잔액_2025[결의금액],잔액_2025[통계목],$C27,잔액_2025[분류 항목],"유사량")=0,"",SUMIFS(잔액_2025[결의금액],잔액_2025[통계목],$C27,잔액_2025[분류 항목],"유사량"))
C28: 관서업무추진비 | G28: =IF(SUMIFS(잔액_2022[결의금액],잔액_2022[통계목],$C28,잔액_2022[분류 항목],"유사량")=0,"",SUMIFS(잔액_2022[결의금액],잔액_2022[통계목],$C28,잔액_2022[분류 항목],"유사량")) | I28: =IF(SUMIFS(잔액_2023[결의금액],잔액_2023[통계목],$C28,잔액_2023[분류 항목],"유사량")=0,"",SUMIFS(잔액_2023[결의금액],잔액_2023[통계목],$C28,잔액_2023[분류 항목],"유사량")) | K28: =IF(SUMIFS(잔액_2024[결의금액],잔액_2024[통계목],$C28,잔액_2024[분류 항목],"유사량")=0,"",SUMIFS(잔액_2024[결의금액],잔액_2024[통계목],$C28,잔액_2024[분류 항목],"유사량")) | M28: =IF(SUMIFS(잔액_2025[결의금액],잔액_2025[통계목],$C28,잔액_2025[분류 항목],"유사량")=0,"",SUMIFS(잔액_2025[결의금액],잔액_2025[통계목],$C28,잔액_2025[분류 항목],"유사량"))
B29: 연구용역비 | C29: 소계 | D29: =SUM(D30:D31) -> 0 | E29: =SUM(E30:E31) -> 0 | F29: =SUM(F30:F31) -> 0 | G29: =SUM(G30:G31) -> 0 | H29: =SUM(H30:H31) -> 0 | I29: =SUM(I30:I31) -> 0 | J29: =SUM(J30:J31) -> 10000000 | K29: =SUM(K30:K31) -> 0 | ... O29: =SUM(O30:O31) -> 0
C30: 일반연구비 | G30: =IF(SUMIFS(잔액_2022[결의금액],잔액_2022[통계목],$C30,잔액_2022[분류 항목],"유사량")=0,"",SUMIFS(잔액_2022[결의금액],잔액_2022[통계목],$C30,잔액_2022[분류 항목],"유사량")) | I30: {=IFERROR(INDEX(잔액_2023[결의금액],MATCH(1,(잔액_2023[통계목]=$C30)*(잔액_2023[분류 항목]="유사량"),0)),"")} | J30: 10000000 | K30: =IF(SUMIFS(잔액_2024[결의금액],잔액_2024[통계목],$C30,잔액_2024[분류 항목],"유사량")=0,"",SUMIFS(잔액_2024[결의금액],잔액_2024[통계목],$C30,잔액_2024[분류 항목],"유사량")) | M30: =IF(SUMIFS(잔액_2025[결의금액],잔액_2025[통계목],$C30,잔액_2025[분류 항목],"유사량")=0,"",SUMIFS(잔액_2025[결의금액],잔액_2025[통계목],$C30,잔액_2025[분류 항목],"유사량"))
C31: 정책연구비 | G31: =IF(SUMIFS(잔액_2022[결의금액],잔액_2022[통계목],$C31,잔액_2022[분류 항목],"유사량")=0,"",SUMIFS(잔액_2022[결의금액],잔액_2022[통계목],$C31,잔액_2022[분류 항목],"유사량")) | I31: =IF(SUMIFS(잔액_2023[결의금액],잔액_2023[통계목],$C31,잔액_2023[분류 항목],"유사량")=0,"",SUMIFS(잔액_2023[결의금액],잔액_2023[통계목],$C31,잔액_2023[분류 항목],"유사량")) | K31: =IF(SUMIFS(잔액_2024[결의금액],잔액_2024[통계목],$C31,잔액_2024[분류 항목],"유사량")=0,"",SUMIFS(잔액_2024[결의금액],잔액_2024[통계목],$C31,잔액_2024[분류 항목],"유사량")) | M31: =IF(SUMIFS(잔액_2025[결의금액],잔액_2025[통계목],$C31,잔액_2025[분류 항목],"유사량")=0,"",SUMIFS(잔액_2025[결의금액],잔액_2025[통계목],$C31,잔액_2025[분류 항목],"유사량"))
B32: 민간이전 | C32: 소계 | D32: =D33 -> 0 | E32: =E33 -> 0 | F32: =F33 -> 0 | G32: =G33 | H32: =H33 -> 0 | I32: =I33 | J32: =J33 -> 6975590 | K32: =K33 | ... O32: =O33 -> 0
C33: 고용부담금 | G33: =IF(SUMIFS(잔액_2022[결의금액],잔액_2022[통계목],$C33,잔액_2022[분류 항목],"유사량")=0,"",SUMIFS(잔액_2022[결의금액],잔액_2022[통계목],$C33,잔액_2022[분류 항목],"유사량")) | I33: =IF(SUMIFS(잔액_2023[결의금액],잔액_2023[통계목],$C33,잔액_2023[분류 항목],"유사량")=0,"",SUMIFS(잔액_2023[결의금액],잔액_2023[통계목],$C33,잔액_2023[분류 항목],"유사량")) | J33: 6975590 | K33: =IF(SUMIFS(잔액_2024[결의금액],잔액_2024[통계목],$C33,잔액_2024[분류 항목],"유사량")=0,"",SUMIFS(잔액_2024[결의금액],잔액_2024[통계목],$C33,잔액_2024[분류 항목],"유사량")) | L33: 6809400 | M33: =IF(SUMIFS(잔액_2025[결의금액],잔액_2025[통계목],$C33,잔액_2025[분류 항목],"유사량")=0,"",SUMIFS(잔액_2025[결의금액],잔액_2025[통계목],$C33,잔액_2025[분류 항목],"유사량")) | N33: 4740930
B34: 건설비 | C34: 소계 | D34: =SUM(D35:D39) -> 0 | E34: =SUM(E35:E39) -> 0 | F34: =SUM(F35:F39) -> 6000000 | G34: =SUM(G35:G39) -> 0 | H34: =SUM(H35:H39) -> 0 | I34: =SUM(I35:I39) -> 0 | J34: =SUM(J35:J39) -> 0 | K34: =SUM(K35:K39) -> 0 | ... O34: =SUM(O35:O39) -> 0
C35: 기본조사설계비 | G35: =IF(SUMIFS(잔액_2022[결의금액],잔액_2022[통계목],$C35,잔액_2022[분류 항목],"유사량")=0,"",SUMIFS(잔액_2022[결의금액],잔액_2022[통계목],$C35,잔액_2022[분류 항목],"유사량")) | I35: =IF(SUMIFS(잔액_2023[결의금액],잔액_2023[통계목],$C35,잔액_2023[분류 항목],"유사량")=0,"",SUMIFS(잔액_2023[결의금액],잔액_2023[통계목],$C35,잔액_2023[분류 항목],"유사량")) | K35: =IF(SUMIFS(잔액_2024[결의금액],잔액_2024[통계목],$C35,잔액_2024[분류 항목],"유사량")=0,"",SUMIFS(잔액_2024[결의금액],잔액_2024[통계목],$C35,잔액_2024[분류 항목],"유사량")) | M35: =IF(SUMIFS(잔액_2025[결의금액],잔액_2025[통계목],$C35,잔액_2025[분류 항목],"유사량")=0,"",SUMIFS(잔액_2025[결의금액],잔액_2025[통계목],$C35,잔액_2025[분류 항목],"유사량"))
C36: 실시설계비 | G36: =IF(SUMIFS(잔액_2022[결의금액],잔액_2022[통계목],$C36,잔액_2022[분류 항목],"유사량")=0,"",SUMIFS(잔액_2022[결의금액],잔액_2022[통계목],$C36,잔액_2022[분류 항목],"유사량")) | I36: =IF(SUMIFS(잔액_2023[결의금액],잔액_2023[통계목],$C36,잔액_2023[분류 항목],"유사량")=0,"",SUMIFS(잔액_2023[결의금액],잔액_2023[통계목],$C36,잔액_2023[분류 항목],"유사량")) | K36: =IF(SUMIFS(잔액_2024[결의금액],잔액_2024[통계목],$C36,잔액_2024[분류 항목],"유사량")=0,"",SUMIFS(잔액_2024[결의금액],잔액_2024[통계목],$C36,잔액_2024[분류 항목],"유사량")) | M36: =IF(SUMIFS(잔액_2025[결의금액],잔액_2025[통계목],$C36,잔액_2025[분류 항목],"유사량")=0,"",SUMIFS(잔액_2025[결의금액],잔액_2025[통계목],$C36,잔액_2025[분류 항목],"유사량"))
C37: 공사비 | F37: 6000000 | G37: =IF(SUMIFS(잔액_2022[결의금액],잔액_2022[통계목],$C37,잔액_2022[분류 항목],"유사량")=0,"",SUMIFS(잔액_2022[결의금액],잔액_2022[통계목],$C37,잔액_2022[분류 항목],"유사량")) | I37: =IF(SUMIFS(잔액_2023[결의금액],잔액_2023[통계목],$C37,잔액_2023[분류 항목],"유사량")=0,"",SUMIFS(잔액_2023[결의금액],잔액_2023[통계목],$C37,잔액_2023[분류 항목],"유사량")) | K37: =IF(SUMIFS(잔액_2024[결의금액],잔액_2024[통계목],$C37,잔액_2024[분류 항목],"유사량")=0,"",SUMIFS(잔액_2024[결의금액],잔액_2024[통계목],$C37,잔액_2024[분류 항목],"유사량")) | M37: =IF(SUMIFS(잔액_2025[결의금액],잔액_2025[통계목],$C37,잔액_2025[분류 항목],"유사량")=0,"",SUMIFS(잔액_2025[결의금액],잔액_2025[통계목],$C37,잔액_2025[분류 항목],"유사량"))
C38: 감리비 | G38: =IF(SUMIFS(잔액_2022[결의금액],잔액_2022[통계목],$C38,잔액_2022[분류 항목],"유사량")=0,"",SUMIFS(잔액_2022[결의금액],잔액_2022[통계목],$C38,잔액_2022[분류 항목],"유사량")) | I38: =IF(SUMIFS(잔액_2023[결의금액],잔액_2023[통계목],$C38,잔액_2023[분류 항목],"유사량")=0,"",SUMIFS(잔액_2023[결의금액],잔액_2023[통계목],$C38,잔액_2023[분류 항목],"유사량")) | K38: =IF(SUMIFS(잔액_2024[결의금액],잔액_2024[통계목],$C38,잔액_2024[분류 항목],"유사량")=0,"",SUMIFS(잔액_2024[결의금액],잔액_2024[통계목],$C38,잔액_2024[분류 항목],"유사량")) | M38: =IF(SUMIFS(잔액_2025[결의금액],잔액_2025[통계목],$C38,잔액_2025[분류 항목],"유사량")=0,"",SUMIFS(잔액_2025[결의금액],잔액_2025[통계목],$C38,잔액_2025[분류 항목],"유사량"))
C39: 시설부대비 | G39: =IF(SUMIFS(잔액_2022[결의금액],잔액_2022[통계목],$C39,잔액_2022[분류 항목],"유사량")=0,"",SUMIFS(잔액_2022[결의금액],잔액_2022[통계목],$C39,잔액_2022[분류 항목],"유사량")) | I39: =IF(SUMIFS(잔액_2023[결의금액],잔액_2023[통계목],$C39,잔액_2023[분류 항목],"유사량")=0,"",SUMIFS(잔액_2023[결의금액],잔액_2023[통계목],$C39,잔액_2023[분류 항목],"유사량")) | K39: =IF(SUMIFS(잔액_2024[결의금액],잔액_2024[통계목],$C39,잔액_2024[분류 항목],"유사량")=0,"",SUMIFS(잔액_2024[결의금액],잔액_2024[통계목],$C39,잔액_2024[분류 항목],"유사량")) | M39: =IF(SUMIFS(잔액_2025[결의금액],잔액_2025[통계목],$C39,잔액_2025[분류 항목],"유사량")=0,"",SUMIFS(잔액_2025[결의금액],잔액_2025[통계목],$C39,잔액_2025[분류 항목],"유사량"))
B40: 유형자산 | C40: 소계 | D40: =D41 -> 0 | E40: =E41 -> 0 | F40: =F41 -> 2000000 | G40: =G41 -> 19025280 | H40: =H41 -> 0 | I40: =I41 -> 109142000 | J40: =J41 -> 37500000 | K40: =K41 | ... O40: =O41 -> 0
...

Sheet 토양수분량
B1: 토양수분량
B2: 편성목 | C2: 통계목 | D2: 2021년 | F2: 2022년 | H2: 2023년 | J2: 2024년 | L2: 2025년 | N2: 2026년
D3: 실행예산 | E3: 잔액 예산 | F3: 실행예산 | G3: 잔액 예산 | H3: 실행예산 | I3: 잔액 예산 | J3: 실행예산 | K3: 잔액 예산 | L3: 실행예산 | M3: 잔액 예산 | N3: 실행예산 | O3: 잔액 예산
B4: 합계 | D4: =SUM(D5,D10,D23,D26,D29,D32,D34,D40,D42,D44,D46) -> 20453200 | E4: =SUM(E5,E10,E23,E26,E29,E32,E34,E40,E42,E44,E46) -> 0 | F4: =SUM(F5,F10,F23,F26,F29,F32,F34,F40,F42,F44,F46) -> 26700000 | G4: =SUM(G5,G10,G23,G26,G29,G32,G34,G40,G42,G44,G46) -> 41525000 | H4: =SUM(H5,H10,H23,H26,H29,H32,H34,H40,H42,H44,H46) -> 55206400 | I4: =SUM(I5,I10,I23,I26,I29,I32,I34,I40,I42,I44,I46) -> 0 | J4: =SUM(J5,J10,J23,J26,J29,J32,J34,J40,J42,J44,J46) -> 30000000 | K4: =SUM(K5,K10,K23,K26,K29,K32,K34,K40,K42,K44,K46) -> 17392120 | ... O4: =SUM(O5,O10,O23,O26,O29,O32,O34,O40,O42,O44,O46) -> 0
B5: 인건비 | C5: 소계 | D5: =SUM(D6:D9) -> 0 | E5: =SUM(E6:E9) -> 0 | F5: =SUM(F6:F9) -> 0 | G5: =SUM(G6:G9) -> 0 | H5: =SUM(H6:H9) -> 11196400 | I5: =SUM(I6:I9) -> 0 | J5: =SUM(J6:J9) -> 0 | K5: =SUM(K6:K9) -> 0 | ... O5: =SUM(O6:O9) -> 0
C6: 보수 | G6: =IF(SUMIFS(잔액_2022[결의금액],잔액_2022[통계목],$C6,잔액_2022[분류 항목],"토양수분량")=0,"",SUMIFS(잔액_2022[결의금액],잔액_2022[통계목],$C6,잔액_2022[분류 항목],"토양수분량")) | I6: =IF(SUMIFS(잔액_2023[결의금액],잔액_2023[통계목],$C6,잔액_2023[분류 항목],"토양수분량")=0,"",SUMIFS(잔액_2023[결의금액],잔액_2023[통계목],$C6,잔액_2023[분류 항목],"토양수분량")) | K6: =IF(SUMIFS(잔액_2024[결의금액],잔액_2024[통계목],$C6,잔액_2024[분류 항목],"토양수분량")=0,"",SUMIFS(잔액_2024[결의금액],잔액_2024[통계목],$C6,잔액_2024[분류 항목],"토양수분량")) | M6: =IF(SUMIFS(잔액_2025[결의금액],잔액_2025[통계목],$C6,잔액_2025[분류 항목],"토양수분량")=0,"",SUMIFS(잔액_2025[결의금액],잔액_2025[통계목],$C6,잔액_2025[분류 항목],"토양수분량"))
C7: 기타직보수 | G7: =IF(SUMIFS(잔액_2022[결의금액],잔액_2022[통계목],$C7,잔액_2022[분류 항목],"토양수분량")=0,"",SUMIFS(잔액_2022[결의금액],잔액_2022[통계목],$C7,잔액_2022[분류 항목],"토양수분량")) | I7: =IF(SUMIFS(잔액_2023[결의금액],잔액_2023[통계목],$C7,잔액_2023[분류 항목],"토양수분량")=0,"",SUMIFS(잔액_2023[결의금액],잔액_2023[통계목],$C7,잔액_2023[분류 항목],"토양수분량")) | K7: =IF(SUMIFS(잔액_2024[결의금액],잔액_2024[통계목],$C7,잔액_2024[분류 항목],"토양수분량")=0,"",SUMIFS(잔액_2024[결의금액],잔액_2024[통계목],$C7,잔액_2024[분류 항목],"토양수분량")) | M7: =IF(SUMIFS(잔액_2025[결의금액],잔액_2025[통계목],$C7,잔액_2025[분류 항목],"토양수분량")=0,"",SUMIFS(잔액_2025[결의금액],잔액_2025[통계목],$C7,잔액_2025[분류 항목],"토양수분량"))
C8: 상용임금 | G8: =IF(SUMIFS(잔액_2022[결의금액],잔액_2022[통계목],$C8,잔액_2022[분류 항목],"토양수분량")=0,"",SUMIFS(잔액_2022[결의금액],잔액_2022[통계목],$C8,잔액_2022[분류 항목],"토양수분량")) | H8: 11196400 | I8: =IF(SUMIFS(잔액_2023[결의금액],잔액_2023[통계목],$C8,잔액_2023[분류 항목],"토양수분량")=0,"",SUMIFS(잔액_2023[결의금액],잔액_2023[통계목],$C8,잔액_2023[분류 항목],"토양수분량")) | K8: =IF(SUMIFS(잔액_2024[결의금액],잔액_2024[통계목],$C8,잔액_2024[분류 항목],"토양수분량")=0,"",SUMIFS(잔액_2024[결의금액],잔액_2024[통계목],$C8,잔액_2024[분류 항목],"토양수분량")) | M8: =IF(SUMIFS(잔액_2025[결의금액],잔액_2025[통계목],$C8,잔액_2025[분류 항목],"토양수분량")=0,"",SUMIFS(잔액_2025[결의금액],잔액_2025[통계목],$C8,잔액_2025[분류 항목],"토양수분량"))
C9: 일용임금 | G9: =IF(SUMIFS(잔액_2022[결의금액],잔액_2022[통계목],$C9,잔액_2022[분류 항목],"토양수분량")=0,"",SUMIFS(잔액_2022[결의금액],잔액_2022[통계목],$C9,잔액_2022[분류 항목],"토양수분량")) | I9: =IF(SUMIFS(잔액_2023[결의금액],잔액_2023[통계목],$C9,잔액_2023[분류 항목],"토양수분량")=0,"",SUMIFS(잔액_2023[결의금액],잔액_2023[통계목],$C9,잔액_2023[분류 항목],"토양수분량")) | K9: =IF(SUMIFS(잔액_2024[결의금액],잔액_2024[통계목],$C9,잔액_2024[분류 항목],"토양수분량")=0,"",SUMIFS(잔액_2024[결의금액],잔액_2024[통계목],$C9,잔액_2024[분류 항목],"토양수분량")) | M9: =IF(SUMIFS(잔액_2025[결의금액],잔액_2025[통계목],$C9,잔액_2025[분류 항목],"토양수분량")=0,"",SUMIFS(잔액_2025[결의금액],잔액_2025[통계목],$C9,잔액_2025[분류 항목],"토양수분량"))
B10: 운영비 | C10: 소계 | D10: =SUM(D11:D22) -> 17184700 | E10: =SUM(E11:E22) -> 0 | F10: =SUM(F11:F22) -> 20700000 | G10: =SUM(G11:G22) -> 0 | H10: =SUM(H11:H22) -> 38050000 | I10: =SUM(I11:I22) -> 0 | J10: =SUM(J11:J22) -> 21560000 | K10: =SUM(K11:K22) -> 0 | ... O10: =SUM(O11:O22) -> 0
C11: 일반수용비 | D11: 16814700 | F11: 6000000 | G11: =IF(SUMIFS(잔액_2022[결의금액],잔액_2022[통계목],$C11,잔액_2022[분류 항목],"토양수분량")=0,"",SUMIFS(잔액_2022[결의금액],잔액_2022[통계목],$C11,잔액_2022[분류 항목],"토양수분량")) | H11: 400000 | I11: =IF(SUMIFS(잔액_2023[결의금액],잔액_2023[통계목],$C11,잔액_2023[분류 항목],"토양수분량")=0,"",SUMIFS(잔액_2023[결의금액],잔액_2023[통계목],$C11,잔액_2023[분류 항목],"토양수분량")) | J11: 500000 | K11: =IF(SUMIFS(잔액_2024[결의금액],잔액_2024[통계목],$C11,잔액_2024[분류 항목],"토양수분량")=0,"",SUMIFS(잔액_2024[결의금액],잔액_2024[통계목],$C11,잔액_2024[분류 항목],"토양수분량")) | M11: =IF(SUMIFS(잔액_2025[결의금액],잔액_2025[통계목],$C11,잔액_2025[분류 항목],"토양수분량")=0,"",SUMIFS(잔액_2025[결의금액],잔액_2025[통계목],$C11,잔액_2025[분류 항목],"토양수분량"))
C12: 공공요금 및 제세 | F12: 4600000 | G12: =IF(SUMIFS(잔액_2022[결의금액],잔액_2022[통계목],$C12,잔액_2022[분류 항목],"토양수분량")=0,"",SUMIFS(잔액_2022[결의금액],잔액_2022[통계목],$C12,잔액_2022[분류 항목],"토양수분량")) | H12: 9550000 | I12: =IF(SUMIFS(잔액_2023[결의금액],잔액_2023[통계목],$C12,잔액_2023[분류 항목],"토양수분량")=0,"",SUMIFS(잔액_2023[결의금액],잔액_2023[통계목],$C12,잔액_2023[분류 항목],"토양수분량")) | J12: 8125000 | K12: =IF(SUMIFS(잔액_2024[결의금액],잔액_2024[통계목],$C12,잔액_2024[분류 항목],"토양수분량")=0,"",SUMIFS(잔액_2024[결의금액],잔액_2024[통계목],$C12,잔액_2024[분류 항목],"토양수분량")) | M12: =IF(SUMIFS(잔액_2025[결의금액],잔액_2025[통계목],$C12,잔액_2025[분류 항목],"토양수분량")=0,"",SUMIFS(잔액_2025[결의금액],잔액_2025[통계목],$C12,잔액_2025[분류 항목],"토양수분량")) | N12: 8000000
C13: 피복비 | G13: =IF(SUMIFS(잔액_2022[결의금액],잔액_2022[통계목],$C13,잔액_2022[분류 항목],"토양수분량")=0,"",SUMIFS(잔액_2022[결의금액],잔액_2022[통계목],$C13,잔액_2022[분류 항목],"토양수분량")) | I13: =IF(SUMIFS(잔액_2023[결의금액],잔액_2023[통계목],$C13,잔액_2023[분류 항목],"토양수분량")=0,"",SUMIFS(잔액_2023[결의금액],잔액_2023[통계목],$C13,잔액_2023[분류 항목],"토양수분량")) | K13: =IF(SUMIFS(잔액_2024[결의금액],잔액_2024[통계목],$C13,잔액_2024[분류 항목],"토양수분량")=0,"",SUMIFS(잔액_2024[결의금액],잔액_2024[통계목],$C13,잔액_2024[분류 항목],"토양수분량")) | M13: =IF(SUMIFS(잔액_2025[결의금액],잔액_2025[통계목],$C13,잔액_2025[분류 항목],"토양수분량")=0,"",SUMIFS(잔액_2025[결의금액],잔액_2025[통계목],$C13,잔액_2025[분류 항목],"토양수분량"))
C14: 특근매식비 | G14: =IF(SUMIFS(잔액_2022[결의금액],잔액_2022[통계목],$C14,잔액_2022[분류 항목],"토양수분량")=0,"",SUMIFS(잔액_2022[결의금액],잔액_2022[통계목],$C14,잔액_2022[분류 항목],"토양수분량")) | I14: =IF(SUMIFS(잔액_2023[결의금액],잔액_2023[통계목],$C14,잔액_2023[분류 항목],"토양수분량")=0,"",SUMIFS(잔액_2023[결의금액],잔액_2023[통계목],$C14,잔액_2023[분류 항목],"토양수분량")) | K14: =IF(SUMIFS(잔액_2024[결의금액],잔액_2024[통계목],$C14,잔액_2024[분류 항목],"토양수분량")=0,"",SUMIFS(잔액_2024[결의금액],잔액_2024[통계목],$C14,잔액_2024[분류 항목],"토양수분량")) | M14: =IF(SUMIFS(잔액_2025[결의금액],잔액_2025[통계목],$C14,잔액_2025[분류 항목],"토양수분량")=0,"",SUMIFS(잔액_2025[결의금액],잔액_2025[통계목],$C14,잔액_2025[분류 항목],"토양수분량"))
C15: 임차료 | F15: 5000000 | G15: =IF(SUMIFS(잔액_2022[결의금액],잔액_2022[통계목],$C15,잔액_2022[분류 항목],"토양수분량")=0,"",SUMIFS(잔액_2022[결의금액],잔액_2022[통계목],$C15,잔액_2022[분류 항목],"토양수분량")) | H15: 4300000 | I15: =IF(SUMIFS(잔액_2023[결의금액],잔액_2023[통계목],$C15,잔액_2023[분류 항목],"토양수분량")=0,"",SUMIFS(잔액_2023[결의금액],잔액_2023[통계목],$C15,잔액_2023[분류 항목],"토양수분량")) | K15: =IF(SUMIFS(잔액_2024[결의금액],잔액_2024[통계목],$C15,잔액_2024[분류 항목],"토양수분량")=0,"",SUMIFS(잔액_2024[결의금액],잔액_2024[통계목],$C15,잔액_2024[분류 항목],"토양수분량")) | M15: =IF(SUMIFS(잔액_2025[결의금액],잔액_2025[통계목],$C15,잔액_2025[분류 항목],"토양수분량")=0,"",SUMIFS(잔액_2025[결의금액],잔액_2025[통계목],$C15,잔액_2025[분류 항목],"토양수분량"))
C16: 유류비 | D16: 370000 | F16: 1000000 | G16: =IF(SUMIFS(잔액_2022[결의금액],잔액_2022[통계목],$C16,잔액_2022[분류 항목],"토양수분량")=0,"",SUMIFS(잔액_2022[결의금액],잔액_2022[통계목],$C16,잔액_2022[분류 항목],"토양수분량")) | H16: 1000000 | I16: =IF(SUMIFS(잔액_2023[결의금액],잔액_2023[통계목],$C16,잔액_2023[분류 항목],"토양수분량")=0,"",SUMIFS(잔액_2023[결의금액],잔액_2023[통계목],$C16,잔액_2023[분류 항목],"토양수분량")) | J16: 960000 | K16: =IF(SUMIFS(잔액_2024[결의금액],잔액_2024[통계목],$C16,잔액_2024[분류 항목],"토양수분량")=0,"",SUMIFS(잔액_2024[결의금액],잔액_2024[통계목],$C16,잔액_2024[분류 항목],"토양수분량")) | M16: =IF(SUMIFS(잔액_2025[결의금액],잔액_2025[통계목],$C16,잔액_2025[분류 항목],"토양수분량")=0,"",SUMIFS(잔액_2025[결의금액],잔액_2025[통계목],$C16,잔액_2025[분류 항목],"토양수분량"))
C17: 시설장비유지비 | F17: 4100000 | G17: =IF(SUMIFS(잔액_2022[결의금액],잔액_2022[통계목],$C17,잔액_2022[분류 항목],"토양수분량")=0,"",SUMIFS(잔액_2022[결의금액],잔액_2022[통계목],$C17,잔액_2022[분류 항목],"토양수분량")) | H17: 22800000 | I17: =IF(SUMIFS(잔액_2023[결의금액],잔액_2023[통계목],$C17,잔액_2023[분류 항목],"토양수분량")=0,"",SUMIFS(잔액_2023[결의금액],잔액_2023[통계목],$C17,잔액_2023[분류 항목],"토양수분량")) | J17: 11975000 | K17: =IF(SUMIFS(잔액_2024[결의금액],잔액_2024[통계목],$C17,잔액_2024[분류 항목],"토양수분량")=0,"",SUMIFS(잔액_2024[결의금액],잔액_2024[통계목],$C17,잔액_2024[분류 항목],"토양수분량")) | L17: 8000000 | M17: =IF(SUMIFS(잔액_2025[결의금액],잔액_2025[통계목],$C17,잔액_2025[분류 항목],"토양수분량")=0,"",SUMIFS(잔액_2025[결의금액],잔액_2025[통계목],$C17,잔액_2025[분류 항목],"토양수분량")) | N17: 3000000
C18: 재료비 | G18: =IF(SUMIFS(잔액_2022[결의금액],잔액_2022[통계목],$C18,잔액_2022[분류 항목],"토양수분량")=0,"",SUMIFS(잔액_2022[결의금액],잔액_2022[통계목],$C18,잔액_2022[분류 항목],"토양수분량")) | I18: =IF(SUMIFS(잔액_2023[결의금액],잔액_2023[통계목],$C18,잔액_2023[분류 항목],"토양수분량")=0,"",SUMIFS(잔액_2023[결의금액],잔액_2023[통계목],$C18,잔액_2023[분류 항목],"토양수분량")) | K18: =IF(SUMIFS(잔액_2024[결의금액],잔액_2024[통계목],$C18,잔액_2024[분류 항목],"토양수분량")=0,"",SUMIFS(잔액_2024[결의금액],잔액_2024[통계목],$C18,잔액_2024[분류 항목],"토양수분량")) | L18: 2000000 | M18: =IF(SUMIFS(잔액_2025[결의금액],잔액_2025[통계목],$C18,잔액_2025[분류 항목],"토양수분량")=0,"",SUMIFS(잔액_2025[결의금액],잔액_2025[통계목],$C18,잔액_2025[분류 항목],"토양수분량"))
C19: 복리후생비 | G19: =IF(SUMIFS(잔액_2022[결의금액],잔액_2022[통계목],$C19,잔액_2022[분류 항목],"토양수분량")=0,"",SUMIFS(잔액_2022[결의금액],잔액_2022[통계목],$C19,잔액_2022[분류 항목],"토양수분량")) | I19: =IF(SUMIFS(잔액_2023[결의금액],잔액_2023[통계목],$C19,잔액_2023[분류 항목],"토양수분량")=0,"",SUMIFS(잔액_2023[결의금액],잔액_2023[통계목],$C19,잔액_2023[분류 항목],"토양수분량")) | K19: =IF(SUMIFS(잔액_2024[결의금액],잔액_2024[통계목],$C19,잔액_2024[분류 항목],"토양수분량")=0,"",SUMIFS(잔액_2024[결의금액],잔액_2024[통계목],$C19,잔액_2024[분류 항목],"토양수분량")) | M19: =IF(SUMIFS(잔액_2025[결의금액],잔액_2025[통계목],$C19,잔액_2025[분류 항목],"토양수분량")=0,"",SUMIFS(잔액_2025[결의금액],잔액_2025[통계목],$C19,잔액_2025[분류 항목],"토양수분량"))
C20: 일반용역비 | G20: =IF(SUMIFS(잔액_2022[결의금액],잔액_2022[통계목],$C20,잔액_2022[분류 항목],"토양수분량")=0,"",SUMIFS(잔액_2022[결의금액],잔액_2022[통계목],$C20,잔액_2022[분류 항목],"토양수분량")) | I20: =IF(SUMIFS(잔액_2023[결의금액],잔액_2023[통계목],$C20,잔액_2023[분류 항목],"토양수분량")=0,"",SUMIFS(잔액_2023[결의금액],잔액_2023[통계목],$C20,잔액_2023[분류 항목],"토양수분량")) | K20: =IF(SUMIFS(잔액_2024[결의금액],잔액_2024[통계목],$C20,잔액_2024[분류 항목],"토양수분량")=0,"",SUMIFS(잔액_2024[결의금액],잔액_2024[통계목],$C20,잔액_2024[분류 항목],"토양수분량")) | M20: =IF(SUMIFS(잔액_2025[결의금액],잔액_2025[통계목],$C20,잔액_2025[분류 항목],"토양수분량")=0,"",SUMIFS(잔액_2025[결의금액],잔액_2025[통계목],$C20,잔액_2025[분류 항목],"토양수분량"))
C21: 관리용역비 | G21: =IF(SUMIFS(잔액_2022[결의금액],잔액_2022[통계목],$C21,잔액_2022[분류 항목],"토양수분량")=0,"",SUMIFS(잔액_2022[결의금액],잔액_2022[통계목],$C21,잔액_2022[분류 항목],"토양수분량")) | I21: =IF(SUMIFS(잔액_2023[결의금액],잔액_2023[통계목],$C21,잔액_2023[분류 항목],"토양수분량")=0,"",SUMIFS(잔액_2023[결의금액],잔액_2023[통계목],$C21,잔액_2023[분류 항목],"토양수분량")) | K21: =IF(SUMIFS(잔액_2024[결의금액],잔액_2024[통계목],$C21,잔액_2024[분류 항목],"토양수분량")=0,"",SUMIFS(잔액_2024[결의금액],잔액_2024[통계목],$C21,잔액_2024[분류 항목],"토양수분량")) | M21: =IF(SUMIFS(잔액_2025[결의금액],잔액_2025[통계목],$C21,잔액_2025[분류 항목],"토양수분량")=0,"",SUMIFS(잔액_2025[결의금액],잔액_2025[통계목],$C21,잔액_2025[분류 항목],"토양수분량"))
C22: 기타운영비 | G22: =IF(SUMIFS(잔액_2022[결의금액],잔액_2022[통계목],$C22,잔액_2022[분류 항목],"토양수분량")=0,"",SUMIFS(잔액_2022[결의금액],잔액_2022[통계목],$C22,잔액_2022[분류 항목],"토양수분량")) | I22: =IF(SUMIFS(잔액_2023[결의금액],잔액_2023[통계목],$C22,잔액_2023[분류 항목],"토양수분량")=0,"",SUMIFS(잔액_2023[결의금액],잔액_2023[통계목],$C22,잔액_2023[분류 항목],"토양수분량")) | K22: =IF(SUMIFS(잔액_2024[결의금액],잔액_2024[통계목],$C22,잔액_2024[분류 항목],"토양수분량")=0,"",SUMIFS(잔액_2024[결의금액],잔액_2024[통계목],$C22,잔액_2024[분류 항목],"토양수분량")) | M22: =IF(SUMIFS(잔액_2025[결의금액],잔액_2025[통계목],$C22,잔액_2025[분류 항목],"토양수분량")=0,"",SUMIFS(잔액_2025[결의금액],잔액_2025[통계목],$C22,잔액_2025[분류 항목],"토양수분량"))
B23: 여비 | C23: 소계 | D23: =SUM(D24:D25) -> 3268500 | E23: =SUM(E24:E25) -> 0 | F23: =SUM(F24:F25) -> 6000000 | G23: =SUM(G24:G25) -> 0 | H23: =SUM(H24:H25) -> 5960000 | I23: =SUM(I24:I25) -> 0 | J23: =SUM(J24:J25) -> 8440000 | K23: =SUM(K24:K25) -> 0 | ... O23: =SUM(O24:O25) -> 0
C24: 국내여비 | D24: 3268500 | F24: 6000000 | G24: =IF(SUMIFS(잔액_2022[결의금액],잔액_2022[통계목],$C24,잔액_2022[분류 항목],"토양수분량")=0,"",SUMIFS(잔액_2022[결의금액],잔액_2022[통계목],$C24,잔액_2022[분류 항목],"토양수분량")) | H24: 5960000 | I24: =IF(SUMIFS(잔액_2023[결의금액],잔액_2023[통계목],$C24,잔액_2023[분류 항목],"토양수분량")=0,"",SUMIFS(잔액_2023[결의금액],잔액_2023[통계목],$C24,잔액_2023[분류 항목],"토양수분량")) | J24: 8440000 | K24: =IF(SUMIFS(잔액_2024[결의금액],잔액_2024[통계목],$C24,잔액_2024[분류 항목],"토양수분량")=0,"",SUMIFS(잔액_2024[결의금액],잔액_2024[통계목],$C24,잔액_2024[분류 항목],"토양수분량")) | L24: 10000000 | M24: =IF(SUMIFS(잔액_2025[결의금액],잔액_2025[통계목],$C24,잔액_2025[분류 항목],"토양수분량")=0,"",SUMIFS(잔액_2025[결의금액],잔액_2025[통계목],$C24,잔액_2025[분류 항목],"토양수분량")) | N24: 9000000
C25: 국외업무여비 | G25: =IF(SUMIFS(잔액_2022[결의금액],잔액_2022[통계목],$C25,잔액_2022[분류 항목],"토양수분량")=0,"",SUMIFS(잔액_2022[결의금액],잔액_2022[통계목],$C25,잔액_2022[분류 항목],"토양수분량")) | I25: =IF(SUMIFS(잔액_2023[결의금액],잔액_2023[통계목],$C25,잔액_2023[분류 항목],"토양수분량")=0,"",SUMIFS(잔액_2023[결의금액],잔액_2023[통계목],$C25,잔액_2023[분류 항목],"토양수분량")) | K25: =IF(SUMIFS(잔액_2024[결의금액],잔액_2024[통계목],$C25,잔액_2024[분류 항목],"토양수분량")=0,"",SUMIFS(잔액_2024[결의금액],잔액_2024[통계목],$C25,잔액_2024[분류 항목],"토양수분량")) | M25: =IF(SUMIFS(잔액_2025[결의금액],잔액_2025[통계목],$C25,잔액_2025[분류 항목],"토양수분량")=0,"",SUMIFS(잔액_2025[결의금액],잔액_2025[통계목],$C25,잔액_2025[분류 항목],"토양수분량"))
B26: 업무추진비 | C26: 소계 | D26: =SUM(D27:D28) -> 0 | E26: =SUM(E27:E28) -> 0 | F26: =SUM(F27:F28) -> 0 | G26: =SUM(G27:G28) -> 0 | H26: =SUM(H27:H28) -> 0 | I26: =SUM(I27:I28) -> 0 | J26: =SUM(J27:J28) -> 0 | K26: =SUM(K27:K28) -> 0 | ... O26: =SUM(O27:O28) -> 0
C27: 사업추진비 | G27: =IF(SUMIFS(잔액_2022[결의금액],잔액_2022[통계목],$C27,잔액_2022[분류 항목],"토양수분량")=0,"",SUMIFS(잔액_2022[결의금액],잔액_2022[통계목],$C27,잔액_2022[분류 항목],"토양수분량")) | I27: =IF(SUMIFS(잔액_2023[결의금액],잔액_2023[통계목],$C27,잔액_2023[분류 항목],"토양수분량")=0,"",SUMIFS(잔액_2023[결의금액],잔액_2023[통계목],$C27,잔액_2023[분류 항목],"토양수분량")) | K27: =IF(SUMIFS(잔액_2024[결의금액],잔액_2024[통계목],$C27,잔액_2024[분류 항목],"토양수분량")=0,"",SUMIFS(잔액_2024[결의금액],잔액_2024[통계목],$C27,잔액_2024[분류 항목],"토양수분량")) | M27: =IF(SUMIFS(잔액_2025[결의금액],잔액_2025[통계목],$C27,잔액_2025[분류 항목],"토양수분량")=0,"",SUMIFS(잔액_2025[결의금액],잔액_2025[통계목],$C27,잔액_2025[분류 항목],"토양수분량"))
C28: 관서업무추진비 | G28: =IF(SUMIFS(잔액_2022[결의금액],잔액_2022[통계목],$C28,잔액_2022[분류 항목],"토양수분량")=0,"",SUMIFS(잔액_2022[결의금액],잔액_2022[통계목],$C28,잔액_2022[분류 항목],"토양수분량")) | I28: =IF(SUMIFS(잔액_2023[결의금액],잔액_2023[통계목],$C28,잔액_2023[분류 항목],"토양수분량")=0,"",SUMIFS(잔액_2023[결의금액],잔액_2023[통계목],$C28,잔액_2023[분류 항목],"토양수분량")) | K28: =IF(SUMIFS(잔액_2024[결의금액],잔액_2024[통계목],$C28,잔액_2024[분류 항목],"토양수분량")=0,"",SUMIFS(잔액_2024[결의금액],잔액_2024[통계목],$C28,잔액_2024[분류 항목],"토양수분량")) | M28: =IF(SUMIFS(잔액_2025[결의금액],잔액_2025[통계목],$C28,잔액_2025[분류 항목],"토양수분량")=0,"",SUMIFS(잔액_2025[결의금액],잔액_2025[통계목],$C28,잔액_2025[분류 항목],"토양수분량"))
B29: 연구용역비 | C29: 소계 | D29: =SUM(D30:D31) -> 0 | E29: =SUM(E30:E31) -> 0 | F29: =SUM(F30:F31) -> 0 | G29: =SUM(G30:G31) -> 0 | H29: =SUM(H30:H31) -> 0 | I29: =SUM(I30:I31) -> 0 | J29: =SUM(J30:J31) -> 0 | K29: =SUM(K30:K31) -> 17392120 | ... O29: =SUM(O30:O31) -> 0
C30: 일반연구비 | G30: =IF(SUMIFS(잔액_2022[결의금액],잔액_2022[통계목],$C30,잔액_2022[분류 항목],"토양수분량")=0,"",SUMIFS(잔액_2022[결의금액],잔액_2022[통계목],$C30,잔액_2022[분류 항목],"토양수분량")) | I30: {=IFERROR(INDEX(잔액_2023[결의금액],MATCH(1,(잔액_2023[통계목]=$C30)*(잔액_2023[분류 항목]="토양수분량"),0)),"")} | K30: =IF(SUMIFS(잔액_2024[결의금액],잔액_2024[통계목],$C30,잔액_2024[분류 항목],"토양수분량")=0,"",SUMIFS(잔액_2024[결의금액],잔액_2024[통계목],$C30,잔액_2024[분류 항목],"토양수분량")) -> 17392120 | M30: =IF(SUMIFS(잔액_2025[결의금액],잔액_2025[통계목],$C30,잔액_2025[분류 항목],"토양수분량")=0,"",SUMIFS(잔액_2025[결의금액],잔액_2025[통계목],$C30,잔액_2025[분류 항목],"토양수분량")) -> 28461330
C31: 정책연구비 | G31: =IF(SUMIFS(잔액_2022[결의금액],잔액_2022[통계목],$C31,잔액_2022[분류 항목],"토양수분량")=0,"",SUMIFS(잔액_2022[결의금액],잔액_2022[통계목],$C31,잔액_2022[분류 항목],"토양수분량")) | I31: =IF(SUMIFS(잔액_2023[결의금액],잔액_2023[통계목],$C31,잔액_2023[분류 항목],"토양수분량")=0,"",SUMIFS(잔액_2023[결의금액],잔액_2023[통계목],$C31,잔액_2023[분류 항목],"토양수분량")) | K31: =IF(SUMIFS(잔액_2024[결의금액],잔액_2024[통계목],$C31,잔액_2024[분류 항목],"토양수분량")=0,"",SUMIFS(잔액_2024[결의금액],잔액_2024[통계목],$C31,잔액_2024[분류 항목],"토양수분량")) | M31: =IF(SUMIFS(잔액_2025[결의금액],잔액_2025[통계목],$C31,잔액_2025[분류 항목],"토양수분량")=0,"",SUMIFS(잔액_2025[결의금액],잔액_2025[통계목],$C31,잔액_2025[분류 항목],"토양수분량"))
B32: 민간이전 | C32: 소계 | D32: =D33 -> 0 | E32: =E33 -> 0 | F32: =F33 -> 0 | G32: =G33 | H32: =H33 -> 0 | I32: =I33 | J32: =J33 -> 0 | K32: =K33 | ... O32: =O33 -> 0
C33: 고용부담금 | G33: =IF(SUMIFS(잔액_2022[결의금액],잔액_2022[통계목],$C33,잔액_2022[분류 항목],"토양수분량")=0,"",SUMIFS(잔액_2022[결의금액],잔액_2022[통계목],$C33,잔액_2022[분류 항목],"토양수분량")) | I33: =IF(SUMIFS(잔액_2023[결의금액],잔액_2023[통계목],$C33,잔액_2023[분류 항목],"토양수분량")=0,"",SUMIFS(잔액_2023[결의금액],잔액_2023[통계목],$C33,잔액_2023[분류 항목],"토양수분량")) | K33: =IF(SUMIFS(잔액_2024[결의금액],잔액_2024[통계목],$C33,잔액_2024[분류 항목],"토양수분량")=0,"",SUMIFS(잔액_2024[결의금액],잔액_2024[통계목],$C33,잔액_2024[분류 항목],"토양수분량")) | M33: =IF(SUMIFS(잔액_2025[결의금액],잔액_2025[통계목],$C33,잔액_2025[분류 항목],"토양수분량")=0,"",SUMIFS(잔액_2025[결의금액],잔액_2025[통계목],$C33,잔액_2025[분류 항목],"토양수분량"))
B34: 건설비 | C34: 소계 | D34: =SUM(D35:D39) -> 0 | E34: =SUM(E35:E39) -> 0 | F34: =SUM(F35:F39) -> 0 | G34: =SUM(G35:G39) -> 0 | H34: =SUM(H35:H39) -> 0 | I34: =SUM(I35:I39) -> 0 | J34: =SUM(J35:J39) -> 0 | K34: =SUM(K35:K39) -> 0 | ... O34: =SUM(O35:O39) -> 0
C35: 기본조사설계비 | G35: =IF(SUMIFS(잔액_2022[결의금액],잔액_2022[통계목],$C35,잔액_2022[분류 항목],"토양수분량")=0,"",SUMIFS(잔액_2022[결의금액],잔액_2022[통계목],$C35,잔액_2022[분류 항목],"토양수분량")) | I35: =IF(SUMIFS(잔액_2023[결의금액],잔액_2023[통계목],$C35,잔액_2023[분류 항목],"토양수분량")=0,"",SUMIFS(잔액_2023[결의금액],잔액_2023[통계목],$C35,잔액_2023[분류 항목],"토양수분량")) | K35: =IF(SUMIFS(잔액_2024[결의금액],잔액_2024[통계목],$C35,잔액_2024[분류 항목],"토양수분량")=0,"",SUMIFS(잔액_2024[결의금액],잔액_2024[통계목],$C35,잔액_2024[분류 항목],"토양수분량")) | M35: =IF(SUMIFS(잔액_2025[결의금액],잔액_2025[통계목],$C35,잔액_2025[분류 항목],"토양수분량")=0,"",SUMIFS(잔액_2025[결의금액],잔액_2025[통계목],$C35,잔액_2025[분류 항목],"토양수분량"))
C36: 실시설계비 | G36: =IF(SUMIFS(잔액_2022[결의금액],잔액_2022[통계목],$C36,잔액_2022[분류 항목],"토양수분량")=0,"",SUMIFS(잔액_2022[결의금액],잔액_2022[통계목],$C36,잔액_2022[분류 항목],"토양수분량")) | I36: =IF(SUMIFS(잔액_2023[결의금액],잔액_2023[통계목],$C36,잔액_2023[분류 항목],"토양수분량")=0,"",SUMIFS(잔액_2023[결의금액],잔액_2023[통계목],$C36,잔액_2023[분류 항목],"토양수분량")) | K36: =IF(SUMIFS(잔액_2024[결의금액],잔액_2024[통계목],$C36,잔액_2024[분류 항목],"토양수분량")=0,"",SUMIFS(잔액_2024[결의금액],잔액_2024[통계목],$C36,잔액_2024[분류 항목],"토양수분량")) | M36: =IF(SUMIFS(잔액_2025[결의금액],잔액_2025[통계목],$C36,잔액_2025[분류 항목],"토양수분량")=0,"",SUMIFS(잔액_2025[결의금액],잔액_2025[통계목],$C36,잔액_2025[분류 항목],"토양수분량"))
C37: 공사비 | G37: =IF(SUMIFS(잔액_2022[결의금액],잔액_2022[통계목],$C37,잔액_2022[분류 항목],"토양수분량")=0,"",SUMIFS(잔액_2022[결의금액],잔액_2022[통계목],$C37,잔액_2022[분류 항목],"토양수분량")) | I37: =IF(SUMIFS(잔액_2023[결의금액],잔액_2023[통계목],$C37,잔액_2023[분류 항목],"토양수분량")=0,"",SUMIFS(잔액_2023[결의금액],잔액_2023[통계목],$C37,잔액_2023[분류 항목],"토양수분량")) | K37: =IF(SUMIFS(잔액_2024[결의금액],잔액_2024[통계목],$C37,잔액_2024[분류 항목],"토양수분량")=0,"",SUMIFS(잔액_2024[결의금액],잔액_2024[통계목],$C37,잔액_2024[분류 항목],"토양수분량")) | M37: =IF(SUMIFS(잔액_2025[결의금액],잔액_2025[통계목],$C37,잔액_2025[분류 항목],"토양수분량")=0,"",SUMIFS(잔액_2025[결의금액],잔액_2025[통계목],$C37,잔액_2025[분류 항목],"토양수분량"))
