Workbook
Name ______________: ______________
Name _______________: _______________
Name ________________: ________________
Name _________________: _________________
Name __________________: __________________
Name ___________________: ___________________
Name ____________________: ____________________
Name _____________________: _____________________
Name ______________________: ______________________
Name _______________________: _______________________
Name __________________________: __________________________
Name ______________________________: ______________________________
Name __________________________________: __________________________________
Name _____________________________________: _____________________________________
Name ______________________________________: ______________________________________
Name ___________________________________________: ___________________________________________
Name ______________________________________________: ______________________________________________
Name ________________________________________________: ________________________________________________
Name __________________________________________________: __________________________________________________
Name ______________________________________________________________: ______________________________________________________________
Name ______________________________________________________________________: ______________________________________________________________________
Name _____________________________________________________________________________: _____________________________________________________________________________
Name _____________________ju8: {"'광피스표'!$A$3:$N$54"}
Name ____________________ju8: {"'광피스표'!$A$3:$N$54"}
Name ___________________ju8: {"'광피스표'!$A$3:$N$54"}
Name __________________ju8: {"'광피스표'!$A$3:$N$54"}
Name _________________ju8: {"'광피스표'!$A$3:$N$54"}
Name ________________ju8: {"'광피스표'!$A$3:$N$54"}
Name _______________ju8: {"'광피스표'!$A$3:$N$54"}
Name ______________ju8: {"'광피스표'!$A$3:$N$54"}
Name _____________ju8: {"'광피스표'!$A$3:$N$54"}
Name ____________ju8: {"'광피스표'!$A$3:$N$54"}
Name ___________ju8: {"'광피스표'!$A$3:$N$54"}
Name ___________q45: {"'용역비'!$A$4:$C$8"}
Name __________ju8: {"'광피스표'!$A$3:$N$54"}
Name _________ju8: {"'광피스표'!$A$3:$N$54"}
Name _________P3: {#N/A,#N/A,FALSE,"배수1"}
Name _________P4: {#N/A,#N/A,FALSE,"혼합골재"}
Name _________P5: {#N/A,#N/A,FALSE,"배수1"}
Name _________P6: {#N/A,#N/A,FALSE,"2~8번"}
Name _________S3: {#N/A,#N/A,FALSE,"포장2"}
Name ________ju8: {"'광피스표'!$A$3:$N$54"}
Name ________P3: {#N/A,#N/A,FALSE,"배수1"}
Name ________P4: {#N/A,#N/A,FALSE,"혼합골재"}
Name ________P5: {#N/A,#N/A,FALSE,"배수1"}
Name ________P6: {#N/A,#N/A,FALSE,"2~8번"}
Name ________q45: {"'용역비'!$A$4:$C$8"}
Name ________q45: {"'용역비'!$A$4:$C$8"}
Name ________q45: {"'용역비'!$A$4:$C$8"}
Name ________S3: {#N/A,#N/A,FALSE,"포장2"}
Name _______ju8: {"'광피스표'!$A$3:$N$54"}
Name _______q45: {"'용역비'!$A$4:$C$8"}
Name _______q45: {"'용역비'!$A$4:$C$8"}
Name _______q45: {"'용역비'!$A$4:$C$8"}
Name ______ju8: {"'광피스표'!$A$3:$N$54"}
Name ______q45: {"'용역비'!$A$4:$C$8"}
Name ______q45: {"'용역비'!$A$4:$C$8"}
Name ______q45: {"'용역비'!$A$4:$C$8"}
Name ______QQ1: {#N/A,#N/A,FALSE,"단가표지"}
Name ______QW1: {#N/A,#N/A,FALSE,"단가표지"}

Sheet 목차  (2)
A2: 목 차
A4: Ⅰ. 원가계산 결과 ……………………………………………………………………………………………………………………………………………… | I4: 1
A5: Ⅱ. 원가계산의 개요 ………………………………………………………………………………………………………………………………………… | I5: 3
A6: Ⅲ. 원가요소별 계산기준 …………………………………………………………………………………………………………………………………… | I6: 5
A7: Ⅳ. 공사원가계산서 …………………………………………………………………………………………………………………………………………… | I7: 7
A8: Ⅴ. 참고자료 …………………………………………………………………………………………………………………………………………… | I8: 38
A9: 1. 증빙자료 …………………………………………………………………………………………………………………………………………… | I9: 41
A10: 1. 물가지 …………………………………………………………………………………………………………………………………………… | I10: 27
A11: 3. 유사실적 …………………………………………………………………………………………………………………………………………… | I11: 50
A12: 2. 유사실적 …………………………………………………………………………………………………………………………………………… | I12: 33
A13: 1. 증빙자료 …………………………………………………………………………………………………………………………………………… | I13: 47
A14: 1. 물가지 …………………………………………………………………………………………………………………………………………… | I14: 39
A15: 2. 견적서 …………………………………………………………………………………………………………………………………………… | I15: 42
... A22: 3. 원가계산용역기관 등록증 …………………………………………………………………………………………………………………………………………… | I22: 82

Sheet 결과
A1: Ⅰ.원가계산 결과
A3: =결과!Q2&" 귀중" -> 귀중
A5: ="우리 연구원은 귀 "&Q2&"의 위촉에 의하여 제시된 자료를 근거로「"&Q3&"」에 대한 예정가격산정을 위해 관련 법령, 기준 및 예정가격 작성기준과 절차를 준수하였으며, 그 결과는 아래와 같습니다." -> 우리 연구원은 귀 의 위촉에 의하여 제시된 자료를 근거로「」에 대한 예정가격산정을 위해 관련 법령, 기준 및 예정가격 작성기준과 절차를 준수하였으며, 그 결과는 아래와 같습니다.
A7: 아 래
O8: (단위: 원)
A9: 품 명 | I9: 단위 | J9: 금 액 | O9: 비 고
A10: =Q3 -> 0 | I10: 식 | J10: =원가계산서!E34 -> 126576230 | O10: Ⅳ. 공사원가계산서참조 | Q10: 결과 시트의 금액 (J10)= 원가계산식 시트의 총원가 (IE33)
A11: ※ 부가가치세 별도

Sheet 산정기준
A1: Ⅲ. 원가요소별 계산기준
A3: 본 원가계산은 제시된 자료를 참고하여 예정가격작성기준(재정경제부예규 제34호, 2026. 1. 2., 이하 '예정가격작성기준'이라 함.)에 의거하여 작성하였다.
A5: 1. 재료비
C6: 재료비는 제시된 제반자료를 참조하여 재료에 대한 소요량을 산출하였으며, 재료비 단가는 기획재정부에 등록된 전문가격조사기관에서 공표한 거래실례가격 및 조사가격을 적용하였다.
A8: 2. 노무비
C9: 노무비는 직접노무비와 간접노무비로 구분하였으며, 직접노무비는 국토교통부 표준품셈의 소요인원을 산정한 후 대한건설협회가 공표한 공사 노임단가를 곱하여 계산하였고, 간접노무비는 예정가격작성기준과 조달청의 2026년 건축 · 산업환경설비공사 원가계산 제비율 적용기준(이하 '조달청적용기준'이라 함.) 요율을 비교하여 더 낮은 비율을 직접노무비에 곱하여 산출하였다.
A11: 3. 경비
C12: 경비는 조달청적용기준을 참고하여 예정가격작성기준에 의거 비목별 배부율을 발췌한 다음, 비목별로 노무비 또는 재료비와 노무비의 합계액에 각각 곱하여 산출하였다.
A14: 4. 일반관리비
C15: 일반관리비는 기업의 유지를 위한 관리활동부문에서 발생하는 제비용으로서 예정가격작성기준에 따라 재료비, 노무비 및 경비의 합계액에 일반관리비율 8%를 곱하여 산출하였다.
A17: 5. 이윤
C18: 이윤은 영업이익을 말하는 것으로서 예정가격작성기준에 의거 노무비, 경비 및 일반관리비의 합계액에 이윤율 15% 곱하여 산출하였다.
A20: ○ 구 매 부 문
B22: 구매부문의 제품 소요량은 제시된 제반자료를 참조하였으며, 제품 단가는 동일한 기준과 조건의 견적가격 또는 조사가격을 적용하였다.

Sheet 원가계산서
A1: 공사원가계산서
H3: (단위: 원)
E4: 원가계산서의 금액 (E열) = 같은 E열 값 * 비율(J열)
A5: 구 분 비 목 | D5: 구 성 비 | E5: 금 액 | G5: 구 성 비 | H5: 비 고
I6: 항목별코드 | J6: 비율(수기) | K6: K열 = 금액(E열)
A7: 순 공 사 원 가 | B7: 재료비 | C7: 직접재료비 | E7: =집계표!E19 -> 63050076 | H7: 직접재료비 = 집계표 시트의 E19 | I7: A1 | J7: 0 | K7: =E7 -> 63050076
C8: 간접재료비 | E8: =ROUNDDOWN(E7*J8,0) -> 0 | I8: A2 | J8: 0 | K8: =E8 -> 0
C9: 소 계 | E9: =SUM(E7:E8) -> 63050076 | I9: A | J9: 0 | K9: =E9 -> 62250076
B10: 노무비 | C10: 직접노무비 | E10: =집계표!G19 -> 12260728 | H10: 직접노무비 = 집계표의 G19 | I10: B1 | J10: 0 | K10: =E10 -> 11826704
C11: 간접노무비 | D11: ="직.노*"&J11*100&"%" -> 직.노*14% | E11: =ROUNDDOWN(E10*J11,0) -> 1716501 | G11: ="직접노무비*"&J11*100&"%" -> 직접노무비*14% | I11: B2 | J11: 0.14 | K11: =E11 -> 1655738
C12: 소 계 | E12: =SUM(E10:E11) -> 13977229 | I12: B | J12: 0 | K12: =E12 -> 13482442
B13: 경 비 | C13: 기계경비 | E13: =집계표!I19 -> 24600000 | H13: 기계경비 = 집계표의 I19 | I13: C4 | J13: 0 | K13: =E13 -> 23400000
C14: 산재보험료 | D14: ="(노)*"&J14*100&"%" -> (노)*3.56% | E14: =ROUNDDOWN((E12)*J14,0) -> 497589 | G14: ="노무비*"&J14*100&"%" -> 노무비*3.56% | I14: C10 | J14: 0.0356 | K14: =E14 -> 479974
C15: 고용보험료 | D15: ="(노)*"&J15*100&"%" -> (노)*1.01% | E15: =ROUNDDOWN((E12)*J15,0) -> 141170 | G15: ="노무비*"&J15*100&"%" -> 노무비*1.01% | I15: C11 | J15: 0.0101 | K15: =E15 -> 136172
C16: 건강보험료 | E16: =ROUNDDOWN((E10)*J16,0) -> 440773 | G16: ="직접노무비*"&J16*100&"%" -> 직접노무비*3.595% | I16: C12 | J16: 0.03595 | K16: =E16 -> 425170
C17: 연금보험료 | E17: =ROUNDDOWN((E10)*J17,0) -> 582384 | G17: ="직접노무비*"&J17*100&"%" -> 직접노무비*4.75% | I17: C13 | J17: 0.0475 | K17: =E17 -> 561768
C18: 노인장기요양보험료 | E18: =ROUNDDOWN((E16)*J18,0) -> 57917 | G18: ="건강보험료*"&J18*100&"%" -> 건강보험료*13.14% | I18: C14 | J18: 0.1314 | K18: =E18 -> 55867
C19: 석면분담금 | E19: =ROUNDDOWN((E12)*J19,0) -> 838 | G19: ="노무비*"&J19*100&"%" -> 노무비*0.006% | J19: 6e-05
C20: 임금채권부담금 | E20: =ROUNDDOWN((E12)*J20,0) -> 12579 | G20: ="노무비*"&J20*100&"%" -> 노무비*0.09% | J20: 0.0009
C21: 퇴직공제부금비 | E21: =ROUNDDOWN((E10)*J21,0) -> 281996 | G21: ="직접노무비*"&J21*100&"%" -> 직접노무비*2.3% | I21: C15 | J21: 0.023 | K21: =E21 -> 281996
C22: 산업안전보건관리비 | D22: ="(재+직.노+(관급-0)/1.1)*"&J22*100&"%"&" < (재+직.노)*3.11%*1.2" -> (재+직.노+(관급-0)/1.1)*3.11% < (재+직.노)*3.11%*1.2 | E22: =ROUNDDOWN((E9+E10)*J22,0) -> 2342166 | G22: ="(재료비+직접노무비)*"&J22*100&"%" -> (재료비+직접노무비)*3.11% | H22: 654,207 < 785,049 | I22: C16 | J22: 0.0311 | K22: =E22 -> 2303787
C23: 기타경비 | D23: ="(재+노)*"&J23*100&"%" -> (재+노)*4.6% | E23: =ROUNDDOWN((E9+E12)*J23,0) -> 3543256 | G23: ="(재료비+노무비)*"&J23*100&"%" -> (재료비+노무비)*4.6% | I23: C20 | J23: 0.046 | K23: =E23 -> 3483695
C24: 환 경 보 전 비 | D24: ="(재+직.노+기.경)*"&J24*100&"%" -> (재+직.노+기.경)*0.5% | G24: ="(재+직.노+기.경)*"&L24*100&"%" -> (재+직.노+기.경)*0% | I24: C25 | J24: 0.005 | K24: =E24 -> 0
C25: 건설하도급보증수수료 | D25: ="(재+직.노+기.경)*"&J25*100&"%" -> (재+직.노+기.경)*0.081% | G25: ="(재+직.노+기.경)*"&L25*100&"%" -> (재+직.노+기.경)*0% | I25: C30 | J25: 0.00081 | K25: =E25 -> 0
C26: 공사 이행 보증수수료 | D26: ="(재+직.노+기.경)*"&J26*100&"%"&"*(1/12)" -> (재+직.노+기.경)*0.0141%*(1/12) | G26: ="(재+직.노+기.경)*"&L26*100&"%"&"*(1/12)" -> (재+직.노+기.경)*0%*(1/12) | I26: C31 | J26: 0.000141 | K26: =E26 -> 0
C27: 건설기계대여보증수수료 | D27: ="(재+직.노+기.경)*"&J27*100&"%" -> (재+직.노+기.경)*0.07% | G27: ="(재+직.노+기.경)*"&L27*100&"%" -> (재+직.노+기.경)*0% | I27: C32 | J27: 0.0007 | K27: =E27 -> 0
C28: 안 전 관 리 비 | E28: =집계표!AD19 -> 0 | I28: C17 | J28: 0 | K28: =E28 -> #REF!
C29: 품 질 관 리 비 | E29: =집계표!AE19 -> 0 | I29: C18 | J29: 0 | K29: =E29 -> #REF!
C30: 소 계 | E30: =SUM(E13:E23) -> 32500668 | I30: C | J30: 0 | K30: =E30 -> 31131389 | N30: =E9+E12+E30 -> 109527973
B31: 합계 | E31: =E9+E12+E30 -> 109527973 | I31: X | J31: 0 | K31: =E31 -> 106863907 | N31: =N30*8% -> 8762237.8
A32: 일 반 관 리 비 | D32: ="(재+노+경)*"&J32*100&"%" -> (재+노+경)*8% | E32: =ROUNDDOWN((E9+E12+E30)*J32,0) -> 8762237 | G32: ="(재료비+노무비+경비)*"&J32*100&"%" -> (재료비+노무비+경비)*8% | I32: D | J32: 0.08 | K32: =E32 -> 8549112 | N32: =(E12+E30+N31)*15% -> 8286020.2
A33: 이 윤 | D33: ="(노+경+일)*"&J33*100&"%" -> (노+경+일)*15% | E33: =TRUNC((E12+E30+E32)*15%,0) -> 8286020 | G33: ="(노무비+경비+일반관리비)*"&J33*100&"%" -> (노무비+경비+일반관리비)*15% | I33: E | J33: 0.15 | K33: =(K12+K30+K32)*J33+909 -> 7975350.5
A34: 총 원 가 | E34: =E31+E32+E33 -> 126576230 | G34: 순공사원가+일반관리비+이윤 | I34: F | J34: 0 | K34: =SUM(K31:K33) -> 1.2338837e+08
A35: 부 가 가 치 세 | D35: ="(총원가)*"&J35*100&"%" -> (총원가)*10% | E35: =TRUNC(E34*10%,0) -> 12657623 | G35: ="(총원가)*"&J35*100&"%" -> (총원가)*10% | I35: H | J35: 0.1 | K35: =ROUNDDOWN((K34)*J35,0) -> 12338836
A36: 합계 | E36: =TRUNC(E34+E35,-3) -> 139233000 | G36: 총원가+부가가치세 (천원미만 절사) | I36: Y | J36: 0 | K36: =K34+K35 -> 1.3572721e+08
A37: 관 급 자 재 대 | E37: =집계표!AA19 -> 0 | I37: J | J37: 0 | K37: =E37 -> 0
A38: 사 급 자 재 대 | E38: =집계표!Z19 -> 0 | I38: K | J38: 0 | K38: =E38 -> #REF!
A39: 폐 기 물 처 리 비 | E39: =집계표!W19 -> 0 | I39: L | J39: 0 | K39: =E39 -> #REF!
A40: 총 공 사 금 액 | E40: =ROUNDDOWN(E36+E37+E38+E39,0) -> 139233000 | J40: 0 | K40: =K36+K37+K38+K39 -> 135727205.45

Sheet 집계표
A1: <표 1>
A2: 공사집계표
L4: (단위: 원)
A5: 품 명 | B5: 단위 | C5: 수량 | D5: 재 료 비 | F5: 노 무 비 | H5: 경 비 | J5: 합 계 | L5: 비고
D6: 단 가 | E6: 금 액 | F6: 단 가 | G6: 금 액 | H6: 단 가 | I6: 금 액 | J6: 단 가 | K6: 금 액 | M6: 손료요율 | N6: 손료구분 | O6: 적용구분 | P6: 합계구분 | Q6: 기계경비 | R6: 운반비 | S6: 작업부산물 | T6: 관급 | U6: 외주비 | V6: 장비비 | W6: 폐기물처리비 | X6: 가설비 | Y6: 잡비제외분 | Z6: 사급자재대 | AA6: 관급자재대 | AB6: 사용자항목1 | AC6: 사용자항목2 | AD6: 안전관리비 | AE6: 품질관리비 | AF6: 작업부산물(철거해체) | AG6: 사용자항목6 | AH6: 사용자항목7 | AI6: 사용자항목8 | AJ6: 사용자항목9 | AK6: 사용자항목10 | AL6: 사용자항목11 | AM6: 사용자항목12 | AN6: 사용자항목13 | AO6: 사용자항목14 | AP6: 사용자항목15 | AQ6: 사용자항목16 | AR6: 사용자항목17 | AS6: 사용자항목18 | AT6: 사용자항목19 | AU6: 간접재료비 | AV6: 품목구분 | AW6: 조달코드 | AX6: 구분
A7: 탱크 설비 | B7: 식 | C7: 1 | D7: =내역서!F71 -> 63050076 | E7: =C7*D7 -> 63050076 | F7: =내역서!H71 -> 12260728 | G7: =C7*F7 -> 12260728 | H7: =내역서!J71 -> 24600000 | I7: =C7*H7 -> 24600000 | J7: =D7+F7+H7 -> 99910804 | K7: =E7+G7+I7 -> 97476780
D8: 내역서 시트의 재료비 F열의 총합값 (F69) | F8: 내역서 시트의 재료비 F열의 총합값 (H69) | H8: 내역서 시트의 재료비 F열의 총합값 (J69)
A19: 합 계 | E19: =SUM(E7:E18) -> 63050076 | G19: =SUM(G7:G18) -> 12260728 | I19: =SUM(I7:I18) -> 24600000 | K19: =SUM(K7:K18) -> 97476780 | Q19: =SUM(#REF!) -> #REF! | R19: =SUM(#REF!) -> #REF! | S19: =SUM(#REF!) -> #REF! | T19: =SUM(#REF!) -> #REF! | U19: =SUM(#REF!) -> #REF! | V19: =SUM(#REF!) -> #REF! | W19: =SUM(#REF!) -> #REF! | X19: =SUM(#REF!) -> #REF! | ... AX19: =SUM(#REF!) -> #REF!

Sheet 내역서
A1: <표 2>
A2: 공사내역서
L4: (단위: 원)
K5: 내역서의 합계(K)의 각 품명에서 재료비(F) + 노무비(H) + 경비(J) 합산값
A7: 품 명 | B7: 규 격 | C7: 단위 | D7: 수량 | E7: 재 료 비 | G7: 노 무 비 | I7: 경 비 | K7: 합계 | L7: 비고
E8: 단 가 | F8: 금 액 | G8: 단 가 | H8: 금 액 | I8: 단 가 | J8: 금 액 | M8: 손료요율 | N8: 손료구분 | O8: 적용구분 | P8: 합계구분 | Q8: 기계경비 | R8: 운반비 | S8: 작업부산물 | T8: 관급 | U8: 외주비 | V8: 장비비 | W8: 폐기물처리비 | X8: 가설비 | Y8: 잡비제외분 | Z8: 사급자재대 | AA8: 관급자재대 | AB8: 사용자항목1 | AC8: 사용자항목2 | AD8: 안전관리비 | AE8: 품질관리비 | AF8: 작업부산물(철거해체) | AG8: 사용자항목6 | AH8: 사용자항목7 | AI8: 사용자항목8 | AJ8: 사용자항목9 | AK8: 사용자항목10 | AL8: 사용자항목11 | AM8: 사용자항목12 | AN8: 사용자항목13 | AO8: 사용자항목14 | AP8: 사용자항목15 | AQ8: 사용자항목16 | AR8: 사용자항목17 | AS8: 사용자항목18 | AT8: 사용자항목19 | AU8: 간접재료비 | AV8: 품목구분 | AW8: 조달코드 | AX8: 구분
A9: □ 탱크 설비
A10: 1. 자재비
A11: SHELL PLATE-STS304 | B11: t6*5'*9200 | C11: SH | D11: 2 | E11: =단가대비표!M7 -> 3400000 | F11: =D11*E11 -> 6800000 | H11: =ROUNDDOWN(D11*G11,0) -> 0 | J11: =ROUNDDOWN(D11*I11,0) -> 0 | K11: =F11+H11+J11 -> 6800000 | N11: ="01" -> 1 | O11: 기계경비 | P11: 1 | Q11: =IF(O11="기계경비",J11,0) -> 0 | R11: =IF(O11="운반비",K11,0) -> 0 | S11: =IF(O11="작업부산물",F11,0) -> 0 | T11: =IF(O11="관급",F11,0) -> 0 | U11: =IF(O11="외주비",J11,0) -> 0 | V11: =IF(O11="장비비",J11,0) -> 0 | W11: =IF(O11="폐기물처리비",K11,0) -> 0 | X11: =IF(O11="가설비",J11,0) -> 0 | Y11: =IF(O11="잡비제외분",F11,0) -> 0 | Z11: =IF(O11="사급자재대",K11,0) -> 0 | AA11: =IF(O11="관급자재대",K11,0) -> 0 | AB11: =IF(O11="사용자항목1",K11,0) -> 0 | AC11: =IF(O11="사용자항목2",K11,0) -> 0 | AD11: =IF(O11="안전관리비",K11,0) -> 0 | AE11: =IF(O11="품질관리비",K11,0) -> 0 | AF11: =IF(O11="작업부산물(철거해체)",K11,0) -> 0 | AG11: =IF(O11="사용자항목6",K11,0) -> 0 | AH11: =IF(O11="사용자항목7",K11,0) -> 0 | AI11: =IF(O11="사용자항목8",K11,0) -> 0 | AJ11: =IF(O11="사용자항목9",K11,0) -> 0 | AK11: =IF(O11="사용자항목10",K11,0) -> 0 | AL11: =IF(O11="사용자항목11",K11,0) -> 0 | AM11: =IF(O11="사용자항목12",K11,0) -> 0 | AN11: =IF(O11="사용자항목13",K11,0) -> 0 | AO11: =IF(O11="사용자항목14",K11,0) -> 0 | AP11: =IF(O11="사용자항목15",K11,0) -> 0 | AQ11: =IF(O11="사용자항목16",K11,0) -> 0 | AR11: =IF(O11="사용자항목17",K11,0) -> 0 | AS11: =IF(O11="사용자항목18",K11,0) -> 0 | AT11: =IF(O11="사용자항목19",K11,0) -> 0 | AY11: 1800000
A12: SHELL PLATE-STS304 | B12: t5*5'*9200 | C12: SH | D12: 1 | E12: =단가대비표!M8 -> 2877200 | F12: =D12*E12 -> 2877200 | K12: =F12+H12+J12 -> 2877200
A13: BOTTOM CONE PLATE-STS304 | B13: t8*5'*10' | C13: SH | D13: 2 | E13: =단가대비표!M9 -> 1898000 | F13: =D13*E13 -> 3796000 | K13: =F13+H13+J13 -> 3796000
A14: ROOF PLATE-STS304 | B14: t4*5'*10' | C14: SH | D14: 2 | E14: =단가대비표!M10 -> 621600 | F14: =D14*E14 -> 1243200 | K14: =F14+H14+J14 -> 1243200
A15: TOP ANGLE-STS304 | B15: L-65*65*t6 | C15: M | D15: 12 | E15: =단가대비표!M11 -> 75000 | F15: =D15*E15 -> 900000 | K15: =F15+H15+J15 -> 900000
A16: LEG-SS400 | B16: H-150*150 | C16: M | D16: 10 | E16: =단가대비표!M12 -> 65000 | F16: =D16*E16 -> 650000 | K16: =F16+H16+J16 -> 650000
A17: LOADCELL FRAME-SS400 | B17: H-150*150 | C17: M | D17: 10 | E17: =단가대비표!M13 -> 65000 | F17: =D17*E17 -> 650000 | K17: =F17+H17+J17 -> 650000
A18: LOAD CELL | B18: ULKS (ALL SUS) | C18: EA | D18: 4 | E18: =단가대비표!M14 -> 1100000 | F18: =D18*E18 -> 4400000 | K18: =F18+H18+J18 -> 4400000
A19: 인디케이터 | B19: AD510A | C19: EA | D19: 1 | E19: =단가대비표!M15 -> 500000 | F19: =D19*E19 -> 500000 | K19: =F19+H19+J19 -> 500000
A20: 전기판넬 | B20: ADIP-SUS 외함 | C20: EA | D20: 1 | E20: =단가대비표!M16 -> 420000 | F20: =D20*E20 -> 420000 | K20: =F20+H20+J20 -> 420000
A21: Summing Box | B21: AD310(4P) | C21: EA | D21: 1 | E21: =단가대비표!M17 -> 150000 | F21: =D21*E21 -> 150000 | K21: =F21+H21+J21 -> 150000
A22: 외부표시기 | B22: 8915C | C22: EA | D22: 1 | E22: =단가대비표!M18 -> 550000 | F22: =D22*E22 -> 550000 | K22: =F22+H22+J22 -> 550000
A23: MAN HOLE-STS304 | B23: Φ500 | C23: SET | D23: 1 | E23: =단가대비표!M19 -> 1400000 | F23: =D23*E23 -> 1400000 | K23: =F23+H23+J23 -> 1400000
... A35: NOZZLE-STS304 | B35: 50A,80A | C35: LOT | D35: 1 | E35: =단가대비표!M31 -> 500000 | F35: =D35*E35 -> 500000 | K35: =F35+H35+J35 -> 500000
A36: 기타잡자재비 | B36: 자재비의 | C36: % | D36: 2 | E36: =SUM(F11:F35) -> 29237400 | F36: =TRUNC(E36*2%,0) -> 584748 | K36: =F36+H36+J36 -> 584748
A37: 2. 제작비
A38: 가공비 | C38: LOT | D38: 1 | E38: =단가대비표!M32 -> 2500000 | F38: =D38*E38 -> 2500000 | K38: =F38+H38+J38 -> 2500000
A39: 제작비 | C39: LOT | D39: 1 | E39: =단가대비표!M33 -> 15000000 | F39: =D39*E39 -> 15000000 | K39: =F39+H39+J39 -> 15000000
A40: PAINTING비 | C40: LOT | D40: 1 | E40: =단가대비표!M34 -> 1700000 | F40: =D40*E40 -> 1700000 | K40: =F40+H40+J40 -> 1700000
A41: 용접부 비파괴검사 | B41: COLOR CHECK | C41: LOT | D41: 1 | I41: =단가대비표!M32 -> 2500000 | J41: =D41*I41 -> 2500000 | K41: =F41+H41+J41 -> 2500000
A42: 산세척비 | C42: LOT | D42: 1 | I42: =단가대비표!M33 -> 15000000 | J42: =D42*I42 -> 15000000 | K42: =F42+H42+J42 -> 15000000
A43: 충수검사 | B43: FULL WATER | C43: LOT | D43: 1 | I43: =단가대비표!M34 -> 1700000 | J43: =D43*I43 -> 1700000 | K43: =F43+H43+J43 -> 1700000
A44: 3. 배관공사
A45: PIPE-STS304 | B45: 50A*S10 | C45: 본 | D45: 2 | E45: =단가대비표!M38 -> 150000 | F45: =D45*E45 -> 300000 | K45: =F45+H45+J45 -> 300000
A46: BALL VALVE-STS304 | B46: 50A*10K | C46: EA | D46: 4 | E46: =단가대비표!M39 -> 300000 | F46: =D46*E46 -> 1200000 | K46: =F46+H46+J46 -> 1200000
A47: 용접TEE-STS304 | B47: 50A*S10 | C47: EA | D47: 1 | E47: =단가대비표!M40 -> 16000 | F47: =D47*E47 -> 16000 | K47: =F47+H47+J47 -> 16000
A48: 용접ELBOW-STS304 | B48: 50A*S10 | C48: EA | D48: 10 | E48: =단가대비표!M41 -> 15000 | F48: =D48*E48 -> 150000 | K48: =F48+H48+J48 -> 150000
A49: FLANGE-STS304 | B49: 50A*10K | C49: EA | D49: 13 | E49: =단가대비표!M42 -> 24000 | F49: =D49*E49 -> 312000 | K49: =F49+H49+J49 -> 312000
A50: GASKET-EPDM | B50: 50A | C50: EA | D50: 12 | E50: =단가대비표!M43 -> 2000 | F50: =D50*E50 -> 24000 | K50: =F50+H50+J50 -> 24000
A51: FLEXIBLE-STS304 | B51: 50A*L300 | C51: EA | D51: 2 | E51: =단가대비표!M44 -> 90000 | F51: =D51*E51 -> 180000 | K51: =F51+H51+J51 -> 180000
A52: HEX.B/N-STS304 | B52: M16 | C52: LOT | D52: 1 | E52: =단가대비표!M45 -> 80000 | F52: =D52*E52 -> 80000 | K52: =F52+H52+J52 -> 80000
A53: Q-COUPLING-STS304 | B53: 2" | C53: SET | D53: 2 | E53: =단가대비표!M46 -> 80000 | F53: =D53*E53 -> 160000 | K53: =F53+H53+J53 -> 160000
...

Sheet 일위대가목록
A1: <표 3>
A2: 일위대가목록
H4: (단위: 원)
A5: 호 표 | B5: 품 명 | C5: 규 격 | D5: 단위 | E5: 재료비 | F5: 노무비 | G5: 경비 | H5: 합계 | I5: 비 고
J6: 구분
A7: 일위 1호 | B7: 강관 용접 배관 | C7: D50 | D7: M | E7: =일위대가표!F21 -> 494 | F7: =일위대가표!H21 -> 24724 | G7: =일위대가표!J21 -> 0 | H7: =E7+F7+G7 -> 25218 | J7: MCA10010100S
A8: 일위 2호 | B8: 발열선 설치 | D8: M | E8: =일위대가표!F36 -> 0 | F8: =일위대가표!H36 -> 5140 | G8: =일위대가표!J36 -> 0 | H8: =E8+F8+G8 -> 5140 | J8: MCA10010090S
A9: 일위 3호 | B9: 탱크설치 | D9: 대 | E9: =일위대가표!F52 -> 0 | F9: =일위대가표!H52 -> 3053237 | G9: =일위대가표!J52 -> 0 | H9: =E9+F9+G9 -> 3053237 | J9: MCA10010100S
A10: 일위 4호 | B10: 탱크철거 | D10: 대 | E10: =일위대가표!F69 -> 0 | F10: =일위대가표!H69 -> 1526617 | G10: =일위대가표!J69 -> 0 | H10: =E10+F10+G10 -> 1526617 | J10: MCA10010090S

Sheet 일위대가표
A1: <표 4>
A2: 일위대가표
M4: (단위: 원)
A5: 품 명 | B5: 규 격 | C5: 단위 | D5: 수 량 | E5: 재 료 비 | G5: 노 무 비 | I5: 경 비 | K5: 합 계 | M5: 비 고
E6: 단 가 | F6: 금 액 | G6: 단 가 | H6: 금 액 | I6: 단 가 | J6: 금 액 | K6: 단 가 | L6: 금 액 | N6: 손료요율 | O6: 손료구분 | P6: 적용구분 | Q6: 합계구분 | R6: 품목구분 | S6: 조달코드 | T6: 구분
A7: [일위 1호] - [강관 용접 배관 M]
A8: 배관공 | C8: 인 | D8: 0.081 | E8: 0 | F8: =ROUNDDOWN(D8*E8,1) -> 0 | G8: =단가대비표!M55 -> 247897 | H8: =TRUNC(D8*G8,0) -> 20079 | I8: 0 | J8: =ROUNDDOWN(D8*I8,1) -> 0 | K8: =E8+G8+I8 -> 247897 | L8: =F8+H8+J8 -> 20079 | O8: 01 | P8: 기계경비 | Q8: 1
A9: 보통인부 | C9: 인 | D9: 0.027 | G9: =단가대비표!M56 -> 172068 | H9: =TRUNC(D9*G9,0) -> 4645 | I9: 0 | J9: =ROUNDDOWN(D9*I9,1) -> 0 | K9: =E9+G9+I9 -> 172068 | L9: =F9+H9+J9 -> 4645 | O9: 01 | P9: 기계경비 | Q9: 1
A10: 공구손료 및 경장비의 기계경비 | B10: 인력품의 2% | C10: 식 | D10: 1 | E10: =TRUNC(SUM(H8:H9)*2%,0) -> 494 | F10: =D10*E10 -> 494
A18: ※ 표준품셈 : 설비1-1-2 참조
A21: 합 계 | F21: =SUM(F8:F14) -> 494 | H21: =SUM(H8:H14) -> 24724 | J21: =SUM(J8:J14) -> 0 | L21: =SUM(L8:L14) -> 24724
A22: [일위 2호] - [발열선 설치 M]
A23: 기계설비공 | C23: 인 | D23: 0.017 | E23: 0 | F23: =ROUNDDOWN(D23*E23,1) -> 0 | G23: =단가대비표!M57 -> 241698 | H23: =TRUNC(D23*G23,0) -> 4108 | I23: 0 | J23: =ROUNDDOWN(D23*I23,1) -> 0 | K23: =E23+G23+I23 -> 241698 | L23: =F23+H23+J23 -> 4108 | O23: 01 | P23: 기계경비 | Q23: 1
A24: 보통인부 | C24: 인 | D24: 0.006 | G24: =단가대비표!M56 -> 172068 | H24: =TRUNC(D24*G24,0) -> 1032 | I24: 0 | J24: =ROUNDDOWN(D24*I24,1) -> 0 | K24: =E24+G24+I24 -> 172068 | L24: =F24+H24+J24 -> 1032 | O24: 01 | P24: 기계경비 | Q24: 1
A33: ※ 표준품셈 : 설비3-4-1 참조
A36: 합 계 | F36: =ROUNDDOWN(SUMIF(Q23:Q35,"1",F23:F35),0) -> 0 | H36: =ROUNDDOWN(SUMIF(Q23:Q35,"1",H23:H35),0) -> 5140 | J36: =SUM(J23:J35) -> 0 | L36: =SUM(L23:L35) -> 5140
A38: [일위 3호] - [탱크설치 대]
A39: 형틀목공 | C39: 인 | D39: 0.13 | E39: 0 | F39: =ROUNDDOWN(D39*E39,1) -> 0 | G39: =단가대비표!M58 -> 275790 | H39: =TRUNC(D39*G39,0) -> 35852 | I39: 0 | J39: =ROUNDDOWN(D39*I39,1) -> 0 | K39: =E39+G39+I39 -> 275790 | L39: =F39+H39+J39 -> 35852 | O39: 01 | P39: 기계경비 | Q39: 1
A40: 플랜트기계설치공 | C40: 인 | D40: 2.13 | G40: =단가대비표!M59 -> 230376 | H40: =TRUNC(D40*G40,0) -> 490700 | I40: 0 | J40: =ROUNDDOWN(D40*I40,1) -> 0 | K40: =E40+G40+I40 -> 230376 | L40: =F40+H40+J40 -> 490700 | O40: 01 | P40: 기계경비 | Q40: 1
A41: 비계공 | C41: 인 | D41: 0.23 | G41: =단가대비표!M60 -> 281939 | H41: =TRUNC(D41*G41,0) -> 64845 | I41: 0 | J41: =ROUNDDOWN(D41*I41,1) -> 0 | K41: =E41+G41+I41 -> 281939 | L41: =F41+H41+J41 -> 64845 | O41: 01 | P41: 기계경비 | Q41: 1
A42: 건설기계운전사 | C42: 인 | D42: 0.78 | G42: =단가대비표!M61 -> 283297 | H42: =TRUNC(D42*G42,0) -> 220971 | I42: 0 | J42: =ROUNDDOWN(D42*I42,1) -> 0 | K42: =E42+G42+I42 -> 283297 | L42: =F42+H42+J42 -> 220971 | O42: 01 | P42: 기계경비 | Q42: 1
A43: 특별인부 | C43: 인 | D43: 9.91 | G43: =단가대비표!M62 -> 226122 | H43: =TRUNC(D43*G43,0) -> 2240869 | I43: 0 | J43: =ROUNDDOWN(D43*I43,1) -> 0 | K43: =E43+G43+I43 -> 226122 | L43: =F43+H43+J43 -> 2240869 | O43: 01 | P43: 기계경비 | Q43: 1
A49: ※ 표준품셈 : 설비13-5-14,1 참조
A52: 합 계 | F52: =ROUNDDOWN(SUMIF(Q39:Q51,"1",F39:F51),0) -> 0 | H52: =ROUNDDOWN(SUMIF(Q39:Q51,"1",H39:H51),0) -> 3053237 | J52: =SUM(J39:J51) -> 0 | L52: =SUM(L39:L51) -> 3053237
A54: [일위 4호] - [탱크철거 대]
A55: 형틀목공 | C55: 인 | D55: =0.13*50% -> 0.065 | E55: 0 | F55: =ROUNDDOWN(D55*E55,1) -> 0 | G55: =단가대비표!M58 -> 275790 | H55: =TRUNC(D55*G55,0) -> 17926 | I55: 0 | J55: =ROUNDDOWN(D55*I55,1) -> 0 | K55: =E55+G55+I55 -> 275790 | L55: =F55+H55+J55 -> 17926 | O55: 01 | P55: 기계경비 | Q55: 1
A56: 플랜트기계설치공 | C56: 인 | D56: =2.13*50% -> 1.065 | G56: =단가대비표!M59 -> 230376 | H56: =TRUNC(D56*G56,0) -> 245350 | I56: 0 | J56: =ROUNDDOWN(D56*I56,1) -> 0 | K56: =E56+G56+I56 -> 230376 | L56: =F56+H56+J56 -> 245350 | O56: 01 | P56: 기계경비 | Q56: 1
A57: 비계공 | C57: 인 | D57: =0.23*50% -> 0.115 | G57: =단가대비표!M60 -> 281939 | H57: =TRUNC(D57*G57,0) -> 32422 | I57: 0 | J57: =ROUNDDOWN(D57*I57,1) -> 0 | K57: =E57+G57+I57 -> 281939 | L57: =F57+H57+J57 -> 32422 | O57: 01 | P57: 기계경비 | Q57: 1
A58: 건설기계운전사 | C58: 인 | D58: =0.78*50% -> 0.39 | G58: =단가대비표!M61 -> 283297 | H58: =TRUNC(D58*G58,0) -> 110485 | I58: 0 | J58: =ROUNDDOWN(D58*I58,1) -> 0 | K58: =E58+G58+I58 -> 283297 | L58: =F58+H58+J58 -> 110485 | O58: 01 | P58: 기계경비 | Q58: 1
A59: 특별인부 | C59: 인 | D59: =9.91*50% -> 4.955 | G59: =단가대비표!M62 -> 226122 | H59: =TRUNC(D59*G59,0) -> 1120434 | I59: 0 | J59: =ROUNDDOWN(D59*I59,1) -> 0 | K59: =E59+G59+I59 -> 226122 | L59: =F59+H59+J59 -> 1120434 | O59: 01 | P59: 기계경비 | Q59: 1
A66: ※ 표준품셈 : 설비13-5-14,1 50% 적용
A69: 합 계 | F69: =ROUNDDOWN(SUMIF(Q55:Q68,"1",F55:F68),0) -> 0 | H69: =ROUNDDOWN(SUMIF(Q55:Q68,"1",H55:H68),0) -> 1526617 | J69: =SUM(J55:J68) -> 0 | L69: =SUM(L55:L68) -> 1526617

Sheet 단가대비표
A1: <표 5>
A2: 단 가 대 비 표
J4: 단가대비표의 조사단가는 수기입력 | N4: 조사기준 : 2026년 6월
A5: 품 명 | B5: 규 격 | C5: 단위 | D5: 거래가격 | F5: 물가정보 | H5: 물가정보 | J5: 조사단가 | M5: 적용단가 | N5: 비 고
D6: 단가 | E6: Page | F6: 단가 | G6: Page | H6: 단가 | I6: Page | J6: A업체 | K6: B업체 | L6: C업체 | O6: 구분
A7: SHELL PLATE-STS304 | B7: t6*5'*9200 | C7: SH | J7: 3400000 | K7: 14700000 | L7: 9660000 | M7: =MIN(D7,H7,J7) -> 3400000
A8: " | B8: t5*5'*9200 | C8: SH | J8: 2877200 | M8: =MIN(D8,H8,J8) -> 2877200
A9: BOTTOM CONE PLATE-STS304 | B9: t8*5'*10' | C9: SH | J9: 1898000 | L9: 2580000 | M9: =MIN(D9,H9,J9) -> 1898000
A10: ROOF PLATE-STS304 | B10: t4*5'*10' | C10: SH | J10: 621600 | L10: 1260000 | M10: =MIN(D10,H10,J10) -> 621600
A11: TOP ANGLE-STS304 | B11: L-65*65*t6 | C11: M | J11: 75000 | M11: =MIN(D11,H11,J11) -> 75000
A12: LEG-SS400 | B12: H-150*150 | C12: M | J12: 65000 | M12: =MIN(D12,H12,J12) -> 65000
A13: LOADCELL FRAME-SS400 | B13: H-150*150 | C13: M | J13: 65000 | M13: =MIN(D13,H13,J13) -> 65000
A14: LOAD CELL | B14: ULKS (ALL SUS) | C14: EA | J14: 1100000 | M14: =MIN(D14,H14,J14) -> 1100000
A15: 인디케이터 | B15: AD510A | C15: EA | J15: 500000 | M15: =MIN(D15,H15,J15) -> 500000
A16: 전기판넬 | B16: ADIP-SUS 외함 | C16: EA | J16: 420000 | M16: =MIN(D16,H16,J16) -> 420000
A17: Summing Box | B17: AD310(4P) | C17: EA | J17: 150000 | M17: =MIN(D17,H17,J17) -> 150000
A18: 외부표시기 | B18: 8915C | C18: EA | J18: 550000 | M18: =MIN(D18,H18,J18) -> 550000
A19: MAN HOLE-STS304 | B19: Φ500 | C19: SET | J19: 1400000 | K19: 1000000 | M19: =MIN(D19,H19,J19) -> 1400000
A20: BREATH VALVE-STS304 | B20: 80A*10K | C20: EA | J20: 1450000 | K20: 1500000 | L20: 2500000 | M20: =MIN(D20,H20,J20) -> 1450000
A21: INSULATIN ANGLE-SS400 | B21: L-50*50*t6 | C21: 본 | J21: 135000 | M21: =MIN(D21,H21,J21) -> 135000
A22: HAND RAIL-SGP | B22: 32A | C22: 본 | J22: 30000 | K22: 3000000 | M22: =MIN(D22,H22,J22) -> 30000
A23: " | B23: 25A | C23: 본 | J23: 25000 | M23: =MIN(D23,H23,J23) -> 25000
A24: LADDER-SS400 | B24: FB-50*t9 | C24: 본 | J24: 30000 | K24: 3000000 | M24: =MIN(D24,H24,J24) -> 30000
A25: " | B25: FB-50*t6 | C25: 본 | J25: 20000 | M25: =MIN(D25,H25,J25) -> 20000
A26: " | B26: FB-38*t6 | C26: 본 | J26: 15000 | M26: =MIN(D26,H26,J26) -> 15000
A27: ROUND BAR-SS400 | B27: Φ19 | C27: 본 | J27: 28000 | M27: =MIN(D27,H27,J27) -> 28000
A28: INTERNAL LADDER-STS304 | B28: Φ18 | C28: 본 | J28: 83000 | M28: =MIN(D28,H28,J28) -> 83000
A29: LEVEL GAUGE-STS304 | B29: FLOT TYPE | C29: SET | J29: 700000 | K29: 3000000 | M29: =MIN(D29,H29,J29) -> 700000
A30: LIFT LUG-STS304 | B30: t20 | C30: EA | J30: 50000 | K30: 1500000 | L30: 200000 | M30: =MIN(D30,H30,J30) -> 50000
A31: NOZZLE-STS304 | B31: 50A,80A | C31: LOT | J31: 500000 | L31: 1000000 | M31: =MIN(D31,H31,J31) -> 500000
A32: 가공비 | C32: LOT | J32: 2500000 | K32: 2500000 | L32: 3500000 | M32: =MIN(D32,H32,J32) -> 2500000
A33: 제작비 | C33: LOT | J33: 15000000 | K33: 20000000 | L33: 22000000 | M33: =MIN(D33,H33,J33) -> 15000000
A34: PAINTING비 | C34: LOT | J34: 1700000 | M34: =MIN(D34,H34,J34) -> 1700000
A35: 용접부 비파괴검사 | B35: COLOR CHECK | C35: LOT | J35: 2700000 | L35: 4000000 | M35: =MIN(D35,H35,J35) -> 2700000
A36: 산세척비 | C36: LOT | J36: 3500000 | L36: 4000000 | M36: =MIN(D36,H36,J36) -> 3500000
A37: 충수검사 | B37: FULL WATER | C37: LOT | J37: 1500000 | L37: 3000000 | M37: =MIN(D37,H37,J37) -> 1500000
A38: PIPE-STS304 | B38: 50A*S10 | C38: 본 | J38: 150000 | K38: 10100000 | M38: =MIN(D38,H38,J38) -> 150000
A39: BALL VALVE-STS304 | B39: 50A*10K | C39: EA | J39: 300000 | M39: =MIN(D39,H39,J39) -> 300000
A40: 용접TEE-STS304 | B40: 50A*S10 | C40: EA | J40: 16000 | M40: =MIN(D40,H40,J40) -> 16000
A41: 용접ELBOW-STS304 | B41: 50A*S10 | C41: EA | J41: 15000 | M41: =MIN(D41,H41,J41) -> 15000
...

Sheet 간노비
A1: <표 6>
A2: 간접노무비율 산출표
G4: 간접노무비율의 비율(G)는 수기 | J4: (단위: %)
A5: 구 분 | G5: 비율 (주1) | I5: 적용율 | J5: 비 고
E7: 건 축 공 사 | G7: 14.5
B8: 공 사 종 류 별 | E8: 토 목 공 사 | G8: 15
E9: 특수공사(포장,준설등) | G9: 15.5
E10: 기타(전문,전기,통신등) | G10: 15 | I10: =G10 -> 15
E11: 50억 미만 | G11: 14 | I11: 14
B12: 공 사 규 모 별 | E12: 50억 ~ 300억 미만 | G12: 15
E13: 300억 이상 | G13: 16
E14: 6개월 미만 | G14: 13 | I14: 13
B15: 공 사 기 간 별 | E15: 6 ~ 12개월 미만 | G15: 15
E16: 12개월 이상 | G16: 17
A17: 조 사 적 용 비 율 (주2) | I17: =TRUNC(SUM(I7:I16)/3,1) -> 14 | J17: 간접노무비율의 조사적용비율 = ( 공사종류별 + 공사규모별 + 공사기간별 적용율 합산값 ) / 3 , 소수점 1자리
B18: 조달청기준비율 | I18: 15 | J18: 수기
B19: 본조사적용비율 | I19: =MIN(I17:I18) -> 14 | J19: 간접노무비율의 조사 적용비율과 조달청 기준 비율 중 작은 값
A20: (주1) 예정가격작성기준 내 공사원가계산시 간접노무비 계산방법 참조
A21: (주2) (공사종류별 + 공사규모별 + 공사기간별) ÷ 3

Sheet 경비
A1: <표 7>
A2: 경비 산출표
G4: (단위: 원)
B5: 비 목 | D5: 배부율(%) (주1) | E5: 배부대상액 (주2) | F5: 금 액 | G5: 비 고
B7: 기계경비 | F7: =집계표!I19 -> 23400000 | G7: =집계표!A1 -> <표 1>
B8: 산재보험료 | F8: =산재!G8 -> 479974 | G8: =산재!A1 -> <표 8>
B9: 고용보험료 | F9: =고용!G8 -> 136172 | G9: =고용!A1 -> <표 9>
B10: 건강보험료 | F10: =건강!G8 -> 425170 | G10: =건강!A1 -> <표 10>
B11: 연금보험료 | F11: =연금!G8 -> 561768 | G11: =연금!A1 -> <표 11>
B12: 노인장기요양보험료 | F12: =장기!G8 -> 55867 | G12: =장기!A1 -> <표 12>
B13: 석면분담금 | F13: =석면!G8 -> 808 | G13: =석면!A1 -> <표 13>
B14: 임금채권부담금 | F14: =임금!G8 -> 12134 | G14: =임금!A1 -> <표 14>
B15: 퇴직공제부금비 | F15: =퇴공!G8 -> 272014 | G15: =퇴공!A1 -> <표 15>
B16: 산업안전보건관리비 | F16: =안전!F8 -> 2303787 | G16: =안전!A1 -> <표 16>
B17: 기타경비 | D17: 4.6 | E17: =원가계산서!E9+원가계산서!E12 -> 75732518 | F17: =TRUNC($D17*E$17%,0) -> 3483695 | G17: 재료비+노무비
B19: 계 | F19: =SUM(F7:$F$18) -> 31131389
A20: (주1) 조달청적용기준 비율
A21: (주2) 공사원가계산서 참조

Sheet 산재
A1: <표 8>
A2: 산재보험료 산출표
I4: (단위: 원)
B5: 비 목 | D5: 적용대상액 (노무비) (주1) | F5: 비율(%) (주2) | G5: 금액 | I5: 비 고
B8: 산재보험료 | D8: =원가계산서!E12 -> 13482442 | F8: 3.56 | G8: =TRUNC(D8*F8%,0) -> 479974 | I8: 산재보험료 금액 = 원가 계산서 노무비 (D8) * 비율 (F8)
A10: (주1) 공사원가계산서 참조
A11: (주2) 조달청적용기준 비율
A12: ="(주2) < 표 "&'[Y:/02. 원가분석본부/2025년 원가계산/부평상권르네상스센터/1. 부평 상권르네상스 스마트 라이트폴 디지털 상권 조성 용역 원가계산 (25.03.14 발행)/보고서/부평 상권르네상스사업 스마트 라이트 폴 디지털 상권 조성 용역 원가계산보고서ver2.xlsx]산재비율'!A1&" > "&'[Y:/02. 원가분석본부/2025년 원가계산/부평상권르네상스센터/1. 부평 상권르네상스 스마트 라이트폴 디지털 상권 조성 용역 원가계산 (25.03.14 발행)/보고서/부평 상권르네상스사업 스마트 라이트 폴 디지털 상권 조성 용역 원가계산보고서ver2.xlsx]산재비율'!A2&" 참조" -> (주2) < 표 (주2) < 표 #ERROR! > #ERROR! 참조 > (주2) < 표 #ERROR! > #ERROR! 참조 참조

Sheet 고용
A1: <표 9>
A2: 고용보험료 산출표
I4: (단위: 원)
B5: 비 목 | D5: 적용대상액 (노무비) (주1) | F5: 비율(%) (주2) | G5: 금 액 | I5: 비 고
B8: 고용보험료 | D8: =원가계산서!E12 -> 13482442 | F8: 1.01 | G8: =TRUNC(D8*F8%,0) -> 136172 | I8: 고용보험료 금액 = 원가 계산서 노무비 (D8) * 비율 (F8)
A10: (주1) 공사원가계산서 참조
A11: (주2) 조달청적용기준 비율

Sheet 건강
A1: <표 10>
A2: 건강보험료 산출표
I4: (단위: 원)
B5: 비 목 | D5: 적용대상액 (직접노무비) (주1) | F5: 비율(%) (주2) | G5: 금액 | I5: 비 고
B8: 건강보험료 | D8: =원가계산서!E10 -> 11826704 | F8: 3.595 | G8: =TRUNC(D8*F8%,0) -> 425170 | I8: 건강보험료 금액 = 원가 계산서 직접 노무비 (D8) * 비율 (F8)
A10: (주1) 공사원가계산서 참조
A11: (주2) 2026년 건축∙산업환경설비공사 원가계산 제비율 적용기준(조달청 2026.04.13.) 참조
A12: ="(주2) < 표 "&'[Y:/02. 원가분석본부/2025년 원가계산/부평상권르네상스센터/1. 부평 상권르네상스 스마트 라이트폴 디지털 상권 조성 용역 원가계산 (25.03.14 발행)/보고서/부평 상권르네상스사업 스마트 라이트 폴 디지털 상권 조성 용역 원가계산보고서ver2.xlsx]산재비율'!A1&" > "&'[Y:/02. 원가분석본부/2025년 원가계산/부평상권르네상스센터/1. 부평 상권르네상스 스마트 라이트폴 디지털 상권 조성 용역 원가계산 (25.03.14 발행)/보고서/부평 상권르네상스사업 스마트 라이트 폴 디지털 상권 조성 용역 원가계산보고서ver2.xlsx]산재비율'!A2&" 참조" -> (주2) < 표 (주2) < 표 #ERROR! > #ERROR! 참조 > (주2) < 표 #ERROR! > #ERROR! 참조 참조

Sheet 연금
A1: <표 11>
A2: 연금보험료 산출표
I4: (단위: 원)
B5: 비 목 | D5: 적용대상액 (직접노무비) (주1) | F5: 비율(%) (주2) | G5: 금액 | I5: 비 고
B8: 연금보험료 | D8: =원가계산서!E10 -> 11826704 | F8: 4.75 | G8: =TRUNC(D8*F8%,0) -> 561768 | I8: 연금보험료 금액 = 원가 계산서 직접 노무비 (D8) * 비율 (F8)
A10: (주1) 공사원가계산서 참조
A11: (주2) 2026년 건축∙산업환경설비공사 원가계산 제비율 적용기준(조달청 2026.04.13.) 참조
A12: ="(주2) < 표 "&'[Y:/02. 원가분석본부/2025년 원가계산/부평상권르네상스센터/1. 부평 상권르네상스 스마트 라이트폴 디지털 상권 조성 용역 원가계산 (25.03.14 발행)/보고서/부평 상권르네상스사업 스마트 라이트 폴 디지털 상권 조성 용역 원가계산보고서ver2.xlsx]산재비율'!A1&" > "&'[Y:/02. 원가분석본부/2025년 원가계산/부평상권르네상스센터/1. 부평 상권르네상스 스마트 라이트폴 디지털 상권 조성 용역 원가계산 (25.03.14 발행)/보고서/부평 상권르네상스사업 스마트 라이트 폴 디지털 상권 조성 용역 원가계산보고서ver2.xlsx]산재비율'!A2&" 참조" -> (주2) < 표 (주2) < 표 #ERROR! > #ERROR! 참조 > (주2) < 표 #ERROR! > #ERROR! 참조 참조

Sheet 장기
A1: <표 12>
A2: 노인장기요양보험료 산출표
I4: (단위: 원)
B5: 비 목 | D5: 적용대상액 (건강보험료) (주1) | F5: 비율(%) (주2) | G5: 금액 | I5: 비 고
B8: 노인장기요양보험료 | D8: =건강!G8 -> 425170 | F8: 13.14 | G8: =TRUNC(D8*F8%,0) -> 55867 | I8: 노인장기요양보험료 = 건강보험료의 금액(G8) * 비율
A10: (주1) 공사원가계산서 참조
A11: (주2) 2026년 건축∙산업환경설비공사 원가계산 제비율 적용기준(조달청 2026.04.13.) 참조
A12: ="(주2) < 표 "&'[Y:/02. 원가분석본부/2025년 원가계산/부평상권르네상스센터/1. 부평 상권르네상스 스마트 라이트폴 디지털 상권 조성 용역 원가계산 (25.03.14 발행)/보고서/부평 상권르네상스사업 스마트 라이트 폴 디지털 상권 조성 용역 원가계산보고서ver2.xlsx]산재비율'!A1&" > "&'[Y:/02. 원가분석본부/2025년 원가계산/부평상권르네상스센터/1. 부평 상권르네상스 스마트 라이트폴 디지털 상권 조성 용역 원가계산 (25.03.14 발행)/보고서/부평 상권르네상스사업 스마트 라이트 폴 디지털 상권 조성 용역 원가계산보고서ver2.xlsx]산재비율'!A2&" 참조" -> (주2) < 표 (주2) < 표 #ERROR! > #ERROR! 참조 > (주2) < 표 #ERROR! > #ERROR! 참조 참조

Sheet 석면
A1: <표 13>
A2: 석면분담금 산출표
I4: (단위: 원)
B5: 비 목 | D5: 적용대상액 (노무비) (주1) | F5: 비율(%) (주2) | G5: 금액 | I5: 비 고
B8: 석면분담금 | D8: =원가계산서!E12 -> 13482442 | F8: 0.006 | G8: =TRUNC(D8*F8%,0) -> 808 | I8: 석면분담금 = 원가계산서의 노무비(간접+직접)(E11) * 비율(0.006)
A10: (주1) 공사원가계산서 참조
A11: (주2) 2026년 건축∙산업환경설비공사 원가계산 제비율 적용기준(조달청 2026.04.13.) 참조
A12: ="(주2) < 표 "&'[Y:/02. 원가분석본부/2025년 원가계산/부평상권르네상스센터/1. 부평 상권르네상스 스마트 라이트폴 디지털 상권 조성 용역 원가계산 (25.03.14 발행)/보고서/부평 상권르네상스사업 스마트 라이트 폴 디지털 상권 조성 용역 원가계산보고서ver2.xlsx]산재비율'!A1&" > "&'[Y:/02. 원가분석본부/2025년 원가계산/부평상권르네상스센터/1. 부평 상권르네상스 스마트 라이트폴 디지털 상권 조성 용역 원가계산 (25.03.14 발행)/보고서/부평 상권르네상스사업 스마트 라이트 폴 디지털 상권 조성 용역 원가계산보고서ver2.xlsx]산재비율'!A2&" 참조" -> (주2) < 표 (주2) < 표 #ERROR! > #ERROR! 참조 > (주2) < 표 #ERROR! > #ERROR! 참조 참조

Sheet 임금
A1: <표 14>
A2: 임금채권부담금 산출표
I4: (단위: 원)
B5: 비 목 | D5: 적용대상액 (노무비) (주1) | F5: 비율(%) (주2) | G5: 금액 | I5: 비 고
B8: 임금채권부담금 | D8: =원가계산서!E12 -> 13482442 | F8: 0.09 | G8: =TRUNC(D8*F8%,0) -> 12134 | I8: 임금채권부담금 = 원가계산서의 노무비(간접+직접)(E11) * 비율(0.09)
A10: (주1) 공사원가계산서 참조
A11: (주2) 2026년 건축∙산업환경설비공사 원가계산 제비율 적용기준(조달청 2026.04.13.) 참조
A12: ="(주2) < 표 "&'[Y:/02. 원가분석본부/2025년 원가계산/부평상권르네상스센터/1. 부평 상권르네상스 스마트 라이트폴 디지털 상권 조성 용역 원가계산 (25.03.14 발행)/보고서/부평 상권르네상스사업 스마트 라이트 폴 디지털 상권 조성 용역 원가계산보고서ver2.xlsx]산재비율'!A1&" > "&'[Y:/02. 원가분석본부/2025년 원가계산/부평상권르네상스센터/1. 부평 상권르네상스 스마트 라이트폴 디지털 상권 조성 용역 원가계산 (25.03.14 발행)/보고서/부평 상권르네상스사업 스마트 라이트 폴 디지털 상권 조성 용역 원가계산보고서ver2.xlsx]산재비율'!A2&" 참조" -> (주2) < 표 (주2) < 표 #ERROR! > #ERROR! 참조 > (주2) < 표 #ERROR! > #ERROR! 참조 참조

Sheet 퇴공
A1: <표 15>
A2: 퇴직공제부금비 산출표
I4: (단위: 원)
B5: 비 목 | D5: 적용대상액 (직접노무비) (주1) | F5: 비율(%) (주2) | G5: 금액 | I5: 비 고
B8: 퇴직공제부금비 | D8: =원가계산서!E10 -> 11826704 | F8: 2.3 | G8: =TRUNC(D8*F8%,0) -> 272014 | I8: 퇴직공제부금비 = 원가계산서의 직접노무비만(E9) * 비율 (2.3)
A10: (주1) 공사원가계산서 참조
A11: (주2) 2026년 건축∙산업환경설비공사 원가계산 제비율 적용기준(조달청 2026.04.13.) 참조
A12: ="(주2) < 표 "&'[Y:/02. 원가분석본부/2025년 원가계산/부평상권르네상스센터/1. 부평 상권르네상스 스마트 라이트폴 디지털 상권 조성 용역 원가계산 (25.03.14 발행)/보고서/부평 상권르네상스사업 스마트 라이트 폴 디지털 상권 조성 용역 원가계산보고서ver2.xlsx]산재비율'!A1&" > "&'[Y:/02. 원가분석본부/2025년 원가계산/부평상권르네상스센터/1. 부평 상권르네상스 스마트 라이트폴 디지털 상권 조성 용역 원가계산 (25.03.14 발행)/보고서/부평 상권르네상스사업 스마트 라이트 폴 디지털 상권 조성 용역 원가계산보고서ver2.xlsx]산재비율'!A2&" 참조" -> (주2) < 표 (주2) < 표 #ERROR! > #ERROR! 참조 > (주2) < 표 #ERROR! > #ERROR! 참조 참조

Sheet 안전
A1: <표 16>
A2: 산업안전보건관리비 산출표
F4: (단위: 원) | I4: 지우지마세요
A5: 비 목 | B5: 적 용 대 상 액 | E5: 비율(%) (주3) | F5: 금 액 | I5: 재료비 | J5: ='[Y:/02. 원가분석본부/2025년 원가계산/부평상권르네상스센터/1. 부평 상권르네상스 스마트 라이트폴 디지털 상권 조성 용역 원가계산 (25.03.14 발행)/보고서/부평 상권르네상스사업 스마트 라이트 폴 디지털 상권 조성 용역 원가계산보고서ver2.xlsx]원가 (2)'!E10 -> #REF!
B6: 재료비 (주1) | C6: 직접노무비 (주2) | D6: 계 | I6: 노무비 | J6: ='[Y:/02. 원가분석본부/2025년 원가계산/부평상권르네상스센터/1. 부평 상권르네상스 스마트 라이트폴 디지털 상권 조성 용역 원가계산 (25.03.14 발행)/보고서/부평 상권르네상스사업 스마트 라이트 폴 디지털 상권 조성 용역 원가계산보고서ver2.xlsx]원가 (2)'!E13 -> #REF!
I7: 경비 | J7: ='[Y:/02. 원가분석본부/2025년 원가계산/부평상권르네상스센터/1. 부평 상권르네상스 스마트 라이트폴 디지털 상권 조성 용역 원가계산 (25.03.14 발행)/보고서/부평 상권르네상스사업 스마트 라이트 폴 디지털 상권 조성 용역 원가계산보고서ver2.xlsx]원가 (2)'!E14+'[Y:/02. 원가분석본부/2025년 원가계산/부평상권르네상스센터/1. 부평 상권르네상스 스마트 라이트폴 디지털 상권 조성 용역 원가계산 (25.03.14 발행)/보고서/부평 상권르네상스사업 스마트 라이트 폴 디지털 상권 조성 용역 원가계산보고서ver2.xlsx]원가 (2)'!E15+'[Y:/02. 원가분석본부/2025년 원가계산/부평상권르네상스센터/1. 부평 상권르네상스 스마트 라이트폴 디지털 상권 조성 용역 원가계산 (25.03.14 발행)/보고서/부평 상권르네상스사업 스마트 라이트 폴 디지털 상권 조성 용역 원가계산보고서ver2.xlsx]원가 (2)'!E16+'[Y:/02. 원가분석본부/2025년 원가계산/부평상권르네상스센터/1. 부평 상권르네상스 스마트 라이트폴 디지털 상권 조성 용역 원가계산 (25.03.14 발행)/보고서/부평 상권르네상스사업 스마트 라이트 폴 디지털 상권 조성 용역 원가계산보고서ver2.xlsx]원가 (2)'!E18 -> #REF!
A8: 산업안전 보건관리비 | B8: =원가계산서!E9 -> 62250076 | C8: =원가계산서!E10 -> 11826704 | D8: =SUM(B8:C8) -> 74076780 | E8: 3.11 | F8: =TRUNC(D8*E8%,0) -> 2303787 | I8: 일반관리비 | J8: =TRUNC(SUM(J5:J7)*'[Y:/02. 원가분석본부/2025년 원가계산/부평상권르네상스센터/1. 부평 상권르네상스 스마트 라이트폴 디지털 상권 조성 용역 원가계산 (25.03.14 발행)/보고서/부평 상권르네상스사업 스마트 라이트 폴 디지털 상권 조성 용역 원가계산보고서ver2.xlsx]원가 (2)'!$H$21%,0) -> #REF!
I9: 이윤 | J9: =TRUNC(SUM(J6:J8)*'[Y:/02. 원가분석본부/2025년 원가계산/부평상권르네상스센터/1. 부평 상권르네상스 스마트 라이트폴 디지털 상권 조성 용역 원가계산 (25.03.14 발행)/보고서/부평 상권르네상스사업 스마트 라이트 폴 디지털 상권 조성 용역 원가계산보고서ver2.xlsx]원가 (2)'!$H$22%,0) -> #REF!
A10: (주1) 공사원가계산서 참조
A11: (주2) 공사원가계산서 참조
A12: (주3) 조달청적용기준 비율
A13: =IF(J12>20000000,"","(주4) 총공사금액(도급금액+도급자관급금액) 2천만원 이상 건설공사에만 적용하므로 본 보고서에서는 제외함.") -> (주4) 총공사금액(도급금액+도급자관급금액) 2천만원 이상 건설공사에만 적용하므로 본 보고서에서는 제외함.
A14: ="(주3) < 표 "&'[Y:/02. 원가분석본부/2025년 원가계산/부평상권르네상스센터/1. 부평 상권르네상스 스마트 라이트폴 디지털 상권 조성 용역 원가계산 (25.03.14 발행)/보고서/부평 상권르네상스사업 스마트 라이트 폴 디지털 상권 조성 용역 원가계산보고서ver2.xlsx]안전비율'!A1&" > "&'[Y:/02. 원가분석본부/2025년 원가계산/부평상권르네상스센터/1. 부평 상권르네상스 스마트 라이트폴 디지털 상권 조성 용역 원가계산 (25.03.14 발행)/보고서/부평 상권르네상스사업 스마트 라이트 폴 디지털 상권 조성 용역 원가계산보고서ver2.xlsx]안전비율'!A2&" 참조" -> (주3) < 표 (주3) < 표 #ERROR! > #ERROR! 참조 > (주3) < 표 #ERROR! > #ERROR! 참조 참조 | I14: 합계 | J14: =SUM(J10:J11) -> 0
A15: =IF(J14>20000000,"","(주4) 총공사금액(도급금액+도급자관급금액) 2천만원 이상 건설공사 적용하므로 본 조사에서는 제외함.") -> (주4) 총공사금액(도급금액+도급자관급금액) 2천만원 이상 건설공사 적용하므로 본 조사에서는 제외함.

Sheet 일반
A1: <표 17>
A2: 일반관리비 산출표
I4: (단위: 원)
B5: 비 목 | C5: 규 격 | D5: 적 용 대 상 액 | H5: 비율(%) (주4) | I5: 금 액
D6: 재료비 (주1) | E6: 노무비 (주2) | F6: 경 비 (주3) | G6: 계
D7: 원가계산서의 재료비(E8) | E7: 원가계산서의 (직접+간접)노무비(E11) | F7: 원가계산서의 경비(E29) | G7: 재료비 + 노무비 + 경비 | I7: 일반관리비 = ( 재료비 + 노무비 + 경비 ) * 비율(8%)
B8: 일반관리비 | D8: =원가계산서!E9 -> 62250076 | E8: =원가계산서!E12 -> 13482442 | F8: =원가계산서!E30 -> 31131389 | G8: =SUM(D8:F8) -> 106863907 | H8: =일반비율!H14 -> 8 | I8: =TRUNC(G8*$H$8%,0) -> 8549112
A10: (주1) 공사원가계산서 참조
A11: (주2) 공사원가계산서 참조
A12: ="(주3) "&경비!A1&" "&경비!A2&" 참조" -> (주3) <표 7> 경비 산출표 참조
A13: ="(주4) "&일반비율!A1&" "&일반비율!A2&" 참조" -> (주4) <표 18> 일반관리비 비율표 참조

Sheet 일반비율
A1: <표 18>
A2: 일반관리비 비율표
H4: (단위: %)
A5: 종 합 공 사 | E5: 전문,전기,정보통신,소방공사 및 그밖의 공사
B6: 공 사 원 가 | D6: 비 율 | F6: 공 사 원 가 | H6: 비 율
B8: 50억원미만 | D8: 8 | F8: 5억원미만 | H8: 8
B9: 50억원- 300억미만 | D9: 6.5 | F9: 5억원- 30억미만 | H9: 6.5
B10: 300억원이상 | D10: 5 | F10: 30억원이상 | H10: 5
B12: 조사적용비율 | H12: =H8 -> 8
B13: 조달청기준비율 | H13: 8
B14: 본조사적용비율 | H14: =MIN(H12:H13) -> 8 | I14: 조사적용비율과 조달청기준비율 중 작은값
A15: ※ 예정가격작성기준 참조

Sheet 이윤
A1: <표 19>
A2: 이윤 산출표
I4: (단위: 원)
B5: 비 목 | C5: 규 격 | D5: 적 용 대 상 액 | H5: 비율(%) (주4) | I5: 금 액
D6: 노무비 (주1) | E6: 경 비 (주2) | F6: 일반관리비 (주3) | G6: 계
D7: 원가계산서의 (직접+간접)노무비(E11) | E7: 원가계산서의 경비(E29) | F7: 일반관리비의 금액(I8) | G7: 노무비 + 경비 + 일반관리비 | I7: 이윤 금액 = ( 노무비 + 경비 + 일반관리비 ) * 비율(15%)
B8: 이 윤 | D8: =원가계산서!E12 -> 13482442 | E8: =원가계산서!E30 -> 31131389 | F8: =일반!I8 -> 8549112 | G8: =SUM(D8:F8) -> 53162943 | H8: =이윤비율!F7 -> 15 | I8: =TRUNC(G8*$H$8%-0/1.1,0) -> 7974441
A10: (주1) 공사원가계산서 참조
A11: (주2) 공사원가계산서 참조
A12: ="(주3) "&일반!A1&" "&일반!A2&" 참조" -> (주3) <표 17> 일반관리비 산출표 참조
A13: ="(주4) "&이윤비율!A1&" "&이윤비율!A2&" 참조" -> (주4) <표 20> 이윤 비율표 참조

Sheet 이윤비율
A1: <표 20>
A2: 이윤 비율표
G4: (단위: %)
B5: 구 분 | D5: 계약예규 기준비율 | E5: 조달청기준 비율 | F5: 조사적용 비율 | G5: 비 고
B7: 시설공사 | D7: 15 | E7: 15 | F7: =MIN(D7:E7) -> 15 | G7: 계약예규 기준비율과 조달청기준비율 중 작은 값
B8: 제조,구매 | D8: 25
B9: 용역 | D9: 10
B10: 수입물품의구입 | D10: 10
A12: ※ 예정가격작성기준 참조
