Workbook
Name excelContent: #REF!
Name excelContent: #REF!

Sheet 일별현황_2026
B3: 스마트 공장 원가계산 업무 일별 현황
B7: * 5일이상 진행건 사유 :
B9: *10일이상 진행건 사유 :
AD11: =TODAY() -> 46189
B12: 기준일 : | C12: =TODAY() -> 46189
B13: 사업연도 | C13: 수행기관(담당기관) | D13: 년도별 누계 | K13: 2026 | L13: 제출상태 | P13: 2026년 세금계산서 | S13: =TODAY() -> 46189 | U13: 진행중 (미완료+ 금일신규) | V13: 비고
D14: 2020 | E14: 2021 | F14: 2022 제출누계 | G14: 2022 제출완료누계 | H14: 2023 | I14: 2024 | J14: 2025 | K14: 누계 (전체건수) | L14: 현황 | N14: 완료건수 | P14: 세금계산서 발행 (누적) | Q14: 발행일자 | R14: 미발행건수
L15: 진행중 | M15: 금일신규 | N15: 현재제출 완료건수 | O15: 금일제출 완료건수 | S15: 금일 제출완료 | T15: 금일 신규
B16: 2025년도 | C16: 강원 | D16: 65 | E16: 23 | F16: 16 | G16: 14 | I16: 4 | J16: 13 | K16: =COUNTIF('세부(구축)'!$B:$B,C16) -> 0 | L16: =COUNTIFS('세부(구축)'!$B:$B,C16,'세부(구축)'!$G:$G,"<>승인") -> 0 | M16: =COUNTIFS('세부(구축)'!$B:$B,C16,'세부(구축)'!$G:$G,"신규") -> 0 | N16: =COUNTIFS('세부(구축)'!$B:$B,C16,'세부(구축)'!$G:$G,"승인") -> 0 | O16: =COUNTIFS('세부(구축)'!$I:$I,$C$12,'세부(구축)'!$B:$B,C16) -> 0 | P16: =COUNTIFS('세부(구축)'!$B:$B,C16,'세부(구축)'!$J:$J,"발행") -> 0 | R16: =K16-P16 -> 0 | S16: =COUNTIFS('세부(구축)'!$I:$I,$C$12,'세부(구축)'!$B:$B,C16) -> 0 | T16: =COUNTIFS('세부(구축)'!$B:$B,C16,'세부(구축)'!$H:$H,TODAY()) -> 0 | U16: =L16+T16 -> 0 | AA16: =IF(OR(AND(ISNUMBER(T16), T16<>0), AND(ISNUMBER(U16), U16<>0), AND(ISNUMBER(S16), S16<>0),AND(ISNUMBER(M16), M16<>0)), 1, 0) -> 0 | AD16: =M16+U16 -> 0 | AE16: =K16=AD16 -> TRUE | AG16: 진행중=자료수령+금일신규-금일신규中당일완료
C17: 경기 | D17: 60 | E17: 101 | F17: 21 | G17: 20 | H17: 1 | I17: 44 | J17: 10 | K17: =COUNTIF('세부(구축)'!$B:$B,C17) -> 0 | L17: =COUNTIFS('세부(구축)'!$B:$B,C17,'세부(구축)'!$G:$G,"<>승인") -> 0 | M17: =COUNTIFS('세부(구축)'!$B:$B,C17,'세부(구축)'!$G:$G,"신규") -> 0 | N17: =COUNTIFS('세부(구축)'!$B:$B,C17,'세부(구축)'!$G:$G,"승인") -> 0 | O17: =COUNTIFS('세부(구축)'!$I:$I,$C$12,'세부(구축)'!$B:$B,C17) -> 0 | P17: =COUNTIFS('세부(구축)'!$B:$B,C17,'세부(구축)'!$J:$J,"발행") -> 0 | R17: =K17-P17 -> 0 | S17: =COUNTIFS('세부(구축)'!$I:$I,$C$12,'세부(구축)'!$B:$B,C17) -> 0 | T17: =COUNTIFS('세부(구축)'!$B:$B,C17,'세부(구축)'!$H:$H,TODAY()) -> 0 | U17: =L17+T17 -> 0 | AA17: =IF(OR(AND(ISNUMBER(T17), T17<>0), AND(ISNUMBER(U17), U17<>0), AND(ISNUMBER(S17), S17<>0),AND(ISNUMBER(M17), M17<>0)), 1, 0) -> 0 | AD17: =M17+U17 -> 0 | AE17: =K17=AD17 -> TRUE | AG17: 진행중=자료수령+금일신규-금일신규中당일완료
C18: 경기북부 | D18: 129 | E18: 111 | F18: 92 | G18: 84 | H18: 0 | I18: 33 | J18: 28 | K18: =COUNTIF('세부(구축)'!$B:$B,C18) -> 0 | L18: =COUNTIFS('세부(구축)'!$B:$B,C18,'세부(구축)'!$G:$G,"<>승인") -> 0 | M18: =COUNTIFS('세부(구축)'!$B:$B,C18,'세부(구축)'!$G:$G,"신규") -> 0 | N18: =COUNTIFS('세부(구축)'!$B:$B,C18,'세부(구축)'!$G:$G,"승인") -> 0 | O18: =COUNTIFS('세부(구축)'!$I:$I,$C$12,'세부(구축)'!$B:$B,C18) -> 0 | P18: =COUNTIFS('세부(구축)'!$B:$B,C18,'세부(구축)'!$J:$J,"발행") -> 0 | R18: =K18-P18 -> 0 | S18: =COUNTIFS('세부(구축)'!$I:$I,$C$12,'세부(구축)'!$B:$B,C18) -> 0 | T18: =COUNTIFS('세부(구축)'!$B:$B,C18,'세부(구축)'!$H:$H,TODAY()) -> 0 | U18: =L18+T18 -> 0 | AA18: =IF(OR(AND(ISNUMBER(T18), T18<>0), AND(ISNUMBER(U18), U18<>0), AND(ISNUMBER(S18), S18<>0),AND(ISNUMBER(M18), M18<>0)), 1, 0) -> 0 | AD18: =M18+U18 -> 0 | AE18: =K18=AD18 -> TRUE | AG18: 진행중=자료수령+금일신규-금일신규中당일완료
C19: 경기대진 | K19: =COUNTIF('세부(구축)'!$B:$B,C19) -> 13 | L19: =COUNTIFS('세부(구축)'!$B:$B,C19,'세부(구축)'!$G:$G,"<>승인") -> 8 | M19: =COUNTIFS('세부(구축)'!$B:$B,C19,'세부(구축)'!$G:$G,"신규") -> 0 | N19: =COUNTIFS('세부(구축)'!$B:$B,C19,'세부(구축)'!$G:$G,"승인") -> 5 | O19: =COUNTIFS('세부(구축)'!$I:$I,$C$12,'세부(구축)'!$B:$B,C19) -> 0 | P19: =COUNTIFS('세부(구축)'!$B:$B,C19,'세부(구축)'!$J:$J,"발행") -> 0 | R19: =K19-P19 -> 13
C20: 경남 | D20: 7 | E20: 25 | F20: 0 | H20: 0 | I20: 100 | J20: 7 | K20: =COUNTIF('세부(구축)'!$B:$B,C20) -> 27 | L20: =COUNTIFS('세부(구축)'!$B:$B,C20,'세부(구축)'!$G:$G,"<>승인") -> 0 | M20: =COUNTIFS('세부(구축)'!$B:$B,C20,'세부(구축)'!$G:$G,"신규") -> 0 | N20: =COUNTIFS('세부(구축)'!$B:$B,C20,'세부(구축)'!$G:$G,"승인") -> 27 | O20: =COUNTIFS('세부(구축)'!$I:$I,$C$12,'세부(구축)'!$B:$B,C20) -> 0 | P20: =COUNTIFS('세부(구축)'!$B:$B,C20,'세부(구축)'!$J:$J,"발행") -> 0 | R20: =K20-P20 -> 27 | S20: =COUNTIFS('세부(구축)'!$I:$I,$C$12,'세부(구축)'!$B:$B,C20) -> 0 | T20: =COUNTIFS('세부(구축)'!$B:$B,C20,'세부(구축)'!$H:$H,TODAY()) -> 0 | U20: =L20+T20 -> 0 | AA20: =IF(OR(AND(ISNUMBER(T20), T20<>0), AND(ISNUMBER(U20), U20<>0), AND(ISNUMBER(S20), S20<>0),AND(ISNUMBER(M20), M20<>0)), 1, 0) -> 0
C21: 경북 | D21: 28 | E21: 64 | F21: 24 | G21: 23 | H21: 0 | I21: 5 | J21: 3 | K21: =COUNTIF('세부(구축)'!$B:$B,C21) -> 13 | L21: =COUNTIFS('세부(구축)'!$B:$B,C21,'세부(구축)'!$G:$G,"<>승인") -> 13 | M21: =COUNTIFS('세부(구축)'!$B:$B,C21,'세부(구축)'!$G:$G,"신규") -> 0 | N21: =COUNTIFS('세부(구축)'!$B:$B,C21,'세부(구축)'!$G:$G,"승인") -> 0 | O21: =COUNTIFS('세부(구축)'!$I:$I,$C$12,'세부(구축)'!$B:$B,C21) -> 0 | P21: =COUNTIFS('세부(구축)'!$B:$B,C21,'세부(구축)'!$J:$J,"발행") -> 0 | R21: =K21-P21 -> 13 | S21: =COUNTIFS('세부(구축)'!$I:$I,$C$12,'세부(구축)'!$B:$B,C21) -> 0 | T21: =COUNTIFS('세부(구축)'!$B:$B,C21,'세부(구축)'!$H:$H,TODAY()) -> 0 | U21: =L21+T21 -> 13 | AA21: =IF(OR(AND(ISNUMBER(T21), T21<>0), AND(ISNUMBER(U21), U21<>0), AND(ISNUMBER(S21), S21<>0),AND(ISNUMBER(M21), M21<>0)), 1, 0) -> 1
C22: 광주 | D22: 20 | E22: 14 | F22: 9 | G22: 9 | H22: 0 | I22: 1 | J22: 22 | K22: =COUNTIF('세부(구축)'!$B:$B,C22) -> 7 | L22: =COUNTIFS('세부(구축)'!$B:$B,C22,'세부(구축)'!$G:$G,"<>승인") -> 5 | M22: =COUNTIFS('세부(구축)'!$B:$B,C22,'세부(구축)'!$G:$G,"신규") -> 0 | N22: =COUNTIFS('세부(구축)'!$B:$B,C22,'세부(구축)'!$G:$G,"승인") -> 2 | O22: =COUNTIFS('세부(구축)'!$I:$I,$C$12,'세부(구축)'!$B:$B,C22) -> 0 | P22: =COUNTIFS('세부(구축)'!$B:$B,C22,'세부(구축)'!$J:$J,"발행") -> 0 | R22: =K22-P22 -> 7 | S22: =COUNTIFS('세부(구축)'!$I:$I,$C$12,'세부(구축)'!$B:$B,C22) -> 0 | T22: =COUNTIFS('세부(구축)'!$B:$B,C22,'세부(구축)'!$H:$H,TODAY()) -> 0 | U22: =L22+T22 -> 5 | AA22: =IF(OR(AND(ISNUMBER(T22), T22<>0), AND(ISNUMBER(U22), U22<>0), AND(ISNUMBER(S22), S22<>0),AND(ISNUMBER(M22), M22<>0)), 1, 0) -> 1
C23: 대구 | D23: 4 | E23: 57 | F23: 10 | G23: 10 | H23: 0 | I23: 9 | J23: 0 | K23: =COUNTIF('세부(구축)'!$B:$B,C23) -> 0 | L23: =COUNTIFS('세부(구축)'!$B:$B,C23,'세부(구축)'!$G:$G,"<>승인") -> 0 | M23: =COUNTIFS('세부(구축)'!$B:$B,C23,'세부(구축)'!$G:$G,"신규") -> 0 | N23: =COUNTIFS('세부(구축)'!$B:$B,C23,'세부(구축)'!$G:$G,"승인") -> 0 | O23: =COUNTIFS('세부(구축)'!$I:$I,$C$12,'세부(구축)'!$B:$B,C23) -> 0 | P23: =COUNTIFS('세부(구축)'!$B:$B,C23,'세부(구축)'!$J:$J,"발행") -> 0 | R23: =K23-P23 -> 0 | S23: =COUNTIFS('세부(구축)'!$I:$I,$C$12,'세부(구축)'!$B:$B,C23) -> 0 | T23: =COUNTIFS('세부(구축)'!$B:$B,C23,'세부(구축)'!$H:$H,TODAY()) -> 0 | U23: =L23+T23 -> 0 | AA23: =IF(OR(AND(ISNUMBER(T23), T23<>0), AND(ISNUMBER(U23), U23<>0), AND(ISNUMBER(S23), S23<>0),AND(ISNUMBER(M23), M23<>0)), 1, 0) -> 0
C24: 대전 | D24: 12 | E24: 10 | F24: 4 | G24: 4 | H24: 0 | I24: 1 | J24: 3 | K24: =COUNTIF('세부(구축)'!$B:$B,C24) -> 0 | L24: =COUNTIFS('세부(구축)'!$B:$B,C24,'세부(구축)'!$G:$G,"<>승인") -> 0 | M24: =COUNTIFS('세부(구축)'!$B:$B,C24,'세부(구축)'!$G:$G,"신규") -> 0 | N24: =COUNTIFS('세부(구축)'!$B:$B,C24,'세부(구축)'!$G:$G,"승인") -> 0 | O24: =COUNTIFS('세부(구축)'!$I:$I,$C$12,'세부(구축)'!$B:$B,C24) -> 0 | P24: =COUNTIFS('세부(구축)'!$B:$B,C24,'세부(구축)'!$J:$J,"발행") -> 0 | R24: =K24-P24 -> 0 | S24: =COUNTIFS('세부(구축)'!$I:$I,$C$12,'세부(구축)'!$B:$B,C24) -> 0 | T24: =COUNTIFS('세부(구축)'!$B:$B,C24,'세부(구축)'!$H:$H,TODAY()) -> 0 | U24: =L24+T24 -> 0 | AA24: =IF(OR(AND(ISNUMBER(T24), T24<>0), AND(ISNUMBER(U24), U24<>0), AND(ISNUMBER(S24), S24<>0),AND(ISNUMBER(M24), M24<>0)), 1, 0) -> 0
C25: 부산 | D25: 7 | E25: 40 | F25: 0 | H25: 0 | I25: 8 | J25: 3 | K25: =COUNTIF('세부(구축)'!$B:$B,C25) -> 0 | L25: =COUNTIFS('세부(구축)'!$B:$B,C25,'세부(구축)'!$G:$G,"<>승인") -> 0 | M25: =COUNTIFS('세부(구축)'!$B:$B,C25,'세부(구축)'!$G:$G,"신규") -> 0 | N25: =COUNTIFS('세부(구축)'!$B:$B,C25,'세부(구축)'!$G:$G,"승인") -> 0 | O25: =COUNTIFS('세부(구축)'!$I:$I,$C$12,'세부(구축)'!$B:$B,C25) -> 0 | P25: =COUNTIFS('세부(구축)'!$B:$B,C25,'세부(구축)'!$J:$J,"발행") -> 0 | R25: =K25-P25 -> 0 | S25: =COUNTIFS('세부(구축)'!$I:$I,$C$12,'세부(구축)'!$B:$B,C25) -> 0 | T25: =COUNTIFS('세부(구축)'!$B:$B,C25,'세부(구축)'!$H:$H,TODAY()) -> 0 | U25: =L25+T25 -> 0 | AA25: =IF(OR(AND(ISNUMBER(T25), T25<>0), AND(ISNUMBER(U25), U25<>0), AND(ISNUMBER(S25), S25<>0),AND(ISNUMBER(M25), M25<>0)), 1, 0) -> 0
C26: 서울 | D26: 46 | E26: 19 | F26: 10 | G26: 8 | H26: 0 | I26: 1 | J26: 0 | K26: =COUNTIF('세부(구축)'!$B:$B,C26) -> 0 | L26: =COUNTIFS('세부(구축)'!$B:$B,C26,'세부(구축)'!$G:$G,"<>승인") -> 0 | M26: =COUNTIFS('세부(구축)'!$B:$B,C26,'세부(구축)'!$G:$G,"신규") -> 0 | N26: =COUNTIFS('세부(구축)'!$B:$B,C26,'세부(구축)'!$G:$G,"승인") -> 0 | O26: =COUNTIFS('세부(구축)'!$I:$I,$C$12,'세부(구축)'!$B:$B,C26) -> 0 | P26: =COUNTIFS('세부(구축)'!$B:$B,C26,'세부(구축)'!$J:$J,"발행") -> 0 | R26: =K26-P26 -> 0 | S26: =COUNTIFS('세부(구축)'!$I:$I,$C$12,'세부(구축)'!$B:$B,C26) -> 0 | T26: =COUNTIFS('세부(구축)'!$B:$B,C26,'세부(구축)'!$H:$H,TODAY()) -> 0 | U26: =L26+T26 -> 0 | AA26: =IF(OR(AND(ISNUMBER(T26), T26<>0), AND(ISNUMBER(U26), U26<>0), AND(ISNUMBER(S26), S26<>0),AND(ISNUMBER(M26), M26<>0)), 1, 0) -> 0
C27: 세종 | D27: 7 | F27: 7 | G27: 6 | H27: 0 | I27: 4 | J27: 3 | K27: =COUNTIF('세부(구축)'!$B:$B,C27) -> 0 | L27: =COUNTIFS('세부(구축)'!$B:$B,C27,'세부(구축)'!$G:$G,"<>승인") -> 0 | M27: =COUNTIFS('세부(구축)'!$B:$B,C27,'세부(구축)'!$G:$G,"신규") -> 0 | N27: =COUNTIFS('세부(구축)'!$B:$B,C27,'세부(구축)'!$G:$G,"승인") -> 0 | O27: =COUNTIFS('세부(구축)'!$I:$I,$C$12,'세부(구축)'!$B:$B,C27) -> 0 | P27: =COUNTIFS('세부(구축)'!$B:$B,C27,'세부(구축)'!$J:$J,"발행") -> 0 | R27: =K27-P27 -> 0 | S27: =COUNTIFS('세부(구축)'!$I:$I,$C$12,'세부(구축)'!$B:$B,C27) -> 0 | T27: =COUNTIFS('세부(구축)'!$B:$B,C27,'세부(구축)'!$H:$H,TODAY()) -> 0 | U27: =L27+T27 -> 0 | AA27: =IF(OR(AND(ISNUMBER(T27), T27<>0), AND(ISNUMBER(U27), U27<>0), AND(ISNUMBER(S27), S27<>0),AND(ISNUMBER(M27), M27<>0)), 1, 0) -> 0
C28: 울산 | D28: 37 | E28: 14 | F28: 6 | G28: 6 | H28: 0 | I28: 2 | J28: 2 | K28: =COUNTIF('세부(구축)'!$B:$B,C28) -> 0 | L28: =COUNTIFS('세부(구축)'!$B:$B,C28,'세부(구축)'!$G:$G,"<>승인") -> 0 | M28: =COUNTIFS('세부(구축)'!$B:$B,C28,'세부(구축)'!$G:$G,"신규") -> 0 | N28: =COUNTIFS('세부(구축)'!$B:$B,C28,'세부(구축)'!$G:$G,"승인") -> 0 | O28: =COUNTIFS('세부(구축)'!$I:$I,$C$12,'세부(구축)'!$B:$B,C28) -> 0 | P28: =COUNTIFS('세부(구축)'!$B:$B,C28,'세부(구축)'!$J:$J,"발행") -> 0 | R28: =K28-P28 -> 0 | S28: =COUNTIFS('세부(구축)'!$I:$I,$C$12,'세부(구축)'!$B:$B,C28) -> 0 | T28: =COUNTIFS('세부(구축)'!$B:$B,C28,'세부(구축)'!$H:$H,TODAY()) -> 0 | U28: =L28+T28 -> 0 | AA28: =IF(OR(AND(ISNUMBER(T28), T28<>0), AND(ISNUMBER(U28), U28<>0), AND(ISNUMBER(S28), S28<>0),AND(ISNUMBER(M28), M28<>0)), 1, 0) -> 0
C29: 인천 | D29: 85 | E29: 65 | F29: 37 | G29: 23 | H29: 0 | I29: 18 | J29: 24 | K29: =COUNTIF('세부(구축)'!$B:$B,C29) -> 13 | L29: =COUNTIFS('세부(구축)'!$B:$B,C29,'세부(구축)'!$G:$G,"<>승인") -> 13 | M29: =COUNTIFS('세부(구축)'!$B:$B,C29,'세부(구축)'!$G:$G,"신규") -> 0 | N29: =COUNTIFS('세부(구축)'!$B:$B,C29,'세부(구축)'!$G:$G,"승인") -> 0 | O29: =COUNTIFS('세부(구축)'!$I:$I,$C$12,'세부(구축)'!$B:$B,C29) -> 0 | P29: =COUNTIFS('세부(구축)'!$B:$B,C29,'세부(구축)'!$J:$J,"발행") -> 0 | R29: =K29-P29 -> 13 | S29: =COUNTIFS('세부(구축)'!$I:$I,$C$12,'세부(구축)'!$B:$B,C29) -> 0 | T29: =COUNTIFS('세부(구축)'!$B:$B,C29,'세부(구축)'!$H:$H,TODAY()) -> 0 | U29: =L29+T29 -> 13 | AA29: =IF(OR(AND(ISNUMBER(T29), T29<>0), AND(ISNUMBER(U29), U29<>0), AND(ISNUMBER(S29), S29<>0),AND(ISNUMBER(M29), M29<>0)), 1, 0) -> 1
C30: 전남 | D30: 36 | E30: 38 | F30: 16 | G30: 15 | H30: 0 | I30: 7 | J30: 7 | K30: =COUNTIF('세부(구축)'!$B:$B,C30) -> 4 | L30: =COUNTIFS('세부(구축)'!$B:$B,C30,'세부(구축)'!$G:$G,"<>승인") -> 1 | M30: =COUNTIFS('세부(구축)'!$B:$B,C30,'세부(구축)'!$G:$G,"신규") -> 0 | N30: =COUNTIFS('세부(구축)'!$B:$B,C30,'세부(구축)'!$G:$G,"승인") -> 3 | O30: =COUNTIFS('세부(구축)'!$I:$I,$C$12,'세부(구축)'!$B:$B,C30) -> 0 | P30: =COUNTIFS('세부(구축)'!$B:$B,C30,'세부(구축)'!$J:$J,"발행") -> 0 | R30: =K30-P30 -> 4 | S30: =COUNTIFS('세부(구축)'!$I:$I,$C$12,'세부(구축)'!$B:$B,C30) -> 0 | T30: =COUNTIFS('세부(구축)'!$B:$B,C30,'세부(구축)'!$H:$H,TODAY()) -> 0 | U30: =L30+T30 -> 1 | AA30: =IF(OR(AND(ISNUMBER(T30), T30<>0), AND(ISNUMBER(U30), U30<>0), AND(ISNUMBER(S30), S30<>0),AND(ISNUMBER(M30), M30<>0)), 1, 0) -> 1
C31: 전북 | D31: 24 | E31: 14 | F31: 22 | G31: 19 | H31: 0 | I31: 19 | J31: 6 | K31: =COUNTIF('세부(구축)'!$B:$B,C31) -> 4 | L31: =COUNTIFS('세부(구축)'!$B:$B,C31,'세부(구축)'!$G:$G,"<>승인") -> 0 | M31: =COUNTIFS('세부(구축)'!$B:$B,C31,'세부(구축)'!$G:$G,"신규") -> 0 | N31: =COUNTIFS('세부(구축)'!$B:$B,C31,'세부(구축)'!$G:$G,"승인") -> 4 | O31: =COUNTIFS('세부(구축)'!$I:$I,$C$12,'세부(구축)'!$B:$B,C31) -> 0 | P31: =COUNTIFS('세부(구축)'!$B:$B,C31,'세부(구축)'!$J:$J,"발행") -> 0 | R31: =K31-P31 -> 4 | S31: =COUNTIFS('세부(구축)'!$I:$I,$C$12,'세부(구축)'!$B:$B,C31) -> 0 | T31: =COUNTIFS('세부(구축)'!$B:$B,C31,'세부(구축)'!$H:$H,TODAY()) -> 0 | U31: =L31+T31 -> 0 | AA31: =IF(OR(AND(ISNUMBER(T31), T31<>0), AND(ISNUMBER(U31), U31<>0), AND(ISNUMBER(S31), S31<>0),AND(ISNUMBER(M31), M31<>0)), 1, 0) -> 0
C32: 제주 | D32: 2 | F32: 11 | G32: 11 | H32: 0 | I32: 1 | J32: 0 | K32: =COUNTIF('세부(구축)'!$B:$B,C32) -> 0 | L32: =COUNTIFS('세부(구축)'!$B:$B,C32,'세부(구축)'!$G:$G,"<>승인") -> 0 | M32: =COUNTIFS('세부(구축)'!$B:$B,C32,'세부(구축)'!$G:$G,"신규") -> 0 | N32: =COUNTIFS('세부(구축)'!$B:$B,C32,'세부(구축)'!$G:$G,"승인") -> 0 | O32: =COUNTIFS('세부(구축)'!$I:$I,$C$12,'세부(구축)'!$B:$B,C32) -> 0 | P32: =COUNTIFS('세부(구축)'!$B:$B,C32,'세부(구축)'!$J:$J,"발행") -> 0 | R32: =K32-P32 -> 0 | S32: =COUNTIFS('세부(구축)'!$I:$I,$C$12,'세부(구축)'!$B:$B,C32) -> 0 | T32: =COUNTIFS('세부(구축)'!$B:$B,C32,'세부(구축)'!$H:$H,TODAY()) -> 0 | U32: =L32+T32 -> 0 | AA32: =IF(OR(AND(ISNUMBER(T32), T32<>0), AND(ISNUMBER(U32), U32<>0), AND(ISNUMBER(S32), S32<>0),AND(ISNUMBER(M32), M32<>0)), 1, 0) -> 0
C33: 충남 | D33: 41 | E33: 34 | F33: 13 | G33: 13 | H33: 0 | I33: 15 | J33: 4 | K33: =COUNTIF('세부(구축)'!$B:$B,C33) -> 0 | L33: =COUNTIFS('세부(구축)'!$B:$B,C33,'세부(구축)'!$G:$G,"<>승인") -> 0 | M33: =COUNTIFS('세부(구축)'!$B:$B,C33,'세부(구축)'!$G:$G,"신규") -> 0 | N33: =COUNTIFS('세부(구축)'!$B:$B,C33,'세부(구축)'!$G:$G,"승인") -> 0 | O33: =COUNTIFS('세부(구축)'!$I:$I,$C$12,'세부(구축)'!$B:$B,C33) -> 0 | P33: =COUNTIFS('세부(구축)'!$B:$B,C33,'세부(구축)'!$J:$J,"발행") -> 0 | R33: =K33-P33 -> 0 | S33: =COUNTIFS('세부(구축)'!$I:$I,$C$12,'세부(구축)'!$B:$B,C33) -> 0 | T33: =COUNTIFS('세부(구축)'!$B:$B,C33,'세부(구축)'!$H:$H,TODAY()) -> 0 | U33: =L33+T33 -> 0 | AA33: =IF(OR(AND(ISNUMBER(T33), T33<>0), AND(ISNUMBER(U33), U33<>0), AND(ISNUMBER(S33), S33<>0),AND(ISNUMBER(M33), M33<>0)), 1, 0) -> 0
C34: 충북 | D34: 33 | E34: 26 | F34: 14 | G34: 13 | H34: 0 | I34: 16 | J34: 9 | K34: =COUNTIF('세부(구축)'!$B:$B,C34) -> 5 | L34: =COUNTIFS('세부(구축)'!$B:$B,C34,'세부(구축)'!$G:$G,"<>승인") -> 1 | M34: =COUNTIFS('세부(구축)'!$B:$B,C34,'세부(구축)'!$G:$G,"신규") -> 0 | N34: =COUNTIFS('세부(구축)'!$B:$B,C34,'세부(구축)'!$G:$G,"승인") -> 4 | O34: =COUNTIFS('세부(구축)'!$I:$I,$C$12,'세부(구축)'!$B:$B,C34) -> 0 | P34: =COUNTIFS('세부(구축)'!$B:$B,C34,'세부(구축)'!$J:$J,"발행") -> 0 | R34: =K34-P34 -> 5 | S34: =COUNTIFS('세부(구축)'!$I:$I,$C$12,'세부(구축)'!$B:$B,C34) -> 0 | T34: =COUNTIFS('세부(구축)'!$B:$B,C34,'세부(구축)'!$H:$H,TODAY()) -> 0 | U34: =L34+T34 -> 1 | AA34: =IF(OR(AND(ISNUMBER(T34), T34<>0), AND(ISNUMBER(U34), U34<>0), AND(ISNUMBER(S34), S34<>0),AND(ISNUMBER(M34), M34<>0)), 1, 0) -> 1
C35: 포항 | D35: 7 | E35: 9 | F35: 0 | H35: 0 | I35: 1 | J35: 0 | K35: =COUNTIF('세부(구축)'!$B:$B,C35) -> 0 | L35: =COUNTIFS('세부(구축)'!$B:$B,C35,'세부(구축)'!$G:$G,"<>승인") -> 0 | M35: =COUNTIFS('세부(구축)'!$B:$B,C35,'세부(구축)'!$G:$G,"신규") -> 0 | N35: =COUNTIFS('세부(구축)'!$B:$B,C35,'세부(구축)'!$G:$G,"승인") -> 0 | O35: =COUNTIFS('세부(구축)'!$I:$I,$C$12,'세부(구축)'!$B:$B,C35) -> 0 | P35: =COUNTIFS('세부(구축)'!$B:$B,C35,'세부(구축)'!$J:$J,"발행") -> 0 | R35: =K35-P35 -> 0 | S35: =COUNTIFS('세부(구축)'!$I:$I,$C$12,'세부(구축)'!$B:$B,C35) -> 0 | T35: =COUNTIFS('세부(구축)'!$B:$B,C35,'세부(구축)'!$H:$H,TODAY()) -> 0 | U35: =L35+T35 -> 0 | AA35: =IF(OR(AND(ISNUMBER(T35), T35<>0), AND(ISNUMBER(U35), U35<>0), AND(ISNUMBER(S35), S35<>0),AND(ISNUMBER(M35), M35<>0)), 1, 0) -> 0
C36: (재)한국혁신의약품컨소시엄 | D36: 32 | E36: 17 | F36: 25 | G36: 25 | H36: 0 | I36: 0 | J36: 0 | K36: =COUNTIF('세부(구축)'!$B:$B,C36) -> 0 | L36: =COUNTIFS('세부(구축)'!$B:$B,C36,'세부(구축)'!$G:$G,"<>승인") -> 0 | M36: =COUNTIFS('세부(구축)'!$B:$B,C36,'세부(구축)'!$G:$G,"신규") -> 0 | N36: =COUNTIFS('세부(구축)'!$B:$B,C36,'세부(구축)'!$G:$G,"승인") -> 0 | O36: =COUNTIFS('세부(구축)'!$I:$I,$C$12,'세부(구축)'!$B:$B,C36) -> 0 | P36: =COUNTIFS('세부(구축)'!$B:$B,C36,'세부(구축)'!$J:$J,"발행") -> 0 | R36: =K36-P36 -> 0 | S36: =COUNTIFS('세부(구축)'!$I:$I,$C$12,'세부(구축)'!$B:$B,C36) -> 0 | T36: =COUNTIFS('세부(구축)'!$B:$B,C36,'세부(구축)'!$H:$H,TODAY()) -> 0 | U36: =L36+T36 -> 0 | AA36: =IF(OR(AND(ISNUMBER(T36), T36<>0), AND(ISNUMBER(U36), U36<>0), AND(ISNUMBER(S36), S36<>0),AND(ISNUMBER(M36), M36<>0)), 1, 0) -> 0
C37: 대구경북금형공업협동조합 | D37: 25 | E37: 14 | F37: 0 | H37: 0 | I37: 0 | J37: 0 | K37: =COUNTIF('세부(구축)'!$B:$B,C37) -> 0 | L37: =COUNTIFS('세부(구축)'!$B:$B,C37,'세부(구축)'!$G:$G,"<>승인") -> 0 | M37: =COUNTIFS('세부(구축)'!$B:$B,C37,'세부(구축)'!$G:$G,"신규") -> 0 | N37: =COUNTIFS('세부(구축)'!$B:$B,C37,'세부(구축)'!$G:$G,"승인") -> 0 | O37: =COUNTIFS('세부(구축)'!$I:$I,$C$12,'세부(구축)'!$B:$B,C37) -> 0 | P37: =COUNTIFS('세부(구축)'!$B:$B,C37,'세부(구축)'!$J:$J,"발행") -> 0 | R37: =K37-P37 -> 0 | S37: =COUNTIFS('세부(구축)'!$I:$I,$C$12,'세부(구축)'!$B:$B,C37) -> 0 | T37: =COUNTIFS('세부(구축)'!$B:$B,C37,'세부(구축)'!$H:$H,TODAY()) -> 0 | U37: =L37+T37 -> 0 | AA37: =IF(OR(AND(ISNUMBER(T37), T37<>0), AND(ISNUMBER(U37), U37<>0), AND(ISNUMBER(S37), S37<>0),AND(ISNUMBER(M37), M37<>0)), 1, 0) -> 0
C38: 대중소기업농어업협력재단 | F38: 0 | H38: 0 | I38: 0 | J38: 0 | K38: =COUNTIF('세부(구축)'!$B:$B,C38) -> 0 | L38: =COUNTIFS('세부(구축)'!$B:$B,C38,'세부(구축)'!$G:$G,"<>승인") -> 0 | M38: =COUNTIFS('세부(구축)'!$B:$B,C38,'세부(구축)'!$G:$G,"신규") -> 0 | N38: =COUNTIFS('세부(구축)'!$B:$B,C38,'세부(구축)'!$G:$G,"승인") -> 0 | O38: =COUNTIFS('세부(구축)'!$I:$I,$C$12,'세부(구축)'!$B:$B,C38) -> 0 | P38: =COUNTIFS('세부(구축)'!$B:$B,C38,'세부(구축)'!$J:$J,"발행") -> 0 | R38: =K38-P38 -> 0 | S38: =COUNTIFS('세부(구축)'!$I:$I,$C$12,'세부(구축)'!$B:$B,C38) -> 0 | T38: =COUNTIFS('세부(구축)'!$B:$B,C38,'세부(구축)'!$H:$H,TODAY()) -> 0 | U38: =L38+T38 -> 0 | AA38: =IF(OR(AND(ISNUMBER(T38), T38<>0), AND(ISNUMBER(U38), U38<>0), AND(ISNUMBER(S38), S38<>0),AND(ISNUMBER(M38), M38<>0)), 1, 0) -> 0
C39: 대한상공회의소 | D39: 24 | E39: 8 | F39: 40 | G39: 40 | H39: 12 | I39: 0 | J39: 18 | K39: =COUNTIF('세부(구축)'!$B:$B,C39) -> 13 | L39: =COUNTIFS('세부(구축)'!$B:$B,C39,'세부(구축)'!$G:$G,"<>승인") -> 0 | M39: =COUNTIFS('세부(구축)'!$B:$B,C39,'세부(구축)'!$G:$G,"신규") -> 0 | N39: =COUNTIFS('세부(구축)'!$B:$B,C39,'세부(구축)'!$G:$G,"승인") -> 13 | O39: =COUNTIFS('세부(구축)'!$I:$I,$C$12,'세부(구축)'!$B:$B,C39) -> 0 | P39: =COUNTIFS('세부(구축)'!$B:$B,C39,'세부(구축)'!$J:$J,"발행") -> 0 | R39: =K39-P39 -> 13 | S39: =COUNTIFS('세부(구축)'!$I:$I,$C$12,'세부(구축)'!$B:$B,C39) -> 0 | T39: =COUNTIFS('세부(구축)'!$B:$B,C39,'세부(구축)'!$H:$H,TODAY()) -> 0 | U39: =L39+T39 -> 0 | AA39: =IF(OR(AND(ISNUMBER(T39), T39<>0), AND(ISNUMBER(U39), U39<>0), AND(ISNUMBER(S39), S39<>0),AND(ISNUMBER(M39), M39<>0)), 1, 0) -> 0
C40: 자동차부품산업진흥재단 | E40: 58 | F40: 0 | H40: 0 | I40: 0 | J40: 0 | K40: =COUNTIF('세부(구축)'!$B:$B,C40) -> 0 | L40: =COUNTIFS('세부(구축)'!$B:$B,C40,'세부(구축)'!$G:$G,"<>승인") -> 0 | M40: =COUNTIFS('세부(구축)'!$B:$B,C40,'세부(구축)'!$G:$G,"신규") -> 0 | N40: =COUNTIFS('세부(구축)'!$B:$B,C40,'세부(구축)'!$G:$G,"승인") -> 0 | O40: =COUNTIFS('세부(구축)'!$I:$I,$C$12,'세부(구축)'!$B:$B,C40) -> 0 | P40: =COUNTIFS('세부(구축)'!$B:$B,C40,'세부(구축)'!$J:$J,"발행") -> 0 | R40: =K40-P40 -> 0 | S40: =COUNTIFS('세부(구축)'!$I:$I,$C$12,'세부(구축)'!$B:$B,C40) -> 0 | T40: =COUNTIFS('세부(구축)'!$B:$B,C40,'세부(구축)'!$H:$H,TODAY()) -> 0 | U40: =L40+T40 -> 0 | AA40: =IF(OR(AND(ISNUMBER(T40), T40<>0), AND(ISNUMBER(U40), U40<>0), AND(ISNUMBER(S40), S40<>0),AND(ISNUMBER(M40), M40<>0)), 1, 0) -> 0
C41: 중소기업기술혁신협회 | D41: 10 | E41: 2 | F41: 17 | G41: 17 | H41: 0 | I41: 0 | J41: 0 | K41: =COUNTIF('세부(구축)'!$B:$B,C41) -> 0 | L41: =COUNTIFS('세부(구축)'!$B:$B,C41,'세부(구축)'!$G:$G,"<>승인") -> 0 | M41: =COUNTIFS('세부(구축)'!$B:$B,C41,'세부(구축)'!$G:$G,"신규") -> 0 | N41: =COUNTIFS('세부(구축)'!$B:$B,C41,'세부(구축)'!$G:$G,"승인") -> 0 | O41: =COUNTIFS('세부(구축)'!$I:$I,$C$12,'세부(구축)'!$B:$B,C41) -> 0 | P41: =COUNTIFS('세부(구축)'!$B:$B,C41,'세부(구축)'!$J:$J,"발행") -> 0 | R41: =K41-P41 -> 0 | S41: =COUNTIFS('세부(구축)'!$I:$I,$C$12,'세부(구축)'!$B:$B,C41) -> 0 | T41: =COUNTIFS('세부(구축)'!$B:$B,C41,'세부(구축)'!$H:$H,TODAY()) -> 0 | U41: =L41+T41 -> 0 | AA41: =IF(OR(AND(ISNUMBER(T41), T41<>0), AND(ISNUMBER(U41), U41<>0), AND(ISNUMBER(S41), S41<>0),AND(ISNUMBER(M41), M41<>0)), 1, 0) -> 0
C42: 중소기업중앙회 | D42: 87 | E42: 62 | F42: 45 | G42: 45 | H42: 29 | I42: 0 | J42: 0 | K42: =COUNTIF('세부(구축)'!$B:$B,C42) -> 0 | L42: =COUNTIFS('세부(구축)'!$B:$B,C42,'세부(구축)'!$G:$G,"<>승인") -> 0 | M42: =COUNTIFS('세부(구축)'!$B:$B,C42,'세부(구축)'!$G:$G,"신규") -> 0 | N42: =COUNTIFS('세부(구축)'!$B:$B,C42,'세부(구축)'!$G:$G,"승인") -> 0 | O42: =COUNTIFS('세부(구축)'!$I:$I,$C$12,'세부(구축)'!$B:$B,C42) -> 0 | P42: =COUNTIFS('세부(구축)'!$B:$B,C42,'세부(구축)'!$J:$J,"발행") -> 0 | R42: =K42-P42 -> 0 | S42: =COUNTIFS('세부(구축)'!$I:$I,$C$12,'세부(구축)'!$B:$B,C42) -> 0 | T42: =COUNTIFS('세부(구축)'!$B:$B,C42,'세부(구축)'!$H:$H,TODAY()) -> 0 | U42: =L42+T42 -> 0 | AA42: =IF(OR(AND(ISNUMBER(T42), T42<>0), AND(ISNUMBER(U42), U42<>0), AND(ISNUMBER(S42), S42<>0),AND(ISNUMBER(M42), M42<>0)), 1, 0) -> 0
C43: 중소기업중앙회-원가감리 | F43: 0 | H43: 0 | I43: 0 | J43: 0 | K43: =COUNTIF('세부(구축)'!$B:$B,C43) -> 0 | L43: =COUNTIFS('세부(구축)'!$B:$B,C43,'세부(구축)'!$G:$G,"<>승인") -> 0 | M43: =COUNTIFS('세부(구축)'!$B:$B,C43,'세부(구축)'!$G:$G,"신규") -> 0 | N43: =COUNTIFS('세부(구축)'!$B:$B,C43,'세부(구축)'!$G:$G,"승인") -> 0 | O43: =COUNTIFS('세부(구축)'!$I:$I,$C$12,'세부(구축)'!$B:$B,C43) -> 0 | P43: =COUNTIFS('세부(구축)'!$B:$B,C43,'세부(구축)'!$J:$J,"발행") -> 0 | R43: =K43-P43 -> 0 | S43: =COUNTIFS('세부(구축)'!$I:$I,$C$12,'세부(구축)'!$B:$B,C43) -> 0 | T43: =COUNTIFS('세부(구축)'!$B:$B,C43,'세부(구축)'!$H:$H,TODAY()) -> 0 | U43: =L43+T43 -> 0 | AA43: =IF(OR(AND(ISNUMBER(T43), T43<>0), AND(ISNUMBER(U43), U43<>0), AND(ISNUMBER(S43), S43<>0),AND(ISNUMBER(M43), M43<>0)), 1, 0) -> 0
C44: 중소벤처기업진흥공단 | E44: 23 | F44: 34 | G44: 33 | H44: 16 | I44: 0 | J44: 0 | K44: =COUNTIF('세부(구축)'!$B:$B,C44) -> 0 | L44: =COUNTIFS('세부(구축)'!$B:$B,C44,'세부(구축)'!$G:$G,"<>승인") -> 0 | M44: =COUNTIFS('세부(구축)'!$B:$B,C44,'세부(구축)'!$G:$G,"신규") -> 0 | N44: =COUNTIFS('세부(구축)'!$B:$B,C44,'세부(구축)'!$G:$G,"승인") -> 0 | O44: =COUNTIFS('세부(구축)'!$I:$I,$C$12,'세부(구축)'!$B:$B,C44) -> 0 | P44: =COUNTIFS('세부(구축)'!$B:$B,C44,'세부(구축)'!$J:$J,"발행") -> 0 | R44: =K44-P44 -> 0 | S44: =COUNTIFS('세부(구축)'!$I:$I,$C$12,'세부(구축)'!$B:$B,C44) -> 0 | T44: =COUNTIFS('세부(구축)'!$B:$B,C44,'세부(구축)'!$H:$H,TODAY()) -> 0 | U44: =L44+T44 -> 0 | AA44: =IF(OR(AND(ISNUMBER(T44), T44<>0), AND(ISNUMBER(U44), U44<>0), AND(ISNUMBER(S44), S44<>0),AND(ISNUMBER(M44), M44<>0)), 1, 0) -> 0
C45: 한국생산기술연구원 | D45: 104 | E45: 11 | F45: 0 | H45: 0 | I45: 0 | J45: 0 | K45: =COUNTIF('세부(구축)'!$B:$B,C45) -> 0 | L45: =COUNTIFS('세부(구축)'!$B:$B,C45,'세부(구축)'!$G:$G,"<>승인") -> 0 | M45: =COUNTIFS('세부(구축)'!$B:$B,C45,'세부(구축)'!$G:$G,"신규") -> 0 | N45: =COUNTIFS('세부(구축)'!$B:$B,C45,'세부(구축)'!$G:$G,"승인") -> 0 | O45: =COUNTIFS('세부(구축)'!$I:$I,$C$12,'세부(구축)'!$B:$B,C45) -> 0 | P45: =COUNTIFS('세부(구축)'!$B:$B,C45,'세부(구축)'!$J:$J,"발행") -> 0 | R45: =K45-P45 -> 0 | S45: =COUNTIFS('세부(구축)'!$I:$I,$C$12,'세부(구축)'!$B:$B,C45) -> 0 | T45: =COUNTIFS('세부(구축)'!$B:$B,C45,'세부(구축)'!$H:$H,TODAY()) -> 0 | U45: =L45+T45 -> 0 | AA45: =IF(OR(AND(ISNUMBER(T45), T45<>0), AND(ISNUMBER(U45), U45<>0), AND(ISNUMBER(S45), S45<>0),AND(ISNUMBER(M45), M45<>0)), 1, 0) -> 0
C46: 한국생산성본부 | E46: 6 | F46: 51 | G46: 45 | H46: 18 | I46: 0 | J46: 50 | K46: =COUNTIF('세부(구축)'!$B:$B,C46) -> 0 | L46: =COUNTIFS('세부(구축)'!$B:$B,C46,'세부(구축)'!$G:$G,"<>승인") -> 0 | M46: =COUNTIFS('세부(구축)'!$B:$B,C46,'세부(구축)'!$G:$G,"신규") -> 0 | N46: =COUNTIFS('세부(구축)'!$B:$B,C46,'세부(구축)'!$G:$G,"승인") -> 0 | O46: =COUNTIFS('세부(구축)'!$I:$I,$C$12,'세부(구축)'!$B:$B,C46) -> 0 | P46: =COUNTIFS('세부(구축)'!$B:$B,C46,'세부(구축)'!$J:$J,"발행") -> 0 | R46: =K46-P46 -> 0 | S46: =COUNTIFS('세부(구축)'!$I:$I,$C$12,'세부(구축)'!$B:$B,C46) -> 0 | T46: =COUNTIFS('세부(구축)'!$B:$B,C46,'세부(구축)'!$H:$H,TODAY()) -> 0 | U46: =L46+T46 -> 0 | AA46: =IF(OR(AND(ISNUMBER(T46), T46<>0), AND(ISNUMBER(U46), U46<>0), AND(ISNUMBER(S46), S46<>0),AND(ISNUMBER(M46), M46<>0)), 1, 0) -> 0
C47: 한국스마트팩토리데이터협회 | D47: 13 | F47: 0 | H47: 0 | I47: 0 | J47: 0 | K47: =COUNTIF('세부(구축)'!$B:$B,C47) -> 0 | L47: =COUNTIFS('세부(구축)'!$B:$B,C47,'세부(구축)'!$G:$G,"<>승인") -> 0 | M47: =COUNTIFS('세부(구축)'!$B:$B,C47,'세부(구축)'!$G:$G,"신규") -> 0 | N47: =COUNTIFS('세부(구축)'!$B:$B,C47,'세부(구축)'!$G:$G,"승인") -> 0 | O47: =COUNTIFS('세부(구축)'!$I:$I,$C$12,'세부(구축)'!$B:$B,C47) -> 0 | P47: =COUNTIFS('세부(구축)'!$B:$B,C47,'세부(구축)'!$J:$J,"발행") -> 0 | R47: =K47-P47 -> 0 | S47: =COUNTIFS('세부(구축)'!$I:$I,$C$12,'세부(구축)'!$B:$B,C47) -> 0 | T47: =COUNTIFS('세부(구축)'!$B:$B,C47,'세부(구축)'!$H:$H,TODAY()) -> 0 | U47: =L47+T47 -> 0 | AA47: =IF(OR(AND(ISNUMBER(T47), T47<>0), AND(ISNUMBER(U47), U47<>0), AND(ISNUMBER(S47), S47<>0),AND(ISNUMBER(M47), M47<>0)), 1, 0) -> 0
...

Sheet 세부(구축)
A1: 세부 내용
A3: 순번 | B3: 요청기관 | C3: 사업분류 | D3: 세부공고명 | E3: 도입기업 | F3: 공급기업 | G3: 상태 | H3: 수령일 | I3: 제출일 | J3: 세금계산서 | K3: 대금수령 | L3: 보고서 작성자 | M3: 비고
A4: 1 | B4: 충북 | C4: 스마트공장 구축 및 고도화 사업(고도화1) | D4: 2026년도 정부형 스마트공장 구축사업 공고(고도화) | E4: ㈜모젤디앤에스 | F4: ㈜컨포트랩 | G4: 승인 | L4: 하은정 | P4: 농업회사법인 주식회사 연우 | Q4: (주)큐이노텍 | R4: =P4=E4 -> FALSE
A5: =A4+1 -> 2 | B5: 충북 | C5: 스마트공장 구축 및 고도화 사업(고도화1) | D5: 2026년도 정부형 스마트공장 구축사업 공고(고도화) | E5: 청호나이스㈜ | F5: 한솔코에버㈜ | G5: 승인 | L5: 하은정 | P5: 주식회사태원글로벌테크 | Q5: (주)큐이노텍 | R5: =P5=E5 -> FALSE
A6: =A5+1 -> 3 | B6: 경기대진 | C6: 스마트공장 구축 및 고도화 사업(고도화1) | D6: 2026년도 정부형 스마트공장 구축사업 공고(고도화) | E6: ㈜노나 | F6: ㈜아이씨엔아이이티 | G6: 승인 | L6: 하은정 | P6: (주)으뜸엘엔에스 | Q6: (주)큐이노텍 | R6: =P6=E6 -> FALSE
A7: =A6+1 -> 4 | B7: 경기대진 | C7: 스마트공장 구축 및 고도화 사업(고도화1) | D7: 2026년도 정부형 스마트공장 구축사업 공고(고도화) | E7: 솔브레인㈜ | F7: ㈜하이지노 | G7: 승인 | L7: 하은정 | P7: 주식회사 미소찬 | Q7: (주)에스엠해썹 | R7: =P7=E7 -> FALSE
A8: =A7+1 -> 5 | B8: 경기대진 | C8: 스마트공장 구축 및 고도화 사업(고도화1) | D8: 2026년도 정부형 스마트공장 구축사업 공고(고도화) | E8: ㈜신성베이커리 | F8: 솔뱅크정보㈜ | G8: 승인 | L8: 하은정 | P8: (주)메가코스 평택공장 | Q8: (주)루텍에스 | R8: =P8=E8 -> FALSE
A9: =A8+1 -> 6 | B9: 경기대진 | C9: 스마트공장 구축 및 고도화 사업(고도화1) | D9: 2026년도 정부형 스마트공장 구축사업 공고(고도화) | E9: ㈜안성기업 | F9: ㈜헤드아이티 | G9: 승인 | L9: 하은정 | P9: (주)태성산업 군포지점 | Q9: (주)루텍에스 | R9: =P9=E9 -> FALSE
A10: =A9+1 -> 7 | B10: 전남 | C10: 스마트공장 구축 및 고도화 사업(고도화1) | D10: 2026년도 정부형 스마트공장 구축사업 공고(고도화) | E10: ㈜삼정내츄럴 | F10: ㈜엘앤에스 | G10: 승인 | L10: 하은정
A11: =A10+1 -> 8 | B11: 전남 | C11: 스마트공장 구축 및 고도화 사업(고도화1) | D11: 2026년도 정부형 스마트공장 구축사업 공고(고도화) | E11: ㈜현대푸드시스템 | F11: ㈜하이스마트 | G11: 승인 | L11: 하은정 | N11: 7/30
A12: =A11+1 -> 9 | B12: 전남 | C12: 스마트공장 구축 및 고도화 사업(고도화1) | D12: 2026년도 정부형 스마트공장 구축사업 공고(고도화) | E12: ㈜경덕농수산 | F12: ㈜하이스마트 | G12: 승인 | L12: 하은정 | N12: 7/30
A13: =A12+1 -> 10 | B13: 한국과학기술원 | C13: 2026 | D13: 2026년 대전 AI 융합지원사업 제조 AI 솔루션 실증지원사업 | E13: 동아프라텍㈜ | F13: ㈜큐빅테크 | G13: 승인 | L13: 하은정 | N13: 8/9
A14: =A13+1 -> 11 | B14: 한국과학기술원 | C14: 2026 | D14: 2026년 대전 AI 융합지원사업 제조 AI 솔루션 실증지원사업 | E14: ㈜쓰리포인트덴탈 | F14: ㈜빛날덴탈스튜디오 | G14: 승인 | L14: 하은정 | P14: =COUNTIFS('세부(구축)'!$B:$B,C16,'세부(구축)'!$G:$G,"승인")
A15: =A14+1 -> 12 | B15: 경기대진 | C15: 스마트공장 구축 및 고도화 사업(동일수준) | D15: 2026년 스마트공장 구축 및 고도화 사업(동일수준) | E15: 에이스메티칼㈜ | F15: 워크핏㈜ | G15: 승인 | L15: 하은정
A16: =A15+1 -> 13 | B16: 광주 | C16: 스마트공장 구축 및 고도화 사업(고도화1) | D16: 2026년도 정부형 스마트공장 구축사업 공고(고도화) | E16: (주)커피볶는집 | F16: 주식회사 하이스마트 | G16: 승인 | L16: 하은정
A17: =A16+1 -> 14 | B17: 광주 | C17: 스마트공장 구축 및 고도화 사업(고도화1) | D17: 2026년도 정부형 스마트공장 구축사업 공고(고도화) | E17: 지금강㈜ | F17: (주)더블유비에스(WBS) | G17: 승인 | L17: 하은정
A18: =A17+1 -> 15 | B18: 광주 | C18: 스마트공장 구축 및 고도화 사업(고도화1) | D18: 2026년도 정부형 스마트공장 구축사업 공고(고도화) | E18: 광주포장산업 | F18: 주식회사 이지엠 | G18: 검토중 | L18: 하은정
A19: =A18+1 -> 16 | B19: 광주 | C19: 스마트공장 구축 및 고도화 사업(고도화1) | D19: 2026년도 정부형 스마트공장 구축사업 공고(고도화) | E19: 주식회사 정상에이치씨 | F19: 알엠텍주식회사 | G19: 검토중 | L19: 하은정
A20: =A19+1 -> 17 | B20: 광주 | C20: 스마트공장 구축 및 고도화 사업(고도화1) | D20: 2026년도 정부형 스마트공장 구축사업 공고(고도화) | E20: (주)아이코디 | F20: (주)쌍용소프트웨어 | G20: 검토중 | L20: 하은정
A21: =A20+1 -> 18 | B21: 광주 | C21: 스마트공장 구축 및 고도화 사업(고도화1) | D21: 2026년도 정부형 스마트공장 구축사업 공고(고도화) | E21: (주)엠피에스아이 | F21: (주)임픽스 | G21: 검토중 | L21: 하은정
A22: =A21+1 -> 19 | B22: 광주 | C22: 스마트공장 구축 및 고도화 사업(고도화1) | D22: 2026년도 정부형 스마트공장 구축사업 공고(고도화) | E22: 화천기공㈜ | F22: 주식회사 지앤씨소프트코리아 | G22: 검토중 | L22: 하은정 | P22: (주)건어명가디앤에이치 | Q22: 솔루션코리아(주) | R22: =P22=E22 -> FALSE
A23: =A22+1 -> 20 | B23: 한국농수산식품유통공사 | C23: 선도형 스마트공장(부처협업형) | D23: 2026년 부처협업형(K-푸드분야) 스마트공장 구축지원사업 | E23: (주)한국소스 | F23: 슬랙앤소프트 | G23: 승인 | L23: 하은정 | P23: (주)광명전기 | Q23: 삼미정보시스템 | R23: =P23=E23 -> FALSE
A24: =A23+1 -> 21 | B24: 한국농수산식품유통공사 | C24: 선도형 스마트공장(부처협업형) | D24: 2026년 부처협업형(K-푸드분야) 스마트공장 구축지원사업 | E24: 이레홍삼공사 | F24: 주식회사 스마트업 | G24: 승인 | L24: 하은정 | P24: (주)광성식품 | Q24: 플랭크 | R24: =P24=E24 -> FALSE
A25: =A24+1 -> 22 | B25: 전북 | C25: 스마트공장 구축 및 고도화 사업(신규구축) | D25: 2026년도 전북 지역특화형 스마트공장 구축지원 사업 공고(기초) | E25: 주식회사 춘향골식품 | F25: 주식회사 이지엠 | G25: 승인 | L25: 하은정 | P25: (주)대세 | Q25: 주식회사 제스텍 | R25: =P25=E25 -> FALSE
A26: =A25+1 -> 23 | B26: 전북 | C26: 스마트공장 구축 및 고도화 사업(신규구축) | D26: 2026년도 전북 지역특화형 스마트공장 구축지원 사업 공고(기초) | E26: 흥부골농업회사법인유한회사 | F26: (주)제이지컴퍼니 | G26: 승인 | L26: 하은정 | P26: (주)대영에스지 | Q26: (주)에이엔디시스템 | R26: =P26=E26 -> FALSE
A27: =A26+1 -> 24 | B27: 전북 | C27: 스마트공장 구축 및 고도화 사업(신규구축) | D27: 2026년도 전북 지역특화형 스마트공장 구축지원 사업 공고(기초) | E27: 마포종합식품 | F27: (주)망고시스템즈 | G27: 승인 | L27: 하은정 | P27: (주)대현산업 | Q27: 솔루션코리아(주) | R27: =P27=E27 -> FALSE
A28: =A27+1 -> 25 | B28: 전북 | C28: 스마트공장 구축 및 고도화 사업(신규구축) | D28: 2026년도 전북 지역특화형 스마트공장 구축지원 사업 공고(기초) | E28: 지리산처럼영농조합법인 | F28: 지음소프트 | G28: 승인 | L28: 하은정 | P28: (주)봉우금속 | Q28: 이크론소프트 | R28: =P28=E28 -> FALSE
A29: =A28+1 -> 26 | B29: 한국농수산식품유통공사 | C29: 선도형 스마트공장(부처협업형) | D29: 2026년 부처협업형(K-푸드분야) 스마트공장 구축지원사업 | E29: 보성일억조코리아 | F29: 주식회사 코드기어 | G29: 승인 | L29: 하은정 | P29: (주)서진밴드 | Q29: (주)미래융합정보기술 | R29: =P29=E29 -> FALSE
A30: =A29+1 -> 27 | B30: 한국농수산식품유통공사 | C30: 선도형 스마트공장(부처협업형) | D30: 2026년 부처협업형(K-푸드분야) 스마트공장 구축지원사업 | E30: 주식회사 스위트바이오 | F30: 주식회사 이노비 | G30: 승인 | L30: 하은정 | P30: (주)성화기계 | Q30: 강한솔루션 | R30: =P30=E30 -> FALSE
A31: =A30+1 -> 28 | B31: 한국농수산식품유통공사 | C31: 선도형 스마트공장(부처협업형) | D31: 2026년 부처협업형(K-푸드분야) 스마트공장 구축지원사업 | E31: 농업회사법인 주식회사 정남미그룹 | F31: 런시스(주) | G31: 승인 | L31: 하은정 | P31: (주)세림 | Q31: 넷플러스주식회사 | R31: =P31=E31 -> FALSE
A32: =A31+1 -> 29 | B32: 스마트제조혁신협회 | C32: 선도형 스마트공장(부처협업형) | D32: 2026년 부처협업형(화장품분야) 스마트공장 구축지원사업 | E32: 바른티에스테크 | F32: 라온비즈컴 주식회사 | G32: 승인 | L32: 하은정 | P32: (주)신라병가 | Q32: (주)투톤 | R32: =P32=E32 -> FALSE
A33: =A32+1 -> 30 | B33: 스마트제조혁신협회 | C33: 선도형 스마트공장(부처협업형) | D33: 2026년 부처협업형(화장품분야) 스마트공장 구축지원사업 | E33: 옥시젠디벨롭먼트(주) | F33: (주)인프라시스템 | G33: 승인 | L33: 하은정 | P33: (주)신화하이드로릭스 | Q33: (주)씨테크시스템 | R33: =P33=E33 -> FALSE
... A78: =A77+1 -> 75 | B78: 경남 | C78: 제조DX멘토단 활용지원(사후관리) | D78: [경남] 2026년 제조DX멘토단 활용지원(사후관리) 도입기업 모집 공고 | E78: 동인테크 | F78: (주)비엔씨정보기술 | G78: 승인 | L78: 하은정 | P78: 희수테크 | Q78: (주)태진시스템 | R78: =P78=E78 -> FALSE
A79: =A78+1 -> 76 | B79: 경남 | C79: 제조DX멘토단 활용지원(사후관리) | D79: [경남] 2026년 제조DX멘토단 활용지원(사후관리) 도입기업 모집 공고 | E79: (주)대륜 | F79: 에스티엘소프트 | G79: 승인 | L79: 하은정
A80: =A79+1 -> 77 | B80: 경남 | C80: 제조DX멘토단 활용지원(사후관리) | D80: [경남] 2026년 제조DX멘토단 활용지원(사후관리) 도입기업 모집 공고 | E80: 제일케미텍 | F80: 주식회사 키소스 | G80: 승인 | L80: 하은정
A81: =A80+1 -> 78 | B81: 경남 | C81: 제조DX멘토단 활용지원(사후관리) | D81: [경남] 2026년 제조DX멘토단 활용지원(사후관리) 도입기업 모집 공고 | E81: 농업회사법인진산명가주식회사 | F81: 주식회사 팔피엠 | G81: 승인 | L81: 하은정
A82: =A81+1 -> 79 | B82: 경남 | C82: 제조DX멘토단 활용지원(사후관리) | D82: [경남] 2026년 제조DX멘토단 활용지원(사후관리) 도입기업 모집 공고 | E82: 세일공업(주) | F82: (주)TIS | G82: 승인 | L82: 하은정
A83: =A82+1 -> 80 | B83: 경남 | C83: 제조DX멘토단 활용지원(사후관리) | D83: [경남] 2026년 제조DX멘토단 활용지원(사후관리) 도입기업 모집 공고 | E83: 금호조침 | F83: (주)매직시스템 | G83: 승인 | L83: 하은정
A84: =A83+1 -> 81 | B84: 경남 | C84: 제조DX멘토단 활용지원(사후관리) | D84: [경남] 2026년 제조DX멘토단 활용지원(사후관리) 도입기업 모집 공고 | E84: 동진기전 | F84: (주)비엔씨정보기술 | G84: 승인 | L84: 하은정
A85: =A84+1 -> 82 | B85: 경남 | C85: 제조DX멘토단 활용지원(사후관리) | D85: [경남] 2026년 제조DX멘토단 활용지원(사후관리) 도입기업 모집 공고 | E85: 삼원기업 | F85: (주)이지지오 | G85: 승인 | L85: 하은정
...

Sheet 결재도장란
P49: 결 재 | Q49: 담당 | S49: 검토 | U49: 이사 | W49: 원장
Q50: 김나경
Q55: =TODAY() -> 46189

Sheet 집계(구축)
A1: 2024년 스마트공장 구축지원사업 진행현황
A3: ○ 용역개요 | K3: =TODAY() -> 46189
A4: 주관기관 | C4: 주요내용 | U4: 전체 | V4: 완료 | W4: 진행중
A5: 중소벤처기업부 | C5: 스마트공장 구축(고도화)을 지원하여 기업의 제조혁신 경쟁력 향상 도모 | U5: =C10+#REF!+#REF!+#REF!+#REF!+#REF!+#REF!+#REF! -> #REF! | V5: =D10+#REF!+#REF!+#REF!+#REF!+#REF!+#REF!+#REF! -> #REF! | W5: =J10+#REF!+#REF!+#REF!+#REF!+#REF!+#REF!+#REF! -> #REF!
U6: ="취소 "&SUM(COUNTIF('세부(구축)'!M:M,"취소"),COUNTIF(#REF!,"취소"),COUNTIF(#REF!,"취소"),COUNTIF(#REF!,"취소"))&"건 포함" -> #REF!
A7: ○ 전체 진행현황
A8: 대상 | C8: 업무진행 | F8: 청구
C9: 수령건수 (A) | D9: 완료* (B) | E9: 진행중 (C=A-B) | F9: 세금계산서 발행(D) | G9: 대금수령 (E) | H9: 취소 | J9: 진행중
A10: =COUNTA(B16:B37)&"개 TP" -> 22개 TP | C10: =C38 -> 29 | D10: =D38 -> 0 | E10: =C10-D10 -> 29 | F10: =F38 -> 0 | G10: =G38 -> 0 | H10: =H38 -> 0 | J10: =C10-D10 -> 29
A11: ="*취소 "&H10&"건 포함" -> *취소 0건 포함 | I11: =D10-H10 -> 0
A13: ○ TP별 세부 진행현황
A14: 순번 | B14: 요청기관 | C14: 업무진행 | F14: 청구 | H14: 취소 | I14: 사업별 구분
C15: 수령건수 (A) | D15: 완료* (B) | E15: 진행중 (C=A-B) | F15: 세금계산서 발행(D) | G15: 대금수령 (E) | I15: (기초 및 고도화지원)농림부-삼성전자 | J15: (기초지원)지자체-삼성전자 | K15: (상생형)고도화-LG이노텍 | L15: (상생형)고도화-LG전자 | M15: (상생형)고도화-삼성전자 | N15: 경남형 스마트 제조혁신 프로젝트 | O15: 선도형 스마트공장(부처협업형) | P15: 스마트공장 AS 지원 | Q15: 스마트공장 구축 및 고도화 사업(고도화1) | R15: 스마트공장 구축 및 고도화 사업(동일수준) | S15: 전북형 스마트 제조혁신 프로젝트 | T15: 탄소중립형 스마트공장
A16: 1 | B16: 경기 | C16: =SUM(D16:E16) -> 0 | D16: =COUNTIFS('세부(구축)'!B:B,'집계(구축)'!B16,'세부(구축)'!G:G,"완료")+H16 -> 0 | E16: =SUM(COUNTIFS('세부(구축)'!B:B,'집계(구축)'!B16,'세부(구축)'!G:G,"작성중"),COUNTIFS('세부(구축)'!B:B,'집계(구축)'!B16,'세부(구축)'!G:G,"접수대기")) -> 0 | F16: =COUNTIFS('세부(구축)'!J:J,"발행",'세부(구축)'!$B:$B,'집계(구축)'!$B16) -> 0 | G16: =COUNTIFS('세부(구축)'!K:K,"수령",'세부(구축)'!$B:$B,'집계(구축)'!$B16) -> 0 | H16: =COUNTIFS('세부(구축)'!$B:$B,'집계(구축)'!B16,'세부(구축)'!$G:$G,"취소") -> 0 | I16: =COUNTIFS('세부(구축)'!B:B,'집계(구축)'!B$16,'세부(구축)'!C:C,'집계(구축)'!$I$15) -> 0 | J16: =COUNTIFS('세부(구축)'!$B:$B,'집계(구축)'!$B$16,'세부(구축)'!$C:$C,'집계(구축)'!J$15) -> 0 | K16: =COUNTIFS('세부(구축)'!$B:$B,'집계(구축)'!$B$16,'세부(구축)'!$C:$C,'집계(구축)'!K$15) -> 0 | L16: =COUNTIFS('세부(구축)'!$B:$B,'집계(구축)'!$B$16,'세부(구축)'!$C:$C,'집계(구축)'!L$15) -> 0 | M16: =COUNTIFS('세부(구축)'!$B:$B,'집계(구축)'!$B$16,'세부(구축)'!$C:$C,'집계(구축)'!M$15) -> 0 | N16: =COUNTIFS('세부(구축)'!$B:$B,'집계(구축)'!$B$16,'세부(구축)'!$C:$C,'집계(구축)'!N$15) -> 0 | O16: =COUNTIFS('세부(구축)'!$B:$B,'집계(구축)'!$B$16,'세부(구축)'!$C:$C,'집계(구축)'!O$15) -> 0 | P16: =COUNTIFS('세부(구축)'!$B:$B,'집계(구축)'!$B$16,'세부(구축)'!$C:$C,'집계(구축)'!P$15) -> 0 | Q16: =COUNTIFS('세부(구축)'!$B:$B,'집계(구축)'!$B$16,'세부(구축)'!$C:$C,'집계(구축)'!Q$15) -> 0 | ... T16: =COUNTIFS('세부(구축)'!$B:$B,'집계(구축)'!$B$16,'세부(구축)'!$C:$C,'집계(구축)'!T$15) -> 0
A17: =A16+1 -> 2 | B17: 경기북부 | C17: =SUM(D17:E17) -> 0 | D17: =COUNTIFS('세부(구축)'!B:B,'집계(구축)'!B17,'세부(구축)'!G:G,"완료")+H17 -> 0 | E17: =SUM(COUNTIFS('세부(구축)'!B:B,'집계(구축)'!B17,'세부(구축)'!G:G,"작성중"),COUNTIFS('세부(구축)'!B:B,'집계(구축)'!B17,'세부(구축)'!G:G,"접수대기")) -> 0 | F17: =COUNTIFS('세부(구축)'!J:J,"발행",'세부(구축)'!B:B,'집계(구축)'!B17) -> 0 | G17: =COUNTIFS('세부(구축)'!K:K,"수령",'세부(구축)'!$B:$B,'집계(구축)'!$B17) -> 0 | H17: =COUNTIFS('세부(구축)'!$B:$B,'집계(구축)'!B17,'세부(구축)'!$G:$G,"취소") -> 0 | I17: =COUNTIFS('세부(구축)'!$B:$B,'집계(구축)'!$B$17,'세부(구축)'!$C:$C,'집계(구축)'!I$15) -> 0 | J17: =COUNTIFS('세부(구축)'!$B:$B,'집계(구축)'!$B$17,'세부(구축)'!$C:$C,'집계(구축)'!J$15) -> 0 | K17: =COUNTIFS('세부(구축)'!$B:$B,'집계(구축)'!$B$17,'세부(구축)'!$C:$C,'집계(구축)'!K$15) -> 0 | L17: =COUNTIFS('세부(구축)'!$B:$B,'집계(구축)'!$B$17,'세부(구축)'!$C:$C,'집계(구축)'!L$15) -> 0 | M17: =COUNTIFS('세부(구축)'!$B:$B,'집계(구축)'!$B$17,'세부(구축)'!$C:$C,'집계(구축)'!M$15) -> 0 | N17: =COUNTIFS('세부(구축)'!$B:$B,'집계(구축)'!$B$17,'세부(구축)'!$C:$C,'집계(구축)'!N$15) -> 0 | O17: =COUNTIFS('세부(구축)'!$B:$B,'집계(구축)'!$B$17,'세부(구축)'!$C:$C,'집계(구축)'!O$15) -> 0 | P17: =COUNTIFS('세부(구축)'!$B:$B,'집계(구축)'!$B$17,'세부(구축)'!$C:$C,'집계(구축)'!P$15) -> 0 | ... T17: =COUNTIFS('세부(구축)'!$B:$B,'집계(구축)'!$B$17,'세부(구축)'!$C:$C,'집계(구축)'!T$15) -> 0
A18: =A17+1 -> 3 | B18: 경남 | C18: =SUM(D18:E18) -> 0 | D18: =COUNTIFS('세부(구축)'!B:B,'집계(구축)'!B18,'세부(구축)'!G:G,"완료")+H18 -> 0 | E18: =SUM(COUNTIFS('세부(구축)'!B:B,'집계(구축)'!B18,'세부(구축)'!G:G,"작성중"),COUNTIFS('세부(구축)'!B:B,'집계(구축)'!B18,'세부(구축)'!G:G,"접수대기")) -> 0 | F18: =COUNTIFS('세부(구축)'!J:J,"발행",'세부(구축)'!B:B,'집계(구축)'!B18) -> 0 | G18: =COUNTIFS('세부(구축)'!K:K,"수령",'세부(구축)'!$B:$B,'집계(구축)'!$B18) -> 0 | H18: =COUNTIFS('세부(구축)'!$B:$B,'집계(구축)'!B18,'세부(구축)'!$G:$G,"취소") -> 0 | I18: =COUNTIFS('세부(구축)'!B:B,'집계(구축)'!B18,'세부(구축)'!C:C,'집계(구축)'!$I$15) -> 0 | J18: =COUNTIFS('세부(구축)'!$B:$B,'집계(구축)'!$B18,'세부(구축)'!$C:$C,'집계(구축)'!J$15) -> 0 | K18: =COUNTIFS('세부(구축)'!$B:$B,'집계(구축)'!$B18,'세부(구축)'!$C:$C,'집계(구축)'!K$15) -> 0 | L18: =COUNTIFS('세부(구축)'!$B:$B,'집계(구축)'!$B18,'세부(구축)'!$C:$C,'집계(구축)'!L$15) -> 0 | M18: =COUNTIFS('세부(구축)'!$B:$B,'집계(구축)'!$B18,'세부(구축)'!$C:$C,'집계(구축)'!M$15) -> 0 | N18: =COUNTIFS('세부(구축)'!$B:$B,'집계(구축)'!$B18,'세부(구축)'!$C:$C,'집계(구축)'!N$15) -> 0 | O18: =COUNTIFS('세부(구축)'!$B:$B,'집계(구축)'!$B18,'세부(구축)'!$C:$C,'집계(구축)'!O$15) -> 0 | P18: =COUNTIFS('세부(구축)'!$B:$B,'집계(구축)'!$B18,'세부(구축)'!$C:$C,'집계(구축)'!P$15) -> 0 | Q18: =COUNTIFS('세부(구축)'!$B:$B,'집계(구축)'!$B18,'세부(구축)'!$C:$C,'집계(구축)'!Q$15) -> 0 | ... T18: =COUNTIFS('세부(구축)'!$B:$B,'집계(구축)'!$B18,'세부(구축)'!$C:$C,'집계(구축)'!T$15) -> 0
A19: =A18+1 -> 4 | B19: 대구 | C19: =SUM(D19:E19) -> 0 | D19: =COUNTIFS('세부(구축)'!B:B,'집계(구축)'!B19,'세부(구축)'!G:G,"완료")+H19 -> 0 | E19: =SUM(COUNTIFS('세부(구축)'!B:B,'집계(구축)'!B19,'세부(구축)'!G:G,"작성중"),COUNTIFS('세부(구축)'!B:B,'집계(구축)'!B19,'세부(구축)'!G:G,"접수대기")) -> 0 | F19: =COUNTIFS('세부(구축)'!J:J,"발행",'세부(구축)'!B:B,'집계(구축)'!B19) -> 0 | G19: =COUNTIFS('세부(구축)'!K:K,"수령",'세부(구축)'!$B:$B,'집계(구축)'!$B19) -> 0 | H19: =COUNTIFS('세부(구축)'!$B:$B,'집계(구축)'!B19,'세부(구축)'!$G:$G,"취소") -> 0 | I19: =COUNTIFS('세부(구축)'!B:B,'집계(구축)'!B19,'세부(구축)'!C:C,'집계(구축)'!$I$15) -> 0 | J19: =COUNTIFS('세부(구축)'!$B:$B,'집계(구축)'!$B19,'세부(구축)'!$C:$C,'집계(구축)'!J$15) -> 0 | K19: =COUNTIFS('세부(구축)'!$B:$B,'집계(구축)'!$B19,'세부(구축)'!$C:$C,'집계(구축)'!K$15) -> 0 | L19: =COUNTIFS('세부(구축)'!$B:$B,'집계(구축)'!$B19,'세부(구축)'!$C:$C,'집계(구축)'!L$15) -> 0 | M19: =COUNTIFS('세부(구축)'!$B:$B,'집계(구축)'!$B19,'세부(구축)'!$C:$C,'집계(구축)'!M$15) -> 0 | N19: =COUNTIFS('세부(구축)'!$B:$B,'집계(구축)'!$B19,'세부(구축)'!$C:$C,'집계(구축)'!N$15) -> 0 | O19: =COUNTIFS('세부(구축)'!$B:$B,'집계(구축)'!$B19,'세부(구축)'!$C:$C,'집계(구축)'!O$15) -> 0 | P19: =COUNTIFS('세부(구축)'!$B:$B,'집계(구축)'!$B19,'세부(구축)'!$C:$C,'집계(구축)'!P$15) -> 0 | Q19: =COUNTIFS('세부(구축)'!$B:$B,'집계(구축)'!$B19,'세부(구축)'!$C:$C,'집계(구축)'!Q$15) -> 0 | ... T19: =COUNTIFS('세부(구축)'!$B:$B,'집계(구축)'!$B19,'세부(구축)'!$C:$C,'집계(구축)'!T$15) -> 0
A20: =A19+1 -> 5 | B20: 대전 | C20: =SUM(D20:E20) -> 0 | D20: =COUNTIFS('세부(구축)'!B:B,'집계(구축)'!B20,'세부(구축)'!G:G,"완료")+H20 -> 0 | E20: =SUM(COUNTIFS('세부(구축)'!B:B,'집계(구축)'!B20,'세부(구축)'!G:G,"작성중"),COUNTIFS('세부(구축)'!B:B,'집계(구축)'!B20,'세부(구축)'!G:G,"접수대기")) -> 0 | F20: =COUNTIFS('세부(구축)'!J:J,"발행",'세부(구축)'!B:B,'집계(구축)'!B20) -> 0 | G20: =COUNTIFS('세부(구축)'!K:K,"수령",'세부(구축)'!$B:$B,'집계(구축)'!$B20) -> 0 | H20: =COUNTIFS('세부(구축)'!$B:$B,'집계(구축)'!B20,'세부(구축)'!$G:$G,"취소") -> 0 | I20: =COUNTIFS('세부(구축)'!B:B,'집계(구축)'!B20,'세부(구축)'!C:C,'집계(구축)'!$I$15) -> 0 | J20: =COUNTIFS('세부(구축)'!$B:$B,'집계(구축)'!$B20,'세부(구축)'!$C:$C,'집계(구축)'!J$15) -> 0 | K20: =COUNTIFS('세부(구축)'!$B:$B,'집계(구축)'!$B20,'세부(구축)'!$C:$C,'집계(구축)'!K$15) -> 0 | L20: =COUNTIFS('세부(구축)'!$B:$B,'집계(구축)'!$B20,'세부(구축)'!$C:$C,'집계(구축)'!L$15) -> 0 | M20: =COUNTIFS('세부(구축)'!$B:$B,'집계(구축)'!$B20,'세부(구축)'!$C:$C,'집계(구축)'!M$15) -> 0 | N20: =COUNTIFS('세부(구축)'!$B:$B,'집계(구축)'!$B20,'세부(구축)'!$C:$C,'집계(구축)'!N$15) -> 0 | O20: =COUNTIFS('세부(구축)'!$B:$B,'집계(구축)'!$B20,'세부(구축)'!$C:$C,'집계(구축)'!O$15) -> 0 | P20: =COUNTIFS('세부(구축)'!$B:$B,'집계(구축)'!$B20,'세부(구축)'!$C:$C,'집계(구축)'!P$15) -> 0 | Q20: =COUNTIFS('세부(구축)'!$B:$B,'집계(구축)'!$B20,'세부(구축)'!$C:$C,'집계(구축)'!Q$15) -> 0 | ... T20: =COUNTIFS('세부(구축)'!$B:$B,'집계(구축)'!$B20,'세부(구축)'!$C:$C,'집계(구축)'!T$15) -> 0
A21: =A20+1 -> 6 | B21: 부산 | C21: =SUM(D21:E21) -> 0 | D21: =COUNTIFS('세부(구축)'!B:B,'집계(구축)'!B21,'세부(구축)'!G:G,"완료")+H21 -> 0 | E21: =SUM(COUNTIFS('세부(구축)'!B:B,'집계(구축)'!B21,'세부(구축)'!G:G,"작성중"),COUNTIFS('세부(구축)'!B:B,'집계(구축)'!B21,'세부(구축)'!G:G,"접수대기")) -> 0 | F21: =COUNTIFS('세부(구축)'!J:J,"발행",'세부(구축)'!B:B,'집계(구축)'!B21) -> 0 | G21: =COUNTIFS('세부(구축)'!K:K,"수령",'세부(구축)'!$B:$B,'집계(구축)'!$B21) -> 0 | H21: =COUNTIFS('세부(구축)'!$B:$B,'집계(구축)'!B21,'세부(구축)'!$G:$G,"취소") -> 0 | I21: =COUNTIFS('세부(구축)'!B:B,'집계(구축)'!B21,'세부(구축)'!C:C,'집계(구축)'!$I$15) -> 0 | J21: =COUNTIFS('세부(구축)'!$B:$B,'집계(구축)'!$B21,'세부(구축)'!$C:$C,'집계(구축)'!J$15) -> 0 | K21: =COUNTIFS('세부(구축)'!$B:$B,'집계(구축)'!$B21,'세부(구축)'!$C:$C,'집계(구축)'!K$15) -> 0 | L21: =COUNTIFS('세부(구축)'!$B:$B,'집계(구축)'!$B21,'세부(구축)'!$C:$C,'집계(구축)'!L$15) -> 0 | M21: =COUNTIFS('세부(구축)'!$B:$B,'집계(구축)'!$B21,'세부(구축)'!$C:$C,'집계(구축)'!M$15) -> 0 | N21: =COUNTIFS('세부(구축)'!$B:$B,'집계(구축)'!$B21,'세부(구축)'!$C:$C,'집계(구축)'!N$15) -> 0 | O21: =COUNTIFS('세부(구축)'!$B:$B,'집계(구축)'!$B21,'세부(구축)'!$C:$C,'집계(구축)'!O$15) -> 0 | P21: =COUNTIFS('세부(구축)'!$B:$B,'집계(구축)'!$B21,'세부(구축)'!$C:$C,'집계(구축)'!P$15) -> 0 | Q21: =COUNTIFS('세부(구축)'!$B:$B,'집계(구축)'!$B21,'세부(구축)'!$C:$C,'집계(구축)'!Q$15) -> 0 | ... T21: =COUNTIFS('세부(구축)'!$B:$B,'집계(구축)'!$B21,'세부(구축)'!$C:$C,'집계(구축)'!T$15) -> 0
A22: =A21+1 -> 7 | B22: 세종 | C22: =SUM(D22:E22) -> 0 | D22: =COUNTIFS('세부(구축)'!B:B,'집계(구축)'!B22,'세부(구축)'!G:G,"완료")+H22 -> 0 | E22: =SUM(COUNTIFS('세부(구축)'!B:B,'집계(구축)'!B22,'세부(구축)'!G:G,"작성중"),COUNTIFS('세부(구축)'!B:B,'집계(구축)'!B22,'세부(구축)'!G:G,"접수대기")) -> 0 | F22: =COUNTIFS('세부(구축)'!J:J,"발행",'세부(구축)'!B:B,'집계(구축)'!B22) -> 0 | G22: =COUNTIFS('세부(구축)'!K:K,"수령",'세부(구축)'!$B:$B,'집계(구축)'!$B22) -> 0 | H22: =COUNTIFS('세부(구축)'!$B:$B,'집계(구축)'!B22,'세부(구축)'!$G:$G,"취소") -> 0 | I22: =COUNTIFS('세부(구축)'!B:B,'집계(구축)'!B22,'세부(구축)'!C:C,'집계(구축)'!$I$15) -> 0 | J22: =COUNTIFS('세부(구축)'!$B:$B,'집계(구축)'!$B22,'세부(구축)'!$C:$C,'집계(구축)'!J$15) -> 0 | K22: =COUNTIFS('세부(구축)'!$B:$B,'집계(구축)'!$B22,'세부(구축)'!$C:$C,'집계(구축)'!K$15) -> 0 | L22: =COUNTIFS('세부(구축)'!$B:$B,'집계(구축)'!$B22,'세부(구축)'!$C:$C,'집계(구축)'!L$15) -> 0 | M22: =COUNTIFS('세부(구축)'!$B:$B,'집계(구축)'!$B22,'세부(구축)'!$C:$C,'집계(구축)'!M$15) -> 0 | N22: =COUNTIFS('세부(구축)'!$B:$B,'집계(구축)'!$B22,'세부(구축)'!$C:$C,'집계(구축)'!N$15) -> 0 | O22: =COUNTIFS('세부(구축)'!$B:$B,'집계(구축)'!$B22,'세부(구축)'!$C:$C,'집계(구축)'!O$15) -> 0 | P22: =COUNTIFS('세부(구축)'!$B:$B,'집계(구축)'!$B22,'세부(구축)'!$C:$C,'집계(구축)'!P$15) -> 0 | Q22: =COUNTIFS('세부(구축)'!$B:$B,'집계(구축)'!$B22,'세부(구축)'!$C:$C,'집계(구축)'!Q$15) -> 0 | ... T22: =COUNTIFS('세부(구축)'!$B:$B,'집계(구축)'!$B22,'세부(구축)'!$C:$C,'집계(구축)'!T$15) -> 0
A23: =A22+1 -> 8 | B23: 울산 | C23: =SUM(D23:E23) -> 0 | D23: =COUNTIFS('세부(구축)'!B:B,'집계(구축)'!B23,'세부(구축)'!G:G,"완료")+H23 -> 0 | E23: =SUM(COUNTIFS('세부(구축)'!B:B,'집계(구축)'!B23,'세부(구축)'!G:G,"작성중"),COUNTIFS('세부(구축)'!B:B,'집계(구축)'!B23,'세부(구축)'!G:G,"접수대기")) -> 0 | F23: =COUNTIFS('세부(구축)'!J:J,"발행",'세부(구축)'!B:B,'집계(구축)'!B23) -> 0 | G23: =COUNTIFS('세부(구축)'!K:K,"수령",'세부(구축)'!$B:$B,'집계(구축)'!$B23) -> 0 | H23: =COUNTIFS('세부(구축)'!$B:$B,'집계(구축)'!B23,'세부(구축)'!$G:$G,"취소") -> 0 | I23: =COUNTIFS('세부(구축)'!B:B,'집계(구축)'!B23,'세부(구축)'!C:C,'집계(구축)'!$I$15) -> 0 | J23: =COUNTIFS('세부(구축)'!$B:$B,'집계(구축)'!$B23,'세부(구축)'!$C:$C,'집계(구축)'!J$15) -> 0 | K23: =COUNTIFS('세부(구축)'!$B:$B,'집계(구축)'!$B23,'세부(구축)'!$C:$C,'집계(구축)'!K$15) -> 0 | L23: =COUNTIFS('세부(구축)'!$B:$B,'집계(구축)'!$B23,'세부(구축)'!$C:$C,'집계(구축)'!L$15) -> 0 | M23: =COUNTIFS('세부(구축)'!$B:$B,'집계(구축)'!$B23,'세부(구축)'!$C:$C,'집계(구축)'!M$15) -> 0 | N23: =COUNTIFS('세부(구축)'!$B:$B,'집계(구축)'!$B23,'세부(구축)'!$C:$C,'집계(구축)'!N$15) -> 0 | O23: =COUNTIFS('세부(구축)'!$B:$B,'집계(구축)'!$B23,'세부(구축)'!$C:$C,'집계(구축)'!O$15) -> 0 | P23: =COUNTIFS('세부(구축)'!$B:$B,'집계(구축)'!$B23,'세부(구축)'!$C:$C,'집계(구축)'!P$15) -> 0 | Q23: =COUNTIFS('세부(구축)'!$B:$B,'집계(구축)'!$B23,'세부(구축)'!$C:$C,'집계(구축)'!Q$15) -> 0 | ... T23: =COUNTIFS('세부(구축)'!$B:$B,'집계(구축)'!$B23,'세부(구축)'!$C:$C,'집계(구축)'!T$15) -> 0
A24: =A23+1 -> 9 | B24: 인천 | C24: =SUM(D24:E24) -> 13 | D24: =COUNTIFS('세부(구축)'!B:B,'집계(구축)'!B24,'세부(구축)'!G:G,"완료")+H24 -> 0 | E24: =SUM(COUNTIFS('세부(구축)'!B:B,'집계(구축)'!B24,'세부(구축)'!G:G,"작성중"),COUNTIFS('세부(구축)'!B:B,'집계(구축)'!B24,'세부(구축)'!G:G,"접수대기")) -> 13 | F24: =COUNTIFS('세부(구축)'!J:J,"발행",'세부(구축)'!B:B,'집계(구축)'!B24) -> 0 | G24: =COUNTIFS('세부(구축)'!K:K,"수령",'세부(구축)'!$B:$B,'집계(구축)'!$B24) -> 0 | H24: =COUNTIFS('세부(구축)'!$B:$B,'집계(구축)'!B24,'세부(구축)'!$G:$G,"취소") -> 0 | I24: =COUNTIFS('세부(구축)'!B:B,'집계(구축)'!B24,'세부(구축)'!C:C,'집계(구축)'!$I$15) -> 0 | J24: =COUNTIFS('세부(구축)'!$B:$B,'집계(구축)'!$B24,'세부(구축)'!$C:$C,'집계(구축)'!J$15) -> 0 | K24: =COUNTIFS('세부(구축)'!$B:$B,'집계(구축)'!$B24,'세부(구축)'!$C:$C,'집계(구축)'!K$15) -> 0 | L24: =COUNTIFS('세부(구축)'!$B:$B,'집계(구축)'!$B24,'세부(구축)'!$C:$C,'집계(구축)'!L$15) -> 0 | M24: =COUNTIFS('세부(구축)'!$B:$B,'집계(구축)'!$B24,'세부(구축)'!$C:$C,'집계(구축)'!M$15) -> 0 | N24: =COUNTIFS('세부(구축)'!$B:$B,'집계(구축)'!$B24,'세부(구축)'!$C:$C,'집계(구축)'!N$15) -> 0 | O24: =COUNTIFS('세부(구축)'!$B:$B,'집계(구축)'!$B24,'세부(구축)'!$C:$C,'집계(구축)'!O$15) -> 0 | P24: =COUNTIFS('세부(구축)'!$B:$B,'집계(구축)'!$B24,'세부(구축)'!$C:$C,'집계(구축)'!P$15) -> 0 | Q24: =COUNTIFS('세부(구축)'!$B:$B,'집계(구축)'!$B24,'세부(구축)'!$C:$C,'집계(구축)'!Q$15) -> 0 | ... T24: =COUNTIFS('세부(구축)'!$B:$B,'집계(구축)'!$B24,'세부(구축)'!$C:$C,'집계(구축)'!T$15) -> 0
A25: =A24+1 -> 10 | B25: 전남 | C25: =SUM(D25:E25) -> 1 | D25: =COUNTIFS('세부(구축)'!B:B,'집계(구축)'!B25,'세부(구축)'!G:G,"완료")+H25 -> 0 | E25: =SUM(COUNTIFS('세부(구축)'!B:B,'집계(구축)'!B25,'세부(구축)'!G:G,"작성중"),COUNTIFS('세부(구축)'!B:B,'집계(구축)'!B25,'세부(구축)'!G:G,"접수대기")) -> 1 | F25: =COUNTIFS('세부(구축)'!J:J,"발행",'세부(구축)'!B:B,'집계(구축)'!B25) -> 0 | G25: =COUNTIFS('세부(구축)'!K:K,"수령",'세부(구축)'!$B:$B,'집계(구축)'!$B25) -> 0 | H25: =COUNTIFS('세부(구축)'!$B:$B,'집계(구축)'!B25,'세부(구축)'!$G:$G,"취소") -> 0 | I25: =COUNTIFS('세부(구축)'!B:B,'집계(구축)'!B25,'세부(구축)'!C:C,'집계(구축)'!$I$15) -> 0 | J25: =COUNTIFS('세부(구축)'!$B:$B,'집계(구축)'!$B25,'세부(구축)'!$C:$C,'집계(구축)'!J$15) -> 0 | K25: =COUNTIFS('세부(구축)'!$B:$B,'집계(구축)'!$B25,'세부(구축)'!$C:$C,'집계(구축)'!K$15) -> 0 | L25: =COUNTIFS('세부(구축)'!$B:$B,'집계(구축)'!$B25,'세부(구축)'!$C:$C,'집계(구축)'!L$15) -> 0 | M25: =COUNTIFS('세부(구축)'!$B:$B,'집계(구축)'!$B25,'세부(구축)'!$C:$C,'집계(구축)'!M$15) -> 0 | N25: =COUNTIFS('세부(구축)'!$B:$B,'집계(구축)'!$B25,'세부(구축)'!$C:$C,'집계(구축)'!N$15) -> 0 | O25: =COUNTIFS('세부(구축)'!$B:$B,'집계(구축)'!$B25,'세부(구축)'!$C:$C,'집계(구축)'!O$15) -> 0 | P25: =COUNTIFS('세부(구축)'!$B:$B,'집계(구축)'!$B25,'세부(구축)'!$C:$C,'집계(구축)'!P$15) -> 0 | Q25: =COUNTIFS('세부(구축)'!$B:$B,'집계(구축)'!$B25,'세부(구축)'!$C:$C,'집계(구축)'!Q$15) -> 4 | ... T25: =COUNTIFS('세부(구축)'!$B:$B,'집계(구축)'!$B25,'세부(구축)'!$C:$C,'집계(구축)'!T$15) -> 0
A26: =A25+1 -> 11 | B26: 전북 | C26: =SUM(D26:E26) -> 0 | D26: =COUNTIFS('세부(구축)'!B:B,'집계(구축)'!B26,'세부(구축)'!G:G,"완료")+H26 -> 0 | E26: =SUM(COUNTIFS('세부(구축)'!B:B,'집계(구축)'!B26,'세부(구축)'!G:G,"작성중"),COUNTIFS('세부(구축)'!B:B,'집계(구축)'!B26,'세부(구축)'!G:G,"접수대기")) -> 0 | F26: =COUNTIFS('세부(구축)'!J:J,"발행",'세부(구축)'!B:B,'집계(구축)'!B26) -> 0 | G26: =COUNTIFS('세부(구축)'!K:K,"수령",'세부(구축)'!$B:$B,'집계(구축)'!$B26) -> 0 | H26: =COUNTIFS('세부(구축)'!$B:$B,'집계(구축)'!B26,'세부(구축)'!$G:$G,"취소") -> 0 | I26: =COUNTIFS('세부(구축)'!B:B,'집계(구축)'!B26,'세부(구축)'!C:C,'집계(구축)'!$I$15) -> 0 | J26: =COUNTIFS('세부(구축)'!$B:$B,'집계(구축)'!$B26,'세부(구축)'!$C:$C,'집계(구축)'!J$15) -> 0 | K26: =COUNTIFS('세부(구축)'!$B:$B,'집계(구축)'!$B26,'세부(구축)'!$C:$C,'집계(구축)'!K$15) -> 0 | L26: =COUNTIFS('세부(구축)'!$B:$B,'집계(구축)'!$B26,'세부(구축)'!$C:$C,'집계(구축)'!L$15) -> 0 | M26: =COUNTIFS('세부(구축)'!$B:$B,'집계(구축)'!$B26,'세부(구축)'!$C:$C,'집계(구축)'!M$15) -> 0 | N26: =COUNTIFS('세부(구축)'!$B:$B,'집계(구축)'!$B26,'세부(구축)'!$C:$C,'집계(구축)'!N$15) -> 0 | O26: =COUNTIFS('세부(구축)'!$B:$B,'집계(구축)'!$B26,'세부(구축)'!$C:$C,'집계(구축)'!O$15) -> 0 | P26: =COUNTIFS('세부(구축)'!$B:$B,'집계(구축)'!$B26,'세부(구축)'!$C:$C,'집계(구축)'!P$15) -> 0 | Q26: =COUNTIFS('세부(구축)'!$B:$B,'집계(구축)'!$B26,'세부(구축)'!$C:$C,'집계(구축)'!Q$15) -> 0 | ... T26: =COUNTIFS('세부(구축)'!$B:$B,'집계(구축)'!$B26,'세부(구축)'!$C:$C,'집계(구축)'!T$15) -> 0
A27: =A26+1 -> 12 | B27: 충남 | C27: =SUM(D27:E27) -> 0 | D27: =COUNTIFS('세부(구축)'!B:B,'집계(구축)'!B27,'세부(구축)'!G:G,"완료")+H27 -> 0 | E27: =SUM(COUNTIFS('세부(구축)'!B:B,'집계(구축)'!B27,'세부(구축)'!G:G,"작성중"),COUNTIFS('세부(구축)'!B:B,'집계(구축)'!B27,'세부(구축)'!G:G,"접수대기")) -> 0 | F27: =COUNTIFS('세부(구축)'!J:J,"발행",'세부(구축)'!B:B,'집계(구축)'!B27) -> 0 | G27: =COUNTIFS('세부(구축)'!K:K,"수령",'세부(구축)'!$B:$B,'집계(구축)'!$B27) -> 0 | H27: =COUNTIFS('세부(구축)'!$B:$B,'집계(구축)'!B27,'세부(구축)'!$G:$G,"취소") -> 0 | I27: =COUNTIFS('세부(구축)'!B:B,'집계(구축)'!B27,'세부(구축)'!C:C,'집계(구축)'!$I$15) -> 0 | J27: =COUNTIFS('세부(구축)'!$B:$B,'집계(구축)'!$B27,'세부(구축)'!$C:$C,'집계(구축)'!J$15) -> 0 | K27: =COUNTIFS('세부(구축)'!$B:$B,'집계(구축)'!$B27,'세부(구축)'!$C:$C,'집계(구축)'!K$15) -> 0 | L27: =COUNTIFS('세부(구축)'!$B:$B,'집계(구축)'!$B27,'세부(구축)'!$C:$C,'집계(구축)'!L$15) -> 0 | M27: =COUNTIFS('세부(구축)'!$B:$B,'집계(구축)'!$B27,'세부(구축)'!$C:$C,'집계(구축)'!M$15) -> 0 | N27: =COUNTIFS('세부(구축)'!$B:$B,'집계(구축)'!$B27,'세부(구축)'!$C:$C,'집계(구축)'!N$15) -> 0 | O27: =COUNTIFS('세부(구축)'!$B:$B,'집계(구축)'!$B27,'세부(구축)'!$C:$C,'집계(구축)'!O$15) -> 0 | P27: =COUNTIFS('세부(구축)'!$B:$B,'집계(구축)'!$B27,'세부(구축)'!$C:$C,'집계(구축)'!P$15) -> 0 | Q27: =COUNTIFS('세부(구축)'!$B:$B,'집계(구축)'!$B27,'세부(구축)'!$C:$C,'집계(구축)'!Q$15) -> 0 | ... T27: =COUNTIFS('세부(구축)'!$B:$B,'집계(구축)'!$B27,'세부(구축)'!$C:$C,'집계(구축)'!T$15) -> 0
A28: =A27+1 -> 13 | B28: 충북 | C28: =SUM(D28:E28) -> 1 | D28: =COUNTIFS('세부(구축)'!B:B,'집계(구축)'!B28,'세부(구축)'!G:G,"완료")+H28 -> 0 | E28: =SUM(COUNTIFS('세부(구축)'!B:B,'집계(구축)'!B28,'세부(구축)'!G:G,"작성중"),COUNTIFS('세부(구축)'!B:B,'집계(구축)'!B28,'세부(구축)'!G:G,"접수대기")) -> 1 | F28: =COUNTIFS('세부(구축)'!J:J,"발행",'세부(구축)'!B:B,'집계(구축)'!B28) -> 0 | G28: =COUNTIFS('세부(구축)'!K:K,"수령",'세부(구축)'!$B:$B,'집계(구축)'!$B28) -> 0 | H28: =COUNTIFS('세부(구축)'!$B:$B,'집계(구축)'!B28,'세부(구축)'!$G:$G,"취소") -> 0 | I28: =COUNTIFS('세부(구축)'!B:B,'집계(구축)'!B28,'세부(구축)'!C:C,'집계(구축)'!$I$15) -> 0 | J28: =COUNTIFS('세부(구축)'!$B:$B,'집계(구축)'!$B28,'세부(구축)'!$C:$C,'집계(구축)'!J$15) -> 0 | K28: =COUNTIFS('세부(구축)'!$B:$B,'집계(구축)'!$B28,'세부(구축)'!$C:$C,'집계(구축)'!K$15) -> 0 | L28: =COUNTIFS('세부(구축)'!$B:$B,'집계(구축)'!$B28,'세부(구축)'!$C:$C,'집계(구축)'!L$15) -> 0 | M28: =COUNTIFS('세부(구축)'!$B:$B,'집계(구축)'!$B28,'세부(구축)'!$C:$C,'집계(구축)'!M$15) -> 0 | N28: =COUNTIFS('세부(구축)'!$B:$B,'집계(구축)'!$B28,'세부(구축)'!$C:$C,'집계(구축)'!N$15) -> 0 | O28: =COUNTIFS('세부(구축)'!$B:$B,'집계(구축)'!$B28,'세부(구축)'!$C:$C,'집계(구축)'!O$15) -> 0 | P28: =COUNTIFS('세부(구축)'!$B:$B,'집계(구축)'!$B28,'세부(구축)'!$C:$C,'집계(구축)'!P$15) -> 0 | Q28: =COUNTIFS('세부(구축)'!$B:$B,'집계(구축)'!$B28,'세부(구축)'!$C:$C,'집계(구축)'!Q$15) -> 2 | ... T28: =COUNTIFS('세부(구축)'!$B:$B,'집계(구축)'!$B28,'세부(구축)'!$C:$C,'집계(구축)'!T$15) -> 0
A29: =A28+1 -> 14 | B29: 제주 | C29: =SUM(D29:E29) -> 0 | D29: =COUNTIFS('세부(구축)'!B:B,'집계(구축)'!B29,'세부(구축)'!G:G,"완료")+H29 -> 0 | E29: =SUM(COUNTIFS('세부(구축)'!B:B,'집계(구축)'!B29,'세부(구축)'!G:G,"작성중"),COUNTIFS('세부(구축)'!B:B,'집계(구축)'!B29,'세부(구축)'!G:G,"접수대기")) -> 0 | F29: =COUNTIFS('세부(구축)'!J:J,"발행",'세부(구축)'!B:B,'집계(구축)'!B29) -> 0 | G29: =COUNTIFS('세부(구축)'!K:K,"수령",'세부(구축)'!$B:$B,'집계(구축)'!$B29) -> 0 | H29: =COUNTIFS('세부(구축)'!$B:$B,'집계(구축)'!B29,'세부(구축)'!$G:$G,"취소") -> 0
A30: =A29+1 -> 15 | B30: 경북 | C30: =SUM(D30:E30) -> 13 | D30: =COUNTIFS('세부(구축)'!B:B,'집계(구축)'!B30,'세부(구축)'!G:G,"완료")+H30 -> 0 | E30: =SUM(COUNTIFS('세부(구축)'!B:B,'집계(구축)'!B30,'세부(구축)'!G:G,"작성중"),COUNTIFS('세부(구축)'!B:B,'집계(구축)'!B30,'세부(구축)'!G:G,"접수대기")) -> 13 | F30: =COUNTIFS('세부(구축)'!J:J,"발행",'세부(구축)'!B:B,'집계(구축)'!B30) -> 0 | G30: =COUNTIFS('세부(구축)'!K:K,"수령",'세부(구축)'!$B:$B,'집계(구축)'!$B30) -> 0 | H30: =COUNTIFS('세부(구축)'!$B:$B,'집계(구축)'!B30,'세부(구축)'!$G:$G,"취소") -> 0
A31: =A30+1 -> 16 | B31: 강원 | C31: =SUM(D31:E31) -> 0 | D31: =COUNTIFS('세부(구축)'!B:B,'집계(구축)'!B31,'세부(구축)'!G:G,"완료")+H31 -> 0 | E31: =SUM(COUNTIFS('세부(구축)'!B:B,'집계(구축)'!B31,'세부(구축)'!G:G,"작성중"),COUNTIFS('세부(구축)'!B:B,'집계(구축)'!B31,'세부(구축)'!G:G,"접수대기")) -> 0 | F31: =COUNTIFS('세부(구축)'!J:J,"발행",'세부(구축)'!B:B,'집계(구축)'!B31) -> 0 | G31: =COUNTIFS('세부(구축)'!K:K,"수령",'세부(구축)'!$B:$B,'집계(구축)'!$B31) -> 0 | H31: =COUNTIFS('세부(구축)'!$B:$B,'집계(구축)'!B31,'세부(구축)'!$G:$G,"취소") -> 0
A32: =A31+1 -> 17 | B32: 포항 | C32: =SUM(D32:E32) -> 0 | D32: =COUNTIFS('세부(구축)'!B:B,'집계(구축)'!B32,'세부(구축)'!G:G,"완료")+H32 -> 0 | E32: =SUM(COUNTIFS('세부(구축)'!B:B,'집계(구축)'!B32,'세부(구축)'!G:G,"작성중"),COUNTIFS('세부(구축)'!B:B,'집계(구축)'!B32,'세부(구축)'!G:G,"접수대기")) -> 0 | F32: =COUNTIFS('세부(구축)'!J:J,"발행",'세부(구축)'!B:B,'집계(구축)'!B32) -> 0 | G32: =COUNTIFS('세부(구축)'!K:K,"수령",'세부(구축)'!$B:$B,'집계(구축)'!$B32) -> 0 | H32: =COUNTIFS('세부(구축)'!$B:$B,'집계(구축)'!B32,'세부(구축)'!$G:$G,"취소") -> 0
A33: =A32+1 -> 18 | B33: 광주 | C33: =SUM(D33:E33) -> 0 | D33: =COUNTIFS('세부(구축)'!B:B,'집계(구축)'!B33,'세부(구축)'!G:G,"완료")+H33 -> 0 | E33: =SUM(COUNTIFS('세부(구축)'!B:B,'집계(구축)'!B33,'세부(구축)'!G:G,"작성중"),COUNTIFS('세부(구축)'!B:B,'집계(구축)'!B33,'세부(구축)'!G:G,"접수대기")) -> 0 | F33: =COUNTIFS('세부(구축)'!J:J,"발행",'세부(구축)'!B:B,'집계(구축)'!B33) -> 0 | G33: =COUNTIFS('세부(구축)'!K:K,"수령",'세부(구축)'!$B:$B,'집계(구축)'!$B33) -> 0 | H33: =COUNTIFS('세부(구축)'!$B:$B,'집계(구축)'!B33,'세부(구축)'!$G:$G,"취소") -> 0
A34: =A33+1 -> 19 | B34: 서울 | C34: =SUM(D34:E34) -> 0 | D34: =COUNTIFS('세부(구축)'!B:B,'집계(구축)'!B34,'세부(구축)'!G:G,"완료")+H34 -> 0 | E34: =SUM(COUNTIFS('세부(구축)'!B:B,'집계(구축)'!B34,'세부(구축)'!G:G,"작성중"),COUNTIFS('세부(구축)'!B:B,'집계(구축)'!B34,'세부(구축)'!G:G,"접수대기")) -> 0 | F34: =COUNTIFS('세부(구축)'!J:J,"발행",'세부(구축)'!B:B,'집계(구축)'!B34) -> 0 | G34: =COUNTIFS('세부(구축)'!K:K,"수령",'세부(구축)'!$B:$B,'집계(구축)'!$B34) -> 0 | H34: =COUNTIFS('세부(구축)'!$B:$B,'집계(구축)'!B34,'세부(구축)'!$G:$G,"취소") -> 0
A35: =A34+1 -> 20 | B35: 한국과학기술원 | C35: =SUM(D35:E35) -> 0 | D35: =COUNTIFS('세부(구축)'!B:B,'집계(구축)'!B35,'세부(구축)'!G:G,"완료")+H35 -> 0 | E35: =SUM(COUNTIFS('세부(구축)'!B:B,'집계(구축)'!B35,'세부(구축)'!G:G,"작성중"),COUNTIFS('세부(구축)'!B:B,'집계(구축)'!B35,'세부(구축)'!G:G,"접수대기")) -> 0 | F35: =COUNTIFS('세부(구축)'!J:J,"발행",'세부(구축)'!B:B,'집계(구축)'!B35) -> 0 | G35: =COUNTIFS('세부(구축)'!K:K,"수령",'세부(구축)'!$B:$B,'집계(구축)'!$B35) -> 0 | H35: =COUNTIFS('세부(구축)'!$B:$B,'집계(구축)'!B35,'세부(구축)'!$G:$G,"취소") -> 0
A36: =A35+1 -> 21 | B36: 경기대진 | C36: =SUM(D36:E36) -> 1 | D36: =COUNTIFS('세부(구축)'!B:B,'집계(구축)'!B36,'세부(구축)'!G:G,"완료")+H36 -> 0 | E36: =SUM(COUNTIFS('세부(구축)'!B:B,'집계(구축)'!B36,'세부(구축)'!G:G,"작성중"),COUNTIFS('세부(구축)'!B:B,'집계(구축)'!B36,'세부(구축)'!G:G,"접수대기")) -> 1 | F36: =COUNTIFS('세부(구축)'!J:J,"발행",'세부(구축)'!B:B,'집계(구축)'!B36) -> 0 | G36: =COUNTIFS('세부(구축)'!K:K,"수령",'세부(구축)'!$B:$B,'집계(구축)'!$B36) -> 0 | H36: =COUNTIFS('세부(구축)'!$B:$B,'집계(구축)'!B36,'세부(구축)'!$G:$G,"취소") -> 0
A37: =A36+1 -> 22 | B37: 이노비즈협회 | C37: =SUM(D37:E37) -> 0 | D37: =COUNTIFS('세부(구축)'!B:B,'집계(구축)'!B37,'세부(구축)'!G:G,"완료")+H37 -> 0 | E37: =SUM(COUNTIFS('세부(구축)'!B:B,'집계(구축)'!B37,'세부(구축)'!G:G,"작성중"),COUNTIFS('세부(구축)'!B:B,'집계(구축)'!B37,'세부(구축)'!G:G,"접수대기")) -> 0 | F37: =COUNTIFS('세부(구축)'!J:J,"발행",'세부(구축)'!B:B,'집계(구축)'!B37) -> 0 | G37: =COUNTIFS('세부(구축)'!K:K,"수령",'세부(구축)'!$B:$B,'집계(구축)'!$B37) -> 0 | H37: =COUNTIFS('세부(구축)'!$B:$B,'집계(구축)'!B37,'세부(구축)'!$G:$G,"취소") -> 0
A38: 합 계 | C38: =SUM(D38:E38) -> 29 | D38: =SUM(D16:D37) -> 0 | E38: =SUM(E16:E37) -> 29 | F38: =SUM(F16:F37) -> 0 | G38: =SUM(G16:G37) -> 0 | H38: =SUM(H16:H37) -> 0 | I38: =SUM(I16:I28) -> 0 | J38: =SUM(J16:J28) -> 0 | K38: =SUM(K16:K28) -> 0 | L38: =SUM(L16:L28) -> 0 | M38: =SUM(M16:M28) -> 0 | N38: =SUM(N16:N28) -> 0 | O38: =SUM(O16:O28) -> 0 | P38: =SUM(P16:P28) -> 0 | ... T38: =SUM(T16:T28) -> 0
A40: ○ 사업별 세부 진행현황
A41: 순번 | B41: 사업명 | C41: 업무진행 | F41: 청구 | H41: 취소 | I41: 사업별 구분
C42: 수령건수 (A) | D42: 완료* (B) | E42: 진행중 (C=A-B) | F42: 세금계산서 발행(D) | G42: 대금수령 (E) | I42: (기초 및 고도화지원)농림부-삼성전자 | J42: (기초지원)지자체-삼성전자 | K42: (상생형)고도화-LG이노텍 | L42: (상생형)고도화-LG전자 | M42: (상생형)고도화-삼성전자 | N42: 경남형 스마트 제조혁신 프로젝트 | O42: 선도형 스마트공장(부처협업형) | P42: 스마트공장 AS 지원 | Q42: 스마트공장 구축 및 고도화 사업(고도화1) | R42: 스마트공장 구축 및 고도화 사업(동일수준) | S42: 전북형 스마트 제조혁신 프로젝트 | T42: 탄소중립형 스마트공장
A43: 1 | B43: (기초 및 고도화지원)농림부-삼성전자 | C43: =SUM(D43:E43) -> 0 | D43: =COUNTIFS('세부(구축)'!C:C,'집계(구축)'!B43,'세부(구축)'!G:G,"완료")+H43 -> 0 | E43: =SUM(COUNTIFS('세부(구축)'!C:C,'집계(구축)'!B43,'세부(구축)'!G:G,"작성중"),COUNTIFS('세부(구축)'!C:C,'집계(구축)'!B43,'세부(구축)'!G:G,"접수대기")) -> 0 | F43: =COUNTIFS('세부(구축)'!J:J,"발행",'세부(구축)'!$C:$C,'집계(구축)'!$B43) -> 0 | G43: =COUNTIFS('세부(구축)'!K:K,"수령",'세부(구축)'!$C:$C,'집계(구축)'!$B43) -> 0 | H43: =COUNTIFS('세부(구축)'!$C:$C,'집계(구축)'!B43,'세부(구축)'!$G:$G,"취소") -> 0 | I43: =COUNTIFS('세부(구축)'!B:B,'집계(구축)'!B$16,'세부(구축)'!C:C,'집계(구축)'!$I$15) -> 0 | J43: =COUNTIFS('세부(구축)'!$B:$B,'집계(구축)'!$B$16,'세부(구축)'!$C:$C,'집계(구축)'!J$15) -> 0 | K43: =COUNTIFS('세부(구축)'!$B:$B,'집계(구축)'!$B$16,'세부(구축)'!$C:$C,'집계(구축)'!K$15) -> 0 | L43: =COUNTIFS('세부(구축)'!$B:$B,'집계(구축)'!$B$16,'세부(구축)'!$C:$C,'집계(구축)'!L$15) -> 0 | M43: =COUNTIFS('세부(구축)'!$B:$B,'집계(구축)'!$B$16,'세부(구축)'!$C:$C,'집계(구축)'!M$15) -> 0 | N43: =COUNTIFS('세부(구축)'!$B:$B,'집계(구축)'!$B$16,'세부(구축)'!$C:$C,'집계(구축)'!N$15) -> 0 | O43: =COUNTIFS('세부(구축)'!$B:$B,'집계(구축)'!$B$16,'세부(구축)'!$C:$C,'집계(구축)'!O$15) -> 0 | P43: =COUNTIFS('세부(구축)'!$B:$B,'집계(구축)'!$B$16,'세부(구축)'!$C:$C,'집계(구축)'!P$15) -> 0 | Q43: =COUNTIFS('세부(구축)'!$B:$B,'집계(구축)'!$B$16,'세부(구축)'!$C:$C,'집계(구축)'!Q$15) -> 0 | ... T43: =COUNTIFS('세부(구축)'!$B:$B,'집계(구축)'!$B$16,'세부(구축)'!$C:$C,'집계(구축)'!T$15) -> 0
...

Sheet 수행
A1: 인원별 수행금액 집계표(완료건에 한함)
A3: 순번 | B3: 성명 | C3: 수행건수(건) | D3: 수행금액(원) | E3: 비고
A4: 1 | B4: 하은정 | C4: =COUNTIFS('세부(구축)'!$G:$G,"완료",'세부(구축)'!$L:$L,수행!B4) -> 0 | D4: =C4*300000 -> 0
A5: 2 | B5: 김기태 | C5: =COUNTIFS('세부(구축)'!$G:$G,"완료",'세부(구축)'!$L:$L,수행!B5) -> 0 | D5: =C5*300000 -> 0
A6: 3 | B6: 지승연 | C6: =COUNTIFS('세부(구축)'!$G:$G,"완료",'세부(구축)'!$L:$L,수행!B6) -> 0 | D6: =C6*300000 -> 0
A7: 4 | B7: 김연아 | C7: =COUNTIFS('세부(구축)'!$G:$G,"완료",'세부(구축)'!$L:$L,수행!B7) -> 0 | D7: =C7*300000 -> 0
A8: 5 | B8: 윤세준 | C8: =COUNTIFS('세부(구축)'!$G:$G,"완료",'세부(구축)'!$L:$L,수행!B8) -> 0 | D8: =C8*300000 -> 0
B9: 합계 | C9: =SUM(C4:C8) -> 0 | D9: =SUM(D4:D8) -> 0
A10: 주) 수행금액 : 건당 30만원(부가세 포함)

Sheet 일별현황(구)
A2: 스마트공장 원가계산 업무 일별 현황
A8: 기준일 : | B8: =TODAY() -> 46189 | T8: ☞ 수행기관 추가 시 가나다순으로 추가하세요
A9: 전담기관 | B9: NO. | C9: 수행기관 (담당기관) | D9: 년도별 누계 | J9: 2025년 누계 | O9: 금일 진행사항 | X9: 2023년 세금계산서 발행건수 | Z9: 2025년 세금계산서 | AD9: 2025년 원가재계산 | AE9: 비고
D10: 2020 | E10: 2021 | F10: 2022 제출누계 | G10: 2022 제출완료누계 | H10: 2023 | I10: 2024 | J10: 누계 | K10: 신규 | L10: 진행중 | M10: 제출 | N10: 취소 | O10: 제출완료 | P10: FP검토 | Q10: 단가검색 | R10: 보고서작성 | T10: 제출누계 | U10: 금일 미제출 | V10: 금일 신규 | W10: 반려 | Z10: 발행건수 | AA10: 발행일자 | AB10: 미발행건수 | AC10: 미발행 사유 및 연락현황 | AF10: 숫자포함여부
A11: 스 마 트 제 조 혁 신 추 진 단 | B11: 1 | C11: 강원 | D11: 65 | E11: 23 | F11: 16 | G11: 14 | I11: 4 | J11: =COUNTIF('세부(구축)'!$B:$B,'일별현황(구)'!C11) -> 0 | K11: =COUNTIFS('세부(구축)'!$B:$B,'일별현황(구)'!C11,'세부(구축)'!$H:$H,TODAY()) -> 0 | L11: =COUNTIFS('세부(구축)'!$B:$B,B56,'세부(구축)'!$G:$G,"미완료") -> 0 | M11: =COUNTIFS('세부(구축)'!$B:$B,'일별현황(구)'!$C11,'세부(구축)'!$G:$G,"완료") -> 0 | N11: =COUNTIFS('세부(구축)'!$B:$B,'일별현황(구)'!$C11,'세부(구축)'!$G:$G,"취소") -> 0 | O11: =COUNTIFS('세부(구축)'!$I:$I,$B$8,'세부(구축)'!$B:$B,$C11) -> 0 | P11: =COUNTIFS([1]상세자료!$C$1:$C$3805,'일별현황(구)'!$C11,[1]상세자료!$K$1:$K$3805,"="&$C$8) -> #VALUE! | Q11: =COUNTIFS([1]상세자료!$C$1:$C$3805,'일별현황(구)'!$C11,[1]상세자료!$Q$1:$Q$3805,"="&$C$8) -> #VALUE! | R11: =COUNTIFS([1]상세자료!$C$1:$C$3805,'일별현황(구)'!$C11,[1]상세자료!$S$1:$S$3805,"="&$C$8) -> #VALUE! | S11: =COUNTIFS([1]상세자료!$C$1:$C$3805,'일별현황(구)'!$C11,[1]상세자료!$T$1:$T$3805,"="&$C$8) -> #VALUE! | T11: =M11+S11 -> #VALUE! | V11: =COUNTIFS([1]상세자료!$C$4:$C$973,'일별현황(구)'!$C11,[1]상세자료!$H$4:$H$973,"미제출") -> #VALUE! | W11: =COUNTIFS('세부(구축)'!$B:$B,'일별현황(구)'!$C11,'세부(구축)'!$G:$G,"반려") -> 0 | Z11: =COUNTIFS('세부(구축)'!$B:$B,'일별현황(구)'!$C11,'세부(구축)'!$J:$J,"발행") -> 0 | AA11: 45755 | AB11: =J11-Z11 -> 0 | AF11: =IF(OR(AND(ISNUMBER(K11), K11<>0), AND(ISNUMBER(L11), L11<>0), AND(ISNUMBER(O11), O11<>0)), 1, 0) -> 0
B12: 2 | C12: 경기 | D12: 60 | E12: 101 | F12: 21 | G12: 20 | H12: 1 | I12: 44 | J12: =COUNTIF('세부(구축)'!$B:$B,'일별현황(구)'!C12) -> 0 | K12: =COUNTIFS('세부(구축)'!$B:$B,'일별현황(구)'!C12,'세부(구축)'!$H:$H,TODAY()) -> 0 | L12: =COUNTIFS('세부(구축)'!$B:$B,'일별현황(구)'!$C12,'세부(구축)'!$G:$G,"작성중") -> 0 | M12: =COUNTIFS('세부(구축)'!$B:$B,'일별현황(구)'!$C12,'세부(구축)'!$G:$G,"완료") -> 0 | N12: =COUNTIFS('세부(구축)'!$B:$B,'일별현황(구)'!$C12,'세부(구축)'!$G:$G,"취소") -> 0 | O12: =COUNTIFS('세부(구축)'!$I:$I,$B$8,'세부(구축)'!$B:$B,$C12) -> 0 | P12: =COUNTIFS([1]상세자료!$C$1:$C$3805,'일별현황(구)'!$C12,[1]상세자료!$K$1:$K$3805,"="&$C$8) -> #VALUE! | Q12: =COUNTIFS([1]상세자료!$C$1:$C$3805,'일별현황(구)'!$C12,[1]상세자료!$Q$1:$Q$3805,"="&$C$8) -> #VALUE! | R12: =COUNTIFS([1]상세자료!$C$1:$C$3805,'일별현황(구)'!$C12,[1]상세자료!$S$1:$S$3805,"="&$C$8) -> #VALUE! | S12: =COUNTIFS([1]상세자료!$C$1:$C$3805,'일별현황(구)'!$C12,[1]상세자료!$T$1:$T$3805,"="&$C$8) -> #VALUE! | T12: =M12+S12 -> #VALUE! | V12: =COUNTIFS([1]상세자료!$C$4:$C$973,'일별현황(구)'!$C12,[1]상세자료!$H$4:$H$973,"미제출") -> #VALUE! | W12: =COUNTIFS('세부(구축)'!$B:$B,'일별현황(구)'!$C12,'세부(구축)'!$G:$G,"반려") -> 0 | Z12: =COUNTIFS('세부(구축)'!$B:$B,'일별현황(구)'!$C12,'세부(구축)'!$J:$J,"발행") -> 0 | AB12: =J12-Z12 -> 0 | AF12: =IF(OR(AND(ISNUMBER(K12), K12<>0), AND(ISNUMBER(L12), L12<>0), AND(ISNUMBER(O12), O12<>0)), 1, 0) -> 0
